Workbook

Sheet Sheet2
A1: Nombre | B1: Bp Id | C1: Columna1 | D1: Columna2 | E1: Descripcion | F1: Estado | G1: Prioridad | H1: Ubicacion | I1: Equipo Administrado Por | J1: Dueno Aplicacion | K1: Dueno Negocio | L1: Administrado Por | M1: Categoria Identidades | N1: Tipo Usuario | O1: ¿Existe módulo de gestión de accesos? | P1: Metodo Autenticacion | Q1: Metodo Autorizacion | R1: ¿Cumple criterios de recepción? | S1: Entregada Identidades | T1: Observacion | U1: Fecha Recepcion | V1: Administrador Aplicativo Externo | W1: Administrador Aplicativo Identidades Principal | X1: Administrador Aplicativo Identidades Backup | Y1: Metodo Reporteria Usuarios | Z1: Metodo Reporteria Perfiles Opciones | AA1: Metodo Gestion | AB1: Metodo Baja Usuarios | AC1: Url Acceso
A2: IBM WebSphere Portal | B2: CHL0017 | C2: =sheet1[[#This Row],[Nombre]]&sheet1[[#This Row],[Bp Id]] -> IBM WebSphere PortalCHL0017 | D2: =VLOOKUP(sheet1[[#This Row],[Columna1]],sheet13[[Columna1]:[Estado]],4,FALSE) -> Operativo | E2: IBM Websphere Portal, es el portal web empresarial que ofrece experiencias sociales altamente personalizadas a los usuarios. Brinda a los usuarios un único punto de acceso a las aplicaciones, servicios, información y conexiones sociales que necesiten. El usuario puede acceder de manera directa a aplicaciones como: BancsLink, Administrador de Remesas, Asesores, Balcones, Cardholder, CreditosCom, Riesgo Global, Reclamos y Requerimientos, BPM, Informes Legales. | F2: Operativo | G2: A - Apetito de Riesgo Disponibilidad | H2: On Premise | I2: TRIBU_CANALES | J2: DANIEL PATRICIO PAZ ENRIQUEZ | K2: JORGE HUMBERTO BRAVO YUNDA | L2: Luis Remigio Bayas Rea | M2: Aplicación del negocio | N2: Usuario Interno | O2: Si | P2: Active Directory | Q2: Active Directory | R2: Si | S2: No
A3: IBM WSRR | B3: INT0007 | C3: =sheet1[[#This Row],[Nombre]]&sheet1[[#This Row],[Bp Id]] -> IBM WSRRINT0007 | D3: =VLOOKUP(sheet1[[#This Row],[Columna1]],sheet13[[Columna1]:[Estado]],4,FALSE) -> Retirado | E3: Herramienta que proporciona el registro de servicios y funciones de repositorio para aplicaciones empresariales de arquitectura orientada a servicios (SOA). | F3: Retirado | G3: E - No Crítica | H3: On Premise | I3: Tribu_Integraciones_Apis | J3: DAVID RODRIGO REVELO RIVERA | K3: DIEGO VLADIMIR JAYA GUAMANZARA | L3: DIEGO VLADIMIR JAYA GUAMANZARA | M3: Consolas de Administración TI | N3: Usuario Interno | O3: Si | P3: Propio | Q3: Propio | R3: No | S3: No | T3: EVALUADA, NO CUMPLE CRITERIOS
A4: ICEPanel | B4: ITM0068 | C4: =sheet1[[#This Row],[Nombre]]&sheet1[[#This Row],[Bp Id]] -> ICEPanelITM0068 | D4: =VLOOKUP(sheet1[[#This Row],[Columna1]],sheet13[[Columna1]:[Estado]],4,FALSE) -> Operativo | E4: Modelado de Arquitectura de Soluciones | F4: Operativo | G4: D - BIA No Crítica | H4: Nube | I4: COE ARQUITECTURA | J4: MAURICIO BLADIMIR AUQUI MIRANDA | K4: LUIS MIGUEL ULLOA MOREIRA | L4: LUIS MIGUEL ULLOA MOREIRA | M4: Aplicación complementaria | N4: Usuario Interno | O4: Si | P4: Entra ID | Q4: Entra ID | R4: No | S4: No | T4: EVALUADA, NO CUMPLE CRITERIOS
A5: Idera | B5: ITM0035 | C5: =sheet1[[#This Row],[Nombre]]&sheet1[[#This Row],[Bp Id]] -> IderaITM0035 | D5: =VLOOKUP(sheet1[[#This Row],[Columna1]],sheet13[[Columna1]:[Estado]],4,FALSE) -> Operativo | E5: Es una aplicación para administrar motores SQL, donde se visualiza eventos que ocurran en las bases de datos como en el servidor | F5: Operativo | G5: D - BIA No Crítica | H5: On Premise | I5: INFRAESTRUCTURA | J5: BYRON ORLANDO MELENDREZ CABRERA | K5: NELSON ANDRES POZO YEPEZ | L5: FELIX ALEXANDER MANJARRES QUEZADA | M5: Consolas de Administración TI | N5: Usuario Interno | O5: Si | P5: Propio | Q5: Propio | R5: Si | S5: No | AC5: Conectarse a Idera y sacar los scripts de migración es_x000D_ Test: POECWDB064
A6: IGNITION | B6: ITM0069 | C6: =sheet1[[#This Row],[Nombre]]&sheet1[[#This Row],[Bp Id]] -> IGNITIONITM0069 | D6: =VLOOKUP(sheet1[[#This Row],[Columna1]],sheet13[[Columna1]:[Estado]],4,FALSE) -> Operativo | E6: Monitoreo de las facilidades de los centros de datos, Sistemas Electricos, Enfriamiento, Electrogenos | F6: Operativo | G6: C - BIA Crítica | H6: On Premise | I6: INFRAESTRUCTURA | J6: BYRON ORLANDO MELENDREZ CABRERA | K6: DIEGO JAVIER SALAZAR MOLINA | L6: DIEGO PAUL BETANCOURT REYES | M6: Aplicación complementaria | N6: Usuario Interno | O6: Si | P6: Propio | Q6: Propio | R6: No | S6: No | T6: EVALUADA, NO CUMPLE CRITERIOS
A7: ILMT | B7: ITM0036 | C7: =sheet1[[#This Row],[Nombre]]&sheet1[[#This Row],[Bp Id]] -> ILMTITM0036 | D7: =VLOOKUP(sheet1[[#This Row],[Columna1]],sheet13[[Columna1]:[Estado]],4,FALSE) -> Operativo | E7: Monitoreo de Software IBM instalado en servidores licenciamiento | F7: Operativo | G7: E - No Crítica | H7: On Premise | I7: INFRAESTRUCTURA | J7: BYRON ORLANDO MELENDREZ CABRERA | K7: HORACIO LEONEL HOLGUIN ALCIVAR | L7: FREDDY VINICIO ESTRELLA HIDALGO | M7: Consolas de Administración TI | N7: Usuario Interno | O7: Si | P7: Propio | Q7: Propio | R7: No | S7: No | T7: EVALUADA, NO CUMPLE CRITERIOS
A8: Impacto 360 | B8: DAT0015 | C8: =sheet1[[#This Row],[Nombre]]&sheet1[[#This Row],[Bp Id]] -> Impacto 360DAT0015 | D8: =VLOOKUP(sheet1[[#This Row],[Columna1]],sheet13[[Columna1]:[Estado]],4,FALSE) -> Operativo | E8: la iniciativa es una plataforma de inteligencia empresarial y análisis de mercado con un enfoque específico en los clientes que utilizan medios de pago del Banco Pichincha (tarjetas de crédito, tarjetas de débito y transferencias digitales). Esta plataforma brinda a los empresarios la capacidad de acceder y visualizar información histórica y resumida de estos clientes, permitiéndoles obtener una visión más detallada y específica de su base de clientes y sus comportamientos de pago. | F8: Operativo | G8: E - No Crítica | H8: Nube | I8: Negocios y Monetización | J8: ANTONIO ALEJANDRO CANAVERAL GIL | K8: SEBASTIAN MUNOZ ANDERSEN | L8: HEVER GONZALEZ GARCIA | M8: Aplicación del negocio | N8: Clientes | O8: Si | P8: Entra ID | Q8: Entra ID | R8: No | S8: No | T8: EVALUADA, NO CUMPLE CRITERIOS
A9: Impresion Documentos | B9: TIE0018 | C9: =sheet1[[#This Row],[Nombre]]&sheet1[[#This Row],[Bp Id]] -> Impresion DocumentosTIE0018 | D9: =VLOOKUP(sheet1[[#This Row],[Columna1]],sheet13[[Columna1]:[Estado]],4,FALSE) -> Operativo | E9: Aplicación que permite levantar documentos de word ejecutando macros. Genera documentos entregados a los clientes, principalmente de solicitudes de crédito. | F9: Operativo | G9: E - No Crítica | H9: On Premise | I9: ACTIVOS | J9: LAURA ELIZABETH CARRASCO UQUILLAS | K9: ANDREA FERNANDA ORTIZ CISNEROS | L9: ERISLAN MARTINEZ JERA | M9: Aplicación del negocio | N9: Usuario Interno | O9: Si | P9: Active Directory | Q9: Propio | R9: Si | S9: Si | T9: Se ingresa por Login Central | U9: 45199 | W9: LIVE LOZADA EDGAR ROBERTO | X9: PAREDES NACIPUCHA EDISSON FERNANDO | AA9: AUTORIZACION: PERFIL SIGLO21_x000D_ ASIGNAR GRUPO DE AD: GA_LOGINC_IMPRESION DE DOCUMENTOS | AC9: https://logincentral.bp.bpichincha.com/
A10: Informes de RedTeam | B10: SEC0083 | C10: =sheet1[[#This Row],[Nombre]]&sheet1[[#This Row],[Bp Id]] -> Informes de RedTeamSEC0083 | D10: =VLOOKUP(sheet1[[#This Row],[Columna1]],sheet13[[Columna1]:[Estado]],4,FALSE) -> Retirado | E10: Herramienta permite la generación automatizada de informes a través de plantillas, además de ofrecer un control centralizado de los hallazgos obtenidos durante los ejercicios ofensivos. Versión v4.2.5, released 9 August 2024, con soporte Local. Se adjunta la certificación de software por ciberseguridad para poder ser utilizado en entono Banco. | F10: Retirado | G10: E - No Crítica | H10: Nube | I10: Ciberseguridad | J10: SANTIAGO ANDRES MEDRANDA MOREJON | K10: JOHNATAN SILVA ORREGO | L10: Allan Paul Gomez Ehmig | M10: Consolas de Administración Seguridad | N10: Usuario Interno | O10: Si | P10: Active Directory | Q10: Active Directory | R10: Si | S10: No | T10: Se hizo una revisión con Arq. de Cyberseguridad y se va a replantear la solución para construir esta aplicación sobre la plataforma de sharepoint en vez de usar software libre, por lo que algunos de los criterios de respuesta podrán cambiar.
A11: informesCredito | B11: PRD0021 | C11: =sheet1[[#This Row],[Nombre]]&sheet1[[#This Row],[Bp Id]] -> informesCreditoPRD0021 | D11: =VLOOKUP(sheet1[[#This Row],[Columna1]],sheet13[[Columna1]:[Estado]],4,FALSE) -> Operativo | E11: Aplicación utilizada por las empresas que contratan el servicio para ver referencias bancarias de los clientes del Banco del Pichincha, pueden ver la cantidad de cifras, altas o bajas de sus cuentas, clientes como Dinners, Artefacta, Movistar lo utilizan. Cada consulta de los clientes tiene un costo. | F11: Operativo | G11: E - No Crítica | H11: Nube | I11: Frente de Soluciones Empresariales | J11: LUIS MIGUEL ULLOA MOREIRA | K11: FABRICIO ANTONIO PEREIRA GARCIA | L11: WILLIAM PATRICIO PANCHI SHUGULI | M11: Aplicación del negocio | N11: Usuario Interno | O11: No | P11: Propio | Q11: Propio | R11: Si | S11: Si | T11: SIGLO21 | U11: 45199 | W11: LIVE LOZADA EDGAR ROBERTO | X11: PAREDES NACIPUCHA EDISSON FERNANDO
A12: Integration Bus Soporte | B12: INT0009 | C12: =sheet1[[#This Row],[Nombre]]&sheet1[[#This Row],[Bp Id]] -> Integration Bus SoporteINT0009 | D12: =VLOOKUP(sheet1[[#This Row],[Columna1]],sheet13[[Columna1]:[Estado]],4,FALSE) -> Operativo | E12: Integration Bus permite administrar y monitorear los flujos de integración que conectan múltiples canales digitales y sistemas backend. Facilita la gestión de servicios, procesamiento de mensajes y orquestación de transacciones entre aplicaciones. Es un componente clave para asegurar la operación continua y la integración eficiente en arquitecturas omnicanal. | F12: Operativo | G12: B - Ecosistema Apetito de Riesgo | H12: On Premise | I12: Tribu_Integraciones_Apis | J12: DAVID RODRIGO REVELO RIVERA | K12: DIEGO VLADIMIR JAYA GUAMANZARA | L12: DIEGO VLADIMIR JAYA GUAMANZARA | M12: Consolas de Administración TI | N12: Usuario Interno | O12: Si | P12: Propio | Q12: Propio | R12: Si | S12: Si | U12: 46197 | V12: ESTRELLA HIDALGO FREDDY VINICIO | W12: FLORES YAGUANA JHONATAN DAMIAN | X12: RAMOS SALAZAR SEBASTIAN MATEO | Y12: Manual | Z12: Manual | AA12: Ingresar al nodo (servidor Unix) correspondiente mediante Cyberark utilizando el usuario root y ejecutar los comandos detallados en el instructivo para administrar usuarios | AB12: Eliminar | AC12: APLICACIÓN HOSTNAME IP_x000D_ Integration Bus Soporte Nodo1 PRECBPIB01 10.151.152.221_x000D_ Integration Bus Soporte Nodo2 PRECBPIB02 10.151.152.222_x000D_ Integration Bus Soporte Cash 1 PRECBPIB10 10.151.152.227_x000D_ Integration Bus Soporte Cash 2 PRECBPIB11 10.151.152.226
A13: Interaction Studio | B13: CUS0010 | C13: =sheet1[[#This Row],[Nombre]]&sheet1[[#This Row],[Bp Id]] -> Interaction StudioCUS0010 | D13: =VLOOKUP(sheet1[[#This Row],[Columna1]],sheet13[[Columna1]:[Estado]],4,FALSE) -> Retirado | E13: Es una herramienta de Salesforce Marketing Cloud que aprende de los datos de manera automática para lograr identificar las siguientes mejores ofertas y/o acciones para cada cliente | F13: Retirado | G13: E - No Crítica | H13: Nube | I13: Negocios Digitales (Campañas y Marketing Digital) | J13: ANTONIO ALEJANDRO CANAVERAL GIL | K13: IVANNA MARIA ZAUZICH POSADA | L13: FREDDY LEONARDO ABAD LEON | M13: Aplicación complementaria | N13: Usuario Interno | O13: Si | P13: Propio | Q13: Propio | R13: No | S13: No | T13: EVALUADA, NO CUMPLE CRITERIOS
A14: Interdin AS400 Gestor | B14: PAY0008 | C14: =sheet1[[#This Row],[Nombre]]&sheet1[[#This Row],[Bp Id]] -> Interdin AS400 GestorPAY0008 | D14: =VLOOKUP(sheet1[[#This Row],[Columna1]],sheet13[[Columna1]:[Estado]],4,FALSE) -> Retirado | E14: No existe descripción | F14: Retirado | G14: C - BIA Crítica | H14: Terceros | I14: MEDIOS_DE_PAGO | J14: DIEGO MANUEL CARRERA BENAVIDES | K14: KATHERINE FATIMA CJURO VERA | L14: JEAN ANEL PROANO FALCONES | M14: Aplicación del negocio | N14: Usuario Interno | O14: No | P14: Propio | Q14: Propio | R14: No | S14: No | T14: REPORTERIA: CORREO A EXTERNO LUEGO SUBIR A GEMA | U14: 45200 | W14: PAREDES NACIPUCHA EDISSON FERNANDO | X14: ALVARADO RAMOS OLGER OSWALDO | Y14: ETL | Z14: ETL | AA14: CREAR TICKET | AB14: Eliminar
A15: Interdin Autorizador CAO | B15: PAY0009 | C15: =sheet1[[#This Row],[Nombre]]&sheet1[[#This Row],[Bp Id]] -> Interdin Autorizador CAOPAY0009 | D15: =VLOOKUP(sheet1[[#This Row],[Columna1]],sheet13[[Columna1]:[Estado]],4,FALSE) -> Retirado | E15: No existe descripción | F15: Retirado | G15: C - BIA Crítica | H15: Terceros | I15: MEDIOS_DE_PAGO | J15: EDWIN GEOVANNY FLORES CASTRO | K15: KATHERINE FATIMA CJURO VERA | L15: JEAN ANEL PROANO FALCONES | M15: Aplicación del negocio | N15: Usuario Interno | O15: No | P15: Propio | Q15: Propio | R15: No | S15: No | T15: CREAR TICKET A INTERDIN PARA SOLICITAR REPORTES DE USUARIO Y PERFILES | U15: 45200 | W15: PAREDES NACIPUCHA EDISSON FERNANDO | X15: ALVARADO RAMOS OLGER OSWALDO | Y15: ETL | Z15: ETL | AA15: CREAR TICKET | AB15: Eliminar
A16: Interdin AS 400/ CAO | B16: PAY0010 | C16: =sheet1[[#This Row],[Nombre]]&sheet1[[#This Row],[Bp Id]] -> Interdin AS 400/ CAOPAY0010 | D16: =VLOOKUP(sheet1[[#This Row],[Columna1]],sheet13[[Columna1]:[Estado]],4,FALSE) -> Operativo | E16: No existe descripción | F16: Operativo | G16: C - BIA Crítica | H16: Terceros | I16: MEDIOS_DE_PAGO | J16: EDWIN GEOVANNY FLORES CASTRO | K16: KATHERINE FATIMA CJURO VERA | L16: JEAN ANEL PROANO FALCONES | M16: Aplicación del negocio | N16: Usuario Interno | O16: Si | P16: Propio | Q16: Propio | R16: Si | S16: Si | T16: PIVI/CAO | U16: 45199 | W16: PAREDES NACIPUCHA EDISSON FERNANDO | X16: ALVARADO RAMOS OLGER OSWALDO
A17: Interdin Servicios Integración | B17: PAY0011 | C17: =sheet1[[#This Row],[Nombre]]&sheet1[[#This Row],[Bp Id]] -> Interdin Servicios IntegraciónPAY0011 | D17: =VLOOKUP(sheet1[[#This Row],[Columna1]],sheet13[[Columna1]:[Estado]],4,FALSE) -> Operativo | E17: INTERDIN SERVICIOS INTEGRACION comprende dos servidores que fueron creados para _x000D_ relacionar servicios de Interdin (Proveedor). | F17: Operativo | G17: B - Ecosistema Apetito de Riesgo | H17: Terceros | I17: MEDIOS_DE_PAGO | J17: EDWIN GEOVANNY FLORES CASTRO | K17: WILLIAM RICHARD CORREA JIMENEZ | L17: DAVID DE JESUS BELLO NIEVES | M17: Componente | N17: Usuario Interno | O17: No | P17: Propio | Q17: Propio | R17: No | S17: No | T17: EVALUADO: NO APLICA RECEPCION_x000D_ Descripción del aplicativo: _x000D_ o INTERDIN SERVICIOS INTEGRACION comprende dos servidores que fueron creados para _x000D_ relacionar servicios de Interdin (Proveedor)._x000D_ o En base al documento ¿BPECU-SEG-044-STD - Estándar de Recepción de Módulos de _x000D_ Gestión de Accesos y Perfiles V 2.1-¿; donde se definen uno de los criterios para recepción _x000D_ es contar con un módulo de gestión de accesos y perfiles. _x000D_ _x000D_ o En la reunión mantenida el jueves 20 de noviembre 2025 en conjunto con el equipo _x000D_ administrador del aplicativo, se concluyó que: ¿Interdin Servicios Integración no es una _x000D_ aplicación, son dos servidores que están relacionados a la aplicación de manera _x000D_ incorrecta. No cuenta con módulo de gestión de usuarios ni perfiles, por lo cual no aplica _x000D_ realizar un proceso de recepción¿. Adicional, se tuvieron las siguientes observaciones: _x000D_ _x000D_ o Edwin Geovanny Flores Castro - LIDER TECNICO DE TRIBU menciona: ¿Más adelante _x000D_ procederé a decomisarla cuando apague los servidores¿, de acuerdo con el correo con _x000D_ asunto: Re: Solicitud entrega del aplicativo a Gestión de Identidades: INTERDIN SERVICIOS _x000D_ INTEGRACION, con fecha 20 de noviembre de 2025. _x000D_ _x000D_ o Se realiza la consulta sobre la fecha de apagado y si existe alguna aplicación en su _x000D_ reemplazo, a lo que Edwin Geovanny Flores Castro - LIDER TECNICO DE TRIBU menciona: _x000D_ ¿Aún no tengo esa información. De momento esta aplicación no es prioritaria para la _x000D_ tribu¿._x000D_ o En referencia a la gestión de usuarios y perfiles: Edwin Geovanny Flores Castro - LIDER _x000D_ TECNICO DE TRIBU menciona: ¿la aplicación en mención no tiene roles ni usuarios¿. | U17: 45981 | V17: FLORES CASTRO EDWIN GEOVANNY
A18: Inversiones | B18: PRD0060 | C18: =sheet1[[#This Row],[Nombre]]&sheet1[[#This Row],[Bp Id]] -> InversionesPRD0060 | D18: =VLOOKUP(sheet1[[#This Row],[Columna1]],sheet13[[Columna1]:[Estado]],4,FALSE) -> Operativo | E18: Aplicacion para venta y postventa de Inversiones. | F18: Operativo | G18: E - No Crítica | H18: Nube | I18: PASIVOS Y SEGUROS | J18: LAURA ELIZABETH CARRASCO UQUILLAS | K18: JONATHAN HERNAN ARIAS HERNANDEZ | L18: MANUEL ABELARDO HARO MONTERO | M18: Aplicación del negocio | N18: Clientes | O18: No | P18: Entra ID | Q18: Entra ID | R18: No | S18: No | T18: Detalle del criterio de recepción:_x000D_ _x000D_ o En base al documento ¿BPECU-SEG-044-STD - Estándar de Recepción de Módulos de Gestión de Accesos y Perfiles V 2.1-¿; donde se definen uno de los criterios para recepción es contar con un módulo de gestión de accesos y perfiles. _x000D_ _x000D_ o En la reunión mantenida el lunes 24 de marzo de 2026 en conjunto con el equipo administrador del aplicativo, se concluyó que: que la aplicación no cuenta con un módulo para la gestión de accesos._x000D_ _x000D_ o Loaiza Armijos Mayi Dayali - EXPERTO PORTAFOLIO PRODUCTOS Y SERVICIOS Nos informa _x000D_ que el acceso es a través de la banca web y va dirigido a clientes finales. _x000D_ _x000D_ o Cabe mencionar que el acceso al módulo de Inversiones dentro del Portal de la Banca Web _x000D_ es de autogestión; es decir, lo realiza directamente el cliente final sin la intervención de _x000D_ ningún asesor. | U18: 46107 | V18: CARRASCO UQUILLAS LAURA ELIZABETH
A19: IPS Intrusion Prevention System | B19: SEC0025 | C19: =sheet1[[#This Row],[Nombre]]&sheet1[[#This Row],[Bp Id]] -> IPS Intrusion Prevention SystemSEC0025 | D19: =VLOOKUP(sheet1[[#This Row],[Columna1]],sheet13[[Columna1]:[Estado]],4,FALSE) -> Operativo | E19: Cisco Firepower Management Center 4600 | F19: Operativo | G19: C - BIA Crítica | H19: On Premise | I19: Ciberseguridad | J19: ERICK DAMIAN RISUENO BENITEZ | K19: MARCO FABRICIO FALCONI NORIEGA | L19: JORGE XAVIER LUCERO GALLEGOS | M19: Consolas de Administración Seguridad | N19: Usuario Interno | O19: Si | P19: Active Directory | Q19: Propio | R19: Si | S19: Si | U19: 45929 | V19: RISUENO BENITEZ ERICK DAMIAN | W19: ZAMBRANO NUNEZ PAUL SANTIAGO | X19: RAMOS SALAZAR SEBASTIAN MATEO | Y19: Manual | Z19: Manual | AA19: GESTIONAR EN LA APLICACION USUARIOS Y ROLES | AC19: Cybeark: _x000D_ https://10.70.88.105/
A20: ISE | B20: SEC0026 | C20: =sheet1[[#This Row],[Nombre]]&sheet1[[#This Row],[Bp Id]] -> ISESEC0026 | D20: =VLOOKUP(sheet1[[#This Row],[Columna1]],sheet13[[Columna1]:[Estado]],4,FALSE) -> Operativo | E20: CONTROL DE ACCESO A LA RED | F20: Operativo | G20: C - BIA Crítica | H20: On Premise | I20: Ciberseguridad | J20: JORGE XAVIER LUCERO GALLEGOS | K20: MARCO FABRICIO FALCONI NORIEGA | L20: ROBERT STALIN SOTO CORONEL | M20: Consolas de Administración Seguridad | N20: Usuario Interno | O20: Si | P20: Active Directory | Q20: Active Directory | R20: Si | S20: Si | U20: 45772 | V20: LUCERO GALLEGOS JORGE XAVIER | W20: BARAHONA ESPINOSA SANTIAGO ISRAEL | X20: BARAHONA ESPINOSA SANTIAGO ISRAEL | Y20: Manual | Z20: Manual | AA20: Generar un ticket en el flujo: "Gestión de Acceso a la Red"; junto con la autorización de Jorge Lucero | AB20: Eliminar | AC20: Cyberark: 10.70.88.110
A21: Jaguar Liquidez Plus | B21: PRD0022 | C21: =sheet1[[#This Row],[Nombre]]&sheet1[[#This Row],[Bp Id]] -> Jaguar Liquidez PlusPRD0022 | D21: =VLOOKUP(sheet1[[#This Row],[Columna1]],sheet13[[Columna1]:[Estado]],4,FALSE) -> Retirado | E21: En portafolio | F21: Retirado | G21: E - No Crítica | H21: Nube | I21: Frente de Soluciones Empresariales | J21: LUIS MIGUEL ULLOA MOREIRA | K21: FABRICIO ANTONIO PEREIRA GARCIA | L21: WILLIAM PATRICIO PANCHI SHUGULI | M21: Aplicación del negocio | N21: Usuario Interno | O21: No | P21: Entra ID | Q21: Entra ID | R21: Si | S21: No | T21: ADMINISTRACION ELIMINADA | AA21: Crear un ticket
A22: Jenkins | B22: ITM0037 | C22: =sheet1[[#This Row],[Nombre]]&sheet1[[#This Row],[Bp Id]] -> JenkinsITM0037 | D22: =VLOOKUP(sheet1[[#This Row],[Columna1]],sheet13[[Columna1]:[Estado]],4,FALSE) -> Retirado | E22: Herramienta de integración continua, utilizado por el proyecto de Omnicanalidad. | F22: Retirado | G22: E - No Crítica | H22: On Premise | I22: COE de Ingeniería | J22: GERMAN MARTIN GUTIERREZ | K22: GERMAN MARTIN GUTIERREZ | L22: GERMAN MARTIN GUTIERREZ | M22: Consolas de Administración TI | N22: Usuario Interno | O22: Si | P22: Propio | Q22: Propio | R22: No | S22: No | T22: EVALUADA, NO CUMPLE CRITERIOS
A23: Kafka | B23: OMN0004 | C23: =sheet1[[#This Row],[Nombre]]&sheet1[[#This Row],[Bp Id]] -> KafkaOMN0004 | D23: =VLOOKUP(sheet1[[#This Row],[Columna1]],sheet13[[Columna1]:[Estado]],4,FALSE) -> Operativo | E23: Basado en una transmisión de evetos,captura datos en tiempo real desde varias fuentes, enruta los flujos de datos a diferentes tecnologías de destino según sea necesario. | F23: Operativo | G23: B - Ecosistema Apetito de Riesgo | H23: On Premise | I23: Tribu_Integraciones_Apis | J23: DAVID RODRIGO REVELO RIVERA | K23: DIEGO VLADIMIR JAYA GUAMANZARA | L23: DIEGO VLADIMIR JAYA GUAMANZARA | M23: Consolas de Administración TI | N23: Usuario Interno | O23: No | P23: Propio | Q23: Propio | R23: No | S23: No | T23: EVALUADO_x000D_ Descripción del aplicativo: _x000D_ o Es una plataforma basada en una transmisión de eventos, captura datos en tiempo real _x000D_ desde varias fuentes, enruta los flujos de datos a diferentes tecnologías de destino según _x000D_ sea necesario._x000D_ Detalle del criterio de recepción: _x000D_ o En base al documento ¿BPECU-SEG-044-STD - Estándar de Recepción de Módulos de _x000D_ Gestión de Accesos y Perfiles V 2.1-¿; donde se definen uno de los criterios para recepción _x000D_ es contar con un módulo de gestión de accesos y perfiles. _x000D_ o Sin embargo: luego de la reunión del 2025/11/24 vía Teams con el equipo administrador _x000D_ del aplicativo informa que Kafka no cuenta con un módulo para la gestión de usuarios y _x000D_ perfiles. | U23: 45986 | V23: VALLEJO SOLORZANO OSCAR DAVID
A24: Kafka Deuna | B24: INT0014 | C24: =sheet1[[#This Row],[Nombre]]&sheet1[[#This Row],[Bp Id]] -> Kafka DeunaINT0014 | D24: =VLOOKUP(sheet1[[#This Row],[Columna1]],sheet13[[Columna1]:[Estado]],4,FALSE) -> Retirado | E24: Broker de eventos de Deuna desplegado en AWS | F24: Retirado | G24: D - BIA No Crítica | H24: Nube | I24: TRIBU_DE_UNA | J24: LUIS JAVIER MARIDUENA NOVILLO | K24: LUIS JAVIER MARIDUENA NOVILLO | L24: LUIS JAVIER MARIDUENA NOVILLO | M24: Consolas de Administración TI | N24: Usuario Interno | O24: Si | P24: Entra ID | Q24: Entra ID | R24: Si | S24: No
A25: Keeper Security | B25: SEC0053 | C25: =sheet1[[#This Row],[Nombre]]&sheet1[[#This Row],[Bp Id]] -> Keeper SecuritySEC0053 | D25: =VLOOKUP(sheet1[[#This Row],[Columna1]],sheet13[[Columna1]:[Estado]],4,FALSE) -> Operativo | E25: Solución para la gestión de contraseñas de los usuarios | F25: Operativo | G25: E - No Crítica | H25: Nube | I25: Ciberseguridad | J25: lvtandaz@pichincha.com TANDAZO GALLEGOS | K25: MARCO FABRICIO FALCONI NORIEGA | L25: ISRAEL SEBASTIAN DE LA TORRE TRUJILLO | M25: Consolas de Administración Seguridad | N25: Usuario Interno | O25: Si | P25: Entra ID | Q25: Entra ID | R25: Si | S25: No
A26: Kriptos | B26: SEC0055 | C26: =sheet1[[#This Row],[Nombre]]&sheet1[[#This Row],[Bp Id]] -> KriptosSEC0055 | D26: =VLOOKUP(sheet1[[#This Row],[Columna1]],sheet13[[Columna1]:[Estado]],4,FALSE) -> Operativo | E26: Solución basada en clasificación artificial que tiene la capacidad de identificar y clasificar los datos de la empresa. | F26: Operativo | G26: E - No Crítica | H26: Nube | I26: Ciberseguridad | J26: FERNANDO JAVIER PALADINES BUSTAMANTE | K26: MARCO FABRICIO FALCONI NORIEGA | L26: MARIA DEL CARMEN PENAHERRERA PLUA | M26: Consolas de Administración Seguridad | N26: Usuario Interno | O26: No | P26: Entra ID | Q26: Entra ID | R26: No | S26: No | T26: Detalle del criterio de recepción:_x000D_ _x000D_ o En base al documento ¿BPECU-SEG-044-STD - Estándar de Recepción de Módulos de Gestión de Accesos y Perfiles V 2.1-¿; donde se definen uno de los criterios para recepción es contar con un módulo de gestión de accesos y perfiles. _x000D_ _x000D_ o En la reunión mantenida el lunes 23 de marzo de 2026 en conjunto con el equipo administrador del aplicativo, se concluyó que: que la aplicación no cuenta con un módulo para la gestión de accesos. | U26: 46104 | V26: VIDAL BARBA GABRIELA VIRGINIA | AA26: Vidal Barba Gabriela Virginia- EXPERTO PLATAFORMAS CIBERSEGURIDAD: Nos informa que el acceso es a través de la asignación de grupos de Azure AD de nomenclatura: GSC_KRIPTOS_XXX, no existen usuarios locales.
A27: Fielweb | B27: SUP0011 | C27: =sheet1[[#This Row],[Nombre]]&sheet1[[#This Row],[Bp Id]] -> FielwebSUP0011 | D27: =VLOOKUP(sheet1[[#This Row],[Columna1]],sheet13[[Columna1]:[Estado]],4,FALSE) -> #N/A | E27: No existe descripción | F27: Operativo | G27: E - No Crítica | H27: Terceros | I27: AREAS_DE_APOYO | J27: FABIAN GEOVANNI PAZMINO UBIDIA | K27: JOSE LUIS ZAPATA ROSERO | L27: FERNANDO JOSE ROLDAN CORREA | M27: Aplicación complementaria | N27: Usuario Interno | O27: Si | P27: Propio | Q27: Propio | R27: No | S27: No | T27: EVALUADA, NO CUMPLE CRITERIOS
A28: LEXMARK CLOUD PRINT MANAGEMENT (CPM) | B28: ITM0038 | C28: =sheet1[[#This Row],[Nombre]]&sheet1[[#This Row],[Bp Id]] -> LEXMARK CLOUD PRINT MANAGEMENT (CPM)ITM0038 | D28: =VLOOKUP(sheet1[[#This Row],[Columna1]],sheet13[[Columna1]:[Estado]],4,FALSE) -> Operativo | E28: Administración Multifunción Lexmark para Integración multifuncionales con Talla Impresión | F28: Operativo | G28: E - No Crítica | H28: Nube | I28: Gerencia Arquitectura Usuario Final | J28: AMPARO MARIANA CARDENAS HUILCA | K28: ABNER ANDY AREVALO BRACAMONTE | L28: ABNER ANDY AREVALO BRACAMONTE | M28: Aplicación complementaria | N28: Usuario Interno | O28: Si | P28: Propio | Q28: Propio | R28: No | S28: No | T28: EVALUADA, NO CUMPLE CRITERIOS
A29: Lexmark Printer Management | B29: ITM0038 | C29: =sheet1[[#This Row],[Nombre]]&sheet1[[#This Row],[Bp Id]] -> Lexmark Printer ManagementITM0038 | D29: =VLOOKUP(sheet1[[#This Row],[Columna1]],sheet13[[Columna1]:[Estado]],4,FALSE) -> Retirado | E29: Administración Multifunción Lexmark para Integración multifuncionales con Talla Impresión | F29: Retirado | G29: E - No Crítica | H29: On Premise | I29: INFRAESTRUCTURA | J29: JOSE LUIS GOYES LARA | L29: ABNER ANDY AREVALO BRACAMONTE | M29: Aplicación complementaria | N29: Usuario Interno | O29: Si | P29: Propio | Q29: Propio | R29: No | S29: No | T29: EVALUADA, NO CUMPLE CRITERIOS
A30: Librarian | B30: ITM0071 | C30: =sheet1[[#This Row],[Nombre]]&sheet1[[#This Row],[Bp Id]] -> LibrarianITM0071 | D30: =VLOOKUP(sheet1[[#This Row],[Columna1]],sheet13[[Columna1]:[Estado]],4,FALSE) -> Retirado | E30: Aplicación de equipo Librarian | F30: Retirado | G30: E - No Crítica | H30: On Premise | I30: COE de Ingeniería | J30: GUILLERMO GABRIEL DEPRATI | K30: DIEGO PAUL AREVALO COSTALES | L30: FERNANDO VINICIO OCHOA CARRION | M30: Consolas de Administración TI | N30: Usuario Interno | O30: Si | P30: Propio | Q30: Propio | R30: No | S30: No | T30: EVALUADA, NO CUMPLE CRITERIOS
A31: ListaObservados | B31: GOB0013 | C31: =sheet1[[#This Row],[Nombre]]&sheet1[[#This Row],[Bp Id]] -> ListaObservadosGOB0013 | D31: =VLOOKUP(sheet1[[#This Row],[Columna1]],sheet13[[Columna1]:[Estado]],4,FALSE) -> Operativo | E31: Es una aplicación que permite la validación de clientes en listas de validación utilizando componentes de terceros (Bridger). | F31: Operativo | G31: B - Ecosistema Apetito de Riesgo | H31: Nube | I31: AREAS_DE_APOYO | J31: FABIAN GEOVANNI PAZMINO UBIDIA | K31: JOSE LUIS ZAPATA ROSERO | L31: FERNANDO JOSE ROLDAN CORREA | M31: Aplicación del negocio | N31: Usuario Interno | O31: Si | P31: PPRD - SIGLO21 | Q31: Siglo 21 | R31: Si | S31: No
A32: LogiFlow | B32: TIE0019 | C32: =sheet1[[#This Row],[Nombre]]&sheet1[[#This Row],[Bp Id]] -> LogiFlowTIE0019 | D32: =VLOOKUP(sheet1[[#This Row],[Columna1]],sheet13[[Columna1]:[Estado]],4,FALSE) -> Operativo | E32: Portal de aplicaciones para la gestión y administracion de procesos del Banco. | F32: Operativo | G32: C - BIA Crítica | H32: On Premise | I32: ACTIVOS | J32: LAURA ELIZABETH CARRASCO UQUILLAS | K32: ANDREA FERNANDA ORTIZ CISNEROS | L32: ERISLAN MARTINEZ JERA | M32: Aplicación del negocio | N32: Usuario Interno | O32: Si | P32: Active Directory | Q32: Propio | R32: Si | S32: Si | U32: 45200 | V32: CISNEROS MANOSALVAS EDGAR NAPOLEON | W32: MEJIA MANZANO ROMEO OCTAVIO | X32: TERAN PIEDRA DAYANARA ABIGAIL | Y32: ETL | Z32: ETL | AA32: GESTIONAR EN LA APLICACION USUARIOS Y ROLES | AB32: Eliminar | AC32: https://flujoempresaslan.uio.bpichincha.com:8046/Pichincha/WebLogiPortal/
A33: LoginCentral | B33: SEC0028 | C33: =sheet1[[#This Row],[Nombre]]&sheet1[[#This Row],[Bp Id]] -> LoginCentralSEC0028 | D33: =VLOOKUP(sheet1[[#This Row],[Columna1]],sheet13[[Columna1]:[Estado]],4,FALSE) -> Operativo | E33: Aplicación que reemplaza al Portal Empresarial respecto al tema de ingreso a las aplicaciones portalizadas, por esta aplicación permite el logueo a todas las aplicaciones portalizadas que dispone BP, el Login Central consume el serbvicio de WsConexioLdap, pose conexión con una BD de datos BD_TALOS y consume servicios del Process Server. | F33: Operativo | G33: B - Ecosistema Apetito de Riesgo | H33: On Premise | I33: Tribu Ciberseguridad | J33: JUAN FELIPE GALLEGO COSSIO | K33: FRANCISCO DAVID CEVALLOS GRANJA | L33: ROBERTO CARLOS PINO CEDENO | M33: Aplicación del negocio | N33: Usuario Interno | O33: Si | P33: Active Directory | Q33: Active Directory | R33: Si | S33: Si | U33: 45200 | W33: FLORES YAGUANA JHONATAN DAMIAN | X33: AUQUILLA CHINCHIN GLADYS ARACELI | Y33: ETL | Z33: ETL | AA33: GRUPOS AD | AB33: Eliminar | AC33: https://logincentral.bp.bpichincha.com/loginCentralizado/loginCentralizado
A34: Logística de Efectivo | B34: CHL0001 | C34: =sheet1[[#This Row],[Nombre]]&sheet1[[#This Row],[Bp Id]] -> Logística de EfectivoCHL0001 | D34: =VLOOKUP(sheet1[[#This Row],[Columna1]],sheet13[[Columna1]:[Estado]],4,FALSE) -> Operativo | E34: Aplicación que permite controlar el pedido de remesas de efectivo desde las agencias a los centros de acopio. Permite administrar en forma adecuada el proceso de Gestión de Logística de Efectivo y Valorados, desde el registro de la recepción de la solicitud, procesamiento, envío y contabilización de remesas en los centros de acopio, ATM¿s, agencias o sucursales y Banco Central. | F34: Operativo | G34: C - BIA Crítica | H34: On Premise | I34: AREAS_DE_APOYO | J34: FABIAN GEOVANNI PAZMINO UBIDIA | K34: PRISCILA ALEXANDRA PARRA LEON | L34: PRISCILA ALEXANDRA PARRA LEON | M34: Aplicación del negocio | N34: Usuario Interno | O34: Si | P34: Active Directory | Q34: Propio | R34: Si | S34: Si | T34: SIGLO21 | U34: 45199 | W34: LIVE LOZADA EDGAR ROBERTO | X34: PAREDES NACIPUCHA EDISSON FERNANDO
A35: Lumu | B35: SEC0056 | C35: =sheet1[[#This Row],[Nombre]]&sheet1[[#This Row],[Bp Id]] -> LumuSEC0056 | D35: =VLOOKUP(sheet1[[#This Row],[Columna1]],sheet13[[Columna1]:[Estado]],4,FALSE) -> Retirado | E35: Aplicación ciberseguridad que ofrece visibilidad y respuesta a amenazas en tiempo real. | F35: Retirado | G35: E - No Crítica | H35: Nube | I35: Ciberseguridad | J35: GABRIELA VIRGINIA VIDAL BARBA | K35: MARCO FABRICIO FALCONI NORIEGA | L35: lvtandaz@pichincha.com TANDAZO GALLEGOS | M35: Consolas de Administración Seguridad | N35: Usuario Interno | O35: Si | P35: Entra ID | Q35: Entra ID | R35: Si | S35: No
A36: Mail Control System | B36: SUP0012 | C36: =sheet1[[#This Row],[Nombre]]&sheet1[[#This Row],[Bp Id]] -> Mail Control SystemSUP0012 | D36: =VLOOKUP(sheet1[[#This Row],[Columna1]],sheet13[[Columna1]:[Estado]],4,FALSE) -> Operativo | E36: Aplicación utilizada por el área Administrativa para gestionar el proceso de entrega y recepción de correspondencia interna. | F36: Operativo | G36: E - No Crítica | H36: Nube | I36: AREAS_DE_APOYO | J36: FABIAN GEOVANNI PAZMINO UBIDIA | K36: LIZETH AURORA ENCALADA RAMON | L36: ABRAHAM JOSUE MOGOLLON VASQUEZ | M36: Aplicación del negocio | N36: Usuario Interno | O36: No | P36: Entra ID | Q36: Entra ID | R36: Si | S36: No | T36: Realizar la recepción: está planificada_x000D_ Detalle del criterio de recepción:_x000D_ _x000D_ o En base al documento ¿BPECU-SEG-044-STD - Estándar de Recepción de Módulos de Gestión de Accesos y Perfiles V 2.1-¿; donde se definen uno de los criterios para recepción es contar con un módulo de gestión de accesos y perfiles._x000D_ _x000D_ o Luego de una reunión mantenida con el equipo administrador del aplicativo se recibió _x000D_ mediante email el día 11 de marzo de 2026 que la aplicación no cuenta con un módulo _x000D_ para la gestión de accesos. Adicional se tuvieron las siguientes observaciones:_x000D_ _x000D_ o Muzzillo Gustavo - INGENIERO INFRAESTRUCTURA TI menciona que Mail Control System: _x000D_ "no posee un módulo de gestión de Usuarios y Permisos, encontrándose estas funciones delegadas al IDP (EntraID) apoyándose en las herramientas MyAccess y MySessions para la gestión de permisos y claves de usuario respectivamente", de acuerdo con el correo con asunto: RE: Solicitud entrega del aplicativo a Gestión de Identidades: Mail Control System, con fecha 11 de marzo de 2026. | U36: 46092 | V36: MUZZILLO GUSTAVO
A37: Mambu | B37: COR0008 | C37: =sheet1[[#This Row],[Nombre]]&sheet1[[#This Row],[Bp Id]] -> MambuCOR0008 | D37: =VLOOKUP(sheet1[[#This Row],[Columna1]],sheet13[[Columna1]:[Estado]],4,FALSE) -> Retirado | E37: No existe descripción | F37: Retirado | G37: E - No Crítica | H37: Nube | I37: Tribu_Integraciones_Apis | J37: DAVID RODRIGO REVELO RIVERA | K37: GILBERT ADRIAN CISNEROS TELLO | L37: GILBERT ADRIAN CISNEROS TELLO | M37: Aplicación del negocio | N37: Usuario Interno | O37: Si | P37: Entra ID | Q37: Entra ID | R37: Si | S37: No
A38: Mambu Deuna | B38: SEC0057 | C38: =sheet1[[#This Row],[Nombre]]&sheet1[[#This Row],[Bp Id]] -> Mambu DeunaSEC0057 | D38: =VLOOKUP(sheet1[[#This Row],[Columna1]],sheet13[[Columna1]:[Estado]],4,FALSE) -> Retirado | E38: Core bancario de uso exlclusivo para Deuna | F38: Retirado | G38: A - Apetito de Riesgo Disponibilidad | H38: Nube | I38: TRIBU_DE_UNA | J38: LUIS JAVIER MARIDUENA NOVILLO | K38: LUIS JAVIER MARIDUENA NOVILLO | L38: LUIS JAVIER MARIDUENA NOVILLO | M38: Aplicación del negocio | N38: Usuario Interno | O38: Si | P38: Entra ID | Q38: Entra ID | R38: Si | S38: No
A39: MatiBOT | B39: ITM0075 | C39: =sheet1[[#This Row],[Nombre]]&sheet1[[#This Row],[Bp Id]] -> MatiBOTITM0075 | D39: =VLOOKUP(sheet1[[#This Row],[Columna1]],sheet13[[Columna1]:[Estado]],4,FALSE) -> Operativo | E39: Brindar a los usuarios la capacidad de realizar solicitudes a través de una interfaz de chat en diversos canales conversacionales, como Microsoft Teams, Web Chat o WhatsApp. | F39: Operativo | G39: E - No Crítica | H39: Nube | I39: Gerencia Arquitectura Usuario Final | J39: FAYOL SMITH MONTANO MELENDEZ | K39: ABNER ANDY AREVALO BRACAMONTE | L39: CARMEN ROCIO AGUILAR MAYANQUER | M39: Aplicación complementaria | N39: Usuario Interno | O39: Si | P39: Entra ID | Q39: Propio | R39: No | S39: No | T39: EVALUADA, NO CUMPLE CRITERIOS
A40: Maze | B40: EDC0006 | C40: =sheet1[[#This Row],[Nombre]]&sheet1[[#This Row],[Bp Id]] -> MazeEDC0006 | D40: =VLOOKUP(sheet1[[#This Row],[Columna1]],sheet13[[Columna1]:[Estado]],4,FALSE) -> Operativo | E40: Herramienta de pruebas con usuarios de prototipos y encuestas masivas moderadas y no moderadas. | F40: Operativo | G40: E - No Crítica | H40: Nube | I40: COE Experiencia | J40: ANTONIO ALEJANDRO CANAVERAL GIL | K40: GABRIEL ANDRES PACHECO TELLO | L40: GABRIEL ANDRES PACHECO TELLO | M40: Utilitario | N40: Usuario Interno | O40: Si | P40: Propio | Q40: Propio | R40: No | S40: No | T40: EVALUADA, NO CUMPLE CRITERIOS
...

Sheet Sheet1
A1: Nombre | B1: Bp Id | C1: Columna1 | D1: Columna2 | E1: Descripcion | F1: Estado | G1: Prioridad | H1: Ubicacion | I1: Equipo Administrado Por | J1: Dueno Aplicacion | K1: Dueno Negocio | L1: Administrado Por | M1: Categoria Identidades | N1: Criterio de inclusion | O1: Tipo Usuario | P1: ¿Existe módulo de gestión de accesos? | Q1: Metodo Autenticacion | R1: Metodo Autorizacion | S1: ¿Cumple criterios de recepción? | T1: Fase | U1: Entregada Identidades | V1: Observacion | W1: Fecha Recepcion | X1: Administrador Aplicativo Externo | Y1: Administrador Aplicativo Identidades Principal | Z1: Administrador Aplicativo Identidades Backup | AA1: Metodo Reporteria Usuarios | AB1: Metodo Reporteria Perfiles Opciones | AC1: Metodo Gestion | AD1: Metodo Baja Usuarios | AE1: Url Acceso
A2: IBM WebSphere Portal | B2: CHL0017 | C2: =sheet13[[#This Row],[Nombre]]&sheet13[[#This Row],[Bp Id]] -> IBM WebSphere PortalCHL0017 | D2: =VLOOKUP(sheet13[[#This Row],[Columna1]],Sheet2!C:S,4,FALSE) -> Operativo | E2: IBM Websphere Portal, es el portal web empresarial que ofrece experiencias sociales altamente personalizadas a los usuarios. Brinda a los usuarios un único punto de acceso a las aplicaciones, servicios, información y conexiones sociales que necesiten. El usuario puede acceder de manera directa a aplicaciones como: BancsLink, Administrador de Remesas, Asesores, Balcones, Cardholder, CreditosCom, Riesgo Global, Reclamos y Requerimientos, BPM, Informes Legales. | F2: Operativo | G2: A - Apetito de Riesgo Disponibilidad | H2: On Premise | I2: TRIBU_CANALES | J2: DANIEL PATRICIO PAZ ENRIQUEZ | K2: JORGE HUMBERTO BRAVO YUNDA | L2: Luis Remigio Bayas Rea | M2: Aplicación del negocio | N2: SI | O2: Usuario Interno | P2: Si | Q2: Active Directory | R2: Active Directory | S2: Si | T2: FASE 0 | U2: No
A3: IBM WSRR | B3: INT0007 | C3: =sheet13[[#This Row],[Nombre]]&sheet13[[#This Row],[Bp Id]] -> IBM WSRRINT0007 | D3: =VLOOKUP(sheet13[[#This Row],[Columna1]],Sheet2!C:S,4,FALSE) -> Retirado | E3: Herramienta que proporciona el registro de servicios y funciones de repositorio para aplicaciones empresariales de arquitectura orientada a servicios (SOA). | F3: Retirado | G3: E - No Crítica | H3: On Premise | I3: Tribu_Integraciones_Apis | J3: DAVID RODRIGO REVELO RIVERA | K3: DIEGO VLADIMIR JAYA GUAMANZARA | L3: DIEGO VLADIMIR JAYA GUAMANZARA | M3: Consolas de Administración TI | N3: NO | O3: Usuario Interno | P3: Si | Q3: Propio | R3: Propio | S3: No | U3: No | V3: EVALUADA, NO CUMPLE CRITERIOS
A4: ICEPanel | B4: ITM0068 | C4: =sheet13[[#This Row],[Nombre]]&sheet13[[#This Row],[Bp Id]] -> ICEPanelITM0068 | D4: =VLOOKUP(sheet13[[#This Row],[Columna1]],Sheet2!C:S,4,FALSE) -> Operativo | E4: Modelado de Arquitectura de Soluciones | F4: Operativo | G4: D - BIA No Crítica | H4: Nube | I4: COE ARQUITECTURA | J4: MAURICIO BLADIMIR AUQUI MIRANDA | K4: LUIS MIGUEL ULLOA MOREIRA | L4: LUIS MIGUEL ULLOA MOREIRA | M4: Aplicación complementaria | N4: SI | O4: Usuario Interno | P4: Si | Q4: Entra ID | R4: Entra ID | S4: No | T4: FASE 0 | U4: No | V4: EVALUADA, NO CUMPLE CRITERIOS
A5: Idera | B5: ITM0035 | C5: =sheet13[[#This Row],[Nombre]]&sheet13[[#This Row],[Bp Id]] -> IderaITM0035 | D5: =VLOOKUP(sheet13[[#This Row],[Columna1]],Sheet2!C:S,4,FALSE) -> Operativo | E5: Es una aplicación para administrar motores SQL, donde se visualiza eventos que ocurran en las bases de datos como en el servidor | F5: Operativo | G5: D - BIA No Crítica | H5: On Premise | I5: INFRAESTRUCTURA | J5: BYRON ORLANDO MELENDREZ CABRERA | K5: NELSON ANDRES POZO YEPEZ | L5: FELIX ALEXANDER MANJARRES QUEZADA | M5: Consolas de Administración TI | N5: SI | O5: Usuario Interno | P5: Si | Q5: Propio | R5: Propio | S5: Si | T5: FASE 0 | U5: No | AE5: Conectarse a Idera y sacar los scripts de migración es_x000D_ Test: POECWDB064
A6: IGNITION | B6: ITM0069 | C6: =sheet13[[#This Row],[Nombre]]&sheet13[[#This Row],[Bp Id]] -> IGNITIONITM0069 | D6: =VLOOKUP(sheet13[[#This Row],[Columna1]],Sheet2!C:S,4,FALSE) -> Operativo | E6: Monitoreo de las facilidades de los centros de datos, Sistemas Electricos, Enfriamiento, Electrogenos | F6: Operativo | G6: C - BIA Crítica | H6: On Premise | I6: INFRAESTRUCTURA | J6: BYRON ORLANDO MELENDREZ CABRERA | K6: DIEGO JAVIER SALAZAR MOLINA | L6: DIEGO PAUL BETANCOURT REYES | M6: Aplicación complementaria | N6: SI | O6: Usuario Interno | P6: Si | Q6: Propio | R6: Propio | S6: No | T6: FASE 0 | U6: No | V6: EVALUADA, NO CUMPLE CRITERIOS
A7: ILMT | B7: ITM0036 | C7: =sheet13[[#This Row],[Nombre]]&sheet13[[#This Row],[Bp Id]] -> ILMTITM0036 | D7: =VLOOKUP(sheet13[[#This Row],[Columna1]],Sheet2!C:S,4,FALSE) -> Operativo | E7: Monitoreo de Software IBM instalado en servidores licenciamiento | F7: Operativo | G7: E - No Crítica | H7: On Premise | I7: INFRAESTRUCTURA | J7: BYRON ORLANDO MELENDREZ CABRERA | K7: HORACIO LEONEL HOLGUIN ALCIVAR | L7: FREDDY VINICIO ESTRELLA HIDALGO | M7: Consolas de Administración TI | N7: SI | O7: Usuario Interno | P7: Si | Q7: Propio | R7: Propio | S7: No | T7: FASE 0 | U7: No | V7: EVALUADA, NO CUMPLE CRITERIOS
A8: Impacto 360 | B8: DAT0015 | C8: =sheet13[[#This Row],[Nombre]]&sheet13[[#This Row],[Bp Id]] -> Impacto 360DAT0015 | D8: =VLOOKUP(sheet13[[#This Row],[Columna1]],Sheet2!C:S,4,FALSE) -> Operativo | E8: la iniciativa es una plataforma de inteligencia empresarial y análisis de mercado con un enfoque específico en los clientes que utilizan medios de pago del Banco Pichincha (tarjetas de crédito, tarjetas de débito y transferencias digitales). Esta plataforma brinda a los empresarios la capacidad de acceder y visualizar información histórica y resumida de estos clientes, permitiéndoles obtener una visión más detallada y específica de su base de clientes y sus comportamientos de pago. | F8: Operativo | G8: E - No Crítica | H8: Nube | I8: Negocios y Monetización | J8: ANTONIO ALEJANDRO CANAVERAL GIL | K8: SEBASTIAN MUNOZ ANDERSEN | L8: HEVER GONZALEZ GARCIA | M8: Aplicación del negocio | N8: NO | O8: Clientes | P8: Si | Q8: Entra ID | R8: Entra ID | S8: No | U8: No | V8: EVALUADA, NO CUMPLE CRITERIOS
A9: Impresion Documentos | B9: TIE0018 | C9: =sheet13[[#This Row],[Nombre]]&sheet13[[#This Row],[Bp Id]] -> Impresion DocumentosTIE0018 | D9: =VLOOKUP(sheet13[[#This Row],[Columna1]],Sheet2!C:S,4,FALSE) -> Operativo | E9: Aplicación que permite levantar documentos de word ejecutando macros. Genera documentos entregados a los clientes, principalmente de solicitudes de crédito. | F9: Operativo | G9: E - No Crítica | H9: On Premise | I9: ACTIVOS | J9: LAURA ELIZABETH CARRASCO UQUILLAS | K9: ANDREA FERNANDA ORTIZ CISNEROS | L9: ERISLAN MARTINEZ JERA | M9: Aplicación del negocio | N9: SI | O9: Usuario Interno | P9: Si | Q9: Active Directory | R9: Propio | S9: Si | U9: Si | V9: Se ingresa por Login Central | W9: 45199 | AC9: AUTORIZACION: PERFIL SIGLO21_x000D_ ASIGNAR GRUPO DE AD: GA_LOGINC_IMPRESION DE DOCUMENTOS | AE9: https://logincentral.bp.bpichincha.com/
A10: Informes de RedTeam | B10: SEC0083 | C10: =sheet13[[#This Row],[Nombre]]&sheet13[[#This Row],[Bp Id]] -> Informes de RedTeamSEC0083 | D10: =VLOOKUP(sheet13[[#This Row],[Columna1]],Sheet2!C:S,4,FALSE) -> Retirado | E10: Herramienta permite la generación automatizada de informes a través de plantillas, además de ofrecer un control centralizado de los hallazgos obtenidos durante los ejercicios ofensivos. Versión v4.2.5, released 9 August 2024, con soporte Local. Se adjunta la certificación de software por ciberseguridad para poder ser utilizado en entono Banco. | F10: Retirado | G10: E - No Crítica | H10: Nube | I10: COE_SEGURIDAD | J10: SANTIAGO ANDRES MEDRANDA MOREJON | K10: JOHNATAN SILVA ORREGO | L10: Allan Paul Gomez Ehmig | M10: Consolas de Administración Seguridad | N10: NO | O10: Usuario Interno | P10: Si | Q10: Active Directory | R10: Active Directory | S10: Si | U10: No | V10: Se hizo una revisión con Arq. de Cyberseguridad y se va a replantear la solución para construir esta aplicación sobre la plataforma de sharepoint en vez de usar software libre, por lo que algunos de los criterios de respuesta podrán cambiar.
A11: informesCredito | B11: PRD0021 | C11: =sheet13[[#This Row],[Nombre]]&sheet13[[#This Row],[Bp Id]] -> informesCreditoPRD0021 | D11: =VLOOKUP(sheet13[[#This Row],[Columna1]],Sheet2!C:S,4,FALSE) -> Operativo | E11: Aplicación utilizada por las empresas que contratan el servicio para ver referencias bancarias de los clientes del Banco del Pichincha, pueden ver la cantidad de cifras, altas o bajas de sus cuentas, clientes como Dinners, Artefacta, Movistar lo utilizan. Cada consulta de los clientes tiene un costo. | F11: Operativo | G11: E - No Crítica | H11: Nube | I11: Frente de Soluciones Empresariales | J11: LUIS MIGUEL ULLOA MOREIRA | K11: FABRICIO ANTONIO PEREIRA GARCIA | L11: WILLIAM PATRICIO PANCHI SHUGULI | M11: Aplicación del negocio | N11: SI | O11: Usuario Interno | P11: No | Q11: Propio | R11: Propio | S11: Si | U11: Si | V11: SIGLO21 | W11: 45199
A12: Integration Bus Soporte | B12: INT0009 | C12: =sheet13[[#This Row],[Nombre]]&sheet13[[#This Row],[Bp Id]] -> Integration Bus SoporteINT0009 | D12: =VLOOKUP(sheet13[[#This Row],[Columna1]],Sheet2!C:S,4,FALSE) -> Operativo | E12: Integration Bus permite administrar y monitorear los flujos de integración que conectan múltiples canales digitales y sistemas backend. Facilita la gestión de servicios, procesamiento de mensajes y orquestación de transacciones entre aplicaciones. Es un componente clave para asegurar la operación continua y la integración eficiente en arquitecturas omnicanal. | F12: Operativo | G12: B - Ecosistema Apetito de Riesgo | H12: On Premise | I12: Tribu_Integraciones_Apis | J12: DAVID RODRIGO REVELO RIVERA | K12: DIEGO VLADIMIR JAYA GUAMANZARA | L12: DIEGO VLADIMIR JAYA GUAMANZARA | M12: Consolas de Administración TI | N12: SI | O12: Usuario Interno | P12: Si | Q12: Propio | R12: Propio | S12: Si | U12: Si | W12: 46197 | X12: ESTRELLA HIDALGO FREDDY VINICIO | Y12: FLORES YAGUANA JHONATAN DAMIAN | Z12: RAMOS SALAZAR SEBASTIAN MATEO | AA12: Manual | AB12: Manual | AC12: Ingresar al nodo (servidor Unix) correspondiente mediante Cyberark utilizando el usuario root y ejecutar los comandos detallados en el instructivo para administrar usuarios | AD12: Eliminar | AE12: APLICACIÓN HOSTNAME IP_x000D_ Integration Bus Soporte Nodo1 PRECBPIB01 10.151.152.221_x000D_ Integration Bus Soporte Nodo2 PRECBPIB02 10.151.152.222_x000D_ Integration Bus Soporte Cash 1 PRECBPIB10 10.151.152.227_x000D_ Integration Bus Soporte Cash 2 PRECBPIB11 10.151.152.226
A13: Interaction Studio | B13: CUS0010 | C13: =sheet13[[#This Row],[Nombre]]&sheet13[[#This Row],[Bp Id]] -> Interaction StudioCUS0010 | D13: =VLOOKUP(sheet13[[#This Row],[Columna1]],Sheet2!C:S,4,FALSE) -> Retirado | E13: Es una herramienta de Salesforce Marketing Cloud que aprende de los datos de manera automática para lograr identificar las siguientes mejores ofertas y/o acciones para cada cliente | F13: Retirado | G13: E - No Crítica | H13: Nube | I13: Negocios Digitales (Campañas y Marketing Digital) | J13: ANTONIO ALEJANDRO CANAVERAL GIL | K13: IVANNA MARIA ZAUZICH POSADA | L13: FREDDY LEONARDO ABAD LEON | M13: Aplicación complementaria | N13: NO | O13: Usuario Interno | P13: Si | Q13: Propio | R13: Propio | S13: No | U13: No | V13: EVALUADA, NO CUMPLE CRITERIOS
A14: Interdin AS400 Gestor | B14: PAY0008 | C14: =sheet13[[#This Row],[Nombre]]&sheet13[[#This Row],[Bp Id]] -> Interdin AS400 GestorPAY0008 | D14: =VLOOKUP(sheet13[[#This Row],[Columna1]],Sheet2!C:S,4,FALSE) -> Retirado | E14: No existe descripción | F14: Retirado | G14: C - BIA Crítica | H14: Terceros | I14: MEDIOS_DE_PAGO | J14: DIEGO MANUEL CARRERA BENAVIDES | K14: KATHERINE FATIMA CJURO VERA | L14: JEAN ANEL PROANO FALCONES | M14: Aplicación del negocio | N14: NO | O14: Usuario Interno | P14: No | Q14: Propio | R14: Propio | S14: No | U14: No | V14: REPORTERIA: CORREO A EXTERNO LUEGO SUBIR A GEMA | W14: 45200 | Y14: PAREDES NACIPUCHA EDISSON FERNANDO | Z14: ALVARADO RAMOS OLGER OSWALDO | AA14: ETL | AB14: ETL | AC14: CREAR TICKET | AD14: Eliminar
A15: Interdin Autorizador CAO | B15: PAY0009 | C15: =sheet13[[#This Row],[Nombre]]&sheet13[[#This Row],[Bp Id]] -> Interdin Autorizador CAOPAY0009 | D15: =VLOOKUP(sheet13[[#This Row],[Columna1]],Sheet2!C:S,4,FALSE) -> Retirado | E15: No existe descripción | F15: Retirado | G15: C - BIA Crítica | H15: Terceros | I15: MEDIOS_DE_PAGO | J15: DIEGO MANUEL CARRERA BENAVIDES | K15: ELIANA ESTEFANIA CARRION ALVARADO | L15: JEAN ANEL PROANO FALCONES | M15: Aplicación del negocio | N15: NO | O15: Usuario Interno | P15: No | Q15: Propio | R15: Propio | S15: No | U15: No | V15: CREAR TICKET A INTERDIN PARA SOLICITAR REPORTES DE USUARIO Y PERFILES | W15: 45200 | Y15: PAREDES NACIPUCHA EDISSON FERNANDO | Z15: ALVARADO RAMOS OLGER OSWALDO | AA15: ETL | AB15: ETL | AC15: CREAR TICKET | AD15: Eliminar
A16: Interdin AS 400/ CAO | B16: PAY0010 | C16: =sheet13[[#This Row],[Nombre]]&sheet13[[#This Row],[Bp Id]] -> Interdin AS 400/ CAOPAY0010 | D16: =VLOOKUP(sheet13[[#This Row],[Columna1]],Sheet2!C:S,4,FALSE) -> Operativo | E16: No existe descripción | F16: Operativo | G16: C - BIA Crítica | H16: Terceros | I16: MEDIOS_DE_PAGO | J16: EDWIN GEOVANNY FLORES CASTRO | K16: KATHERINE FATIMA CJURO VERA | L16: JEAN ANEL PROANO FALCONES | M16: Aplicación del negocio | N16: SI | O16: Usuario Interno | P16: Si | Q16: Propio | R16: Propio | S16: Si | U16: Si | V16: PIVI/CAO | W16: 45199
A17: Interdin Servicios Integración | B17: PAY0011 | C17: =sheet13[[#This Row],[Nombre]]&sheet13[[#This Row],[Bp Id]] -> Interdin Servicios IntegraciónPAY0011 | D17: =VLOOKUP(sheet13[[#This Row],[Columna1]],Sheet2!C:S,4,FALSE) -> Operativo | E17: INTERDIN SERVICIOS INTEGRACION comprende dos servidores que fueron creados para _x000D_ relacionar servicios de Interdin (Proveedor). | F17: Operativo | G17: B - Ecosistema Apetito de Riesgo | H17: Terceros | I17: MEDIOS_DE_PAGO | J17: EDWIN GEOVANNY FLORES CASTRO | K17: WILLIAM RICHARD CORREA JIMENEZ | L17: DAVID DE JESUS BELLO NIEVES | M17: Componente | N17: NO | O17: Usuario Interno | P17: No | Q17: Propio | R17: Propio | S17: No | U17: No | V17: EVALUADO: NO APLICA RECEPCION_x000D_ Descripción del aplicativo: _x000D_ o INTERDIN SERVICIOS INTEGRACION comprende dos servidores que fueron creados para _x000D_ relacionar servicios de Interdin (Proveedor)._x000D_ o En base al documento ¿BPECU-SEG-044-STD - Estándar de Recepción de Módulos de _x000D_ Gestión de Accesos y Perfiles V 2.1-¿; donde se definen uno de los criterios para recepción _x000D_ es contar con un módulo de gestión de accesos y perfiles. _x000D_ _x000D_ o En la reunión mantenida el jueves 20 de noviembre 2025 en conjunto con el equipo _x000D_ administrador del aplicativo, se concluyó que: ¿Interdin Servicios Integración no es una _x000D_ aplicación, son dos servidores que están relacionados a la aplicación de manera _x000D_ incorrecta. No cuenta con módulo de gestión de usuarios ni perfiles, por lo cual no aplica _x000D_ realizar un proceso de recepción¿. Adicional, se tuvieron las siguientes observaciones: _x000D_ _x000D_ o Edwin Geovanny Flores Castro - LIDER TECNICO DE TRIBU menciona: ¿Más adelante _x000D_ procederé a decomisarla cuando apague los servidores¿, de acuerdo con el correo con _x000D_ asunto: Re: Solicitud entrega del aplicativo a Gestión de Identidades: INTERDIN SERVICIOS _x000D_ INTEGRACION, con fecha 20 de noviembre de 2025. _x000D_ _x000D_ o Se realiza la consulta sobre la fecha de apagado y si existe alguna aplicación en su _x000D_ reemplazo, a lo que Edwin Geovanny Flores Castro - LIDER TECNICO DE TRIBU menciona: _x000D_ ¿Aún no tengo esa información. De momento esta aplicación no es prioritaria para la _x000D_ tribu¿._x000D_ o En referencia a la gestión de usuarios y perfiles: Edwin Geovanny Flores Castro - LIDER _x000D_ TECNICO DE TRIBU menciona: ¿la aplicación en mención no tiene roles ni usuarios¿. | W17: 45981 | X17: FLORES CASTRO EDWIN GEOVANNY
A18: Inversiones | B18: PRD0060 | C18: =sheet13[[#This Row],[Nombre]]&sheet13[[#This Row],[Bp Id]] -> InversionesPRD0060 | D18: =VLOOKUP(sheet13[[#This Row],[Columna1]],Sheet2!C:S,4,FALSE) -> Operativo | E18: Aplicacion para venta y postventa de Inversiones. | F18: Operativo | G18: E - No Crítica | H18: Nube | I18: PASIVOS Y SEGUROS | J18: LAURA ELIZABETH CARRASCO UQUILLAS | K18: JONATHAN HERNAN ARIAS HERNANDEZ | L18: MANUEL ABELARDO HARO MONTERO | M18: Aplicación del negocio | N18: NO | O18: Clientes | P18: No | Q18: Entra ID | R18: Entra ID | S18: No | U18: No | V18: Detalle del criterio de recepción:_x000D_ _x000D_ o En base al documento ¿BPECU-SEG-044-STD - Estándar de Recepción de Módulos de Gestión de Accesos y Perfiles V 2.1-¿; donde se definen uno de los criterios para recepción es contar con un módulo de gestión de accesos y perfiles. _x000D_ _x000D_ o En la reunión mantenida el lunes 24 de marzo de 2026 en conjunto con el equipo administrador del aplicativo, se concluyó que: que la aplicación no cuenta con un módulo para la gestión de accesos._x000D_ _x000D_ o Loaiza Armijos Mayi Dayali - EXPERTO PORTAFOLIO PRODUCTOS Y SERVICIOS Nos informa _x000D_ que el acceso es a través de la banca web y va dirigido a clientes finales. _x000D_ _x000D_ o Cabe mencionar que el acceso al módulo de Inversiones dentro del Portal de la Banca Web _x000D_ es de autogestión; es decir, lo realiza directamente el cliente final sin la intervención de _x000D_ ningún asesor. | W18: 46107 | X18: CARRASCO UQUILLAS LAURA ELIZABETH
A19: IPS Intrusion Prevention System | B19: SEC0025 | C19: =sheet13[[#This Row],[Nombre]]&sheet13[[#This Row],[Bp Id]] -> IPS Intrusion Prevention SystemSEC0025 | D19: =VLOOKUP(sheet13[[#This Row],[Columna1]],Sheet2!C:S,4,FALSE) -> Operativo | E19: Cisco Firepower Management Center 4600 | F19: Operativo | G19: C - BIA Crítica | H19: On Premise | I19: Plataformas Ciberseguridad | J19: ERICK DAMIAN RISUENO BENITEZ | K19: MARCO FABRICIO FALCONI NORIEGA | L19: JORGE XAVIER LUCERO GALLEGOS | M19: Consolas de Administración Seguridad | N19: SI | O19: Usuario Interno | P19: Si | Q19: Active Directory | R19: Propio | S19: Si | U19: Si | W19: 45929 | X19: RISUENO BENITEZ ERICK DAMIAN | Y19: ZAMBRANO NUNEZ PAUL SANTIAGO | Z19: RAMOS SALAZAR SEBASTIAN MATEO | AA19: Manual | AB19: Manual | AC19: GESTIONAR EN LA APLICACION USUARIOS Y ROLES | AE19: Cybeark: _x000D_ https://10.70.88.105/
A20: ISE | B20: SEC0026 | C20: =sheet13[[#This Row],[Nombre]]&sheet13[[#This Row],[Bp Id]] -> ISESEC0026 | D20: =VLOOKUP(sheet13[[#This Row],[Columna1]],Sheet2!C:S,4,FALSE) -> Operativo | E20: CONTROL DE ACCESO A LA RED | F20: Operativo | G20: C - BIA Crítica | H20: On Premise | I20: Plataformas Ciberseguridad | J20: JORGE XAVIER LUCERO GALLEGOS | K20: MARCO FABRICIO FALCONI NORIEGA | L20: ROBERT STALIN SOTO CORONEL | M20: Consolas de Administración Seguridad | N20: SI | O20: Usuario Interno | P20: Si | Q20: Active Directory | R20: Active Directory | S20: Si | U20: Si | W20: 45772 | X20: LUCERO GALLEGOS JORGE XAVIER | Y20: ALVARADO BORJA JORGE ESTEBAN | Z20: BARAHONA ESPINOSA SANTIAGO ISRAEL | AA20: Manual | AB20: Manual | AC20: Generar un ticket en el flujo: "Gestión de Acceso a la Red"; junto con la autorización de Jorge Lucero | AD20: Eliminar | AE20: Cyberark: 10.70.88.110
A21: Jaguar Liquidez Plus | B21: PRD0022 | C21: =sheet13[[#This Row],[Nombre]]&sheet13[[#This Row],[Bp Id]] -> Jaguar Liquidez PlusPRD0022 | D21: =VLOOKUP(sheet13[[#This Row],[Columna1]],Sheet2!C:S,4,FALSE) -> Retirado | E21: En portafolio | F21: Retirado | G21: E - No Crítica | H21: Nube | I21: Frente de Soluciones Empresariales | J21: LUIS MIGUEL ULLOA MOREIRA | K21: FABRICIO ANTONIO PEREIRA GARCIA | L21: WILLIAM PATRICIO PANCHI SHUGULI | M21: Aplicación del negocio | N21: NO | O21: Usuario Interno | P21: No | Q21: Entra ID | R21: Entra ID | S21: Si | U21: No | V21: ADMINISTRACION ELIMINADA | AC21: Crear un ticket
A22: Jenkins | B22: ITM0037 | C22: =sheet13[[#This Row],[Nombre]]&sheet13[[#This Row],[Bp Id]] -> JenkinsITM0037 | D22: =VLOOKUP(sheet13[[#This Row],[Columna1]],Sheet2!C:S,4,FALSE) -> Retirado | E22: Herramienta de integración continua, utilizado por el proyecto de Omnicanalidad. | F22: Retirado | G22: E - No Crítica | H22: On Premise | I22: COE de Ingeniería | J22: GERMAN MARTIN GUTIERREZ | K22: GERMAN MARTIN GUTIERREZ | L22: GERMAN MARTIN GUTIERREZ | M22: Consolas de Administración TI | N22: NO | O22: Usuario Interno | P22: Si | Q22: Propio | R22: Propio | S22: No | U22: No | V22: EVALUADA, NO CUMPLE CRITERIOS
A23: Kafka | B23: OMN0004 | C23: =sheet13[[#This Row],[Nombre]]&sheet13[[#This Row],[Bp Id]] -> KafkaOMN0004 | D23: =VLOOKUP(sheet13[[#This Row],[Columna1]],Sheet2!C:S,4,FALSE) -> Operativo | E23: Basado en una transmisión de evetos,captura datos en tiempo real desde varias fuentes, enruta los flujos de datos a diferentes tecnologías de destino según sea necesario. | F23: Operativo | G23: B - Ecosistema Apetito de Riesgo | H23: On Premise | I23: Tribu_Integraciones_Apis | J23: DAVID RODRIGO REVELO RIVERA | K23: DIEGO VLADIMIR JAYA GUAMANZARA | L23: DIEGO VLADIMIR JAYA GUAMANZARA | M23: Consolas de Administración TI | N23: SI | O23: Usuario Interno | P23: No | Q23: Propio | R23: Propio | S23: No | T23: FASE 0 | U23: No | V23: EVALUADO_x000D_ Descripción del aplicativo: _x000D_ o Es una plataforma basada en una transmisión de eventos, captura datos en tiempo real _x000D_ desde varias fuentes, enruta los flujos de datos a diferentes tecnologías de destino según _x000D_ sea necesario._x000D_ Detalle del criterio de recepción: _x000D_ o En base al documento ¿BPECU-SEG-044-STD - Estándar de Recepción de Módulos de _x000D_ Gestión de Accesos y Perfiles V 2.1-¿; donde se definen uno de los criterios para recepción _x000D_ es contar con un módulo de gestión de accesos y perfiles. _x000D_ o Sin embargo: luego de la reunión del 2025/11/24 vía Teams con el equipo administrador _x000D_ del aplicativo informa que Kafka no cuenta con un módulo para la gestión de usuarios y _x000D_ perfiles. | W23: 45986 | X23: VALLEJO SOLORZANO OSCAR DAVID
A24: Kafka Deuna | B24: INT0014 | C24: =sheet13[[#This Row],[Nombre]]&sheet13[[#This Row],[Bp Id]] -> Kafka DeunaINT0014 | D24: =VLOOKUP(sheet13[[#This Row],[Columna1]],Sheet2!C:S,4,FALSE) -> Retirado | E24: Broker de eventos de Deuna desplegado en AWS | F24: Retirado | G24: D - BIA No Crítica | H24: Nube | I24: TRIBU_DE_UNA | J24: LUIS JAVIER MARIDUENA NOVILLO | K24: LUIS JAVIER MARIDUENA NOVILLO | L24: LUIS JAVIER MARIDUENA NOVILLO | M24: Consolas de Administración TI | N24: NO | O24: Usuario Interno | P24: Si | Q24: Entra ID | R24: Entra ID | S24: Si | U24: No
A25: Keeper Security | B25: SEC0053 | C25: =sheet13[[#This Row],[Nombre]]&sheet13[[#This Row],[Bp Id]] -> Keeper SecuritySEC0053 | D25: =VLOOKUP(sheet13[[#This Row],[Columna1]],Sheet2!C:S,4,FALSE) -> Operativo | E25: Solución para la gestión de contraseñas de los usuarios | F25: Operativo | G25: E - No Crítica | H25: Nube | I25: Plataformas Ciberseguridad | J25: LAURA VALERIA TANDAZO GALLEGOS | K25: MARCO FABRICIO FALCONI NORIEGA | L25: ISRAEL SEBASTIAN DE LA TORRE TRUJILLO | M25: Consolas de Administración Seguridad | N25: SI | O25: Usuario Interno | P25: Si | Q25: Entra ID | R25: Entra ID | S25: Si | T25: FASE 0 | U25: No
