Workbook

Sheet Leeme
B2: Modelo Power BI · Portafolio 2026 de Gestión de Identidades
B3: Especificación para replicar en Power BI el dashboard PDF (4 páginas). Fuente: ACTIVIDADES_GI.xlsx, hoja «Actividades GI 2026».
B5: Cómo usar este libro
B6: 1. Parámetros | C6: Hoja «Parametros»: fecha de corte y umbrales. Las celdas amarillas con texto azul son las únicas que se editan. Todo lo demás se recalcula.
B7: 2. Tabla de hechos | C7: Hoja «fHitos»: un registro por hito del plan 2026. Columnas A–L son la copia del origen; M (NIST_Categoria) es la propuesta de mapeo a validar; N en adelante son columnas calculadas con fórmula Excel (su equivalente DAX está en «Columnas_DAX»).
B8: 3. Dimensiones | C8: dFrente (Actividad → Frente, editable), dNIST (categorías CSF 2.0), dEstado y dTipo (orden y colores), dCalendario.
B9: 4. Medidas | C9: Hoja «Medidas_DAX»: todas las medidas con carpeta, formato y el visual donde se usan. Se copian a Power BI con «Nueva medida».
B10: 5. Visuales | C10: Hoja «Visuales»: cada visual del dashboard, tipo de visual en Power BI, campos y formato condicional.
B11: 6. Validación | C11: Hoja «Validacion»: KPIs calculados con fórmulas Excel y el valor publicado en el PDF. Si Power BI da otro número, revisar la medida.
B12: 7. Power Query | C12: Hoja «PowerQuery_M»: script para cargar el Excel original y reproducir fHitos dentro de Power BI.
B13: 8. Tema | C13: Hoja «Tema_PowerBI»: JSON con la paleta Banco Pichincha. Guardar como .json e importarlo en Vista > Temas > Examinar temas.
B15: Modelo recomendado
B16: Relaciones | C16: dCalendario[Fecha] 1 → * fHitos[Fecha Fin Planificación] (activa) dCalendario[Fecha] 1 → * fHitos[Fecha Fin] (inactiva, se activa con USERELATIONSHIP en [Cierres Reales]) dFrente[Actividad] 1 → * fHitos[Actividad] dNIST[Codigo] 1 → * fHitos[NIST_Categoria] dEstado[Estado] 1 → * fHitos[Estado] dTipo[Tipo] 1 → * fHitos[Tipo Actividad] Parametros: tabla desconectada de una fila.
B17: Opción A (rápida) | C17: Importar directamente las tablas de este libro (fHitos, dFrente, dNIST, dEstado, dTipo, dCalendario, Parametros). Las columnas calculadas llegan con el valor que Excel calculó: al cambiar la fecha de corte hay que abrir el libro en Excel, guardar y actualizar Power BI.
B18: Opción B (recomendada) | C18: Cargar el Excel original con el script de «PowerQuery_M», importar de este libro solo las dimensiones y la columna NIST_Categoria, y crear las columnas calculadas con el DAX de «Columnas_DAX». La fecha de corte se toma de la tabla Parametros.
B19: Clave de unión | C19: ID = número de fila del hito en la hoja «Actividades GI 2026» (fila Excel − 1). Si se insertan filas en el origen, volver a revisar el mapeo NIST, que va por ID.
B21: Reglas de negocio
B22: Recurrente | C22: Hito con valor en «Frecuencia» (mensual, semestral, diario). Se excluye de avance, SPI y estados.
B23: Avance esperado | C23: (Corte − Fecha Inicio) / (Fecha Fin Planificación − Fecha Inicio), acotado entre 0 y 1.
B24: Estado | C24: Completado: avance = 100%. Vencido: < 100% y fecha plan < corte. Por iniciar: 0% y sin inicio o inicio posterior al corte. En riesgo: avance − esperado ≤ umbral (−25 pts). En plazo: el resto.
B25: SPI | C25: Avance real promedio / avance esperado promedio (hitos no recurrentes). Azul ≥ 0,90; amarillo 0,75–0,89; rojo < 0,75.
B26: Frente | C26: Agrupación de «Actividad» en 10 frentes de trabajo (tabla dFrente, editable).
B27: NIST_Categoria | C27: Propuesta inferida por palabras clave: la columna NIST del Excel original está vacía. Validar con Gobierno CS antes de publicar.
B29: Convención de colores | C29: Texto azul sobre fondo amarillo = dato editable. Texto negro = fórmula. Fondo gris azulado = columna calculada.

Sheet fHitos
A1: ID | B1: Periodo | C1: Actividad | D1: Descripcion_Hitos | E1: Frecuencia | F1: Tipo Actividad | G1: Encargado | H1: Fecha Inicio | I1: Fecha Fin | J1: Fecha Fin Planificación | K1: % avance | L1: Observación | M1: NIST_Categoria | N1: Frente | O1: NIST_Funcion | P1: Lider | Q1: NumEncargados | R1: Recurrente | S1: AvanceEsperado | T1: Brecha | U1: Estado | V1: Abierto | W1: DiasVencido | X1: DiasRestantes | Y1: MesPlan | Z1: MesCierre | AA1: PlanFinDeMes | AB1: FinIgualPlan | AC1: DQ_FinFuturo | AD1: DQ_FinAntesInicio | AE1: EsRegulatorio | AF1: CodigoPMC | AG1: Expuesto
A2: 1 | B2: 2026 | C2: Gestor de Identidades Sailpoint | Fase 1 | D2: Integración con fuente autoritativa de internos Success Factors | Conector nativo | F2: Iniciativa | G2: Ana María Vergara | H2: 45658 | I2: 46087 | J2: 46084 | K2: 1 | M2: PR.AA-01 | N2: =IFERROR(INDEX(dFrente!$B$2:$B$76,MATCH(C2,dFrente!$A$2:$A$76,0)),"Sin frente") -> SailPoint IGA | O2: =IFERROR(INDEX(dNIST!$B$2:$B$13,MATCH(M2,dNIST!$A$2:$A$13,0)),"") -> PR | P2: =TRIM(IFERROR(LEFT(G2,FIND(CHAR(10),G2)-1),G2)) -> Ana María Vergara | Q2: =LEN(TRIM(G2))-LEN(SUBSTITUTE(TRIM(G2),CHAR(10),""))+1 -> 1 | R2: =IF(E2<>"","Sí","No") -> No | S2: =IF(OR(J2="",H2=""),"",IF(J2<=H2,IF(FechaCorte>=J2,1,0),MAX(0,MIN(1,(FechaCorte-H2)/(J2-H2))))) -> 1 | T2: =IF(S2="","",K2-S2) -> 0 | U2: =IF(R2="Sí","Recurrente",IF(K2>=1,"Completado",IF(AND(J2<>"",J2<FechaCorte),"Vencido",IF(AND(K2=0,OR(H2="",H2>FechaCorte)),"Por iniciar",IF(AND(T2<>"",T2<=UmbralRiesgo),"En riesgo","En plazo"))))) -> Completado | V2: =IF(OR(U2="Vencido",U2="En riesgo",U2="En plazo",U2="Por iniciar"),1,0) -> 0 | W2: =IF(U2="Vencido",FechaCorte-J2,"") | X2: =IF(AND(V2=1,U2<>"Vencido"),J2-FechaCorte,"") | Y2: =IF(J2="","",DATE(YEAR(J2),MONTH(J2),1)) -> 46082 | Z2: =IF(AND(U2="Completado",I2<>""),IF(I2<=FechaCorte,DATE(YEAR(I2),MONTH(I2),1),""),"") -> 46082 | AA2: =IF(J2="","",IF(DAY(J2+1)=1,1,0)) -> 0 | AB2: =IF(AND(U2="Completado",I2<>"",I2=J2),1,0) -> 0 | AC2: =IF(AND(K2>=1,I2<>""),IF(I2>FechaCorte,1,0),0) -> 0 | AD2: =IF(AND(I2<>"",H2<>""),IF(I2<H2,1,0),0) -> 0 | AE2: =IF(OR(F2="Riesgos",F2="Obs. Auditoría"),1,0) -> 0 | AF2: =IFERROR(MID(D2,FIND("PMC-",D2),8),"") | AG2: =IF(AND(V2=1,J2<>""),IF(AND(J2>=FechaCorte,J2<=HorizonteExpuestos),1,0),0) -> 0
A3: 2 | B3: 2026 | C3: Gestor de Identidades Sailpoint | Fase 1 | D3: Integración aplicaciones conectadas: AD, EntraID, Bancs, Siglo21, RHDS y Logiflow | F3: Iniciativa | G3: Ana María Vergara | H3: 45658 | I3: 46087 | J3: 46084 | K3: 1 | M3: PR.AA-01 | N3: =IFERROR(INDEX(dFrente!$B$2:$B$76,MATCH(C3,dFrente!$A$2:$A$76,0)),"Sin frente") -> SailPoint IGA | O3: =IFERROR(INDEX(dNIST!$B$2:$B$13,MATCH(M3,dNIST!$A$2:$A$13,0)),"") -> PR | P3: =TRIM(IFERROR(LEFT(G3,FIND(CHAR(10),G3)-1),G3)) -> Ana María Vergara | Q3: =LEN(TRIM(G3))-LEN(SUBSTITUTE(TRIM(G3),CHAR(10),""))+1 -> 1 | R3: =IF(E3<>"","Sí","No") -> No | S3: =IF(OR(J3="",H3=""),"",IF(J3<=H3,IF(FechaCorte>=J3,1,0),MAX(0,MIN(1,(FechaCorte-H3)/(J3-H3))))) -> 1 | T3: =IF(S3="","",K3-S3) -> 0 | U3: =IF(R3="Sí","Recurrente",IF(K3>=1,"Completado",IF(AND(J3<>"",J3<FechaCorte),"Vencido",IF(AND(K3=0,OR(H3="",H3>FechaCorte)),"Por iniciar",IF(AND(T3<>"",T3<=UmbralRiesgo),"En riesgo","En plazo"))))) -> Completado | V3: =IF(OR(U3="Vencido",U3="En riesgo",U3="En plazo",U3="Por iniciar"),1,0) -> 0 | W3: =IF(U3="Vencido",FechaCorte-J3,"") | X3: =IF(AND(V3=1,U3<>"Vencido"),J3-FechaCorte,"") | Y3: =IF(J3="","",DATE(YEAR(J3),MONTH(J3),1)) -> 46082 | Z3: =IF(AND(U3="Completado",I3<>""),IF(I3<=FechaCorte,DATE(YEAR(I3),MONTH(I3),1),""),"") -> 46082 | AA3: =IF(J3="","",IF(DAY(J3+1)=1,1,0)) -> 0 | AB3: =IF(AND(U3="Completado",I3<>"",I3=J3),1,0) -> 0 | AC3: =IF(AND(K3>=1,I3<>""),IF(I3>FechaCorte,1,0),0) -> 0 | AD3: =IF(AND(I3<>"",H3<>""),IF(I3<H3,1,0),0) -> 0 | AE3: =IF(OR(F3="Riesgos",F3="Obs. Auditoría"),1,0) -> 0 | AF3: =IFERROR(MID(D3,FIND("PMC-",D3),8),"") | AG3: =IF(AND(V3=1,J3<>""),IF(AND(J3>=FechaCorte,J3<=HorizonteExpuestos),1,0),0) -> 0
A4: 3 | B4: 2026 | C4: Gestor de Identidades Sailpoint | Fase 1 | D4: Implementación módulo usuarios externos y genéricos NERM | F4: Iniciativa | G4: Ana María Vergara | H4: 45839 | I4: 46087 | J4: 46084 | K4: 1 | M4: PR.AA-01 | N4: =IFERROR(INDEX(dFrente!$B$2:$B$76,MATCH(C4,dFrente!$A$2:$A$76,0)),"Sin frente") -> SailPoint IGA | O4: =IFERROR(INDEX(dNIST!$B$2:$B$13,MATCH(M4,dNIST!$A$2:$A$13,0)),"") -> PR | P4: =TRIM(IFERROR(LEFT(G4,FIND(CHAR(10),G4)-1),G4)) -> Ana María Vergara | Q4: =LEN(TRIM(G4))-LEN(SUBSTITUTE(TRIM(G4),CHAR(10),""))+1 -> 1 | R4: =IF(E4<>"","Sí","No") -> No | S4: =IF(OR(J4="",H4=""),"",IF(J4<=H4,IF(FechaCorte>=J4,1,0),MAX(0,MIN(1,(FechaCorte-H4)/(J4-H4))))) -> 1 | T4: =IF(S4="","",K4-S4) -> 0 | U4: =IF(R4="Sí","Recurrente",IF(K4>=1,"Completado",IF(AND(J4<>"",J4<FechaCorte),"Vencido",IF(AND(K4=0,OR(H4="",H4>FechaCorte)),"Por iniciar",IF(AND(T4<>"",T4<=UmbralRiesgo),"En riesgo","En plazo"))))) -> Completado | V4: =IF(OR(U4="Vencido",U4="En riesgo",U4="En plazo",U4="Por iniciar"),1,0) -> 0 | W4: =IF(U4="Vencido",FechaCorte-J4,"") | X4: =IF(AND(V4=1,U4<>"Vencido"),J4-FechaCorte,"") | Y4: =IF(J4="","",DATE(YEAR(J4),MONTH(J4),1)) -> 46082 | Z4: =IF(AND(U4="Completado",I4<>""),IF(I4<=FechaCorte,DATE(YEAR(I4),MONTH(I4),1),""),"") -> 46082 | AA4: =IF(J4="","",IF(DAY(J4+1)=1,1,0)) -> 0 | AB4: =IF(AND(U4="Completado",I4<>"",I4=J4),1,0) -> 0 | AC4: =IF(AND(K4>=1,I4<>""),IF(I4>FechaCorte,1,0),0) -> 0 | AD4: =IF(AND(I4<>"",H4<>""),IF(I4<H4,1,0),0) -> 0 | AE4: =IF(OR(F4="Riesgos",F4="Obs. Auditoría"),1,0) -> 0 | AF4: =IFERROR(MID(D4,FIND("PMC-",D4),8),"") | AG4: =IF(AND(V4=1,J4<>""),IF(AND(J4>=FechaCorte,J4<=HorizonteExpuestos),1,0),0) -> 0
A5: 4 | B5: 2026 | C5: Gestor de Identidades Sailpoint | Fase 1 | D5: Depuración accesos acorde al cargo Red de Agencias | F5: Iniciativa | G5: Ana María Fierro | H5: 45962 | I5: 46087 | J5: 46087 | K5: 1 | M5: PR.AA-05 | N5: =IFERROR(INDEX(dFrente!$B$2:$B$76,MATCH(C5,dFrente!$A$2:$A$76,0)),"Sin frente") -> SailPoint IGA | O5: =IFERROR(INDEX(dNIST!$B$2:$B$13,MATCH(M5,dNIST!$A$2:$A$13,0)),"") -> PR | P5: =TRIM(IFERROR(LEFT(G5,FIND(CHAR(10),G5)-1),G5)) -> Ana María Fierro | Q5: =LEN(TRIM(G5))-LEN(SUBSTITUTE(TRIM(G5),CHAR(10),""))+1 -> 1 | R5: =IF(E5<>"","Sí","No") -> No | S5: =IF(OR(J5="",H5=""),"",IF(J5<=H5,IF(FechaCorte>=J5,1,0),MAX(0,MIN(1,(FechaCorte-H5)/(J5-H5))))) -> 1 | T5: =IF(S5="","",K5-S5) -> 0 | U5: =IF(R5="Sí","Recurrente",IF(K5>=1,"Completado",IF(AND(J5<>"",J5<FechaCorte),"Vencido",IF(AND(K5=0,OR(H5="",H5>FechaCorte)),"Por iniciar",IF(AND(T5<>"",T5<=UmbralRiesgo),"En riesgo","En plazo"))))) -> Completado | V5: =IF(OR(U5="Vencido",U5="En riesgo",U5="En plazo",U5="Por iniciar"),1,0) -> 0 | W5: =IF(U5="Vencido",FechaCorte-J5,"") | X5: =IF(AND(V5=1,U5<>"Vencido"),J5-FechaCorte,"") | Y5: =IF(J5="","",DATE(YEAR(J5),MONTH(J5),1)) -> 46082 | Z5: =IF(AND(U5="Completado",I5<>""),IF(I5<=FechaCorte,DATE(YEAR(I5),MONTH(I5),1),""),"") -> 46082 | AA5: =IF(J5="","",IF(DAY(J5+1)=1,1,0)) -> 0 | AB5: =IF(AND(U5="Completado",I5<>"",I5=J5),1,0) -> 1 | AC5: =IF(AND(K5>=1,I5<>""),IF(I5>FechaCorte,1,0),0) -> 0 | AD5: =IF(AND(I5<>"",H5<>""),IF(I5<H5,1,0),0) -> 0 | AE5: =IF(OR(F5="Riesgos",F5="Obs. Auditoría"),1,0) -> 0 | AF5: =IFERROR(MID(D5,FIND("PMC-",D5),8),"") | AG5: =IF(AND(V5=1,J5<>""),IF(AND(J5>=FechaCorte,J5<=HorizonteExpuestos),1,0),0) -> 0
A6: 5 | B6: 2026 | C6: Gestor de Identidades Sailpoint | Fase 1 | D6: Depuración accesos acorde al cargo Microfinanzas | Tecnología | Banca Personas | F6: Iniciativa | G6: Ana María Fierro | H6: 45992 | J6: 46387 | K6: 0.5 | M6: PR.AA-05 | N6: =IFERROR(INDEX(dFrente!$B$2:$B$76,MATCH(C6,dFrente!$A$2:$A$76,0)),"Sin frente") -> SailPoint IGA | O6: =IFERROR(INDEX(dNIST!$B$2:$B$13,MATCH(M6,dNIST!$A$2:$A$13,0)),"") -> PR | P6: =TRIM(IFERROR(LEFT(G6,FIND(CHAR(10),G6)-1),G6)) -> Ana María Fierro | Q6: =LEN(TRIM(G6))-LEN(SUBSTITUTE(TRIM(G6),CHAR(10),""))+1 -> 1 | R6: =IF(E6<>"","Sí","No") -> No | S6: =IF(OR(J6="",H6=""),"",IF(J6<=H6,IF(FechaCorte>=J6,1,0),MAX(0,MIN(1,(FechaCorte-H6)/(J6-H6))))) -> 0.75189873 | T6: =IF(S6="","",K6-S6) -> -0.25189873 | U6: =IF(R6="Sí","Recurrente",IF(K6>=1,"Completado",IF(AND(J6<>"",J6<FechaCorte),"Vencido",IF(AND(K6=0,OR(H6="",H6>FechaCorte)),"Por iniciar",IF(AND(T6<>"",T6<=UmbralRiesgo),"En riesgo","En plazo"))))) -> En riesgo | V6: =IF(OR(U6="Vencido",U6="En riesgo",U6="En plazo",U6="Por iniciar"),1,0) -> 1 | W6: =IF(U6="Vencido",FechaCorte-J6,"") | X6: =IF(AND(V6=1,U6<>"Vencido"),J6-FechaCorte,"") -> 98 | Y6: =IF(J6="","",DATE(YEAR(J6),MONTH(J6),1)) -> 46357 | Z6: =IF(AND(U6="Completado",I6<>""),IF(I6<=FechaCorte,DATE(YEAR(I6),MONTH(I6),1),""),"") | AA6: =IF(J6="","",IF(DAY(J6+1)=1,1,0)) -> 1 | AB6: =IF(AND(U6="Completado",I6<>"",I6=J6),1,0) -> 0 | AC6: =IF(AND(K6>=1,I6<>""),IF(I6>FechaCorte,1,0),0) -> 0 | AD6: =IF(AND(I6<>"",H6<>""),IF(I6<H6,1,0),0) -> 0 | AE6: =IF(OR(F6="Riesgos",F6="Obs. Auditoría"),1,0) -> 0 | AF6: =IFERROR(MID(D6,FIND("PMC-",D6),8),"") | AG6: =IF(AND(V6=1,J6<>""),IF(AND(J6>=FechaCorte,J6<=HorizonteExpuestos),1,0),0) -> 0
A7: 6 | B7: 2026 | C7: Gestor de Identidades Sailpoint | Fase 1 | D7: Implementación modelo de accesos basado en roles | F7: Iniciativa | G7: Richard Requelme | H7: 46082 | I7: 46084 | J7: 46084 | K7: 1 | M7: PR.AA-05 | N7: =IFERROR(INDEX(dFrente!$B$2:$B$76,MATCH(C7,dFrente!$A$2:$A$76,0)),"Sin frente") -> SailPoint IGA | O7: =IFERROR(INDEX(dNIST!$B$2:$B$13,MATCH(M7,dNIST!$A$2:$A$13,0)),"") -> PR | P7: =TRIM(IFERROR(LEFT(G7,FIND(CHAR(10),G7)-1),G7)) -> Richard Requelme | Q7: =LEN(TRIM(G7))-LEN(SUBSTITUTE(TRIM(G7),CHAR(10),""))+1 -> 1 | R7: =IF(E7<>"","Sí","No") -> No | S7: =IF(OR(J7="",H7=""),"",IF(J7<=H7,IF(FechaCorte>=J7,1,0),MAX(0,MIN(1,(FechaCorte-H7)/(J7-H7))))) -> 1 | T7: =IF(S7="","",K7-S7) -> 0 | U7: =IF(R7="Sí","Recurrente",IF(K7>=1,"Completado",IF(AND(J7<>"",J7<FechaCorte),"Vencido",IF(AND(K7=0,OR(H7="",H7>FechaCorte)),"Por iniciar",IF(AND(T7<>"",T7<=UmbralRiesgo),"En riesgo","En plazo"))))) -> Completado | V7: =IF(OR(U7="Vencido",U7="En riesgo",U7="En plazo",U7="Por iniciar"),1,0) -> 0 | W7: =IF(U7="Vencido",FechaCorte-J7,"") | X7: =IF(AND(V7=1,U7<>"Vencido"),J7-FechaCorte,"") | Y7: =IF(J7="","",DATE(YEAR(J7),MONTH(J7),1)) -> 46082 | Z7: =IF(AND(U7="Completado",I7<>""),IF(I7<=FechaCorte,DATE(YEAR(I7),MONTH(I7),1),""),"") -> 46082 | AA7: =IF(J7="","",IF(DAY(J7+1)=1,1,0)) -> 0 | AB7: =IF(AND(U7="Completado",I7<>"",I7=J7),1,0) -> 1 | AC7: =IF(AND(K7>=1,I7<>""),IF(I7>FechaCorte,1,0),0) -> 0 | AD7: =IF(AND(I7<>"",H7<>""),IF(I7<H7,1,0),0) -> 0 | AE7: =IF(OR(F7="Riesgos",F7="Obs. Auditoría"),1,0) -> 0 | AF7: =IFERROR(MID(D7,FIND("PMC-",D7),8),"") | AG7: =IF(AND(V7=1,J7<>""),IF(AND(J7>=FechaCorte,J7<=HorizonteExpuestos),1,0),0) -> 0
A8: 7 | B8: 2026 | C8: Gestor de Identidades Sailpoint | Fase 1 | D8: Eliminación de accesos a personal de Negocios (Red de Agencias) para cambiar perfiles globales y centros de costos directamente. | F8: Iniciativa | G8: Ana María Fierro | H8: 46082 | I8: 46080 | J8: 46080 | K8: 1 | L8: Gestionaban 1478 requerimientos al mes, que pasaron a GI. | M8: PR.AA-05 | N8: =IFERROR(INDEX(dFrente!$B$2:$B$76,MATCH(C8,dFrente!$A$2:$A$76,0)),"Sin frente") -> SailPoint IGA | O8: =IFERROR(INDEX(dNIST!$B$2:$B$13,MATCH(M8,dNIST!$A$2:$A$13,0)),"") -> PR | P8: =TRIM(IFERROR(LEFT(G8,FIND(CHAR(10),G8)-1),G8)) -> Ana María Fierro | Q8: =LEN(TRIM(G8))-LEN(SUBSTITUTE(TRIM(G8),CHAR(10),""))+1 -> 1 | R8: =IF(E8<>"","Sí","No") -> No | S8: =IF(OR(J8="",H8=""),"",IF(J8<=H8,IF(FechaCorte>=J8,1,0),MAX(0,MIN(1,(FechaCorte-H8)/(J8-H8))))) -> 1 | T8: =IF(S8="","",K8-S8) -> 0 | U8: =IF(R8="Sí","Recurrente",IF(K8>=1,"Completado",IF(AND(J8<>"",J8<FechaCorte),"Vencido",IF(AND(K8=0,OR(H8="",H8>FechaCorte)),"Por iniciar",IF(AND(T8<>"",T8<=UmbralRiesgo),"En riesgo","En plazo"))))) -> Completado | V8: =IF(OR(U8="Vencido",U8="En riesgo",U8="En plazo",U8="Por iniciar"),1,0) -> 0 | W8: =IF(U8="Vencido",FechaCorte-J8,"") | X8: =IF(AND(V8=1,U8<>"Vencido"),J8-FechaCorte,"") | Y8: =IF(J8="","",DATE(YEAR(J8),MONTH(J8),1)) -> 46054 | Z8: =IF(AND(U8="Completado",I8<>""),IF(I8<=FechaCorte,DATE(YEAR(I8),MONTH(I8),1),""),"") -> 46054 | AA8: =IF(J8="","",IF(DAY(J8+1)=1,1,0)) -> 0 | AB8: =IF(AND(U8="Completado",I8<>"",I8=J8),1,0) -> 1 | AC8: =IF(AND(K8>=1,I8<>""),IF(I8>FechaCorte,1,0),0) -> 0 | AD8: =IF(AND(I8<>"",H8<>""),IF(I8<H8,1,0),0) -> 1 | AE8: =IF(OR(F8="Riesgos",F8="Obs. Auditoría"),1,0) -> 0 | AF8: =IFERROR(MID(D8,FIND("PMC-",D8),8),"") | AG8: =IF(AND(V8=1,J8<>""),IF(AND(J8>=FechaCorte,J8<=HorizonteExpuestos),1,0),0) -> 0
A9: 8 | B9: 2026 | C9: Gestor de Identidades Sailpoint | Fase 2 | D9: Inactivar cuentas de usuarios por vacaciones/licencias/maternidad, etc. (Flujo y revisión RRHH) | F9: Iniciativa | G9: Ana María Vergara | H9: 46327 | J9: 46387 | K9: 0 | L9: Dependencia de revisión con RRHH. Se realizará el acercamiento para validar la factibilidad de implementación | M9: PR.AA-01 | N9: =IFERROR(INDEX(dFrente!$B$2:$B$76,MATCH(C9,dFrente!$A$2:$A$76,0)),"Sin frente") -> SailPoint IGA | O9: =IFERROR(INDEX(dNIST!$B$2:$B$13,MATCH(M9,dNIST!$A$2:$A$13,0)),"") -> PR | P9: =TRIM(IFERROR(LEFT(G9,FIND(CHAR(10),G9)-1),G9)) -> Ana María Vergara | Q9: =LEN(TRIM(G9))-LEN(SUBSTITUTE(TRIM(G9),CHAR(10),""))+1 -> 1 | R9: =IF(E9<>"","Sí","No") -> No | S9: =IF(OR(J9="",H9=""),"",IF(J9<=H9,IF(FechaCorte>=J9,1,0),MAX(0,MIN(1,(FechaCorte-H9)/(J9-H9))))) -> 0 | T9: =IF(S9="","",K9-S9) -> 0 | U9: =IF(R9="Sí","Recurrente",IF(K9>=1,"Completado",IF(AND(J9<>"",J9<FechaCorte),"Vencido",IF(AND(K9=0,OR(H9="",H9>FechaCorte)),"Por iniciar",IF(AND(T9<>"",T9<=UmbralRiesgo),"En riesgo","En plazo"))))) -> Por iniciar | V9: =IF(OR(U9="Vencido",U9="En riesgo",U9="En plazo",U9="Por iniciar"),1,0) -> 1 | W9: =IF(U9="Vencido",FechaCorte-J9,"") | X9: =IF(AND(V9=1,U9<>"Vencido"),J9-FechaCorte,"") -> 98 | Y9: =IF(J9="","",DATE(YEAR(J9),MONTH(J9),1)) -> 46357 | Z9: =IF(AND(U9="Completado",I9<>""),IF(I9<=FechaCorte,DATE(YEAR(I9),MONTH(I9),1),""),"") | AA9: =IF(J9="","",IF(DAY(J9+1)=1,1,0)) -> 1 | AB9: =IF(AND(U9="Completado",I9<>"",I9=J9),1,0) -> 0 | AC9: =IF(AND(K9>=1,I9<>""),IF(I9>FechaCorte,1,0),0) -> 0 | AD9: =IF(AND(I9<>"",H9<>""),IF(I9<H9,1,0),0) -> 0 | AE9: =IF(OR(F9="Riesgos",F9="Obs. Auditoría"),1,0) -> 0 | AF9: =IFERROR(MID(D9,FIND("PMC-",D9),8),"") | AG9: =IF(AND(V9=1,J9<>""),IF(AND(J9>=FechaCorte,J9<=HorizonteExpuestos),1,0),0) -> 0
A10: 9 | B10: 2026 | C10: Gestor de Identidades Sailpoint | Fase 2 | D10: Evaluación automatización y Monitoreo de Accesos VPN Integrado a ISC SailPoint | F10: Iniciativa | G10: Jhonny Barreiro | H10: 46143 | J10: 46235 | K10: 0.05 | L10: en diseño de definiciones | M10: DE.CM | N10: =IFERROR(INDEX(dFrente!$B$2:$B$76,MATCH(C10,dFrente!$A$2:$A$76,0)),"Sin frente") -> SailPoint IGA | O10: =IFERROR(INDEX(dNIST!$B$2:$B$13,MATCH(M10,dNIST!$A$2:$A$13,0)),"") -> DE | P10: =TRIM(IFERROR(LEFT(G10,FIND(CHAR(10),G10)-1),G10)) -> Jhonny Barreiro | Q10: =LEN(TRIM(G10))-LEN(SUBSTITUTE(TRIM(G10),CHAR(10),""))+1 -> 1 | R10: =IF(E10<>"","Sí","No") -> No | S10: =IF(OR(J10="",H10=""),"",IF(J10<=H10,IF(FechaCorte>=J10,1,0),MAX(0,MIN(1,(FechaCorte-H10)/(J10-H10))))) -> 1 | T10: =IF(S10="","",K10-S10) -> -0.95 | U10: =IF(R10="Sí","Recurrente",IF(K10>=1,"Completado",IF(AND(J10<>"",J10<FechaCorte),"Vencido",IF(AND(K10=0,OR(H10="",H10>FechaCorte)),"Por iniciar",IF(AND(T10<>"",T10<=UmbralRiesgo),"En riesgo","En plazo"))))) -> Vencido | V10: =IF(OR(U10="Vencido",U10="En riesgo",U10="En plazo",U10="Por iniciar"),1,0) -> 1 | W10: =IF(U10="Vencido",FechaCorte-J10,"") -> 54 | X10: =IF(AND(V10=1,U10<>"Vencido"),J10-FechaCorte,"") | Y10: =IF(J10="","",DATE(YEAR(J10),MONTH(J10),1)) -> 46235 | Z10: =IF(AND(U10="Completado",I10<>""),IF(I10<=FechaCorte,DATE(YEAR(I10),MONTH(I10),1),""),"") | AA10: =IF(J10="","",IF(DAY(J10+1)=1,1,0)) -> 0 | AB10: =IF(AND(U10="Completado",I10<>"",I10=J10),1,0) -> 0 | AC10: =IF(AND(K10>=1,I10<>""),IF(I10>FechaCorte,1,0),0) -> 0 | AD10: =IF(AND(I10<>"",H10<>""),IF(I10<H10,1,0),0) -> 0 | AE10: =IF(OR(F10="Riesgos",F10="Obs. Auditoría"),1,0) -> 0 | AF10: =IFERROR(MID(D10,FIND("PMC-",D10),8),"") | AG10: =IF(AND(V10=1,J10<>""),IF(AND(J10>=FechaCorte,J10<=HorizonteExpuestos),1,0),0) -> 0
A11: 10 | B11: 2026 | C11: Gestor de Identidades Sailpoint | Fase 2 | D11: Implementar la deshabilitación automática en SailPoint para el offboarding de internos | F11: Iniciativa | G11: Ana María Vergara | H11: 46143 | I11: 46143 | J11: 46143 | K11: 1 | L11: Flujo implementado dependencia con "end date" consumido desde SSFF | M11: PR.AA-01 | N11: =IFERROR(INDEX(dFrente!$B$2:$B$76,MATCH(C11,dFrente!$A$2:$A$76,0)),"Sin frente") -> SailPoint IGA | O11: =IFERROR(INDEX(dNIST!$B$2:$B$13,MATCH(M11,dNIST!$A$2:$A$13,0)),"") -> PR | P11: =TRIM(IFERROR(LEFT(G11,FIND(CHAR(10),G11)-1),G11)) -> Ana María Vergara | Q11: =LEN(TRIM(G11))-LEN(SUBSTITUTE(TRIM(G11),CHAR(10),""))+1 -> 1 | R11: =IF(E11<>"","Sí","No") -> No | S11: =IF(OR(J11="",H11=""),"",IF(J11<=H11,IF(FechaCorte>=J11,1,0),MAX(0,MIN(1,(FechaCorte-H11)/(J11-H11))))) -> 1 | T11: =IF(S11="","",K11-S11) -> 0 | U11: =IF(R11="Sí","Recurrente",IF(K11>=1,"Completado",IF(AND(J11<>"",J11<FechaCorte),"Vencido",IF(AND(K11=0,OR(H11="",H11>FechaCorte)),"Por iniciar",IF(AND(T11<>"",T11<=UmbralRiesgo),"En riesgo","En plazo"))))) -> Completado | V11: =IF(OR(U11="Vencido",U11="En riesgo",U11="En plazo",U11="Por iniciar"),1,0) -> 0 | W11: =IF(U11="Vencido",FechaCorte-J11,"") | X11: =IF(AND(V11=1,U11<>"Vencido"),J11-FechaCorte,"") | Y11: =IF(J11="","",DATE(YEAR(J11),MONTH(J11),1)) -> 46143 | Z11: =IF(AND(U11="Completado",I11<>""),IF(I11<=FechaCorte,DATE(YEAR(I11),MONTH(I11),1),""),"") -> 46143 | AA11: =IF(J11="","",IF(DAY(J11+1)=1,1,0)) -> 0 | AB11: =IF(AND(U11="Completado",I11<>"",I11=J11),1,0) -> 1 | AC11: =IF(AND(K11>=1,I11<>""),IF(I11>FechaCorte,1,0),0) -> 0 | AD11: =IF(AND(I11<>"",H11<>""),IF(I11<H11,1,0),0) -> 0 | AE11: =IF(OR(F11="Riesgos",F11="Obs. Auditoría"),1,0) -> 0 | AF11: =IFERROR(MID(D11,FIND("PMC-",D11),8),"") | AG11: =IF(AND(V11=1,J11<>""),IF(AND(J11>=FechaCorte,J11<=HorizonteExpuestos),1,0),0) -> 0
A12: 11 | B12: 2026 | C12: Gestor de Identidades Sailpoint | Fase 2 | D12: Ajustar las notificaciones generadas por ISC para retirar informaión sensible. Ajustar formatos | F12: Mejora | G12: Ana María Vergara | H12: 46143 | J12: 46387 | K12: 0.25 | L12: - Revisión integral de datos sensibles en comunicados fueron retirados - Flujo notificación onboarding de usuarios externos revisado e implementado - Fecha fin vigencia externos (comunicado). | M12: PR.AA-01 | N12: =IFERROR(INDEX(dFrente!$B$2:$B$76,MATCH(C12,dFrente!$A$2:$A$76,0)),"Sin frente") -> SailPoint IGA | O12: =IFERROR(INDEX(dNIST!$B$2:$B$13,MATCH(M12,dNIST!$A$2:$A$13,0)),"") -> PR | P12: =TRIM(IFERROR(LEFT(G12,FIND(CHAR(10),G12)-1),G12)) -> Ana María Vergara | Q12: =LEN(TRIM(G12))-LEN(SUBSTITUTE(TRIM(G12),CHAR(10),""))+1 -> 1 | R12: =IF(E12<>"","Sí","No") -> No | S12: =IF(OR(J12="",H12=""),"",IF(J12<=H12,IF(FechaCorte>=J12,1,0),MAX(0,MIN(1,(FechaCorte-H12)/(J12-H12))))) -> 0.59836066 | T12: =IF(S12="","",K12-S12) -> -0.34836066 | U12: =IF(R12="Sí","Recurrente",IF(K12>=1,"Completado",IF(AND(J12<>"",J12<FechaCorte),"Vencido",IF(AND(K12=0,OR(H12="",H12>FechaCorte)),"Por iniciar",IF(AND(T12<>"",T12<=UmbralRiesgo),"En riesgo","En plazo"))))) -> En riesgo | V12: =IF(OR(U12="Vencido",U12="En riesgo",U12="En plazo",U12="Por iniciar"),1,0) -> 1 | W12: =IF(U12="Vencido",FechaCorte-J12,"") | X12: =IF(AND(V12=1,U12<>"Vencido"),J12-FechaCorte,"") -> 98 | Y12: =IF(J12="","",DATE(YEAR(J12),MONTH(J12),1)) -> 46357 | Z12: =IF(AND(U12="Completado",I12<>""),IF(I12<=FechaCorte,DATE(YEAR(I12),MONTH(I12),1),""),"") | AA12: =IF(J12="","",IF(DAY(J12+1)=1,1,0)) -> 1 | AB12: =IF(AND(U12="Completado",I12<>"",I12=J12),1,0) -> 0 | AC12: =IF(AND(K12>=1,I12<>""),IF(I12>FechaCorte,1,0),0) -> 0 | AD12: =IF(AND(I12<>"",H12<>""),IF(I12<H12,1,0),0) -> 0 | AE12: =IF(OR(F12="Riesgos",F12="Obs. Auditoría"),1,0) -> 0 | AF12: =IFERROR(MID(D12,FIND("PMC-",D12),8),"") | AG12: =IF(AND(V12=1,J12<>""),IF(AND(J12>=FechaCorte,J12<=HorizonteExpuestos),1,0),0) -> 0
A13: 12 | B13: 2026 | C13: Gestor de Identidades Sailpoint | Fase 2 | D13: Revisión duplicidad tickets generados desde ISC | F13: Mejora | G13: Ana María Vergara | H13: 46143 | J13: 46326 | K13: 0.75 | L13: - En proceso de revisión dependencia con la marca SailPoint - Se requiere soporte del proveedor Heaven a espera de apertura de adenda de servicios - 16 Sept 2026 se realizaron las pruebas en ambiente de test y se desplegaron de forma exitosa. Se solicita a marca SailPoint el despliegue en producción, en espera de respuesta de confirmación | M13: PR.AA-01 | N13: =IFERROR(INDEX(dFrente!$B$2:$B$76,MATCH(C13,dFrente!$A$2:$A$76,0)),"Sin frente") -> SailPoint IGA | O13: =IFERROR(INDEX(dNIST!$B$2:$B$13,MATCH(M13,dNIST!$A$2:$A$13,0)),"") -> PR | P13: =TRIM(IFERROR(LEFT(G13,FIND(CHAR(10),G13)-1),G13)) -> Ana María Vergara | Q13: =LEN(TRIM(G13))-LEN(SUBSTITUTE(TRIM(G13),CHAR(10),""))+1 -> 1 | R13: =IF(E13<>"","Sí","No") -> No | S13: =IF(OR(J13="",H13=""),"",IF(J13<=H13,IF(FechaCorte>=J13,1,0),MAX(0,MIN(1,(FechaCorte-H13)/(J13-H13))))) -> 0.79781421 | T13: =IF(S13="","",K13-S13) -> -0.047814208 | U13: =IF(R13="Sí","Recurrente",IF(K13>=1,"Completado",IF(AND(J13<>"",J13<FechaCorte),"Vencido",IF(AND(K13=0,OR(H13="",H13>FechaCorte)),"Por iniciar",IF(AND(T13<>"",T13<=UmbralRiesgo),"En riesgo","En plazo"))))) -> En plazo | V13: =IF(OR(U13="Vencido",U13="En riesgo",U13="En plazo",U13="Por iniciar"),1,0) -> 1 | W13: =IF(U13="Vencido",FechaCorte-J13,"") | X13: =IF(AND(V13=1,U13<>"Vencido"),J13-FechaCorte,"") -> 37 | Y13: =IF(J13="","",DATE(YEAR(J13),MONTH(J13),1)) -> 46296 | Z13: =IF(AND(U13="Completado",I13<>""),IF(I13<=FechaCorte,DATE(YEAR(I13),MONTH(I13),1),""),"") | AA13: =IF(J13="","",IF(DAY(J13+1)=1,1,0)) -> 1 | AB13: =IF(AND(U13="Completado",I13<>"",I13=J13),1,0) -> 0 | AC13: =IF(AND(K13>=1,I13<>""),IF(I13>FechaCorte,1,0),0) -> 0 | AD13: =IF(AND(I13<>"",H13<>""),IF(I13<H13,1,0),0) -> 0 | AE13: =IF(OR(F13="Riesgos",F13="Obs. Auditoría"),1,0) -> 0 | AF13: =IFERROR(MID(D13,FIND("PMC-",D13),8),"") | AG13: =IF(AND(V13=1,J13<>""),IF(AND(J13>=FechaCorte,J13<=HorizonteExpuestos),1,0),0) -> 0
A14: 13 | B14: 2026 | C14: Gestor de Identidades Sailpoint | Fase 2 | D14: Ajustar configuración para catálogo "Cambio Centro Costos" reducción generación tickets | F14: Mejora | G14: Ana María Vergara | H14: 46143 | I14: 46173 | J14: 46173 | K14: 1 | L14: Se implemento el ajuste en SailPoint para que solo consuma las aplicaciones en las que se debe generar un cambio en el centro de costos | M14: PR.AA-01 | N14: =IFERROR(INDEX(dFrente!$B$2:$B$76,MATCH(C14,dFrente!$A$2:$A$76,0)),"Sin frente") -> SailPoint IGA | O14: =IFERROR(INDEX(dNIST!$B$2:$B$13,MATCH(M14,dNIST!$A$2:$A$13,0)),"") -> PR | P14: =TRIM(IFERROR(LEFT(G14,FIND(CHAR(10),G14)-1),G14)) -> Ana María Vergara | Q14: =LEN(TRIM(G14))-LEN(SUBSTITUTE(TRIM(G14),CHAR(10),""))+1 -> 1 | R14: =IF(E14<>"","Sí","No") -> No | S14: =IF(OR(J14="",H14=""),"",IF(J14<=H14,IF(FechaCorte>=J14,1,0),MAX(0,MIN(1,(FechaCorte-H14)/(J14-H14))))) -> 1 | T14: =IF(S14="","",K14-S14) -> 0 | U14: =IF(R14="Sí","Recurrente",IF(K14>=1,"Completado",IF(AND(J14<>"",J14<FechaCorte),"Vencido",IF(AND(K14=0,OR(H14="",H14>FechaCorte)),"Por iniciar",IF(AND(T14<>"",T14<=UmbralRiesgo),"En riesgo","En plazo"))))) -> Completado | V14: =IF(OR(U14="Vencido",U14="En riesgo",U14="En plazo",U14="Por iniciar"),1,0) -> 0 | W14: =IF(U14="Vencido",FechaCorte-J14,"") | X14: =IF(AND(V14=1,U14<>"Vencido"),J14-FechaCorte,"") | Y14: =IF(J14="","",DATE(YEAR(J14),MONTH(J14),1)) -> 46143 | Z14: =IF(AND(U14="Completado",I14<>""),IF(I14<=FechaCorte,DATE(YEAR(I14),MONTH(I14),1),""),"") -> 46143 | AA14: =IF(J14="","",IF(DAY(J14+1)=1,1,0)) -> 1 | AB14: =IF(AND(U14="Completado",I14<>"",I14=J14),1,0) -> 1 | AC14: =IF(AND(K14>=1,I14<>""),IF(I14>FechaCorte,1,0),0) -> 0 | AD14: =IF(AND(I14<>"",H14<>""),IF(I14<H14,1,0),0) -> 0 | AE14: =IF(OR(F14="Riesgos",F14="Obs. Auditoría"),1,0) -> 0 | AF14: =IFERROR(MID(D14,FIND("PMC-",D14),8),"") | AG14: =IF(AND(V14=1,J14<>""),IF(AND(J14>=FechaCorte,J14<=HorizonteExpuestos),1,0),0) -> 0
A15: 14 | B15: 2026 | C15: Gestor de Identidades Sailpoint | Fase 2 | D15: Cambio de dominio de sailpoint.com a pichincha.com para las notificaciones generadas. | F15: Mejora | G15: Ana María Vergara | H15: 46113 | I15: 46153 | J15: 46153 | K15: 1 | M15: PR.AA-01 | N15: =IFERROR(INDEX(dFrente!$B$2:$B$76,MATCH(C15,dFrente!$A$2:$A$76,0)),"Sin frente") -> SailPoint IGA | O15: =IFERROR(INDEX(dNIST!$B$2:$B$13,MATCH(M15,dNIST!$A$2:$A$13,0)),"") -> PR | P15: =TRIM(IFERROR(LEFT(G15,FIND(CHAR(10),G15)-1),G15)) -> Ana María Vergara | Q15: =LEN(TRIM(G15))-LEN(SUBSTITUTE(TRIM(G15),CHAR(10),""))+1 -> 1 | R15: =IF(E15<>"","Sí","No") -> No | S15: =IF(OR(J15="",H15=""),"",IF(J15<=H15,IF(FechaCorte>=J15,1,0),MAX(0,MIN(1,(FechaCorte-H15)/(J15-H15))))) -> 1 | T15: =IF(S15="","",K15-S15) -> 0 | U15: =IF(R15="Sí","Recurrente",IF(K15>=1,"Completado",IF(AND(J15<>"",J15<FechaCorte),"Vencido",IF(AND(K15=0,OR(H15="",H15>FechaCorte)),"Por iniciar",IF(AND(T15<>"",T15<=UmbralRiesgo),"En riesgo","En plazo"))))) -> Completado | V15: =IF(OR(U15="Vencido",U15="En riesgo",U15="En plazo",U15="Por iniciar"),1,0) -> 0 | W15: =IF(U15="Vencido",FechaCorte-J15,"") | X15: =IF(AND(V15=1,U15<>"Vencido"),J15-FechaCorte,"") | Y15: =IF(J15="","",DATE(YEAR(J15),MONTH(J15),1)) -> 46143 | Z15: =IF(AND(U15="Completado",I15<>""),IF(I15<=FechaCorte,DATE(YEAR(I15),MONTH(I15),1),""),"") -> 46143 | AA15: =IF(J15="","",IF(DAY(J15+1)=1,1,0)) -> 0 | AB15: =IF(AND(U15="Completado",I15<>"",I15=J15),1,0) -> 1 | AC15: =IF(AND(K15>=1,I15<>""),IF(I15>FechaCorte,1,0),0) -> 0 | AD15: =IF(AND(I15<>"",H15<>""),IF(I15<H15,1,0),0) -> 0 | AE15: =IF(OR(F15="Riesgos",F15="Obs. Auditoría"),1,0) -> 0 | AF15: =IFERROR(MID(D15,FIND("PMC-",D15),8),"") | AG15: =IF(AND(V15=1,J15<>""),IF(AND(J15>=FechaCorte,J15<=HorizonteExpuestos),1,0),0) -> 0
A16: 15 | B16: 2026 | C16: Gestor de Identidades Sailpoint | Fase 2 | D16: Sincronización Campo AD Manager | F16: Mejora | G16: Ana María Vergara | H16: 46143 | I16: 46155 | J16: 46155 | K16: 1 | M16: PR.AA-01 | N16: =IFERROR(INDEX(dFrente!$B$2:$B$76,MATCH(C16,dFrente!$A$2:$A$76,0)),"Sin frente") -> SailPoint IGA | O16: =IFERROR(INDEX(dNIST!$B$2:$B$13,MATCH(M16,dNIST!$A$2:$A$13,0)),"") -> PR | P16: =TRIM(IFERROR(LEFT(G16,FIND(CHAR(10),G16)-1),G16)) -> Ana María Vergara | Q16: =LEN(TRIM(G16))-LEN(SUBSTITUTE(TRIM(G16),CHAR(10),""))+1 -> 1 | R16: =IF(E16<>"","Sí","No") -> No | S16: =IF(OR(J16="",H16=""),"",IF(J16<=H16,IF(FechaCorte>=J16,1,0),MAX(0,MIN(1,(FechaCorte-H16)/(J16-H16))))) -> 1 | T16: =IF(S16="","",K16-S16) -> 0 | U16: =IF(R16="Sí","Recurrente",IF(K16>=1,"Completado",IF(AND(J16<>"",J16<FechaCorte),"Vencido",IF(AND(K16=0,OR(H16="",H16>FechaCorte)),"Por iniciar",IF(AND(T16<>"",T16<=UmbralRiesgo),"En riesgo","En plazo"))))) -> Completado | V16: =IF(OR(U16="Vencido",U16="En riesgo",U16="En plazo",U16="Por iniciar"),1,0) -> 0 | W16: =IF(U16="Vencido",FechaCorte-J16,"") | X16: =IF(AND(V16=1,U16<>"Vencido"),J16-FechaCorte,"") | Y16: =IF(J16="","",DATE(YEAR(J16),MONTH(J16),1)) -> 46143 | Z16: =IF(AND(U16="Completado",I16<>""),IF(I16<=FechaCorte,DATE(YEAR(I16),MONTH(I16),1),""),"") -> 46143 | AA16: =IF(J16="","",IF(DAY(J16+1)=1,1,0)) -> 0 | AB16: =IF(AND(U16="Completado",I16<>"",I16=J16),1,0) -> 1 | AC16: =IF(AND(K16>=1,I16<>""),IF(I16>FechaCorte,1,0),0) -> 0 | AD16: =IF(AND(I16<>"",H16<>""),IF(I16<H16,1,0),0) -> 0 | AE16: =IF(OR(F16="Riesgos",F16="Obs. Auditoría"),1,0) -> 0 | AF16: =IFERROR(MID(D16,FIND("PMC-",D16),8),"") | AG16: =IF(AND(V16=1,J16<>""),IF(AND(J16>=FechaCorte,J16<=HorizonteExpuestos),1,0),0) -> 0
A17: 16 | B17: 2026 | C17: Gestor de Identidades Sailpoint | Fase 2 | D17: Depuración usuarios duplicados en AD | Identificación y corrección de inconsistencias asociadas a la causa raíz | F17: Incidencia | G17: Ana María Vergara | H17: 46155 | I17: 46161 | J17: 46161 | K17: 1 | L17: 108 usuarios duplicados. Se incluye en el control mensual de TCS. | M17: PR.AA-01 | N17: =IFERROR(INDEX(dFrente!$B$2:$B$76,MATCH(C17,dFrente!$A$2:$A$76,0)),"Sin frente") -> SailPoint IGA | O17: =IFERROR(INDEX(dNIST!$B$2:$B$13,MATCH(M17,dNIST!$A$2:$A$13,0)),"") -> PR | P17: =TRIM(IFERROR(LEFT(G17,FIND(CHAR(10),G17)-1),G17)) -> Ana María Vergara | Q17: =LEN(TRIM(G17))-LEN(SUBSTITUTE(TRIM(G17),CHAR(10),""))+1 -> 1 | R17: =IF(E17<>"","Sí","No") -> No | S17: =IF(OR(J17="",H17=""),"",IF(J17<=H17,IF(FechaCorte>=J17,1,0),MAX(0,MIN(1,(FechaCorte-H17)/(J17-H17))))) -> 1 | T17: =IF(S17="","",K17-S17) -> 0 | U17: =IF(R17="Sí","Recurrente",IF(K17>=1,"Completado",IF(AND(J17<>"",J17<FechaCorte),"Vencido",IF(AND(K17=0,OR(H17="",H17>FechaCorte)),"Por iniciar",IF(AND(T17<>"",T17<=UmbralRiesgo),"En riesgo","En plazo"))))) -> Completado | V17: =IF(OR(U17="Vencido",U17="En riesgo",U17="En plazo",U17="Por iniciar"),1,0) -> 0 | W17: =IF(U17="Vencido",FechaCorte-J17,"") | X17: =IF(AND(V17=1,U17<>"Vencido"),J17-FechaCorte,"") | Y17: =IF(J17="","",DATE(YEAR(J17),MONTH(J17),1)) -> 46143 | Z17: =IF(AND(U17="Completado",I17<>""),IF(I17<=FechaCorte,DATE(YEAR(I17),MONTH(I17),1),""),"") -> 46143 | AA17: =IF(J17="","",IF(DAY(J17+1)=1,1,0)) -> 0 | AB17: =IF(AND(U17="Completado",I17<>"",I17=J17),1,0) -> 1 | AC17: =IF(AND(K17>=1,I17<>""),IF(I17>FechaCorte,1,0),0) -> 0 | AD17: =IF(AND(I17<>"",H17<>""),IF(I17<H17,1,0),0) -> 0 | AE17: =IF(OR(F17="Riesgos",F17="Obs. Auditoría"),1,0) -> 0 | AF17: =IFERROR(MID(D17,FIND("PMC-",D17),8),"") | AG17: =IF(AND(V17=1,J17<>""),IF(AND(J17>=FechaCorte,J17<=HorizonteExpuestos),1,0),0) -> 0
A18: 17 | B18: 2026 | C18: Gestor de Identidades Sailpoint | Fase 2 | D18: Modificación campo "Last Name" en Externos y revisar novedad en los apellidos que se envia desde ISC hacia el AD. | F18: Iniciativa | G18: Ana María Vergara Jhonny Barreiro | H18: 46155 | I18: 46168 | J18: 46168 | K18: 1 | M18: PR.AA-01 | N18: =IFERROR(INDEX(dFrente!$B$2:$B$76,MATCH(C18,dFrente!$A$2:$A$76,0)),"Sin frente") -> SailPoint IGA | O18: =IFERROR(INDEX(dNIST!$B$2:$B$13,MATCH(M18,dNIST!$A$2:$A$13,0)),"") -> PR | P18: =TRIM(IFERROR(LEFT(G18,FIND(CHAR(10),G18)-1),G18)) -> Ana María Vergara | Q18: =LEN(TRIM(G18))-LEN(SUBSTITUTE(TRIM(G18),CHAR(10),""))+1 -> 2 | R18: =IF(E18<>"","Sí","No") -> No | S18: =IF(OR(J18="",H18=""),"",IF(J18<=H18,IF(FechaCorte>=J18,1,0),MAX(0,MIN(1,(FechaCorte-H18)/(J18-H18))))) -> 1 | T18: =IF(S18="","",K18-S18) -> 0 | U18: =IF(R18="Sí","Recurrente",IF(K18>=1,"Completado",IF(AND(J18<>"",J18<FechaCorte),"Vencido",IF(AND(K18=0,OR(H18="",H18>FechaCorte)),"Por iniciar",IF(AND(T18<>"",T18<=UmbralRiesgo),"En riesgo","En plazo"))))) -> Completado | V18: =IF(OR(U18="Vencido",U18="En riesgo",U18="En plazo",U18="Por iniciar"),1,0) -> 0 | W18: =IF(U18="Vencido",FechaCorte-J18,"") | X18: =IF(AND(V18=1,U18<>"Vencido"),J18-FechaCorte,"") | Y18: =IF(J18="","",DATE(YEAR(J18),MONTH(J18),1)) -> 46143 | Z18: =IF(AND(U18="Completado",I18<>""),IF(I18<=FechaCorte,DATE(YEAR(I18),MONTH(I18),1),""),"") -> 46143 | AA18: =IF(J18="","",IF(DAY(J18+1)=1,1,0)) -> 0 | AB18: =IF(AND(U18="Completado",I18<>"",I18=J18),1,0) -> 1 | AC18: =IF(AND(K18>=1,I18<>""),IF(I18>FechaCorte,1,0),0) -> 0 | AD18: =IF(AND(I18<>"",H18<>""),IF(I18<H18,1,0),0) -> 0 | AE18: =IF(OR(F18="Riesgos",F18="Obs. Auditoría"),1,0) -> 0 | AF18: =IFERROR(MID(D18,FIND("PMC-",D18),8),"") | AG18: =IF(AND(V18=1,J18<>""),IF(AND(J18>=FechaCorte,J18<=HorizonteExpuestos),1,0),0) -> 0
A19: 18 | B19: 2026 | C19: Gestor de Identidades Sailpoint | Fase 2 | D19: Revisión de Fusion: Integración de aplicación - Revisión de lectura y aprovisionamiento automatizado por Sailpoint a Fusion | F19: Iniciativa | G19: Richard Requelme Ana María Vergara | H19: 46213 | J19: 46265 | K19: 0.9 | L19: 15- sep - Se crearon los roles, pendiente análisis de Assertiva para creación de APs 17-Ago - Se ejecutaron las pruebas del conector, fueron exitosas. Pendiente confirmar roles con Agencia y Dueño de app Se encendio el conector en modo lectura, se levantaron con QA los escenarios, se tiene pendiente las pruebas en producción | M19: PR.AA-01 | N19: =IFERROR(INDEX(dFrente!$B$2:$B$76,MATCH(C19,dFrente!$A$2:$A$76,0)),"Sin frente") -> SailPoint IGA | O19: =IFERROR(INDEX(dNIST!$B$2:$B$13,MATCH(M19,dNIST!$A$2:$A$13,0)),"") -> PR | P19: =TRIM(IFERROR(LEFT(G19,FIND(CHAR(10),G19)-1),G19)) -> Richard Requelme | Q19: =LEN(TRIM(G19))-LEN(SUBSTITUTE(TRIM(G19),CHAR(10),""))+1 -> 2 | R19: =IF(E19<>"","Sí","No") -> No | S19: =IF(OR(J19="",H19=""),"",IF(J19<=H19,IF(FechaCorte>=J19,1,0),MAX(0,MIN(1,(FechaCorte-H19)/(J19-H19))))) -> 1 | T19: =IF(S19="","",K19-S19) -> -0.1 | U19: =IF(R19="Sí","Recurrente",IF(K19>=1,"Completado",IF(AND(J19<>"",J19<FechaCorte),"Vencido",IF(AND(K19=0,OR(H19="",H19>FechaCorte)),"Por iniciar",IF(AND(T19<>"",T19<=UmbralRiesgo),"En riesgo","En plazo"))))) -> Vencido | V19: =IF(OR(U19="Vencido",U19="En riesgo",U19="En plazo",U19="Por iniciar"),1,0) -> 1 | W19: =IF(U19="Vencido",FechaCorte-J19,"") -> 24 | X19: =IF(AND(V19=1,U19<>"Vencido"),J19-FechaCorte,"") | Y19: =IF(J19="","",DATE(YEAR(J19),MONTH(J19),1)) -> 46235 | Z19: =IF(AND(U19="Completado",I19<>""),IF(I19<=FechaCorte,DATE(YEAR(I19),MONTH(I19),1),""),"") | AA19: =IF(J19="","",IF(DAY(J19+1)=1,1,0)) -> 1 | AB19: =IF(AND(U19="Completado",I19<>"",I19=J19),1,0) -> 0 | AC19: =IF(AND(K19>=1,I19<>""),IF(I19>FechaCorte,1,0),0) -> 0 | AD19: =IF(AND(I19<>"",H19<>""),IF(I19<H19,1,0),0) -> 0 | AE19: =IF(OR(F19="Riesgos",F19="Obs. Auditoría"),1,0) -> 0 | AF19: =IFERROR(MID(D19,FIND("PMC-",D19),8),"") | AG19: =IF(AND(V19=1,J19<>""),IF(AND(J19>=FechaCorte,J19<=HorizonteExpuestos),1,0),0) -> 0
A20: 19 | B20: 2026 | C20: Gestor de Identidades Sailpoint | Fase 2 | D20: Análisis integración Monitoreo de Fraude | F20: Proyecto | G20: Ana María Vergara Richard Requelme Jhonny Barreiro | H20: 46113 | J20: 46295 | K20: 0.7 | L20: - 17-ago- Se corrigio el esquema y está pendiente del lado del dueño del aplicativo la confirmación de la integración total (auth + autorización) Monitoreo Fraude: Acercamiento con el proyecto en revisión de integración con Entra ID (autenticación) | M20: PR.AA-01 | N20: =IFERROR(INDEX(dFrente!$B$2:$B$76,MATCH(C20,dFrente!$A$2:$A$76,0)),"Sin frente") -> SailPoint IGA | O20: =IFERROR(INDEX(dNIST!$B$2:$B$13,MATCH(M20,dNIST!$A$2:$A$13,0)),"") -> PR | P20: =TRIM(IFERROR(LEFT(G20,FIND(CHAR(10),G20)-1),G20)) -> Ana María Vergara | Q20: =LEN(TRIM(G20))-LEN(SUBSTITUTE(TRIM(G20),CHAR(10),""))+1 -> 3 | R20: =IF(E20<>"","Sí","No") -> No | S20: =IF(OR(J20="",H20=""),"",IF(J20<=H20,IF(FechaCorte>=J20,1,0),MAX(0,MIN(1,(FechaCorte-H20)/(J20-H20))))) -> 0.96703297 | T20: =IF(S20="","",K20-S20) -> -0.26703297 | U20: =IF(R20="Sí","Recurrente",IF(K20>=1,"Completado",IF(AND(J20<>"",J20<FechaCorte),"Vencido",IF(AND(K20=0,OR(H20="",H20>FechaCorte)),"Por iniciar",IF(AND(T20<>"",T20<=UmbralRiesgo),"En riesgo","En plazo"))))) -> En riesgo | V20: =IF(OR(U20="Vencido",U20="En riesgo",U20="En plazo",U20="Por iniciar"),1,0) -> 1 | W20: =IF(U20="Vencido",FechaCorte-J20,"") | X20: =IF(AND(V20=1,U20<>"Vencido"),J20-FechaCorte,"") -> 6 | Y20: =IF(J20="","",DATE(YEAR(J20),MONTH(J20),1)) -> 46266 | Z20: =IF(AND(U20="Completado",I20<>""),IF(I20<=FechaCorte,DATE(YEAR(I20),MONTH(I20),1),""),"") | AA20: =IF(J20="","",IF(DAY(J20+1)=1,1,0)) -> 1 | AB20: =IF(AND(U20="Completado",I20<>"",I20=J20),1,0) -> 0 | AC20: =IF(AND(K20>=1,I20<>""),IF(I20>FechaCorte,1,0),0) -> 0 | AD20: =IF(AND(I20<>"",H20<>""),IF(I20<H20,1,0),0) -> 0 | AE20: =IF(OR(F20="Riesgos",F20="Obs. Auditoría"),1,0) -> 0 | AF20: =IFERROR(MID(D20,FIND("PMC-",D20),8),"") | AG20: =IF(AND(V20=1,J20<>""),IF(AND(J20>=FechaCorte,J20<=HorizonteExpuestos),1,0),0) -> 1
A21: 20 | B21: 2026 | C21: Gestor de Identidades Sailpoint | Fase 2 | D21: Análisis integración AS400 - GAF | F21: Proyecto | G21: Ana María Vergara | H21: 46113 | J21: 46387 | K21: 0.5 | L21: - GAF: Solicitud interdependencia a la célula. En etapa de evaluación - 17/08/2026 Se identificó la necesidad de construir un microservicio para disponibilizar la información que consume SailPoint. El proveedor NTTData compartió una proforma para la construcción, valor que esta fuera del presupuesto | M21: PR.AA-01 | N21: =IFERROR(INDEX(dFrente!$B$2:$B$76,MATCH(C21,dFrente!$A$2:$A$76,0)),"Sin frente") -> SailPoint IGA | O21: =IFERROR(INDEX(dNIST!$B$2:$B$13,MATCH(M21,dNIST!$A$2:$A$13,0)),"") -> PR | P21: =TRIM(IFERROR(LEFT(G21,FIND(CHAR(10),G21)-1),G21)) -> Ana María Vergara | Q21: =LEN(TRIM(G21))-LEN(SUBSTITUTE(TRIM(G21),CHAR(10),""))+1 -> 1 | R21: =IF(E21<>"","Sí","No") -> No | S21: =IF(OR(J21="",H21=""),"",IF(J21<=H21,IF(FechaCorte>=J21,1,0),MAX(0,MIN(1,(FechaCorte-H21)/(J21-H21))))) -> 0.64233577 | T21: =IF(S21="","",K21-S21) -> -0.14233577 | U21: =IF(R21="Sí","Recurrente",IF(K21>=1,"Completado",IF(AND(J21<>"",J21<FechaCorte),"Vencido",IF(AND(K21=0,OR(H21="",H21>FechaCorte)),"Por iniciar",IF(AND(T21<>"",T21<=UmbralRiesgo),"En riesgo","En plazo"))))) -> En plazo | V21: =IF(OR(U21="Vencido",U21="En riesgo",U21="En plazo",U21="Por iniciar"),1,0) -> 1 | W21: =IF(U21="Vencido",FechaCorte-J21,"") | X21: =IF(AND(V21=1,U21<>"Vencido"),J21-FechaCorte,"") -> 98 | Y21: =IF(J21="","",DATE(YEAR(J21),MONTH(J21),1)) -> 46357 | Z21: =IF(AND(U21="Completado",I21<>""),IF(I21<=FechaCorte,DATE(YEAR(I21),MONTH(I21),1),""),"") | AA21: =IF(J21="","",IF(DAY(J21+1)=1,1,0)) -> 1 | AB21: =IF(AND(U21="Completado",I21<>"",I21=J21),1,0) -> 0 | AC21: =IF(AND(K21>=1,I21<>""),IF(I21>FechaCorte,1,0),0) -> 0 | AD21: =IF(AND(I21<>"",H21<>""),IF(I21<H21,1,0),0) -> 0 | AE21: =IF(OR(F21="Riesgos",F21="Obs. Auditoría"),1,0) -> 0 | AF21: =IFERROR(MID(D21,FIND("PMC-",D21),8),"") | AG21: =IF(AND(V21=1,J21<>""),IF(AND(J21>=FechaCorte,J21<=HorizonteExpuestos),1,0),0) -> 0
A22: 21 | B22: 2026 | C22: Gestor de Identidades Sailpoint | Fase 2 | D22: Análisis integración PIVI - CAO (Interdin) | F22: Proyecto | G22: Ana María Vergara | H22: 46113 | J22: 46387 | K22: 0.5 | L22: - PIVI | CAO: Solicitud interdependencia a la célula. En etapa de evaluación - 17/08/2026 La célula de Interdin - William Correa comunica que por temas de capacidad no es viable contar con el análisis técnico de integración por lo que quedaría en backlog | M22: PR.AA-01 | N22: =IFERROR(INDEX(dFrente!$B$2:$B$76,MATCH(C22,dFrente!$A$2:$A$76,0)),"Sin frente") -> SailPoint IGA | O22: =IFERROR(INDEX(dNIST!$B$2:$B$13,MATCH(M22,dNIST!$A$2:$A$13,0)),"") -> PR | P22: =TRIM(IFERROR(LEFT(G22,FIND(CHAR(10),G22)-1),G22)) -> Ana María Vergara | Q22: =LEN(TRIM(G22))-LEN(SUBSTITUTE(TRIM(G22),CHAR(10),""))+1 -> 1 | R22: =IF(E22<>"","Sí","No") -> No | S22: =IF(OR(J22="",H22=""),"",IF(J22<=H22,IF(FechaCorte>=J22,1,0),MAX(0,MIN(1,(FechaCorte-H22)/(J22-H22))))) -> 0.64233577 | T22: =IF(S22="","",K22-S22) -> -0.14233577 | U22: =IF(R22="Sí","Recurrente",IF(K22>=1,"Completado",IF(AND(J22<>"",J22<FechaCorte),"Vencido",IF(AND(K22=0,OR(H22="",H22>FechaCorte)),"Por iniciar",IF(AND(T22<>"",T22<=UmbralRiesgo),"En riesgo","En plazo"))))) -> En plazo | V22: =IF(OR(U22="Vencido",U22="En riesgo",U22="En plazo",U22="Por iniciar"),1,0) -> 1 | W22: =IF(U22="Vencido",FechaCorte-J22,"") | X22: =IF(AND(V22=1,U22<>"Vencido"),J22-FechaCorte,"") -> 98 | Y22: =IF(J22="","",DATE(YEAR(J22),MONTH(J22),1)) -> 46357 | Z22: =IF(AND(U22="Completado",I22<>""),IF(I22<=FechaCorte,DATE(YEAR(I22),MONTH(I22),1),""),"") | AA22: =IF(J22="","",IF(DAY(J22+1)=1,1,0)) -> 1 | AB22: =IF(AND(U22="Completado",I22<>"",I22=J22),1,0) -> 0 | AC22: =IF(AND(K22>=1,I22<>""),IF(I22>FechaCorte,1,0),0) -> 0 | AD22: =IF(AND(I22<>"",H22<>""),IF(I22<H22,1,0),0) -> 0 | AE22: =IF(OR(F22="Riesgos",F22="Obs. Auditoría"),1,0) -> 0 | AF22: =IFERROR(MID(D22,FIND("PMC-",D22),8),"") | AG22: =IF(AND(V22=1,J22<>""),IF(AND(J22>=FechaCorte,J22<=HorizonteExpuestos),1,0),0) -> 0
A23: 22 | B23: 2026 | C23: Gestor de Identidades Sailpoint | Fase 2 | D23: Reemplazo microservicios Bancs, Siglo21, Logiflow | F23: Proyecto | G23: Ana María Vergara | H23: 46113 | J23: 46387 | K23: 0.5 | L23: - Microservicio Bancs: con retraso - Microservicio Siglo21: dependencia de micro de bancs - Microservicio Logiflow: En proceso. Pruebas funcionales 18/08/2026 | M23: PR.AA-01 | N23: =IFERROR(INDEX(dFrente!$B$2:$B$76,MATCH(C23,dFrente!$A$2:$A$76,0)),"Sin frente") -> SailPoint IGA | O23: =IFERROR(INDEX(dNIST!$B$2:$B$13,MATCH(M23,dNIST!$A$2:$A$13,0)),"") -> PR | P23: =TRIM(IFERROR(LEFT(G23,FIND(CHAR(10),G23)-1),G23)) -> Ana María Vergara | Q23: =LEN(TRIM(G23))-LEN(SUBSTITUTE(TRIM(G23),CHAR(10),""))+1 -> 1 | R23: =IF(E23<>"","Sí","No") -> No | S23: =IF(OR(J23="",H23=""),"",IF(J23<=H23,IF(FechaCorte>=J23,1,0),MAX(0,MIN(1,(FechaCorte-H23)/(J23-H23))))) -> 0.64233577 | T23: =IF(S23="","",K23-S23) -> -0.14233577 | U23: =IF(R23="Sí","Recurrente",IF(K23>=1,"Completado",IF(AND(J23<>"",J23<FechaCorte),"Vencido",IF(AND(K23=0,OR(H23="",H23>FechaCorte)),"Por iniciar",IF(AND(T23<>"",T23<=UmbralRiesgo),"En riesgo","En plazo"))))) -> En plazo | V23: =IF(OR(U23="Vencido",U23="En riesgo",U23="En plazo",U23="Por iniciar"),1,0) -> 1 | W23: =IF(U23="Vencido",FechaCorte-J23,"") | X23: =IF(AND(V23=1,U23<>"Vencido"),J23-FechaCorte,"") -> 98 | Y23: =IF(J23="","",DATE(YEAR(J23),MONTH(J23),1)) -> 46357 | Z23: =IF(AND(U23="Completado",I23<>""),IF(I23<=FechaCorte,DATE(YEAR(I23),MONTH(I23),1),""),"") | AA23: =IF(J23="","",IF(DAY(J23+1)=1,1,0)) -> 1 | AB23: =IF(AND(U23="Completado",I23<>"",I23=J23),1,0) -> 0 | AC23: =IF(AND(K23>=1,I23<>""),IF(I23>FechaCorte,1,0),0) -> 0 | AD23: =IF(AND(I23<>"",H23<>""),IF(I23<H23,1,0),0) -> 0 | AE23: =IF(OR(F23="Riesgos",F23="Obs. Auditoría"),1,0) -> 0 | AF23: =IFERROR(MID(D23,FIND("PMC-",D23),8),"") | AG23: =IF(AND(V23=1,J23<>""),IF(AND(J23>=FechaCorte,J23<=HorizonteExpuestos),1,0),0) -> 0
A24: 23 | B24: 2026 | C24: Gestor de Identidades Sailpoint | Fase 2 | D24: Integración automática CRM Salesforce. Análisis construcción roles automáticos | F24: Proyecto | G24: Ana María Vergara Richard Requelme Jhonny Barreiro | H24: 46113 | J24: 46295 | K24: 0.95 | L24: - 15- sept- quitar el CSV -17 ago - Se remite los roles validados (con agencia y con el dueño del app) para creación de roles y proceder con el encendido CRM: Conector implementado, activo modo lectura | M24: PR.AA-05 | N24: =IFERROR(INDEX(dFrente!$B$2:$B$76,MATCH(C24,dFrente!$A$2:$A$76,0)),"Sin frente") -> SailPoint IGA | O24: =IFERROR(INDEX(dNIST!$B$2:$B$13,MATCH(M24,dNIST!$A$2:$A$13,0)),"") -> PR | P24: =TRIM(IFERROR(LEFT(G24,FIND(CHAR(10),G24)-1),G24)) -> Ana María Vergara | Q24: =LEN(TRIM(G24))-LEN(SUBSTITUTE(TRIM(G24),CHAR(10),""))+1 -> 3 | R24: =IF(E24<>"","Sí","No") -> No | S24: =IF(OR(J24="",H24=""),"",IF(J24<=H24,IF(FechaCorte>=J24,1,0),MAX(0,MIN(1,(FechaCorte-H24)/(J24-H24))))) -> 0.96703297 | T24: =IF(S24="","",K24-S24) -> -0.017032967 | U24: =IF(R24="Sí","Recurrente",IF(K24>=1,"Completado",IF(AND(J24<>"",J24<FechaCorte),"Vencido",IF(AND(K24=0,OR(H24="",H24>FechaCorte)),"Por iniciar",IF(AND(T24<>"",T24<=UmbralRiesgo),"En riesgo","En plazo"))))) -> En plazo | V24: =IF(OR(U24="Vencido",U24="En riesgo",U24="En plazo",U24="Por iniciar"),1,0) -> 1 | W24: =IF(U24="Vencido",FechaCorte-J24,"") | X24: =IF(AND(V24=1,U24<>"Vencido"),J24-FechaCorte,"") -> 6 | Y24: =IF(J24="","",DATE(YEAR(J24),MONTH(J24),1)) -> 46266 | Z24: =IF(AND(U24="Completado",I24<>""),IF(I24<=FechaCorte,DATE(YEAR(I24),MONTH(I24),1),""),"") | AA24: =IF(J24="","",IF(DAY(J24+1)=1,1,0)) -> 1 | AB24: =IF(AND(U24="Completado",I24<>"",I24=J24),1,0) -> 0 | AC24: =IF(AND(K24>=1,I24<>""),IF(I24>FechaCorte,1,0),0) -> 0 | AD24: =IF(AND(I24<>"",H24<>""),IF(I24<H24,1,0),0) -> 0 | AE24: =IF(OR(F24="Riesgos",F24="Obs. Auditoría"),1,0) -> 0 | AF24: =IFERROR(MID(D24,FIND("PMC-",D24),8),"") | AG24: =IF(AND(V24=1,J24<>""),IF(AND(J24>=FechaCorte,J24<=HorizonteExpuestos),1,0),0) -> 1
A25: 24 | B25: 2026 | C25: Gestor de Identidades Sailpoint | Fase 2 | D25: Diferencia hora comunicados generados por Sailpoint | F25: Mejora | G25: Ana María Vergara | H25: 46209 | I25: 46233 | J25: 46233 | K25: 1 | L25: Diferencia de 5 horas aprox entre la fecha y hora de la notificación y la fecha y hora reales de envío del correo Ticket de soporte generado para atención de Assertiva #3260 21/07/2026 Comunicado con diferencia de hora corregido | M25: PR.AA-01 | N25: =IFERROR(INDEX(dFrente!$B$2:$B$76,MATCH(C25,dFrente!$A$2:$A$76,0)),"Sin frente") -> SailPoint IGA | O25: =IFERROR(INDEX(dNIST!$B$2:$B$13,MATCH(M25,dNIST!$A$2:$A$13,0)),"") -> PR | P25: =TRIM(IFERROR(LEFT(G25,FIND(CHAR(10),G25)-1),G25)) -> Ana María Vergara | Q25: =LEN(TRIM(G25))-LEN(SUBSTITUTE(TRIM(G25),CHAR(10),""))+1 -> 1 | R25: =IF(E25<>"","Sí","No") -> No | S25: =IF(OR(J25="",H25=""),"",IF(J25<=H25,IF(FechaCorte>=J25,1,0),MAX(0,MIN(1,(FechaCorte-H25)/(J25-H25))))) -> 1 | T25: =IF(S25="","",K25-S25) -> 0 | U25: =IF(R25="Sí","Recurrente",IF(K25>=1,"Completado",IF(AND(J25<>"",J25<FechaCorte),"Vencido",IF(AND(K25=0,OR(H25="",H25>FechaCorte)),"Por iniciar",IF(AND(T25<>"",T25<=UmbralRiesgo),"En riesgo","En plazo"))))) -> Completado | V25: =IF(OR(U25="Vencido",U25="En riesgo",U25="En plazo",U25="Por iniciar"),1,0) -> 0 | W25: =IF(U25="Vencido",FechaCorte-J25,"") | X25: =IF(AND(V25=1,U25<>"Vencido"),J25-FechaCorte,"") | Y25: =IF(J25="","",DATE(YEAR(J25),MONTH(J25),1)) -> 46204 | Z25: =IF(AND(U25="Completado",I25<>""),IF(I25<=FechaCorte,DATE(YEAR(I25),MONTH(I25),1),""),"") -> 46204 | AA25: =IF(J25="","",IF(DAY(J25+1)=1,1,0)) -> 0 | AB25: =IF(AND(U25="Completado",I25<>"",I25=J25),1,0) -> 1 | AC25: =IF(AND(K25>=1,I25<>""),IF(I25>FechaCorte,1,0),0) -> 0 | AD25: =IF(AND(I25<>"",H25<>""),IF(I25<H25,1,0),0) -> 0 | AE25: =IF(OR(F25="Riesgos",F25="Obs. Auditoría"),1,0) -> 0 | AF25: =IFERROR(MID(D25,FIND("PMC-",D25),8),"") | AG25: =IF(AND(V25=1,J25<>""),IF(AND(J25>=FechaCorte,J25<=HorizonteExpuestos),1,0),0) -> 0
A26: 25 | B26: 2026 | C26: Gestor de Identidades Sailpoint | Fase 2 | D26: Soporte Assertiva: Flujo Genéricos ATM´s | #2953 (Eliminación) | F26: Mejora | G26: Richard Requelme Ana María Vergara | H26: 46143 | I26: 46173 | J26: 46173 | K26: 1 | L26: Se configura para que se elimine automáticamente el genérico en AD, BANCS y Siglo una vez ingresado por el flujo de eliminación. | M26: PR.AA-05 | N26: =IFERROR(INDEX(dFrente!$B$2:$B$76,MATCH(C26,dFrente!$A$2:$A$76,0)),"Sin frente") -> SailPoint IGA | O26: =IFERROR(INDEX(dNIST!$B$2:$B$13,MATCH(M26,dNIST!$A$2:$A$13,0)),"") -> PR | P26: =TRIM(IFERROR(LEFT(G26,FIND(CHAR(10),G26)-1),G26)) -> Richard Requelme | Q26: =LEN(TRIM(G26))-LEN(SUBSTITUTE(TRIM(G26),CHAR(10),""))+1 -> 2 | R26: =IF(E26<>"","Sí","No") -> No | S26: =IF(OR(J26="",H26=""),"",IF(J26<=H26,IF(FechaCorte>=J26,1,0),MAX(0,MIN(1,(FechaCorte-H26)/(J26-H26))))) -> 1 | T26: =IF(S26="","",K26-S26) -> 0 | U26: =IF(R26="Sí","Recurrente",IF(K26>=1,"Completado",IF(AND(J26<>"",J26<FechaCorte),"Vencido",IF(AND(K26=0,OR(H26="",H26>FechaCorte)),"Por iniciar",IF(AND(T26<>"",T26<=UmbralRiesgo),"En riesgo","En plazo"))))) -> Completado | V26: =IF(OR(U26="Vencido",U26="En riesgo",U26="En plazo",U26="Por iniciar"),1,0) -> 0 | W26: =IF(U26="Vencido",FechaCorte-J26,"") | X26: =IF(AND(V26=1,U26<>"Vencido"),J26-FechaCorte,"") | Y26: =IF(J26="","",DATE(YEAR(J26),MONTH(J26),1)) -> 46143 | Z26: =IF(AND(U26="Completado",I26<>""),IF(I26<=FechaCorte,DATE(YEAR(I26),MONTH(I26),1),""),"") -> 46143 | AA26: =IF(J26="","",IF(DAY(J26+1)=1,1,0)) -> 1 | AB26: =IF(AND(U26="Completado",I26<>"",I26=J26),1,0) -> 1 | AC26: =IF(AND(K26>=1,I26<>""),IF(I26>FechaCorte,1,0),0) -> 0 | AD26: =IF(AND(I26<>"",H26<>""),IF(I26<H26,1,0),0) -> 0 | AE26: =IF(OR(F26="Riesgos",F26="Obs. Auditoría"),1,0) -> 0 | AF26: =IFERROR(MID(D26,FIND("PMC-",D26),8),"") | AG26: =IF(AND(V26=1,J26<>""),IF(AND(J26>=FechaCorte,J26<=HorizonteExpuestos),1,0),0) -> 0
A27: 26 | B27: 2026 | C27: Gestor de Identidades Sailpoint | Fase 2 | D27: Corrección de roles reportados con inconsistencia | E27: Mensual | F27: Operación | G27: Richard Requelme Ana María Vergara | H27: 46113 | K27: 1 | L27: - Las sesiones de revisión de roles se generan una vez al mes con el equipo de Assertiva, se analiza y se realiza las correcciones reportadas - Actividad ejecutada bajo demanda | M27: PR.AA-05 | N27: =IFERROR(INDEX(dFrente!$B$2:$B$76,MATCH(C27,dFrente!$A$2:$A$76,0)),"Sin frente") -> SailPoint IGA | O27: =IFERROR(INDEX(dNIST!$B$2:$B$13,MATCH(M27,dNIST!$A$2:$A$13,0)),"") -> PR | P27: =TRIM(IFERROR(LEFT(G27,FIND(CHAR(10),G27)-1),G27)) -> Richard Requelme | Q27: =LEN(TRIM(G27))-LEN(SUBSTITUTE(TRIM(G27),CHAR(10),""))+1 -> 2 | R27: =IF(E27<>"","Sí","No") -> Sí | S27: =IF(OR(J27="",H27=""),"",IF(J27<=H27,IF(FechaCorte>=J27,1,0),MAX(0,MIN(1,(FechaCorte-H27)/(J27-H27))))) | T27: =IF(S27="","",K27-S27) | U27: =IF(R27="Sí","Recurrente",IF(K27>=1,"Completado",IF(AND(J27<>"",J27<FechaCorte),"Vencido",IF(AND(K27=0,OR(H27="",H27>FechaCorte)),"Por iniciar",IF(AND(T27<>"",T27<=UmbralRiesgo),"En riesgo","En plazo"))))) -> Recurrente | V27: =IF(OR(U27="Vencido",U27="En riesgo",U27="En plazo",U27="Por iniciar"),1,0) -> 0 | W27: =IF(U27="Vencido",FechaCorte-J27,"") | X27: =IF(AND(V27=1,U27<>"Vencido"),J27-FechaCorte,"") | Y27: =IF(J27="","",DATE(YEAR(J27),MONTH(J27),1)) | Z27: =IF(AND(U27="Completado",I27<>""),IF(I27<=FechaCorte,DATE(YEAR(I27),MONTH(I27),1),""),"") | AA27: =IF(J27="","",IF(DAY(J27+1)=1,1,0)) | AB27: =IF(AND(U27="Completado",I27<>"",I27=J27),1,0) -> 0 | AC27: =IF(AND(K27>=1,I27<>""),IF(I27>FechaCorte,1,0),0) -> 0 | AD27: =IF(AND(I27<>"",H27<>""),IF(I27<H27,1,0),0) -> 0 | AE27: =IF(OR(F27="Riesgos",F27="Obs. Auditoría"),1,0) -> 0 | AF27: =IFERROR(MID(D27,FIND("PMC-",D27),8),"") | AG27: =IF(AND(V27=1,J27<>""),IF(AND(J27>=FechaCorte,J27<=HorizonteExpuestos),1,0),0) -> 0
A28: 27 | B28: 2026 | C28: Gestor de Identidades Sailpoint | Fase 2 | D28: Revisión, Ajustes y Corrección Implementación Rol Ejecutivo Integral 2.0 | F28: Proyecto | G28: Ana María Vergara | H28: 46204 | J28: 46218 | K28: 0.5 | L28: - Revisión integral del proceso del levantamiento de roles para el piloto Ejecutivo Integral 2.0 - Corrección de roles asociados - Sesión y comunicación con los responsables del proyecto piloto - Procesamiento de 130 usuarios bajo este esquema - Comunicación del proceso al equipo interno y externo | M28: PR.AA-05 | N28: =IFERROR(INDEX(dFrente!$B$2:$B$76,MATCH(C28,dFrente!$A$2:$A$76,0)),"Sin frente") -> SailPoint IGA | O28: =IFERROR(INDEX(dNIST!$B$2:$B$13,MATCH(M28,dNIST!$A$2:$A$13,0)),"") -> PR | P28: =TRIM(IFERROR(LEFT(G28,FIND(CHAR(10),G28)-1),G28)) -> Ana María Vergara | Q28: =LEN(TRIM(G28))-LEN(SUBSTITUTE(TRIM(G28),CHAR(10),""))+1 -> 1 | R28: =IF(E28<>"","Sí","No") -> No | S28: =IF(OR(J28="",H28=""),"",IF(J28<=H28,IF(FechaCorte>=J28,1,0),MAX(0,MIN(1,(FechaCorte-H28)/(J28-H28))))) -> 1 | T28: =IF(S28="","",K28-S28) -> -0.5 | U28: =IF(R28="Sí","Recurrente",IF(K28>=1,"Completado",IF(AND(J28<>"",J28<FechaCorte),"Vencido",IF(AND(K28=0,OR(H28="",H28>FechaCorte)),"Por iniciar",IF(AND(T28<>"",T28<=UmbralRiesgo),"En riesgo","En plazo"))))) -> Vencido | V28: =IF(OR(U28="Vencido",U28="En riesgo",U28="En plazo",U28="Por iniciar"),1,0) -> 1 | W28: =IF(U28="Vencido",FechaCorte-J28,"") -> 71 | X28: =IF(AND(V28=1,U28<>"Vencido"),J28-FechaCorte,"") | Y28: =IF(J28="","",DATE(YEAR(J28),MONTH(J28),1)) -> 46204 | Z28: =IF(AND(U28="Completado",I28<>""),IF(I28<=FechaCorte,DATE(YEAR(I28),MONTH(I28),1),""),"") | AA28: =IF(J28="","",IF(DAY(J28+1)=1,1,0)) -> 0 | AB28: =IF(AND(U28="Completado",I28<>"",I28=J28),1,0) -> 0 | AC28: =IF(AND(K28>=1,I28<>""),IF(I28>FechaCorte,1,0),0) -> 0 | AD28: =IF(AND(I28<>"",H28<>""),IF(I28<H28,1,0),0) -> 0 | AE28: =IF(OR(F28="Riesgos",F28="Obs. Auditoría"),1,0) -> 0 | AF28: =IFERROR(MID(D28,FIND("PMC-",D28),8),"") | AG28: =IF(AND(V28=1,J28<>""),IF(AND(J28>=FechaCorte,J28<=HorizonteExpuestos),1,0),0) -> 0
A29: 28 | B29: 2026 | C29: Gestor de Identidades Sailpoint | Fase 2 | D29: Revisión y correlación de cuentas huérfanas en AD | F29: Iniciativa | G29: Ana María Vergara Richard Requelme Bryan Uyana | H29: 46266 | J29: 46356 | K29: 0.5 | L29: Se genero el ticket #3446 para identificar la causa raiz | M29: PR.AA-01 | N29: =IFERROR(INDEX(dFrente!$B$2:$B$76,MATCH(C29,dFrente!$A$2:$A$76,0)),"Sin frente") -> SailPoint IGA | O29: =IFERROR(INDEX(dNIST!$B$2:$B$13,MATCH(M29,dNIST!$A$2:$A$13,0)),"") -> PR | P29: =TRIM(IFERROR(LEFT(G29,FIND(CHAR(10),G29)-1),G29)) -> Ana María Vergara | Q29: =LEN(TRIM(G29))-LEN(SUBSTITUTE(TRIM(G29),CHAR(10),""))+1 -> 3 | R29: =IF(E29<>"","Sí","No") -> No | S29: =IF(OR(J29="",H29=""),"",IF(J29<=H29,IF(FechaCorte>=J29,1,0),MAX(0,MIN(1,(FechaCorte-H29)/(J29-H29))))) -> 0.25555556 | T29: =IF(S29="","",K29-S29) -> 0.24444444 | U29: =IF(R29="Sí","Recurrente",IF(K29>=1,"Completado",IF(AND(J29<>"",J29<FechaCorte),"Vencido",IF(AND(K29=0,OR(H29="",H29>FechaCorte)),"Por iniciar",IF(AND(T29<>"",T29<=UmbralRiesgo),"En riesgo","En plazo"))))) -> En plazo | V29: =IF(OR(U29="Vencido",U29="En riesgo",U29="En plazo",U29="Por iniciar"),1,0) -> 1 | W29: =IF(U29="Vencido",FechaCorte-J29,"") | X29: =IF(AND(V29=1,U29<>"Vencido"),J29-FechaCorte,"") -> 67 | Y29: =IF(J29="","",DATE(YEAR(J29),MONTH(J29),1)) -> 46327 | Z29: =IF(AND(U29="Completado",I29<>""),IF(I29<=FechaCorte,DATE(YEAR(I29),MONTH(I29),1),""),"") | AA29: =IF(J29="","",IF(DAY(J29+1)=1,1,0)) -> 1 | AB29: =IF(AND(U29="Completado",I29<>"",I29=J29),1,0) -> 0 | AC29: =IF(AND(K29>=1,I29<>""),IF(I29>FechaCorte,1,0),0) -> 0 | AD29: =IF(AND(I29<>"",H29<>""),IF(I29<H29,1,0),0) -> 0 | AE29: =IF(OR(F29="Riesgos",F29="Obs. Auditoría"),1,0) -> 0 | AF29: =IFERROR(MID(D29,FIND("PMC-",D29),8),"") | AG29: =IF(AND(V29=1,J29<>""),IF(AND(J29>=FechaCorte,J29<=HorizonteExpuestos),1,0),0) -> 0
A30: 29 | B30: 2026 | C30: Gestor de Identidades Sailpoint | Fase 2 | D30: Cambio en el ciclo de vida de offboarding para usuarios internos y externos en AD. (No se mantendrán por 30 días, se eliminará el mismo día). | F30: Proyecto | G30: Ana María Vergara | H30: 46202 | J30: 46280 | K30: 0.7 | L30: - Solicitud soporte Assertiva ticket #3089 - Análisis de impacto sobre identidades VIP o excepcionadas - Se mantendrá una sesión el viernes 24/06/2026 con el equipo de Assertiva para realizar pruebas sobre el grupo de excepción de AD, para garantizar que la cuenta se mantenga y no sea eliminada - Eliminación lista marcada sobre usuarios excepcionados en NERM, para manejar un proceso transversal para todas las identidades - 17/08/2026 Se crea el grupo de AD: Grupo usuarios VIP, para agregar a los usuarios que requieren excepción en el proceso de offboarding | M30: PR.AA-01 | N30: =IFERROR(INDEX(dFrente!$B$2:$B$76,MATCH(C30,dFrente!$A$2:$A$76,0)),"Sin frente") -> SailPoint IGA | O30: =IFERROR(INDEX(dNIST!$B$2:$B$13,MATCH(M30,dNIST!$A$2:$A$13,0)),"") -> PR | P30: =TRIM(IFERROR(LEFT(G30,FIND(CHAR(10),G30)-1),G30)) -> Ana María Vergara | Q30: =LEN(TRIM(G30))-LEN(SUBSTITUTE(TRIM(G30),CHAR(10),""))+1 -> 1 | R30: =IF(E30<>"","Sí","No") -> No | S30: =IF(OR(J30="",H30=""),"",IF(J30<=H30,IF(FechaCorte>=J30,1,0),MAX(0,MIN(1,(FechaCorte-H30)/(J30-H30))))) -> 1 | T30: =IF(S30="","",K30-S30) -> -0.3 | U30: =IF(R30="Sí","Recurrente",IF(K30>=1,"Completado",IF(AND(J30<>"",J30<FechaCorte),"Vencido",IF(AND(K30=0,OR(H30="",H30>FechaCorte)),"Por iniciar",IF(AND(T30<>"",T30<=UmbralRiesgo),"En riesgo","En plazo"))))) -> Vencido | V30: =IF(OR(U30="Vencido",U30="En riesgo",U30="En plazo",U30="Por iniciar"),1,0) -> 1 | W30: =IF(U30="Vencido",FechaCorte-J30,"") -> 9 | X30: =IF(AND(V30=1,U30<>"Vencido"),J30-FechaCorte,"") | Y30: =IF(J30="","",DATE(YEAR(J30),MONTH(J30),1)) -> 46266 | Z30: =IF(AND(U30="Completado",I30<>""),IF(I30<=FechaCorte,DATE(YEAR(I30),MONTH(I30),1),""),"") | AA30: =IF(J30="","",IF(DAY(J30+1)=1,1,0)) -> 0 | AB30: =IF(AND(U30="Completado",I30<>"",I30=J30),1,0) -> 0 | AC30: =IF(AND(K30>=1,I30<>""),IF(I30>FechaCorte,1,0),0) -> 0 | AD30: =IF(AND(I30<>"",H30<>""),IF(I30<H30,1,0),0) -> 0 | AE30: =IF(OR(F30="Riesgos",F30="Obs. Auditoría"),1,0) -> 0 | AF30: =IFERROR(MID(D30,FIND("PMC-",D30),8),"") | AG30: =IF(AND(V30=1,J30<>""),IF(AND(J30>=FechaCorte,J30<=HorizonteExpuestos),1,0),0) -> 0
