Workbook

Sheet Guía
A1: Gestión de Identidades 2026 — Especificación del modelo de datos y DAX
A2: Todo lo necesario para reconstruir en Power BI el dashboard ejecutivo del PDF. Fecha de corte de referencia: 17/09/2026.
A3: Hoja | B3: Contenido | C3: Cómo usarla
A5: Hoja | B5: Contenido | C5: Cómo usarla
A6: Parámetros | B6: Fecha de corte y metas de cada KPI. | C6: Única hoja editable. Cambiar la fecha de corte recalcula toda la hoja F_Hitos y la validación. En Power BI se replica como tabla desconectada D_Parametros.
A7: F_Hitos | B7: Los 177 hitos con las 6 columnas calculadas implementadas en fórmula Excel viva. | C7: Sirve como prueba de concepto y como fuente si se trabaja solo en Excel. Las columnas M a R se recalculan solas.
A8: Tablas del Modelo | B8: Esquema estrella: tablas, campos, tipo de dato y relaciones. | C8: Construir en este orden: dimensiones, hechos, relaciones, columnas calculadas, medidas.
A9: Columnas Calculadas | B9: 7 columnas con su DAX y su equivalente en fórmula Excel. | C9: Crear en Power BI como columnas calculadas sobre F_Hitos, nunca como medidas: se usan para filtrar y segmentar.
A10: Medidas DAX | B10: 26 medidas organizadas por carpeta, con formato, interpretación y valor esperado al corte. | C10: Copiar el DAX tal cual. Verificar cada valor contra la columna "Valor al corte".
A11: Calendario y Cortes | B11: DAX de D_Calendario y D_Corte (snapshots mensuales). | C11: D_Corte es lo único que hoy no existe en el origen y es obligatorio para el KPI de tendencia.
A12: Visuales del Dashboard | B12: Los 12 visuales del PDF con sus campos, medidas y formato condicional. | C12: Una fila por visual: qué tipo usar, qué va en cada área de datos y cómo pintarlo.
A13: Semáforo y Formato | B13: Reglas de color, umbrales y medidas de color dinámico. | C13: Un solo criterio de semáforo para todo el informe.
A14: Reglas NIST | B14: Reglas de palabra clave que generan la clasificación NIST propuesta. | C14: La columna NIST viene vacía en el origen; estas reglas la reconstruyen. Requiere validación del área.
A15: Validación | B15: 18 cifras de control calculadas en vivo sobre F_Hitos. | C15: Si una medida DAX no coincide con estos valores, el error está en el modelo, no en el visual.
A16: Orden de implementación sugerido
A17: # | B17: Paso | C17: Detalle
A19: 1 | B19: Saneamiento del origen | C19: Completar NIST, criticidad y las 22 fechas fin de planificación faltantes. Desdoblar la columna Encargado (hasta 3 nombres por celda) en una tabla puente.
A20: 2 | B20: Carga y modelo | C20: Crear las dimensiones y F_Hitos, marcar D_Calendario como tabla de fechas y establecer las 5 relaciones.
A21: 3 | B21: Columnas calculadas | C21: Las 7 columnas de la hoja correspondiente. Validar Estado y Avance_Esperado antes de seguir.
A22: 4 | B22: Medidas base | C22: Las 12 medidas de las carpetas 00_Base y 01_Avance. Contrastar con la hoja Validación.
A23: 5 | B23: Medidas de KPI y riesgo | C23: Carpetas 02_KPI, 03_Riesgo y 04_Tendencia.
A24: 6 | B24: Visuales | C24: Construir página por página siguiendo la hoja Visuales del Dashboard.
A25: 7 | B25: Snapshot mensual | C25: Programar la escritura de D_Corte el último día hábil de cada mes; sin esto no hay tendencia ni curva histórica.

Sheet Parámetros
A1: Parámetros del tablero
A2: Celdas amarillas = editables. Todo el libro y las medidas DAX las referencian.
A3: Parámetro | B3: Valor | C3: Nombre en Power BI | D3: Uso
B4: 46282
A5: Fecha de corte | B5: 2026-09-17 | C5: Corte | D5: Base de Avance_Esperado, Estado y Días_Vencidos. En DAX se resuelve con MAX(D_Corte[Fecha_Corte]).
A6: Meta ICP | B6: 0.95 | C6: Meta_ICP | D6: Umbral verde del índice de cumplimiento.
A7: Meta % hitos atrasados | B7: 0.1 | C7: Meta_Atrasados | D7: Máximo tolerado de hitos vencidos.
A8: Meta días de atraso | B8: 15 | C8: Meta_Dias | D8: Máximo tolerado de desviación promedio.
A9: Meta % críticos completados | B9: 0.8 | C9: Meta_Criticos | D9: Mínimo de hitos de proyecto, riesgo y auditoría cerrados.
A10: Meta SLA de cierre en fecha | B10: 0.9 | C10: Meta_SLA | D10: Mínimo de hitos cerrados dentro de su fecha planificada.
A11: Meta desviación (pp) | B11: -0.05 | C11: Meta_Desviacion | D11: Brecha máxima tolerada entre avance real y esperado.
A12: Tolerancia ámbar | B12: 46296 | C12: Tol_Ambar | D12: Un KPI hasta 15% bajo su meta es ámbar; más abajo, rojo.
A13: Inicio del Q4 | B13: 2026-10-01 | C13: Inicio_Q4 | D13: Corte para la medida de carga pendiente del último trimestre.

Sheet F_Hitos
A1: Periodo | B1: Frente | C1: Hito | D1: Tipo_Actividad | E1: Responsable_Principal | F1: Encargados | G1: Fecha_Inicio | H1: Fecha_Fin_Plan | I1: Fecha_Fin_Real | J1: Avance_Real | K1: NIST_Propuesto | L1: Observacion | M1: Avance_Esperado | N1: Desviacion_pp | O1: Estado | P1: Dias_Vencidos | Q1: Es_Critica | R1: Cerrado_En_Fecha
A2: 2026 | B2: Gestor de Identidades Sailpoint | Fase 1 | C2: Integración con fuente autoritativa de internos Success Factors | Conector nativo | D2: Iniciativa | E2: Ana María Vergara | F2: Ana María Vergara | G2: 45658 | H2: 46084 | I2: 46087 | J2: 1 | K2: PROTECT | M2: =IF(OR(G2="",H2=""),"",IF(H2<=G2,1,MIN(1,MAX(0,(Parámetros!$B$4-G2)/(H2-G2))))) -> 1 | N2: =IF(M2="","",J2-M2) -> 0 | O2: =IF(J2>=1,"Completado",IF(H2="","Sin fecha plan",IF(H2<Parámetros!$B$4,"Atrasado",IF(J2<=0,"No iniciado","En proceso")))) -> Completado | P2: =IF(AND(J2<1,H2<>"",H2<Parámetros!$B$4),Parámetros!$B$4-H2,0) -> 0 | Q2: =IF(OR(D2="Proyecto",D2="Riesgos",D2="Obs. Auditoría"),"Sí","No") -> No | R2: =IF(I2="","",IF(I2<=H2,1,0)) -> 0
A3: 2026 | B3: Gestor de Identidades Sailpoint | Fase 1 | C3: Integración aplicaciones conectadas: AD, EntraID, Bancs, Siglo21, RHDS y Logiflow | D3: Iniciativa | E3: Ana María Vergara | F3: Ana María Vergara | G3: 45658 | H3: 46084 | I3: 46087 | J3: 1 | K3: PROTECT | M3: =IF(OR(G3="",H3=""),"",IF(H3<=G3,1,MIN(1,MAX(0,(Parámetros!$B$4-G3)/(H3-G3))))) -> 1 | N3: =IF(M3="","",J3-M3) -> 0 | O3: =IF(J3>=1,"Completado",IF(H3="","Sin fecha plan",IF(H3<Parámetros!$B$4,"Atrasado",IF(J3<=0,"No iniciado","En proceso")))) -> Completado | P3: =IF(AND(J3<1,H3<>"",H3<Parámetros!$B$4),Parámetros!$B$4-H3,0) -> 0 | Q3: =IF(OR(D3="Proyecto",D3="Riesgos",D3="Obs. Auditoría"),"Sí","No") -> No | R3: =IF(I3="","",IF(I3<=H3,1,0)) -> 0
A4: 2026 | B4: Gestor de Identidades Sailpoint | Fase 1 | C4: Implementación módulo usuarios externos y genéricos NERM | D4: Iniciativa | E4: Ana María Vergara | F4: Ana María Vergara | G4: 45839 | H4: 46084 | I4: 46087 | J4: 1 | K4: PROTECT | M4: =IF(OR(G4="",H4=""),"",IF(H4<=G4,1,MIN(1,MAX(0,(Parámetros!$B$4-G4)/(H4-G4))))) -> 1 | N4: =IF(M4="","",J4-M4) -> 0 | O4: =IF(J4>=1,"Completado",IF(H4="","Sin fecha plan",IF(H4<Parámetros!$B$4,"Atrasado",IF(J4<=0,"No iniciado","En proceso")))) -> Completado | P4: =IF(AND(J4<1,H4<>"",H4<Parámetros!$B$4),Parámetros!$B$4-H4,0) -> 0 | Q4: =IF(OR(D4="Proyecto",D4="Riesgos",D4="Obs. Auditoría"),"Sí","No") -> No | R4: =IF(I4="","",IF(I4<=H4,1,0)) -> 0
A5: 2026 | B5: Gestor de Identidades Sailpoint | Fase 1 | C5: Depuración accesos acorde al cargo Red de Agencias | D5: Iniciativa | E5: Ana María Fierro | F5: Ana María Fierro | G5: 45962 | H5: 46087 | I5: 46087 | J5: 1 | K5: PROTECT | M5: =IF(OR(G5="",H5=""),"",IF(H5<=G5,1,MIN(1,MAX(0,(Parámetros!$B$4-G5)/(H5-G5))))) -> 1 | N5: =IF(M5="","",J5-M5) -> 0 | O5: =IF(J5>=1,"Completado",IF(H5="","Sin fecha plan",IF(H5<Parámetros!$B$4,"Atrasado",IF(J5<=0,"No iniciado","En proceso")))) -> Completado | P5: =IF(AND(J5<1,H5<>"",H5<Parámetros!$B$4),Parámetros!$B$4-H5,0) -> 0 | Q5: =IF(OR(D5="Proyecto",D5="Riesgos",D5="Obs. Auditoría"),"Sí","No") -> No | R5: =IF(I5="","",IF(I5<=H5,1,0)) -> 1
A6: 2026 | B6: Gestor de Identidades Sailpoint | Fase 1 | C6: Depuración accesos acorde al cargo Microfinanzas | Tecnología | Banca Personas | D6: Iniciativa | E6: Ana María Fierro | F6: Ana María Fierro | G6: 45992 | H6: 46387 | J6: 0.5 | K6: PROTECT | M6: =IF(OR(G6="",H6=""),"",IF(H6<=G6,1,MIN(1,MAX(0,(Parámetros!$B$4-G6)/(H6-G6))))) -> 0.73417722 | N6: =IF(M6="","",J6-M6) -> -0.23417722 | O6: =IF(J6>=1,"Completado",IF(H6="","Sin fecha plan",IF(H6<Parámetros!$B$4,"Atrasado",IF(J6<=0,"No iniciado","En proceso")))) -> En proceso | P6: =IF(AND(J6<1,H6<>"",H6<Parámetros!$B$4),Parámetros!$B$4-H6,0) -> 0 | Q6: =IF(OR(D6="Proyecto",D6="Riesgos",D6="Obs. Auditoría"),"Sí","No") -> No | R6: =IF(I6="","",IF(I6<=H6,1,0))
A7: 2026 | B7: Gestor de Identidades Sailpoint | Fase 1 | C7: Implementación modelo de accesos basado en roles | D7: Iniciativa | E7: Richard Requelme | F7: Richard Requelme | G7: 46082 | H7: 46084 | I7: 46084 | J7: 1 | K7: PROTECT | M7: =IF(OR(G7="",H7=""),"",IF(H7<=G7,1,MIN(1,MAX(0,(Parámetros!$B$4-G7)/(H7-G7))))) -> 1 | N7: =IF(M7="","",J7-M7) -> 0 | O7: =IF(J7>=1,"Completado",IF(H7="","Sin fecha plan",IF(H7<Parámetros!$B$4,"Atrasado",IF(J7<=0,"No iniciado","En proceso")))) -> Completado | P7: =IF(AND(J7<1,H7<>"",H7<Parámetros!$B$4),Parámetros!$B$4-H7,0) -> 0 | Q7: =IF(OR(D7="Proyecto",D7="Riesgos",D7="Obs. Auditoría"),"Sí","No") -> No | R7: =IF(I7="","",IF(I7<=H7,1,0)) -> 1
A8: 2026 | B8: Gestor de Identidades Sailpoint | Fase 1 | C8: Eliminación de accesos a personal de Negocios (Red de Agencias) para cambiar perfiles globales y centros de costos directamente. | D8: Iniciativa | E8: Ana María Fierro | F8: Ana María Fierro | G8: 46082 | H8: 46080 | I8: 46080 | J8: 1 | K8: PROTECT | L8: Gestionaban 1478 requerimientos al mes, que pasaron a GI. | M8: =IF(OR(G8="",H8=""),"",IF(H8<=G8,1,MIN(1,MAX(0,(Parámetros!$B$4-G8)/(H8-G8))))) -> 1 | N8: =IF(M8="","",J8-M8) -> 0 | O8: =IF(J8>=1,"Completado",IF(H8="","Sin fecha plan",IF(H8<Parámetros!$B$4,"Atrasado",IF(J8<=0,"No iniciado","En proceso")))) -> Completado | P8: =IF(AND(J8<1,H8<>"",H8<Parámetros!$B$4),Parámetros!$B$4-H8,0) -> 0 | Q8: =IF(OR(D8="Proyecto",D8="Riesgos",D8="Obs. Auditoría"),"Sí","No") -> No | R8: =IF(I8="","",IF(I8<=H8,1,0)) -> 1
A9: 2026 | B9: Gestor de Identidades Sailpoint | Fase 2 | C9: Inactivar cuentas de usuarios por vacaciones/licencias/maternidad, etc. (Flujo y revisión RRHH) | D9: Iniciativa | E9: Ana María Vergara | F9: Ana María Vergara | G9: 46327 | H9: 46387 | J9: 0 | K9: PROTECT | L9: Dependencia de revisión con RRHH. Se realizará el acercamiento para validar la factibilidad de implementación | M9: =IF(OR(G9="",H9=""),"",IF(H9<=G9,1,MIN(1,MAX(0,(Parámetros!$B$4-G9)/(H9-G9))))) -> 0 | N9: =IF(M9="","",J9-M9) -> 0 | O9: =IF(J9>=1,"Completado",IF(H9="","Sin fecha plan",IF(H9<Parámetros!$B$4,"Atrasado",IF(J9<=0,"No iniciado","En proceso")))) -> No iniciado | P9: =IF(AND(J9<1,H9<>"",H9<Parámetros!$B$4),Parámetros!$B$4-H9,0) -> 0 | Q9: =IF(OR(D9="Proyecto",D9="Riesgos",D9="Obs. Auditoría"),"Sí","No") -> No | R9: =IF(I9="","",IF(I9<=H9,1,0))
A10: 2026 | B10: Gestor de Identidades Sailpoint | Fase 2 | C10: Evaluación automatización y Monitoreo de Accesos VPN Integrado a ISC SailPoint | D10: Iniciativa | E10: Jhonny Barreiro | F10: Jhonny Barreiro | G10: 46143 | H10: 46235 | J10: 0.05 | K10: DETECT | L10: en diseño de definiciones | M10: =IF(OR(G10="",H10=""),"",IF(H10<=G10,1,MIN(1,MAX(0,(Parámetros!$B$4-G10)/(H10-G10))))) -> 1 | N10: =IF(M10="","",J10-M10) -> -0.95 | O10: =IF(J10>=1,"Completado",IF(H10="","Sin fecha plan",IF(H10<Parámetros!$B$4,"Atrasado",IF(J10<=0,"No iniciado","En proceso")))) -> Atrasado | P10: =IF(AND(J10<1,H10<>"",H10<Parámetros!$B$4),Parámetros!$B$4-H10,0) -> 47 | Q10: =IF(OR(D10="Proyecto",D10="Riesgos",D10="Obs. Auditoría"),"Sí","No") -> No | R10: =IF(I10="","",IF(I10<=H10,1,0))
A11: 2026 | B11: Gestor de Identidades Sailpoint | Fase 2 | C11: Implementar la deshabilitación automática en SailPoint para el offboarding de internos | D11: Iniciativa | E11: Ana María Vergara | F11: Ana María Vergara | G11: 46143 | H11: 46143 | I11: 46143 | J11: 1 | K11: PROTECT | L11: Flujo implementado dependencia con "end date" consumido desde SSFF | M11: =IF(OR(G11="",H11=""),"",IF(H11<=G11,1,MIN(1,MAX(0,(Parámetros!$B$4-G11)/(H11-G11))))) -> 1 | N11: =IF(M11="","",J11-M11) -> 0 | O11: =IF(J11>=1,"Completado",IF(H11="","Sin fecha plan",IF(H11<Parámetros!$B$4,"Atrasado",IF(J11<=0,"No iniciado","En proceso")))) -> Completado | P11: =IF(AND(J11<1,H11<>"",H11<Parámetros!$B$4),Parámetros!$B$4-H11,0) -> 0 | Q11: =IF(OR(D11="Proyecto",D11="Riesgos",D11="Obs. Auditoría"),"Sí","No") -> No | R11: =IF(I11="","",IF(I11<=H11,1,0)) -> 1
A12: 2026 | B12: Gestor de Identidades Sailpoint | Fase 2 | C12: Ajustar las notificaciones generadas por ISC para retirar informaión sensible. Ajustar formatos | D12: Mejora | E12: Ana María Vergara | F12: Ana María Vergara | G12: 46143 | H12: 46387 | J12: 0.25 | K12: PROTECT | L12: - Revisión integral de datos sensibles en comunicados fueron retirados - Flujo notificación onboarding de usuarios externos revisado e implementado - Fecha fin vigencia externos (comunicado). | M12: =IF(OR(G12="",H12=""),"",IF(H12<=G12,1,MIN(1,MAX(0,(Parámetros!$B$4-G12)/(H12-G12))))) -> 0.56967213 | N12: =IF(M12="","",J12-M12) -> -0.31967213 | O12: =IF(J12>=1,"Completado",IF(H12="","Sin fecha plan",IF(H12<Parámetros!$B$4,"Atrasado",IF(J12<=0,"No iniciado","En proceso")))) -> En proceso | P12: =IF(AND(J12<1,H12<>"",H12<Parámetros!$B$4),Parámetros!$B$4-H12,0) -> 0 | Q12: =IF(OR(D12="Proyecto",D12="Riesgos",D12="Obs. Auditoría"),"Sí","No") -> No | R12: =IF(I12="","",IF(I12<=H12,1,0))
A13: 2026 | B13: Gestor de Identidades Sailpoint | Fase 2 | C13: Revisión duplicidad tickets generados desde ISC | D13: Mejora | E13: Ana María Vergara | F13: Ana María Vergara | G13: 46143 | H13: 46326 | J13: 0.75 | K13: PROTECT | L13: - En proceso de revisión dependencia con la marca SailPoint - Se requiere soporte del proveedor Heaven a espera de apertura de adenda de servicios - 16 Sept 2026 se realizaron las pruebas en ambiente de test y se desplegaron de forma exitosa. Se sol | M13: =IF(OR(G13="",H13=""),"",IF(H13<=G13,1,MIN(1,MAX(0,(Parámetros!$B$4-G13)/(H13-G13))))) -> 0.75956284 | N13: =IF(M13="","",J13-M13) -> -0.0095628415 | O13: =IF(J13>=1,"Completado",IF(H13="","Sin fecha plan",IF(H13<Parámetros!$B$4,"Atrasado",IF(J13<=0,"No iniciado","En proceso")))) -> En proceso | P13: =IF(AND(J13<1,H13<>"",H13<Parámetros!$B$4),Parámetros!$B$4-H13,0) -> 0 | Q13: =IF(OR(D13="Proyecto",D13="Riesgos",D13="Obs. Auditoría"),"Sí","No") -> No | R13: =IF(I13="","",IF(I13<=H13,1,0))
A14: 2026 | B14: Gestor de Identidades Sailpoint | Fase 2 | C14: Ajustar configuración para catálogo "Cambio Centro Costos" reducción generación tickets | D14: Mejora | E14: Ana María Vergara | F14: Ana María Vergara | G14: 46143 | H14: 46173 | I14: 46173 | J14: 1 | K14: PROTECT | L14: Se implemento el ajuste en SailPoint para que solo consuma las aplicaciones en las que se debe generar un cambio en el centro de costos | M14: =IF(OR(G14="",H14=""),"",IF(H14<=G14,1,MIN(1,MAX(0,(Parámetros!$B$4-G14)/(H14-G14))))) -> 1 | N14: =IF(M14="","",J14-M14) -> 0 | O14: =IF(J14>=1,"Completado",IF(H14="","Sin fecha plan",IF(H14<Parámetros!$B$4,"Atrasado",IF(J14<=0,"No iniciado","En proceso")))) -> Completado | P14: =IF(AND(J14<1,H14<>"",H14<Parámetros!$B$4),Parámetros!$B$4-H14,0) -> 0 | Q14: =IF(OR(D14="Proyecto",D14="Riesgos",D14="Obs. Auditoría"),"Sí","No") -> No | R14: =IF(I14="","",IF(I14<=H14,1,0)) -> 1
A15: 2026 | B15: Gestor de Identidades Sailpoint | Fase 2 | C15: Cambio de dominio de sailpoint.com a pichincha.com para las notificaciones generadas. | D15: Mejora | E15: Ana María Vergara | F15: Ana María Vergara | G15: 46113 | H15: 46153 | I15: 46153 | J15: 1 | K15: PROTECT | M15: =IF(OR(G15="",H15=""),"",IF(H15<=G15,1,MIN(1,MAX(0,(Parámetros!$B$4-G15)/(H15-G15))))) -> 1 | N15: =IF(M15="","",J15-M15) -> 0 | O15: =IF(J15>=1,"Completado",IF(H15="","Sin fecha plan",IF(H15<Parámetros!$B$4,"Atrasado",IF(J15<=0,"No iniciado","En proceso")))) -> Completado | P15: =IF(AND(J15<1,H15<>"",H15<Parámetros!$B$4),Parámetros!$B$4-H15,0) -> 0 | Q15: =IF(OR(D15="Proyecto",D15="Riesgos",D15="Obs. Auditoría"),"Sí","No") -> No | R15: =IF(I15="","",IF(I15<=H15,1,0)) -> 1
A16: 2026 | B16: Gestor de Identidades Sailpoint | Fase 2 | C16: Sincronización Campo AD Manager | D16: Mejora | E16: Ana María Vergara | F16: Ana María Vergara | G16: 46143 | H16: 46155 | I16: 46155 | J16: 1 | K16: PROTECT | M16: =IF(OR(G16="",H16=""),"",IF(H16<=G16,1,MIN(1,MAX(0,(Parámetros!$B$4-G16)/(H16-G16))))) -> 1 | N16: =IF(M16="","",J16-M16) -> 0 | O16: =IF(J16>=1,"Completado",IF(H16="","Sin fecha plan",IF(H16<Parámetros!$B$4,"Atrasado",IF(J16<=0,"No iniciado","En proceso")))) -> Completado | P16: =IF(AND(J16<1,H16<>"",H16<Parámetros!$B$4),Parámetros!$B$4-H16,0) -> 0 | Q16: =IF(OR(D16="Proyecto",D16="Riesgos",D16="Obs. Auditoría"),"Sí","No") -> No | R16: =IF(I16="","",IF(I16<=H16,1,0)) -> 1
A17: 2026 | B17: Gestor de Identidades Sailpoint | Fase 2 | C17: Depuración usuarios duplicados en AD | Identificación y corrección de inconsistencias asociadas a la causa raíz | D17: Incidencia | E17: Ana María Vergara | F17: Ana María Vergara | G17: 46155 | H17: 46161 | I17: 46161 | J17: 1 | K17: RESPOND | L17: 108 usuarios duplicados. Se incluye en el control mensual de TCS. | M17: =IF(OR(G17="",H17=""),"",IF(H17<=G17,1,MIN(1,MAX(0,(Parámetros!$B$4-G17)/(H17-G17))))) -> 1 | N17: =IF(M17="","",J17-M17) -> 0 | O17: =IF(J17>=1,"Completado",IF(H17="","Sin fecha plan",IF(H17<Parámetros!$B$4,"Atrasado",IF(J17<=0,"No iniciado","En proceso")))) -> Completado | P17: =IF(AND(J17<1,H17<>"",H17<Parámetros!$B$4),Parámetros!$B$4-H17,0) -> 0 | Q17: =IF(OR(D17="Proyecto",D17="Riesgos",D17="Obs. Auditoría"),"Sí","No") -> No | R17: =IF(I17="","",IF(I17<=H17,1,0)) -> 1
A18: 2026 | B18: Gestor de Identidades Sailpoint | Fase 2 | C18: Modificación campo "Last Name" en Externos y revisar novedad en los apellidos que se envia desde ISC hacia el AD. | D18: Iniciativa | E18: Ana María Vergara | F18: Ana María Vergara Jhonny Barreiro | G18: 46155 | H18: 46168 | I18: 46168 | J18: 1 | K18: PROTECT | M18: =IF(OR(G18="",H18=""),"",IF(H18<=G18,1,MIN(1,MAX(0,(Parámetros!$B$4-G18)/(H18-G18))))) -> 1 | N18: =IF(M18="","",J18-M18) -> 0 | O18: =IF(J18>=1,"Completado",IF(H18="","Sin fecha plan",IF(H18<Parámetros!$B$4,"Atrasado",IF(J18<=0,"No iniciado","En proceso")))) -> Completado | P18: =IF(AND(J18<1,H18<>"",H18<Parámetros!$B$4),Parámetros!$B$4-H18,0) -> 0 | Q18: =IF(OR(D18="Proyecto",D18="Riesgos",D18="Obs. Auditoría"),"Sí","No") -> No | R18: =IF(I18="","",IF(I18<=H18,1,0)) -> 1
A19: 2026 | B19: Gestor de Identidades Sailpoint | Fase 2 | C19: Revisión de Fusion: Integración de aplicación - Revisión de lectura y aprovisionamiento automatizado por Sailpoint a Fusion | D19: Iniciativa | E19: Richard Requelme | F19: Richard Requelme Ana María Vergara | G19: 46213 | H19: 46265 | J19: 0.9 | K19: PROTECT | L19: 15- sep - Se crearon los roles, pendiente análisis de Assertiva para creación de APs 17-Ago - Se ejecutaron las pruebas del conector, fueron exitosas. Pendiente confirmar roles con Agencia y Dueño de app Se encendio el conector en modo lectura, se l | M19: =IF(OR(G19="",H19=""),"",IF(H19<=G19,1,MIN(1,MAX(0,(Parámetros!$B$4-G19)/(H19-G19))))) -> 1 | N19: =IF(M19="","",J19-M19) -> -0.1 | O19: =IF(J19>=1,"Completado",IF(H19="","Sin fecha plan",IF(H19<Parámetros!$B$4,"Atrasado",IF(J19<=0,"No iniciado","En proceso")))) -> Atrasado | P19: =IF(AND(J19<1,H19<>"",H19<Parámetros!$B$4),Parámetros!$B$4-H19,0) -> 17 | Q19: =IF(OR(D19="Proyecto",D19="Riesgos",D19="Obs. Auditoría"),"Sí","No") -> No | R19: =IF(I19="","",IF(I19<=H19,1,0))
A20: 2026 | B20: Gestor de Identidades Sailpoint | Fase 2 | C20: Análisis integración Monitoreo de Fraude | D20: Proyecto | E20: Ana María Vergara | F20: Ana María Vergara Richard Requelme Jhonny Barreiro | G20: 46113 | H20: 46295 | J20: 0.7 | K20: DETECT | L20: - 17-ago- Se corrigio el esquema y está pendiente del lado del dueño del aplicativo la confirmación de la integración total (auth + autorización) Monitoreo Fraude: Acercamiento con el proyecto en revisión de integración con Entra ID (autenticación) | M20: =IF(OR(G20="",H20=""),"",IF(H20<=G20,1,MIN(1,MAX(0,(Parámetros!$B$4-G20)/(H20-G20))))) -> 0.92857143 | N20: =IF(M20="","",J20-M20) -> -0.22857143 | O20: =IF(J20>=1,"Completado",IF(H20="","Sin fecha plan",IF(H20<Parámetros!$B$4,"Atrasado",IF(J20<=0,"No iniciado","En proceso")))) -> En proceso | P20: =IF(AND(J20<1,H20<>"",H20<Parámetros!$B$4),Parámetros!$B$4-H20,0) -> 0 | Q20: =IF(OR(D20="Proyecto",D20="Riesgos",D20="Obs. Auditoría"),"Sí","No") -> Sí | R20: =IF(I20="","",IF(I20<=H20,1,0))
A21: 2026 | B21: Gestor de Identidades Sailpoint | Fase 2 | C21: Análisis integración AS400 - GAF | D21: Proyecto | E21: Ana María Vergara | F21: Ana María Vergara | G21: 46113 | H21: 46387 | J21: 0.5 | K21: IDENTIFY | L21: - GAF: Solicitud interdependencia a la célula. En etapa de evaluación - 17/08/2026 Se identificó la necesidad de construir un microservicio para disponibilizar la información que consume SailPoint. El proveedor NTTData compartió una proforma para l | M21: =IF(OR(G21="",H21=""),"",IF(H21<=G21,1,MIN(1,MAX(0,(Parámetros!$B$4-G21)/(H21-G21))))) -> 0.61678832 | N21: =IF(M21="","",J21-M21) -> -0.11678832 | O21: =IF(J21>=1,"Completado",IF(H21="","Sin fecha plan",IF(H21<Parámetros!$B$4,"Atrasado",IF(J21<=0,"No iniciado","En proceso")))) -> En proceso | P21: =IF(AND(J21<1,H21<>"",H21<Parámetros!$B$4),Parámetros!$B$4-H21,0) -> 0 | Q21: =IF(OR(D21="Proyecto",D21="Riesgos",D21="Obs. Auditoría"),"Sí","No") -> Sí | R21: =IF(I21="","",IF(I21<=H21,1,0))
A22: 2026 | B22: Gestor de Identidades Sailpoint | Fase 2 | C22: Análisis integración PIVI - CAO (Interdin) | D22: Proyecto | E22: Ana María Vergara | F22: Ana María Vergara | G22: 46113 | H22: 46387 | J22: 0.5 | K22: IDENTIFY | L22: - PIVI | CAO: Solicitud interdependencia a la célula. En etapa de evaluación - 17/08/2026 La célula de Interdin - William Correa comunica que por temas de capacidad no es viable contar con el análisis técnico de integración por lo que quedaría en ba | M22: =IF(OR(G22="",H22=""),"",IF(H22<=G22,1,MIN(1,MAX(0,(Parámetros!$B$4-G22)/(H22-G22))))) -> 0.61678832 | N22: =IF(M22="","",J22-M22) -> -0.11678832 | O22: =IF(J22>=1,"Completado",IF(H22="","Sin fecha plan",IF(H22<Parámetros!$B$4,"Atrasado",IF(J22<=0,"No iniciado","En proceso")))) -> En proceso | P22: =IF(AND(J22<1,H22<>"",H22<Parámetros!$B$4),Parámetros!$B$4-H22,0) -> 0 | Q22: =IF(OR(D22="Proyecto",D22="Riesgos",D22="Obs. Auditoría"),"Sí","No") -> Sí | R22: =IF(I22="","",IF(I22<=H22,1,0))
A23: 2026 | B23: Gestor de Identidades Sailpoint | Fase 2 | C23: Reemplazo microservicios Bancs, Siglo21, Logiflow | D23: Proyecto | E23: Ana María Vergara | F23: Ana María Vergara | G23: 46113 | H23: 46387 | J23: 0.5 | K23: PROTECT | L23: - Microservicio Bancs: con retraso - Microservicio Siglo21: dependencia de micro de bancs - Microservicio Logiflow: En proceso. Pruebas funcionales 18/08/2026 | M23: =IF(OR(G23="",H23=""),"",IF(H23<=G23,1,MIN(1,MAX(0,(Parámetros!$B$4-G23)/(H23-G23))))) -> 0.61678832 | N23: =IF(M23="","",J23-M23) -> -0.11678832 | O23: =IF(J23>=1,"Completado",IF(H23="","Sin fecha plan",IF(H23<Parámetros!$B$4,"Atrasado",IF(J23<=0,"No iniciado","En proceso")))) -> En proceso | P23: =IF(AND(J23<1,H23<>"",H23<Parámetros!$B$4),Parámetros!$B$4-H23,0) -> 0 | Q23: =IF(OR(D23="Proyecto",D23="Riesgos",D23="Obs. Auditoría"),"Sí","No") -> Sí | R23: =IF(I23="","",IF(I23<=H23,1,0))
A24: 2026 | B24: Gestor de Identidades Sailpoint | Fase 2 | C24: Integración automática CRM Salesforce. Análisis construcción roles automáticos | D24: Proyecto | E24: Ana María Vergara | F24: Ana María Vergara Richard Requelme Jhonny Barreiro | G24: 46113 | H24: 46295 | J24: 0.95 | K24: IDENTIFY | L24: - 15- sept- quitar el CSV -17 ago - Se remite los roles validados (con agencia y con el dueño del app) para creación de roles y proceder con el encendido CRM: Conector implementado, activo modo lectura | M24: =IF(OR(G24="",H24=""),"",IF(H24<=G24,1,MIN(1,MAX(0,(Parámetros!$B$4-G24)/(H24-G24))))) -> 0.92857143 | N24: =IF(M24="","",J24-M24) -> 0.021428571 | O24: =IF(J24>=1,"Completado",IF(H24="","Sin fecha plan",IF(H24<Parámetros!$B$4,"Atrasado",IF(J24<=0,"No iniciado","En proceso")))) -> En proceso | P24: =IF(AND(J24<1,H24<>"",H24<Parámetros!$B$4),Parámetros!$B$4-H24,0) -> 0 | Q24: =IF(OR(D24="Proyecto",D24="Riesgos",D24="Obs. Auditoría"),"Sí","No") -> Sí | R24: =IF(I24="","",IF(I24<=H24,1,0))
A25: 2026 | B25: Gestor de Identidades Sailpoint | Fase 2 | C25: Diferencia hora comunicados generados por Sailpoint | D25: Mejora | E25: Ana María Vergara | F25: Ana María Vergara | G25: 46209 | H25: 46233 | I25: 46233 | J25: 1 | K25: PROTECT | L25: Diferencia de 5 horas aprox entre la fecha y hora de la notificación y la fecha y hora reales de envío del correo Ticket de soporte generado para atención de Assertiva #3260 21/07/2026 Comunicado con diferencia de hora corregido | M25: =IF(OR(G25="",H25=""),"",IF(H25<=G25,1,MIN(1,MAX(0,(Parámetros!$B$4-G25)/(H25-G25))))) -> 1 | N25: =IF(M25="","",J25-M25) -> 0 | O25: =IF(J25>=1,"Completado",IF(H25="","Sin fecha plan",IF(H25<Parámetros!$B$4,"Atrasado",IF(J25<=0,"No iniciado","En proceso")))) -> Completado | P25: =IF(AND(J25<1,H25<>"",H25<Parámetros!$B$4),Parámetros!$B$4-H25,0) -> 0 | Q25: =IF(OR(D25="Proyecto",D25="Riesgos",D25="Obs. Auditoría"),"Sí","No") -> No | R25: =IF(I25="","",IF(I25<=H25,1,0)) -> 1
A26: 2026 | B26: Gestor de Identidades Sailpoint | Fase 2 | C26: Soporte Assertiva: Flujo Genéricos ATM´s | #2953 (Eliminación) | D26: Mejora | E26: Richard Requelme | F26: Richard Requelme Ana María Vergara | G26: 46143 | H26: 46173 | I26: 46173 | J26: 1 | K26: PROTECT | L26: Se configura para que se elimine automáticamente el genérico en AD, BANCS y Siglo una vez ingresado por el flujo de eliminación. | M26: =IF(OR(G26="",H26=""),"",IF(H26<=G26,1,MIN(1,MAX(0,(Parámetros!$B$4-G26)/(H26-G26))))) -> 1 | N26: =IF(M26="","",J26-M26) -> 0 | O26: =IF(J26>=1,"Completado",IF(H26="","Sin fecha plan",IF(H26<Parámetros!$B$4,"Atrasado",IF(J26<=0,"No iniciado","En proceso")))) -> Completado | P26: =IF(AND(J26<1,H26<>"",H26<Parámetros!$B$4),Parámetros!$B$4-H26,0) -> 0 | Q26: =IF(OR(D26="Proyecto",D26="Riesgos",D26="Obs. Auditoría"),"Sí","No") -> No | R26: =IF(I26="","",IF(I26<=H26,1,0)) -> 1
A27: 2026 | B27: Gestor de Identidades Sailpoint | Fase 2 | C27: Corrección de roles reportados con inconsistencia | D27: Operación | E27: Richard Requelme | F27: Richard Requelme Ana María Vergara | G27: 46113 | J27: 1 | K27: PROTECT | L27: - Las sesiones de revisión de roles se generan una vez al mes con el equipo de Assertiva, se analiza y se realiza las correcciones reportadas - Actividad ejecutada bajo demanda | M27: =IF(OR(G27="",H27=""),"",IF(H27<=G27,1,MIN(1,MAX(0,(Parámetros!$B$4-G27)/(H27-G27))))) | N27: =IF(M27="","",J27-M27) | O27: =IF(J27>=1,"Completado",IF(H27="","Sin fecha plan",IF(H27<Parámetros!$B$4,"Atrasado",IF(J27<=0,"No iniciado","En proceso")))) -> Completado | P27: =IF(AND(J27<1,H27<>"",H27<Parámetros!$B$4),Parámetros!$B$4-H27,0) -> 0 | Q27: =IF(OR(D27="Proyecto",D27="Riesgos",D27="Obs. Auditoría"),"Sí","No") -> No | R27: =IF(I27="","",IF(I27<=H27,1,0))
A28: 2026 | B28: Gestor de Identidades Sailpoint | Fase 2 | C28: Revisión, Ajustes y Corrección Implementación Rol Ejecutivo Integral 2.0 | D28: Proyecto | E28: Ana María Vergara | F28: Ana María Vergara | G28: 46204 | H28: 46218 | J28: 0.5 | K28: PROTECT | L28: - Revisión integral del proceso del levantamiento de roles para el piloto Ejecutivo Integral 2.0 - Corrección de roles asociados - Sesión y comunicación con los responsables del proyecto piloto - Procesamiento de 130 usuarios bajo este esquema - Comu | M28: =IF(OR(G28="",H28=""),"",IF(H28<=G28,1,MIN(1,MAX(0,(Parámetros!$B$4-G28)/(H28-G28))))) -> 1 | N28: =IF(M28="","",J28-M28) -> -0.5 | O28: =IF(J28>=1,"Completado",IF(H28="","Sin fecha plan",IF(H28<Parámetros!$B$4,"Atrasado",IF(J28<=0,"No iniciado","En proceso")))) -> Atrasado | P28: =IF(AND(J28<1,H28<>"",H28<Parámetros!$B$4),Parámetros!$B$4-H28,0) -> 64 | Q28: =IF(OR(D28="Proyecto",D28="Riesgos",D28="Obs. Auditoría"),"Sí","No") -> Sí | R28: =IF(I28="","",IF(I28<=H28,1,0))
A29: 2026 | B29: Gestor de Identidades Sailpoint | Fase 2 | C29: Revisión y correlación de cuentas huérfanas en AD | D29: Iniciativa | E29: Ana María Vergara | F29: Ana María Vergara Richard Requelme Bryan Uyana | G29: 46266 | H29: 46356 | J29: 0.5 | K29: PROTECT | L29: Se genero el ticket #3446 para identificar la causa raiz | M29: =IF(OR(G29="",H29=""),"",IF(H29<=G29,1,MIN(1,MAX(0,(Parámetros!$B$4-G29)/(H29-G29))))) -> 0.17777778 | N29: =IF(M29="","",J29-M29) -> 0.32222222 | O29: =IF(J29>=1,"Completado",IF(H29="","Sin fecha plan",IF(H29<Parámetros!$B$4,"Atrasado",IF(J29<=0,"No iniciado","En proceso")))) -> En proceso | P29: =IF(AND(J29<1,H29<>"",H29<Parámetros!$B$4),Parámetros!$B$4-H29,0) -> 0 | Q29: =IF(OR(D29="Proyecto",D29="Riesgos",D29="Obs. Auditoría"),"Sí","No") -> No | R29: =IF(I29="","",IF(I29<=H29,1,0))
A30: 2026 | B30: Gestor de Identidades Sailpoint | Fase 2 | C30: Cambio en el ciclo de vida de offboarding para usuarios internos y externos en AD. (No se mantendrán por 30 días, se eliminará el mismo día). | D30: Proyecto | E30: Ana María Vergara | F30: Ana María Vergara | G30: 46202 | H30: 46280 | J30: 0.7 | K30: PROTECT | L30: - Solicitud soporte Assertiva ticket #3089 - Análisis de impacto sobre identidades VIP o excepcionadas - Se mantendrá una sesión el viernes 24/06/2026 con el equipo de Assertiva para realizar pruebas sobre el grupo de excepción de AD, para garantizar | M30: =IF(OR(G30="",H30=""),"",IF(H30<=G30,1,MIN(1,MAX(0,(Parámetros!$B$4-G30)/(H30-G30))))) -> 1 | N30: =IF(M30="","",J30-M30) -> -0.3 | O30: =IF(J30>=1,"Completado",IF(H30="","Sin fecha plan",IF(H30<Parámetros!$B$4,"Atrasado",IF(J30<=0,"No iniciado","En proceso")))) -> Atrasado | P30: =IF(AND(J30<1,H30<>"",H30<Parámetros!$B$4),Parámetros!$B$4-H30,0) -> 2 | Q30: =IF(OR(D30="Proyecto",D30="Riesgos",D30="Obs. Auditoría"),"Sí","No") -> Sí | R30: =IF(I30="","",IF(I30<=H30,1,0))
A31: 2026 | B31: Gestor de Identidades Sailpoint | Fase 2 | C31: Deshabilitación automática baja colaborador | D31: Proyecto | E31: Ana María Vergara | F31: Ana María Vergara | G31: 46107 | H31: 46148 | I31: 46148 | J31: 1 | K31: PROTECT | L31: - Solicitud Soporte Assertiva #2762 - Proceso implementado operativo. Depedencia con la carga en SSFF del atributo "end date" | M31: =IF(OR(G31="",H31=""),"",IF(H31<=G31,1,MIN(1,MAX(0,(Parámetros!$B$4-G31)/(H31-G31))))) -> 1 | N31: =IF(M31="","",J31-M31) -> 0 | O31: =IF(J31>=1,"Completado",IF(H31="","Sin fecha plan",IF(H31<Parámetros!$B$4,"Atrasado",IF(J31<=0,"No iniciado","En proceso")))) -> Completado | P31: =IF(AND(J31<1,H31<>"",H31<Parámetros!$B$4),Parámetros!$B$4-H31,0) -> 0 | Q31: =IF(OR(D31="Proyecto",D31="Riesgos",D31="Obs. Auditoría"),"Sí","No") -> Sí | R31: =IF(I31="","",IF(I31<=H31,1,0)) -> 1
A32: 2026 | B32: Gestor de Identidades Sailpoint | Fase 2 | C32: Flujo de Deshabilitación de Cuentas/permisos - Usuarios Cesantes /Crossboarding- Conector BANCS | D32: Operación | E32: Richard Requelme | F32: Richard Requelme Bryan Uyana | G32: 46082 | H32: 46265 | J32: 0.5 | K32: PROTECT | L32: Se levanto un workflow ya establecido para cuentas cesantes y que haga el reprocesamiento. Sin embargo toca ajustar la configuración para el crossboarding | M32: =IF(OR(G32="",H32=""),"",IF(H32<=G32,1,MIN(1,MAX(0,(Parámetros!$B$4-G32)/(H32-G32))))) -> 1 | N32: =IF(M32="","",J32-M32) -> -0.5 | O32: =IF(J32>=1,"Completado",IF(H32="","Sin fecha plan",IF(H32<Parámetros!$B$4,"Atrasado",IF(J32<=0,"No iniciado","En proceso")))) -> Atrasado | P32: =IF(AND(J32<1,H32<>"",H32<Parámetros!$B$4),Parámetros!$B$4-H32,0) -> 17 | Q32: =IF(OR(D32="Proyecto",D32="Riesgos",D32="Obs. Auditoría"),"Sí","No") -> No | R32: =IF(I32="","",IF(I32<=H32,1,0))
A33: 2026 | B33: Gestor de Identidades Sailpoint | Fase 2 | C33: Revisión y correlación de cuentas huérfanas en Bancs | D33: Operación | E33: Richard Requelme | F33: Richard Requelme Bryan Uyana | G33: 46082 | H33: 46265 | J33: 0.5 | K33: PROTECT | L33: Se deshabilito cuentas cesantes. Sin embargo, se debe regularizar la información de las cuentas no correlacionadas para el control en vuelo | M33: =IF(OR(G33="",H33=""),"",IF(H33<=G33,1,MIN(1,MAX(0,(Parámetros!$B$4-G33)/(H33-G33))))) -> 1 | N33: =IF(M33="","",J33-M33) -> -0.5 | O33: =IF(J33>=1,"Completado",IF(H33="","Sin fecha plan",IF(H33<Parámetros!$B$4,"Atrasado",IF(J33<=0,"No iniciado","En proceso")))) -> Atrasado | P33: =IF(AND(J33<1,H33<>"",H33<Parámetros!$B$4),Parámetros!$B$4-H33,0) -> 17 | Q33: =IF(OR(D33="Proyecto",D33="Riesgos",D33="Obs. Auditoría"),"Sí","No") -> No | R33: =IF(I33="","",IF(I33<=H33,1,0))
A34: 2026 | B34: Gestor de Identidades Sailpoint | Fase 2 | C34: Asociación de cuentas privilegiadas (ENTRAID y AD) -priv.- y no el nominado (sailpoint) Correlacionar las cuentas priv. a la identidad del usuario en Sailpoint | D34: Operación | E34: Richard Requelme | F34: Richard Requelme Bryan Uyana | G34: 46082 | H34: 46272 | I34: 46272 | J34: 1 | K34: PROTECT | L34: -15 de sept - se enciende el conector nuevo de privc En la reunión de seguimiento con Assertiva se reviso este tema, y se vio dos opciones para trabajar este tema, se genero un ticket a Assertiva para regularizar. Para las privc, se evalua ajustes en | M34: =IF(OR(G34="",H34=""),"",IF(H34<=G34,1,MIN(1,MAX(0,(Parámetros!$B$4-G34)/(H34-G34))))) -> 1 | N34: =IF(M34="","",J34-M34) -> 0 | O34: =IF(J34>=1,"Completado",IF(H34="","Sin fecha plan",IF(H34<Parámetros!$B$4,"Atrasado",IF(J34<=0,"No iniciado","En proceso")))) -> Completado | P34: =IF(AND(J34<1,H34<>"",H34<Parámetros!$B$4),Parámetros!$B$4-H34,0) -> 0 | Q34: =IF(OR(D34="Proyecto",D34="Riesgos",D34="Obs. Auditoría"),"Sí","No") -> No | R34: =IF(I34="","",IF(I34<=H34,1,0)) -> 1
A35: 2026 | B35: Certificación de Accesos: Accesos usuarios | C35: Depuración de cuentas de usuarios priv. y privc. | D35: Operación | E35: Richard Requelme | F35: Richard Requelme Bryan Uyana | G35: 46235 | H35: 46265 | I35: 46265 | J35: 1 | K35: DETECT | M35: =IF(OR(G35="",H35=""),"",IF(H35<=G35,1,MIN(1,MAX(0,(Parámetros!$B$4-G35)/(H35-G35))))) -> 1 | N35: =IF(M35="","",J35-M35) -> 0 | O35: =IF(J35>=1,"Completado",IF(H35="","Sin fecha plan",IF(H35<Parámetros!$B$4,"Atrasado",IF(J35<=0,"No iniciado","En proceso")))) -> Completado | P35: =IF(AND(J35<1,H35<>"",H35<Parámetros!$B$4),Parámetros!$B$4-H35,0) -> 0 | Q35: =IF(OR(D35="Proyecto",D35="Riesgos",D35="Obs. Auditoría"),"Sí","No") -> No | R35: =IF(I35="","",IF(I35<=H35,1,0)) -> 1
A36: 2026 | B36: Gestor de Identidades Sailpoint | Fase 2 | C36: Flujo de Deshabilitación de Cuentas/permisos - Usuarios Cesantes /Crossboarding- Conector RHDS | D36: Operación | E36: Richard Requelme | F36: Richard Requelme | G36: 46082 | H36: 46325 | J36: 0.1 | K36: PROTECT | L36: Se tiene el análisis de las cuentas no correlacionadas. Se debe determinar causa raíz y corrección. | M36: =IF(OR(G36="",H36=""),"",IF(H36<=G36,1,MIN(1,MAX(0,(Parámetros!$B$4-G36)/(H36-G36))))) -> 0.82304527 | N36: =IF(M36="","",J36-M36) -> -0.72304527 | O36: =IF(J36>=1,"Completado",IF(H36="","Sin fecha plan",IF(H36<Parámetros!$B$4,"Atrasado",IF(J36<=0,"No iniciado","En proceso")))) -> En proceso | P36: =IF(AND(J36<1,H36<>"",H36<Parámetros!$B$4),Parámetros!$B$4-H36,0) -> 0 | Q36: =IF(OR(D36="Proyecto",D36="Riesgos",D36="Obs. Auditoría"),"Sí","No") -> No | R36: =IF(I36="","",IF(I36<=H36,1,0))
A37: 2026 | B37: Gestor de Identidades Sailpoint | Fase 2 | C37: Revisión y correlación de cuentas huérfanas RHDS | D37: Operación | E37: Richard Requelme | F37: Richard Requelme Bryan Uyana | G37: 46082 | H37: 46295 | J37: 0.1 | K37: PROTECT | L37: Se tiene el análisis de las cuentas no correlacionadas. Se debe determinar causa raíz y corrección. | M37: =IF(OR(G37="",H37=""),"",IF(H37<=G37,1,MIN(1,MAX(0,(Parámetros!$B$4-G37)/(H37-G37))))) -> 0.93896714 | N37: =IF(M37="","",J37-M37) -> -0.83896714 | O37: =IF(J37>=1,"Completado",IF(H37="","Sin fecha plan",IF(H37<Parámetros!$B$4,"Atrasado",IF(J37<=0,"No iniciado","En proceso")))) -> En proceso | P37: =IF(AND(J37<1,H37<>"",H37<Parámetros!$B$4),Parámetros!$B$4-H37,0) -> 0 | Q37: =IF(OR(D37="Proyecto",D37="Riesgos",D37="Obs. Auditoría"),"Sí","No") -> No | R37: =IF(I37="","",IF(I37<=H37,1,0))
A38: 2026 | B38: Regularización de Roles | C38: Regularización de Accesos y Permisos Crowstrike. Desde la aplicación hacia ISC Sailpoint | D38: Operación | E38: Jhonny Barreiro | F38: Jhonny Barreiro | G38: 46211 | H38: 46233 | J38: 0.5 | K38: PROTECT | L38: Se incia con Valerai Tandazo la depuracion de accesos en Crowstrike, Fase 1 en la aplicación. Fase 2 en ISC actualmente en la aplicación | M38: =IF(OR(G38="",H38=""),"",IF(H38<=G38,1,MIN(1,MAX(0,(Parámetros!$B$4-G38)/(H38-G38))))) -> 1 | N38: =IF(M38="","",J38-M38) -> -0.5 | O38: =IF(J38>=1,"Completado",IF(H38="","Sin fecha plan",IF(H38<Parámetros!$B$4,"Atrasado",IF(J38<=0,"No iniciado","En proceso")))) -> Atrasado | P38: =IF(AND(J38<1,H38<>"",H38<Parámetros!$B$4),Parámetros!$B$4-H38,0) -> 49 | Q38: =IF(OR(D38="Proyecto",D38="Riesgos",D38="Obs. Auditoría"),"Sí","No") -> No | R38: =IF(I38="","",IF(I38<=H38,1,0))
A39: 2026 | B39: Regularización de Roles | C39: Regularización de Accesos y Permisos Firewall Checkpoint. Desde la aplicación hacia ISC Sailpoint | D39: Operación | E39: Jhonny Barreiro | F39: Jhonny Barreiro | G39: 46211 | H39: 46233 | J39: 0.75 | K39: PROTECT | L39: Se incia con Maria Peñaherrera la depuracion de accesos en Firewall Checkpoint, Fase 1 en la aplicación. Fase 2 en ISC actualmente en la aplicación | M39: =IF(OR(G39="",H39=""),"",IF(H39<=G39,1,MIN(1,MAX(0,(Parámetros!$B$4-G39)/(H39-G39))))) -> 1 | N39: =IF(M39="","",J39-M39) -> -0.25 | O39: =IF(J39>=1,"Completado",IF(H39="","Sin fecha plan",IF(H39<Parámetros!$B$4,"Atrasado",IF(J39<=0,"No iniciado","En proceso")))) -> Atrasado | P39: =IF(AND(J39<1,H39<>"",H39<Parámetros!$B$4),Parámetros!$B$4-H39,0) -> 49 | Q39: =IF(OR(D39="Proyecto",D39="Riesgos",D39="Obs. Auditoría"),"Sí","No") -> No | R39: =IF(I39="","",IF(I39<=H39,1,0))
A40: 2026 | B40: Gestión de accesos y permisos | C40: Integración de nuevas fuentes al control - Access Request Center - Fuentes Nube (My Access). | D40: Iniciativa | E40: Richard Requelme | F40: Richard Requelme Bryan Uyana | G40: 46163 | H40: 46203 | I40: 46203 | J40: 1 | K40: PROTECT | L40: Se levantaron scripts para obtener la información y se creo una pestaña en GEMA para visualizar todos los permisos asignados fuera del rol | M40: =IF(OR(G40="",H40=""),"",IF(H40<=G40,1,MIN(1,MAX(0,(Parámetros!$B$4-G40)/(H40-G40))))) -> 1 | N40: =IF(M40="","",J40-M40) -> 0 | O40: =IF(J40>=1,"Completado",IF(H40="","Sin fecha plan",IF(H40<Parámetros!$B$4,"Atrasado",IF(J40<=0,"No iniciado","En proceso")))) -> Completado | P40: =IF(AND(J40<1,H40<>"",H40<Parámetros!$B$4),Parámetros!$B$4-H40,0) -> 0 | Q40: =IF(OR(D40="Proyecto",D40="Riesgos",D40="Obs. Auditoría"),"Sí","No") -> No | R40: =IF(I40="","",IF(I40<=H40,1,0)) -> 1
...

Sheet Tablas del Modelo
A1: Esquema estrella
A2: Una tabla de hechos con grano de un hito y cinco dimensiones. Sin este modelo, el waterfall y el decomposition tree no funcionan.
A3: Tabla | B3: Rol | C3: Grano / contenido | D3: Campos clave | E3: Origen
A5: F_Hitos | B5: Hechos | C5: Un hito del plan (177 filas). | D5: id_hito, id_frente, id_responsable, id_tipo, id_nist, Fecha_Inicio, Fecha_Fin_Plan, Fecha_Fin_Real, Avance_Real | E5: Hoja "Actividades GI 2026" del archivo origen
A6: D_Frente | B6: Dimensión | C6: 74 frentes de trabajo (Sailpoint F1/F2, Certificación de Accesos, Base de Datos, NERM, FTP-SFTP…). | D6: id_frente, Frente, Programa | E6: Distinct de la columna Actividad
A7: D_Responsable | B7: Dimensión | C7: 12 personas. Requiere tabla puente: la columna Encargado trae hasta 3 nombres en una celda. | D7: id_responsable, Responsable, Célula | E7: Split de la columna Encargado
A8: D_Tipo | B8: Dimensión | C8: 7 tipos: Operación, Iniciativa, Proyecto, Mejora, Riesgos, Obs. Auditoría, Incidencia. | D8: id_tipo, Tipo_Actividad, Es_Critico | E8: Distinct de Tipo Actividad
A9: D_NIST | B9: Dimensión | C9: 6 funciones del NIST CSF 2.0 más el orden de presentación. | D9: id_nist, Funcion, Orden, Descripcion | E9: Tabla manual (ver hoja Reglas NIST)
A10: D_Calendario | B10: Dimensión de fecha | C10: Un día de 2025-01-01 a 2026-12-31. Marcar como tabla de fechas. | D10: Fecha, Año, Mes, MesAño, NumMes, Trimestre | E10: DAX CALENDAR (ver hoja Calendario y Cortes)
A11: D_Corte | B11: Dimensión desconectada | C11: Un snapshot mensual del plan. Hoy NO existe: es el habilitador del KPI de tendencia. | D11: Fecha_Corte, id_hito, Avance_Real, Estado | E11: Copia programada de F_Hitos a fin de mes
A12: D_Parametros | B12: Desconectada | C12: Metas y umbrales de cada KPI. | D12: Parametro, Valor | E12: Hoja Parámetros de este libro
A13: Relaciones
A14: Desde | B14: Hacia | C14: Cardinalidad | D14: Dirección | E14: Nota
A15: F_Hitos[id_frente] | B15: D_Frente[id_frente] | C15: Muchos a uno | D15: Simple
A16: F_Hitos[id_responsable] | B16: D_Responsable[id_responsable] | C16: Muchos a uno | D16: Simple | E16: Si se usa tabla puente, muchos a muchos con filtro cruzado simple
A17: F_Hitos[id_tipo] | B17: D_Tipo[id_tipo] | C17: Muchos a uno | D17: Simple
A18: F_Hitos[id_nist] | B18: D_NIST[id_nist] | C18: Muchos a uno | D18: Simple
A19: F_Hitos[Fecha_Fin_Plan] | B19: D_Calendario[Fecha] | C19: Muchos a uno | D19: Simple | E19: Relación ACTIVA: el eje temporal del tablero es la fecha comprometida
A20: F_Hitos[Fecha_Fin_Real] | B20: D_Calendario[Fecha] | C20: Muchos a uno | D20: Simple | E20: Relación INACTIVA: se activa con USERELATIONSHIP en la medida de cierres reales
A21: D_Corte[id_hito] | B21: F_Hitos[id_hito] | C21: Muchos a uno | D21: Simple | E21: Solo si se quiere comparar snapshots contra el estado vigente

Sheet Columnas Calculadas
A1: Columnas calculadas sobre F_Hitos
A2: Son columnas, no medidas: se usan para segmentar, filtrar y colorear. Crear en este orden.
A3: # | B3: Columna | C3: Tipo / formato | D3: DAX (Power BI) | E3: Equivalente Excel (hoja F_Hitos) | F3: Por qué existe
A5: 1 | B5: Avance_Esperado | C5: Decimal, 0% | D5: Avance_Esperado = VAR _corte = MAX ( D_Corte[Fecha_Corte] ) VAR _ini = F_Hitos[Fecha_Inicio] VAR _fin = F_Hitos[Fecha_Fin_Plan] RETURN IF ( OR ( ISBLANK ( _ini ), ISBLANK ( _fin ) ), BLANK (), MINX ( { 1, MAXX ( { 0, DIVIDE ( _corte - _ini, _fin - _ini ) }, [Value] ) }, [Value] ) ) | E5: =IF(OR(G2="",H2=""),"",MIN(1,MAX(0,(Corte-G2)/(H2-G2)))) | F5: Línea base contra la que se mide todo. Acotada entre 0 y 1: un hito que ya venció no puede "esperar" más de 100%.
A6: 2 | B6: Desviacion_pp | C6: Decimal, 0% | D6: Desviacion_pp = IF ( ISBLANK ( F_Hitos[Avance_Esperado] ), BLANK (), F_Hitos[Avance_Real] - F_Hitos[Avance_Esperado] ) | E6: =IF(M2="","",J2-M2) | F6: Convierte el atraso en puntos porcentuales recuperables. Es la métrica del waterfall y del scatter.
A7: 3 | B7: Estado | C7: Texto | D7: Estado = VAR _corte = MAX ( D_Corte[Fecha_Corte] ) RETURN SWITCH ( TRUE (), F_Hitos[Avance_Real] >= 1, "Completado", ISBLANK ( F_Hitos[Fecha_Fin_Plan] ), "Sin fecha plan", F_Hitos[Fecha_Fin_Plan] < _corte, "Atrasado", F_Hitos[Avance_Real] <= 0, "No iniciado", "En proceso" ) | E7: =IF(J2>=1,"Completado",IF(H2="","Sin fecha plan",IF(H2<Corte,"Atrasado",IF(J2<=0,"No iniciado","En proceso")))) | F7: Estado SIEMPRE calculado, nunca digitado. El orden de las condiciones importa: completado gana sobre atrasado.
A8: 4 | B8: Dias_Vencidos | C8: Entero | D8: Dias_Vencidos = VAR _corte = MAX ( D_Corte[Fecha_Corte] ) RETURN IF ( F_Hitos[Avance_Real] < 1 && NOT ISBLANK ( F_Hitos[Fecha_Fin_Plan] ), MAX ( 0, INT ( _corte - F_Hitos[Fecha_Fin_Plan] ) ), 0 ) | E8: =IF(AND(J2<1,H2<>"",H2<Corte),Corte-H2,0) | F8: Mide la severidad del atraso, no solo su existencia. Ordena la matriz de priorización.
A9: 5 | B9: Es_Critica | C9: Texto (Sí/No) | D9: Es_Critica = IF ( F_Hitos[Tipo_Actividad] IN { "Proyecto", "Riesgos", "Obs. Auditoría" }, "Sí", "No" ) | E9: =IF(OR(D2="Proyecto",D2="Riesgos",D2="Obs. Auditoría"),"Sí","No") | F9: Proxy de criticidad mientras el área no formalice la columna Criticidad (sí existe en la hoja 2025). Sustituir en cuanto esté.
A10: 6 | B10: Cerrado_En_Fecha | C10: Entero (1/0) | D10: Cerrado_En_Fecha = IF ( ISBLANK ( F_Hitos[Fecha_Fin_Real] ), BLANK (), IF ( F_Hitos[Fecha_Fin_Real] <= F_Hitos[Fecha_Fin_Plan], 1, 0 ) ) | E10: =IF(I2="","",IF(I2<=H2,1,0)) | F10: Alimenta el SLA de cierre. En blanco para los no cerrados: no deben contar como incumplimiento.
A11: 7 | B11: Banda_Avance | C11: Texto | D11: Banda_Avance = SWITCH ( TRUE (), F_Hitos[Avance_Real] >= 1, "5. Completado", F_Hitos[Avance_Real] >= 0.75, "4. 75-99%", F_Hitos[Avance_Real] >= 0.5, "3. 50-74%", F_Hitos[Avance_Real] > 0, "2. 1-49%", "1. Sin iniciar" ) | E11: (no requerida en Excel) | F11: Eje del funnel de maduración. El prefijo numérico ordena las etapas sin columna de orden adicional.

Sheet Medidas DAX
A1: Medidas DAX
A2: 26 medidas. La columna "Valor al corte" es el resultado esperado con los datos actuales: si no coincide, el error está en el modelo.
A3: # | B3: Carpeta | C3: Medida | D3: Formato | E3: DAX | F3: Interpretación ejecutiva | G3: Valor al corte
A5: 1 | B5: 00_Base | C5: Total Hitos | D5: #,##0 | E5: Total Hitos = COUNTROWS ( F_Hitos ) | F5: Universo del plan vigente. | G5: 177
A6: 2 | B6: 00_Base | C6: Fecha Corte | D6: dd/mm/yyyy | E6: Fecha Corte = MAX ( D_Corte[Fecha_Corte] ) | F6: Fecha de referencia de todo el tablero. Centralizarla evita que cada medida use TODAY(). | G6: 17/09/2026
A7: 3 | B7: 00_Base | C7: Hitos Completados | D7: #,##0 | E7: Hitos Completados = CALCULATE ( [Total Hitos], F_Hitos[Estado] = "Completado" ) | F7: Hitos cerrados al 100%. | G7: 92
A8: 4 | B8: 00_Base | C8: Hitos En Proceso | D8: #,##0 | E8: Hitos En Proceso = CALCULATE ( [Total Hitos], F_Hitos[Estado] = "En proceso" ) | F8: Trabajo vivo dentro de fecha. | G8: 57
A9: 5 | B9: 00_Base | C9: Hitos Atrasados | D9: #,##0 | E9: Hitos Atrasados = CALCULATE ( [Total Hitos], F_Hitos[Estado] = "Atrasado" ) | F9: Vencidos sin cerrar: la cola de incumplimiento. | G9: 25
A10: 6 | B10: 00_Base | C10: Hitos No Iniciados | D10: #,##0 | E10: Hitos No Iniciados = CALCULATE ( [Total Hitos], F_Hitos[Estado] = "No iniciado" ) | F10: Sin arranque y aún en fecha. | G10: 3
A11: 7 | B11: 01_Avance | C11: Avance Real % | D11: 0.0% | E11: Avance Real % = AVERAGE ( F_Hitos[Avance_Real] ) | F11: Titular del tablero. Promedio simple: cada hito pesa igual mientras no exista ponderación por esfuerzo. | G11: 71.7%
A12: 8 | B12: 01_Avance | C12: Avance Esperado % | D12: 0.0% | E12: Avance Esperado % = AVERAGE ( F_Hitos[Avance_Esperado] ) | F12: Dónde debería estar el plan por tiempo transcurrido. | G12: 84.7%
A13: 9 | B13: 01_Avance | C13: Desviacion pp | D13: +0.0;-0.0 | E13: Desviacion pp = [Avance Real %] - [Avance Esperado %] | F13: Brecha en puntos porcentuales. Es la métrica que descompone el waterfall. | G13: -13.0 pp
A14: 10 | B14: 01_Avance | C14: Contribucion Desviacion pp | D14: +0.0;-0.0 | E14: Contribucion Desviacion pp = VAR _hitos = COUNTROWS ( F_Hitos ) VAR _total = CALCULATE ( COUNTROWS ( F_Hitos ), ALLSELECTED ( F_Hitos ) ) RETURN DIVIDE ( _hitos, _total ) * [Desviacion pp] | F14: Cuántos de los 13 puntos aporta cada categoría. Suma exacta al total: es lo que hace válido el waterfall. | G14: Iniciativa -4.5 Proyecto -3.2
A15: 11 | B15: 02_KPI | C15: ICP | D15: 0% | E15: ICP = DIVIDE ( [Avance Real %], [Avance Esperado %] ) | F15: Índice de cumplimiento: ritmo real contra ritmo comprometido. Bajo 90% el cierre anual está en riesgo. | G15: 85%
... A30: 26 | B30: 05_Formato | C30: Titulo Dinamico | D30: Texto | E30: Titulo Dinamico = "Plan 2026 · corte " & FORMAT ( [Fecha Corte], "dd-mmm-yyyy" ) & " · ICP " & FORMAT ( [ICP], "0%" ) | F30: Encabezado del informe que se actualiza solo con el corte. | G30: Plan 2026 · corte 17-sep-2026 · ICP 85%

Sheet Calendario y Cortes
A1: Tablas de fecha y snapshots
A2: D_Calendario habilita la curva S. D_Corte es el único componente que hoy no existe y sin él no hay tendencia.
A3: Objeto | B3: DAX / procedimiento | C3: Nota
A5: D_Calendario | B5: D_Calendario = VAR _min = DATE ( 2025, 1, 1 ) VAR _max = DATE ( 2026, 12, 31 ) RETURN ADDCOLUMNS ( CALENDAR ( _min, _max ), "Año", YEAR ( [Date] ), "NumMes", MONTH ( [Date] ), "Mes", FORMAT ( [Date], "mmm" ), "MesAño", FORMAT ( [Date], "mmm-yy" ), "Trimestre", "Q" & FORMAT ( [Date], "q" ), "FinDeMes", EOMONTH ( [Date], 0 ) ) | C5: Marcar como tabla de fechas por la columna Date. Ordenar MesAño por una columna entera AñoMes = Año*100+NumMes, o el eje de la curva S saldrá alfabético.
A6: D_Corte (snapshot) | B6: Procedimiento, no DAX: 1. Flujo programado el último día hábil del mes. 2. Copiar de F_Hitos: id_hito, Avance_Real, Estado, Fecha_Fin_Plan. 3. Añadir la columna Fecha_Corte con la fecha del snapshot. 4. Append a la tabla histórica (nunca sobrescribir). | C6: Tabla desconectada del modelo salvo por id_hito. Es lo que habilita [ICP Mes Anterior], [Tendencia ICP] y la curva histórica real de avance.
A7: Corte vigente | B7: Fecha Corte = MAX ( D_Corte[Fecha_Corte] ) | C7: Mientras no exista D_Corte, sustituir por una tabla de un solo valor o por TODAY(). No usar TODAY() dentro de cada columna calculada: el modelo deja de ser reproducible hacia atrás.
A8: Relación inactiva | B8: Cierres Reales Acumulados (alternativa) = CALCULATE ( COUNTROWS ( F_Hitos ), USERELATIONSHIP ( F_Hitos[Fecha_Fin_Real], D_Calendario[Fecha] ), DATESBETWEEN ( D_Calendario[Fecha], MIN ( D_Calendario[Fecha] ) - 400, MAX ( D_Calendario[Fecha] ) ) ) | C8: Más eficiente que FILTER(ALL(...)) sobre tablas grandes. Con 177 filas cualquiera de las dos sirve.

Sheet Visuales del Dashboard
A1: Los 12 visuales del PDF
A2: Una fila por visual: qué tipo usar, qué va en cada área de datos y cómo se colorea.
A3: Pág. | B3: Visual | C3: Tipo en Power BI | D3: Campos / ejes | E3: Medidas | F3: Formato y color | G3: Por qué este visual
A5: 1 | B5: 6 KPI cards | C5: Tarjeta (Card) o KPI | D5: — | E5: [Avance Real %], [ICP], [Hitos Atrasados], [% Criticos Completados], [SLA Cierre en Fecha %], [Carga Q4 Pendiente] | F5: Barra lateral de 3 px con [Color Semaforo …]. Subtítulo con la medida de contexto. | G5: Estado global en tres segundos; punto de entrada del comité.
A6: 1 | B6: Cumplimiento vs meta | C6: Gauge | D6: — | E6: Valor: [ICP] · Objetivo: Meta_ICP · Mínimo 0, Máximo 1 | F6: Color del relleno por [Color Semaforo ICP]. Zonas 0-80 / 80-95 / 95-100. | G6: Comunica posición respecto de un umbral, que es la pregunta de gobierno.
A7: 1 | B7: KPIs vs objetivo | C7: Gráfico de viñetas (bullet, visual de AppSource) o barras con línea de objetivo | D7: Categoría: nombre del KPI (tabla desconectada D_KPI) | E7: [Valor KPI] (medida SWITCH sobre D_KPI) y [Meta KPI] | F7: Bandas cualitativas en gris; barra por semáforo; marca negra de objetivo. | G7: Sustituye seis gauges y permite comparar KPIs con unidades distintas.
A8: 1 | B8: Curva de cierres | C8: Gráfico de líneas | D8: Eje X: D_Calendario[MesAño] | E8: [Plan Acumulado] (línea punteada gris) y [Cierres Reales Acumulados] (línea sólida) | F8: Línea de referencia constante en la fecha de corte; etiqueta con [Brecha de Cierres]. | G8: Única pregunta temporal del tablero: si la brecha se abre o se cierra.
A9: 1 | B9: Embudo de maduración | C9: Funnel | D9: Grupo: F_Hitos[Banda_Avance] (acumulado descendente) | E9: [Total Hitos] | F9: Degradado azul a verde; etiqueta de porcentaje del primer valor. | G9: Muestra dónde se pierde el flujo: la última milla entre 75% y el cierre.
A10: 1 | B10: Estado por función NIST | C10: Barras apiladas horizontales | D10: Eje: D_NIST[Funcion] · Leyenda: F_Hitos[Estado] | E10: [Total Hitos] | F10: Colores fijos por estado: verde, azul, rojo, gris. | G10: Compara la mezcla de estados entre funciones manteniendo el volumen visible.
A11: 1 | B11: Frentes con mayor desviación | C11: Tabla / Matriz | D11: Filas: D_Frente[Frente] (Top N = 6 por [Desviacion pp] ascendente) | E11: [Total Hitos], [Avance Real %], [Avance Esperado %], [Desviacion pp] | F11: Barras de datos en la columna de avance; fuente por [Color Semaforo Desviacion]. | G11: Detalle acotado: suficiente para decidir, insuficiente para perderse.
A12: 2 | B12: Origen de la brecha | C12: Cascada (Waterfall) | D12: Categoría: D_Tipo[Tipo_Actividad] · Desglose: opcionalmente D_NIST | E12: [Contribucion Desviacion pp] | F12: Aumento verde, disminución roja, total azul. Ordenar por contribución. | G12: Único visual que explica una variación de forma aditiva.
A13: 2 | B13: Causa raíz del atraso | C13: Árbol de descomposición | D13: Analizar: [Hitos Atrasados] · Explicar por: Tipo, Responsable, Frente, NIST | E13: [Hitos Atrasados] | F13: Bloquear los dos primeros niveles; dejar el tercero libre para el comité. | G13: Convierte un agregado en un destinatario de acción concreto.
A14: 2 | B14: Dispersión avance | C14: Dispersión (Scatter) | D14: X: [Avance Esperado %] · Y: [Avance Real %] · Detalle: F_Hitos[Hito] · Tamaño: [Total Hitos] | E14: [Avance Real %], [Avance Esperado %] | F14: Línea de referencia X=Y; color por [Color Semaforo Desviacion]; sombreado bajo la diagonal. | G14: Expone la dispersión del portafolio, no solo su promedio.
A15: 2 | B15: Desviación NIST × Tipo | C15: Matriz con formato condicional | D15: Filas: D_NIST[Funcion] · Columnas: D_Tipo[Tipo_Actividad] | E15: [Desviacion pp] (valor) y [Total Hitos] (intensidad) | F15: Escala divergente rojo-blanco-verde centrada en 0; transparencia por volumen. | G15: Localiza focos que una tabla plana esconde.
... A18: 3 | B18: Top vencidos | C18: Matriz | D18: Filas: Frente, Hito · Valores por columna | E18: [Dias Atraso Maximo], [Avance Real %], Responsable, Tipo, NIST | F18: Iconos de semáforo en avance; días en rojo sobre 45. Top N = 8 por días. | G18: El detalle ejecutivo se entrega acotado y priorizado.

Sheet Semáforo y Formato
A1: Un solo criterio de color para todo el informe
A2: Si el color cambia de significado entre visuales, el tablero deja de leerse de un vistazo.
A3: Nivel | B3: Regla | C3: Hex | D3: Acción esperada
A5: Verde | B5: KPI en meta o mejor | C5: #107C41 | D5: Informar y sostener
A6: Ámbar | B6: Hasta 15% por debajo de la meta | C6: #D97706 | D6: Plan de recuperación con fecha comprometida
A7: Rojo | B7: Más de 15% por debajo de la meta, o hito crítico vencido más de 30 días | C7: #C42B1C | D7: Escalar a comité
A8: Gris | B8: Sin dato suficiente (sin fecha base o sin hitos en la celda) | C8: #8A94A6 | D8: Sanear el dato antes de interpretar
A9: Medidas de color dinámico
A10: Medida | B10: DAX | C10: Dónde se aplica
A11: Color Semaforo ICP | B11: Color Semaforo ICP = VAR _meta = MAX ( D_Parametros[Meta_ICP] ) VAR _tol = MAX ( D_Parametros[Tol_Ambar] ) RETURN SWITCH ( TRUE (), [ICP] >= _meta, "#107C41", [ICP] >= _meta * ( 1 - _tol ), "#D97706", "#C42B1C" ) | C11: Tarjeta del ICP, gauge y cualquier visual filtrado por cumplimiento. Formato condicional > Color de fuente > Formato por campo.
A12: Color Semaforo Desviacion | B12: Color Semaforo Desviacion = SWITCH ( TRUE (), ISBLANK ( [Desviacion pp] ), "#8A94A6", [Desviacion pp] > -0.08, "#107C41", [Desviacion pp] > -0.18, "#D97706", "#C42B1C" ) | C12: Heatmaps NIST × Tipo y Responsable × NIST, treemap, scatter y tabla de frentes.
A13: Color Semaforo Dias | B13: Color Semaforo Dias = SWITCH ( TRUE (), [Dias Atraso Maximo] = 0, "#8A94A6", [Dias Atraso Maximo] <= 15, "#D97706", "#C42B1C" ) | C13: Columna de días vencidos en la matriz de priorización.
A14: Icono Estado | B14: Icono Estado = SWITCH ( SELECTEDVALUE ( F_Hitos[Estado] ), "Completado", 3, "En proceso", 2, "Atrasado", 1, 0 ) | C14: Formato condicional > Iconos > por valor de campo, en la matriz de detalle.

Sheet Reglas NIST
A1: Clasificación NIST CSF 2.0 — propuesta
A2: La columna NIST viene vacía en los 177 registros del origen. Estas reglas la reconstruyen; requieren validación del área antes de reportar el KPI de cobertura.
A3: Orden | B3: Función | C3: Palabras clave en Frente + Hito (o tipo de actividad) | D3: Hitos asignados | E3: Criterio
A5: 1 | B5: RECOVER | C5: continuidad, recuperación, respaldo, netbackup, obsolescencia | D5: 3 | E5: Capacidad de restablecer el servicio de identidades.
A6: 2 | B6: RESPOND | C6: tipo = Incidencia; incidente, bloqueo, remediación, corrección de inconsistencias | D6: 13 | E6: Reacción ante un evento ya ocurrido.
A7: 3 | B7: DETECT | C7: monitoreo, caso de uso, alerta, detección, certificación, control, indicador, KRI | D7: 42 | E7: Capacidad de descubrir accesos indebidos ya otorgados.
A8: 4 | B8: GOVERN | C8: tipo = Riesgos u Obs. Auditoría; instructivo, documentación, política, gobierno, dashboard, reportería, PMC- | D8: 23 | E8: Marco, política y rendición de cuentas (función nueva de CSF 2.0).
A9: 5 | B9: IDENTIFY | C9: inventario, levantamiento, análisis, identificación, recepción de aplicaciones, calidad de datos, evaluación | D9: 10 | E9: Conocer el universo antes de protegerlo.
A10: 6 | B10: PROTECT | C10: resto: accesos, roles, perfiles, contraseñas, MFA, depuración, onboarding, offboarding, genéricos, privilegiados | D10: 86 | E10: Categoría por defecto: PR.AA, el corazón de la gestión de identidades.
A11: Las reglas se evalúan en orden: el primer criterio que coincide asigna la función. Un hito, una función primaria. El desbalance resultante (86 Protect frente a 10 Identify y 3 Recover) es un hallazgo del análisis, no un defecto de la regla.

Sheet Validación
A1: Cifras de control al corte
A2: Calculadas en vivo sobre la hoja F_Hitos. Contrastar cada medida DAX contra esta columna antes de publicar el informe.
A3: # | B3: Cifra de control | C3: Medida DAX equivalente | D3: Fórmula Excel | E3: Valor calculado | F3: Esperado | G3: Check
A4: 1 | B4: Total de hitos | C4: [Total Hitos] | D4: =COUNTA(F_Hitos!$C$2:$C$178) | E4: =COUNTA(F_Hitos!$C$2:$C$178) -> 177 | F4: 177 | G4: =IF(ABS(E4-F4)<=MAX(0.51,ABS(F4)*0.01),"OK","Revisar") -> OK
A5: 2 | B5: Avance real del plan | C5: [Avance Real %] | D5: =AVERAGE(F_Hitos!$J$2:$J$178) | E5: =AVERAGE(F_Hitos!$J$2:$J$178) -> 0.71706215 | F5: 0.717 | G5: =IF(ABS(E5-F5)<=MAX(0.51,ABS(F5)*0.01),"OK","Revisar") -> OK
A6: 3 | B6: Avance esperado del plan | C6: [Avance Esperado %] | D6: =AVERAGE(F_Hitos!$M$2:$M$178) | E6: =AVERAGE(F_Hitos!$M$2:$M$178) -> 0.84678675 | F6: 0.847 | G6: =IF(ABS(E6-F6)<=MAX(0.51,ABS(F6)*0.01),"OK","Revisar") -> OK
A7: 4 | B7: Índice de cumplimiento | C7: [ICP] | D7: =IFERROR(E5/E6,0) | E7: =IFERROR(E5/E6,0) -> 0.84680369 | F7: 0.847 | G7: =IF(ABS(E7-F7)<=MAX(0.51,ABS(F7)*0.01),"OK","Revisar") -> OK
A8: 5 | B8: Desviación (pp) | C8: [Desviacion pp] | D8: =E5-E6 | E8: =E5-E6 -> -0.12972461 | F8: -0.13 | G8: =IF(ABS(E8-F8)<=MAX(0.51,ABS(F8)*0.01),"OK","Revisar") -> OK
A9: 6 | B9: Hitos completados | C9: [Hitos Completados] | D9: =COUNTIF(F_Hitos!$O$2:$O$178,"Completado") | E9: =COUNTIF(F_Hitos!$O$2:$O$178,"Completado") -> 92 | F9: 92 | G9: =IF(ABS(E9-F9)<=MAX(0.51,ABS(F9)*0.01),"OK","Revisar") -> OK
A10: 7 | B10: Hitos en proceso | C10: [Hitos En Proceso] | D10: =COUNTIF(F_Hitos!$O$2:$O$178,"En proceso") | E10: =COUNTIF(F_Hitos!$O$2:$O$178,"En proceso") -> 57 | F10: 57 | G10: =IF(ABS(E10-F10)<=MAX(0.51,ABS(F10)*0.01),"OK","Revisar") -> OK
A11: 8 | B11: Hitos atrasados | C11: [Hitos Atrasados] | D11: =COUNTIF(F_Hitos!$O$2:$O$178,"Atrasado") | E11: =COUNTIF(F_Hitos!$O$2:$O$178,"Atrasado") -> 25 | F11: 25 | G11: =IF(ABS(E11-F11)<=MAX(0.51,ABS(F11)*0.01),"OK","Revisar") -> OK
A12: 9 | B12: Hitos no iniciados | C12: [Hitos No Iniciados] | D12: =COUNTIF(F_Hitos!$O$2:$O$178,"No iniciado") | E12: =COUNTIF(F_Hitos!$O$2:$O$178,"No iniciado") -> 3 | F12: 3 | G12: =IF(ABS(E12-F12)<=MAX(0.51,ABS(F12)*0.01),"OK","Revisar") -> OK
A13: 10 | B13: % de hitos atrasados | C13: [% Hitos Atrasados] | D13: =IFERROR(E11/E4,0) | E13: =IFERROR(E11/E4,0) -> 0.14124294 | F13: 0.141 | G13: =IF(ABS(E13-F13)<=MAX(0.51,ABS(F13)*0.01),"OK","Revisar") -> OK
