Workbook

Sheet Parametros
A1: PARÁMETROS DEL MODELO — POA 2026
A3: Fecha de Corte | B3: 46258
A4: Umbral Verde (Gap ≤) | B4: 5
A5: Umbral Amarillo (Gap ≤) | B5: 20
A6: Umbral % Cierres Q4 (Riesgo) | B6: 55
A7: Umbral Brecha Q4 (Riesgo) | B7: 6
A9: Nota: las celdas amarillas son parámetros editables. Todo el modelo (Datos_POA, Resumen_Gerencias) recalcula automáticamente al cambiarlos.

Sheet Datos_POA
A1: Codigo | B1: Nombre_Iniciativa | C1: Actividad_Detallada | D1: Fecha_Inicio | E1: Fecha_Fin | F1: Avance_Real_Pct | G1: Avance_Esperado_Pct | H1: Gap_pp | I1: Semaforo | J1: Situacion | K1: Estado | L1: Usuario | M1: Gerencia_Responsable | N1: Tipo_Gestion | O1: Es_Q4 | P1: Es_Vencida | Q1: Es_Proxima_30d
A2: AR-01 | B2: IAM - Gestor de identidades interno (Fase 2) | C2: Habilitar el módulo para externos ""NERM"". Despliegue y estabilización en producción. Habilitar roles de Internos basados en el cargo de SSFF. Habilitar roles para Filiales (Acovi, App Deuna, Almesa, Vaserum) Despliegue, estabilización y entrega a operaciones Resolver deuda técnica integraciones" Eliminar dependencias WSO2: Desacoplar aplicaciones que usan la plataforma WSO2 (Servicios Omnicanalidad, login central, motor de transferencias, SGG, Portal 8) Apagado plataforma WSO2 | D2: 45383 | E2: 46689 | F2: 35 | G2: =IF(OR(D2="",E2="",E2<=D2),"",MIN(100,MAX(0,(Parametros!$B$3-D2)/(E2-D2)*100))) -> 66.998469 | H2: =IF(G2="","",G2-F2) -> 31.998469 | I2: =IF(K2="Finalizado","Verde",IF(G2="","Amarillo",IF(H2<=Parametros!$B$4,"Verde",IF(H2<=Parametros!$B$5,"Amarillo","Rojo")))) -> Rojo | J2: =IF(K2="Finalizado","Completado",IF(G2="","Sin fecha válida - revisar plazos",IF(H2<=Parametros!$B$4,"En tiempo, según lo planificado",IF(H2<=Parametros!$B$5,"Atraso leve - seguimiento cercano ("&TEXT(H2,"0.0")&" p.p.)","Atraso crítico - requiere intervención ("&TEXT(H2,"0.0")&" p.p.)")))) -> Atraso crítico - requiere intervención (32.0 p.p.) | K2: En ejecución | L2: VERDEZOTO GARCIA ROCIO PIEDAD;#29 | M2: COE Arquitectura | N2: Proyecto | O2: =IF(AND(E2<>"",YEAR(E2)=YEAR(Parametros!$B$3),MONTH(E2)>=10),1,0) -> 0 | P2: =IF(AND(E2<Parametros!$B$3,K2<>"Finalizado"),1,0) -> 0 | Q2: =IF(AND(E2>=Parametros!$B$3,E2<=Parametros!$B$3+30,K2<>"Finalizado"),1,0) -> 0
A3: AR-02 | B3: Adquisición e implementación herramienta de modelamiento de amenazas | C3: Integrar el modelamiento de amenazas en aplicaciones de Banco en base al número de licencias adquiridas | D3: 45658 | E3: 46387 | F3: 80 | G3: =IF(OR(D3="",E3="",E3<=D3),"",MIN(100,MAX(0,(Parametros!$B$3-D3)/(E3-D3)*100))) -> 82.304527 | H3: =IF(G3="","",G3-F3) -> 2.3045267 | I3: =IF(K3="Finalizado","Verde",IF(G3="","Amarillo",IF(H3<=Parametros!$B$4,"Verde",IF(H3<=Parametros!$B$5,"Amarillo","Rojo")))) -> Verde | J3: =IF(K3="Finalizado","Completado",IF(G3="","Sin fecha válida - revisar plazos",IF(H3<=Parametros!$B$4,"En tiempo, según lo planificado",IF(H3<=Parametros!$B$5,"Atraso leve - seguimiento cercano ("&TEXT(H3,"0.0")&" p.p.)","Atraso crítico - requiere intervención ("&TEXT(H3,"0.0")&" p.p.)")))) -> En tiempo, según lo planificado | K3: En ejecución | L3: BURGOS SHUGULI MARCELO VINICIO;#394 | M3: COE Arquitectura | N3: Proyecto | O3: =IF(AND(E3<>"",YEAR(E3)=YEAR(Parametros!$B$3),MONTH(E3)>=10),1,0) -> 1 | P3: =IF(AND(E3<Parametros!$B$3,K3<>"Finalizado"),1,0) -> 0 | Q3: =IF(AND(E3>=Parametros!$B$3,E3<=Parametros!$B$3+30,K3<>"Finalizado"),1,0) -> 0
A4: AR-03 | B4: Actualización de la plataforma de CyberArk (Fase1-Fase2) | C4: Cambio de versión a 14.x Switch de plataforma de módulos adicionales a la boveda Implementación PSMP en CyberArk v14.6 — Privileged Session Manager for SSH | D4: 45566 | E4: 46111 | F4: 100 | G4: =IF(OR(D4="",E4="",E4<=D4),"",MIN(100,MAX(0,(Parametros!$B$3-D4)/(E4-D4)*100))) -> 100 | H4: =IF(G4="","",G4-F4) -> 0 | I4: =IF(K4="Finalizado","Verde",IF(G4="","Amarillo",IF(H4<=Parametros!$B$4,"Verde",IF(H4<=Parametros!$B$5,"Amarillo","Rojo")))) -> Verde | J4: =IF(K4="Finalizado","Completado",IF(G4="","Sin fecha válida - revisar plazos",IF(H4<=Parametros!$B$4,"En tiempo, según lo planificado",IF(H4<=Parametros!$B$5,"Atraso leve - seguimiento cercano ("&TEXT(H4,"0.0")&" p.p.)","Atraso crítico - requiere intervención ("&TEXT(H4,"0.0")&" p.p.)")))) -> Completado | K4: Finalizado | L4: NOGALES LEON LUIS GUSTAVO;#17;#SOTO CORONEL ROBERT STALIN;#344 | M4: COE Arquitectura | N4: Proyecto | O4: =IF(AND(E4<>"",YEAR(E4)=YEAR(Parametros!$B$3),MONTH(E4)>=10),1,0) -> 0 | P4: =IF(AND(E4<Parametros!$B$3,K4<>"Finalizado"),1,0) -> 0 | Q4: =IF(AND(E4>=Parametros!$B$3,E4<=Parametros!$B$3+30,K4<>"Finalizado"),1,0) -> 0
A5: AR-04 | B5: IAM - Gestor de identidades interno (Fase 1) | C5: "1.1 Integración fuentes autoritativas: SSFF / NERM 1.2 Integración sistemas conectados: Bancs, Siglo21, RHDS, Logiflow 1.3 Integración sistemas no conectados - Service Now 1.4 Construcción Worflows ABM usuarios 1.5 Construcción Roles de Acceso" 1.6. Eliminar dependencias WSO2 - Desacoplar aplicaciones que usan la plataforma WSO2 (Servicios Omnicanalidad, login central, motor de transferencias, SGG, Portal 8) Apagado plataforma WSO2 | D5: 45383 | E5: 46111 | F5: 100 | G5: =IF(OR(D5="",E5="",E5<=D5),"",MIN(100,MAX(0,(Parametros!$B$3-D5)/(E5-D5)*100))) -> 100 | H5: =IF(G5="","",G5-F5) -> 0 | I5: =IF(K5="Finalizado","Verde",IF(G5="","Amarillo",IF(H5<=Parametros!$B$4,"Verde",IF(H5<=Parametros!$B$5,"Amarillo","Rojo")))) -> Verde | J5: =IF(K5="Finalizado","Completado",IF(G5="","Sin fecha válida - revisar plazos",IF(H5<=Parametros!$B$4,"En tiempo, según lo planificado",IF(H5<=Parametros!$B$5,"Atraso leve - seguimiento cercano ("&TEXT(H5,"0.0")&" p.p.)","Atraso crítico - requiere intervención ("&TEXT(H5,"0.0")&" p.p.)")))) -> Completado | K5: Finalizado | L5: RAMIREZ ESPINOSA CARLOS ALBERTO;#16;#VERDEZOTO GARCIA ROCIO PIEDAD;#29 | M5: COE Arquitectura | N5: Proyecto | O5: =IF(AND(E5<>"",YEAR(E5)=YEAR(Parametros!$B$3),MONTH(E5)>=10),1,0) -> 0 | P5: =IF(AND(E5<Parametros!$B$3,K5<>"Finalizado"),1,0) -> 0 | Q5: =IF(AND(E5>=Parametros!$B$3,E5<=Parametros!$B$3+30,K5<>"Finalizado"),1,0) -> 0
A6: AR-05 | B6: Gestión de Incidentes de Seguridad e Inteligencia de Amenazas - Service Now (Fase2) | C6: Ajuste funcionalidad SIR & TIP para el equipo de Respuesta a Incidentes usando la plataforma de Service Now y los módulos Secops | D6: 45383 | E6: 46202 | F6: 89 | G6: =IF(OR(D6="",E6="",E6<=D6),"",MIN(100,MAX(0,(Parametros!$B$3-D6)/(E6-D6)*100))) -> 100 | H6: =IF(G6="","",G6-F6) -> 11 | I6: =IF(K6="Finalizado","Verde",IF(G6="","Amarillo",IF(H6<=Parametros!$B$4,"Verde",IF(H6<=Parametros!$B$5,"Amarillo","Rojo")))) -> Amarillo | J6: =IF(K6="Finalizado","Completado",IF(G6="","Sin fecha válida - revisar plazos",IF(H6<=Parametros!$B$4,"En tiempo, según lo planificado",IF(H6<=Parametros!$B$5,"Atraso leve - seguimiento cercano ("&TEXT(H6,"0.0")&" p.p.)","Atraso crítico - requiere intervención ("&TEXT(H6,"0.0")&" p.p.)")))) -> Atraso leve - seguimiento cercano (11.0 p.p.) | K6: En ejecución | L6: SILVA PROANO SANTIAGO DAVID;#389 | M6: COE Arquitectura | N6: Proyecto | O6: =IF(AND(E6<>"",YEAR(E6)=YEAR(Parametros!$B$3),MONTH(E6)>=10),1,0) -> 0 | P6: =IF(AND(E6<Parametros!$B$3,K6<>"Finalizado"),1,0) -> 1 | Q6: =IF(AND(E6>=Parametros!$B$3,E6<=Parametros!$B$3+30,K6<>"Finalizado"),1,0) -> 0
A7: AR-06 | B7: Optimización procedimiento de evaluación de plantilla Línea Base | C7: Despliegue de los componentes de CIS CAT Pro en Infraestructura On-premise de Banco Pichincha | D7: 46027 | E7: 46295 | F7: 90 | G7: =IF(OR(D7="",E7="",E7<=D7),"",MIN(100,MAX(0,(Parametros!$B$3-D7)/(E7-D7)*100))) -> 86.19403 | H7: =IF(G7="","",G7-F7) -> -3.8059701 | I7: =IF(K7="Finalizado","Verde",IF(G7="","Amarillo",IF(H7<=Parametros!$B$4,"Verde",IF(H7<=Parametros!$B$5,"Amarillo","Rojo")))) -> Verde | J7: =IF(K7="Finalizado","Completado",IF(G7="","Sin fecha válida - revisar plazos",IF(H7<=Parametros!$B$4,"En tiempo, según lo planificado",IF(H7<=Parametros!$B$5,"Atraso leve - seguimiento cercano ("&TEXT(H7,"0.0")&" p.p.)","Atraso crítico - requiere intervención ("&TEXT(H7,"0.0")&" p.p.)")))) -> En tiempo, según lo planificado | K7: En ejecución | L7: SILVA PROANO SANTIAGO DAVID;#389 | M7: COE Arquitectura | N7: POA | O7: =IF(AND(E7<>"",YEAR(E7)=YEAR(Parametros!$B$3),MONTH(E7)>=10),1,0) -> 0 | P7: =IF(AND(E7<Parametros!$B$3,K7<>"Finalizado"),1,0) -> 0 | Q7: =IF(AND(E7>=Parametros!$B$3,E7<=Parametros!$B$3+30,K7<>"Finalizado"),1,0) -> 0
A8: AR-07 | B8: Reestructurar los estandares Windows y Linux para mejorar el proceso de medición de configuraciones de Ciberseguridad | C8: Creación de estándar para Servidores Members Server, AD Servers y Windows 2025 | D8: 46027 | E8: 46234 | F8: 100 | G8: =IF(OR(D8="",E8="",E8<=D8),"",MIN(100,MAX(0,(Parametros!$B$3-D8)/(E8-D8)*100))) -> 100 | H8: =IF(G8="","",G8-F8) -> 0 | I8: =IF(K8="Finalizado","Verde",IF(G8="","Amarillo",IF(H8<=Parametros!$B$4,"Verde",IF(H8<=Parametros!$B$5,"Amarillo","Rojo")))) -> Verde | J8: =IF(K8="Finalizado","Completado",IF(G8="","Sin fecha válida - revisar plazos",IF(H8<=Parametros!$B$4,"En tiempo, según lo planificado",IF(H8<=Parametros!$B$5,"Atraso leve - seguimiento cercano ("&TEXT(H8,"0.0")&" p.p.)","Atraso crítico - requiere intervención ("&TEXT(H8,"0.0")&" p.p.)")))) -> Completado | K8: Finalizado | L8: SILVA PROANO SANTIAGO DAVID;#389 | M8: COE Arquitectura | N8: POA | O8: =IF(AND(E8<>"",YEAR(E8)=YEAR(Parametros!$B$3),MONTH(E8)>=10),1,0) -> 0 | P8: =IF(AND(E8<Parametros!$B$3,K8<>"Finalizado"),1,0) -> 0 | Q8: =IF(AND(E8>=Parametros!$B$3,E8<=Parametros!$B$3+30,K8<>"Finalizado"),1,0) -> 0
A9: AR-08 | B9: Mejora del proceso de Gestión de Software Utilitario - Integración con el proceso de Software Utilitario de TI (Workplace) | C9: Integración con el proceso de TI, para gestión centralizada del Software Utilitario de Usuarios Finales | D9: 46027 | E9: 46234 | F9: 100 | G9: =IF(OR(D9="",E9="",E9<=D9),"",MIN(100,MAX(0,(Parametros!$B$3-D9)/(E9-D9)*100))) -> 100 | H9: =IF(G9="","",G9-F9) -> 0 | I9: =IF(K9="Finalizado","Verde",IF(G9="","Amarillo",IF(H9<=Parametros!$B$4,"Verde",IF(H9<=Parametros!$B$5,"Amarillo","Rojo")))) -> Verde | J9: =IF(K9="Finalizado","Completado",IF(G9="","Sin fecha válida - revisar plazos",IF(H9<=Parametros!$B$4,"En tiempo, según lo planificado",IF(H9<=Parametros!$B$5,"Atraso leve - seguimiento cercano ("&TEXT(H9,"0.0")&" p.p.)","Atraso crítico - requiere intervención ("&TEXT(H9,"0.0")&" p.p.)")))) -> Completado | K9: Finalizado | L9: SILVA PROANO SANTIAGO DAVID;#389 | M9: COE Arquitectura | N9: POA | O9: =IF(AND(E9<>"",YEAR(E9)=YEAR(Parametros!$B$3),MONTH(E9)>=10),1,0) -> 0 | P9: =IF(AND(E9<Parametros!$B$3,K9<>"Finalizado"),1,0) -> 0 | Q9: =IF(AND(E9>=Parametros!$B$3,E9<=Parametros!$B$3+30,K9<>"Finalizado"),1,0) -> 0
A10: AR-09 | B10: Mejora Proceso SSDLC | C10: "Ampliar la cobertura de SAST y DAST Optimizar el control dinamico con DAST Acompañar al equipo de Devops a la plataforma de GitHub" | D10: 45719 | E10: 46568 | F10: 58 | G10: =IF(OR(D10="",E10="",E10<=D10),"",MIN(100,MAX(0,(Parametros!$B$3-D10)/(E10-D10)*100))) -> 63.486455 | H10: =IF(G10="","",G10-F10) -> 5.4864547 | I10: =IF(K10="Finalizado","Verde",IF(G10="","Amarillo",IF(H10<=Parametros!$B$4,"Verde",IF(H10<=Parametros!$B$5,"Amarillo","Rojo")))) -> Amarillo | J10: =IF(K10="Finalizado","Completado",IF(G10="","Sin fecha válida - revisar plazos",IF(H10<=Parametros!$B$4,"En tiempo, según lo planificado",IF(H10<=Parametros!$B$5,"Atraso leve - seguimiento cercano ("&TEXT(H10,"0.0")&" p.p.)","Atraso crítico - requiere intervención ("&TEXT(H10,"0.0")&" p.p.)")))) -> Atraso leve - seguimiento cercano (5.5 p.p.) | K10: En ejecución | L10: GUEVARA LOPEZ SALOMON DARIO;#380 | M10: COE Arquitectura | N10: POA | O10: =IF(AND(E10<>"",YEAR(E10)=YEAR(Parametros!$B$3),MONTH(E10)>=10),1,0) -> 0 | P10: =IF(AND(E10<Parametros!$B$3,K10<>"Finalizado"),1,0) -> 0 | Q10: =IF(AND(E10>=Parametros!$B$3,E10<=Parametros!$B$3+30,K10<>"Finalizado"),1,0) -> 0
A11: AR-10 | B11: HARDWARE IPS & FIREWALL | C11: Despliegue de Infraestructura Palo Alto en los siguientes entornos: EnP, Terceros y Filiales | D11: 45366 | E11: 46965 | F11: 60 | G11: =IF(OR(D11="",E11="",E11<=D11),"",MIN(100,MAX(0,(Parametros!$B$3-D11)/(E11-D11)*100))) -> 55.784866 | H11: =IF(G11="","",G11-F11) -> -4.2151345 | I11: =IF(K11="Finalizado","Verde",IF(G11="","Amarillo",IF(H11<=Parametros!$B$4,"Verde",IF(H11<=Parametros!$B$5,"Amarillo","Rojo")))) -> Verde | J11: =IF(K11="Finalizado","Completado",IF(G11="","Sin fecha válida - revisar plazos",IF(H11<=Parametros!$B$4,"En tiempo, según lo planificado",IF(H11<=Parametros!$B$5,"Atraso leve - seguimiento cercano ("&TEXT(H11,"0.0")&" p.p.)","Atraso crítico - requiere intervención ("&TEXT(H11,"0.0")&" p.p.)")))) -> En tiempo, según lo planificado | K11: En ejecución | L11: PUNINA CORDOVA CARINA PRISCILA;#393 | M11: COE Arquitectura | N11: Proyecto | O11: =IF(AND(E11<>"",YEAR(E11)=YEAR(Parametros!$B$3),MONTH(E11)>=10),1,0) -> 0 | P11: =IF(AND(E11<Parametros!$B$3,K11<>"Finalizado"),1,0) -> 0 | Q11: =IF(AND(E11>=Parametros!$B$3,E11<=Parametros!$B$3+30,K11<>"Finalizado"),1,0) -> 0
A12: AR-12 | B12: Extender los controles de seguridad Cloud - Firewall Palo Alto Azure (Fase 1 - Azure Inicio Fase 2) | C12: Despliegue en Nube Azure de EnP y Productivo | D12: 46037 | E12: 46387 | F12: 100 | G12: =IF(OR(D12="",E12="",E12<=D12),"",MIN(100,MAX(0,(Parametros!$B$3-D12)/(E12-D12)*100))) -> 63.142857 | H12: =IF(G12="","",G12-F12) -> -36.857143 | I12: =IF(K12="Finalizado","Verde",IF(G12="","Amarillo",IF(H12<=Parametros!$B$4,"Verde",IF(H12<=Parametros!$B$5,"Amarillo","Rojo")))) -> Verde | J12: =IF(K12="Finalizado","Completado",IF(G12="","Sin fecha válida - revisar plazos",IF(H12<=Parametros!$B$4,"En tiempo, según lo planificado",IF(H12<=Parametros!$B$5,"Atraso leve - seguimiento cercano ("&TEXT(H12,"0.0")&" p.p.)","Atraso crítico - requiere intervención ("&TEXT(H12,"0.0")&" p.p.)")))) -> Completado | K12: Finalizado | L12: NOGALES LEON LUIS GUSTAVO;#17 | M12: COE Arquitectura | N12: Proyecto | O12: =IF(AND(E12<>"",YEAR(E12)=YEAR(Parametros!$B$3),MONTH(E12)>=10),1,0) -> 1 | P12: =IF(AND(E12<Parametros!$B$3,K12<>"Finalizado"),1,0) -> 0 | Q12: =IF(AND(E12>=Parametros!$B$3,E12<=Parametros!$B$3+30,K12<>"Finalizado"),1,0) -> 0
A13: AR-13 | B13: Gestor de Vulnerabilidades | C13: Repotenciar el gestor de vulnerabilidades | D13: 46037 | E13: 46387 | F13: 10 | G13: =IF(OR(D13="",E13="",E13<=D13),"",MIN(100,MAX(0,(Parametros!$B$3-D13)/(E13-D13)*100))) -> 63.142857 | H13: =IF(G13="","",G13-F13) -> 53.142857 | I13: =IF(K13="Finalizado","Verde",IF(G13="","Amarillo",IF(H13<=Parametros!$B$4,"Verde",IF(H13<=Parametros!$B$5,"Amarillo","Rojo")))) -> Rojo | J13: =IF(K13="Finalizado","Completado",IF(G13="","Sin fecha válida - revisar plazos",IF(H13<=Parametros!$B$4,"En tiempo, según lo planificado",IF(H13<=Parametros!$B$5,"Atraso leve - seguimiento cercano ("&TEXT(H13,"0.0")&" p.p.)","Atraso crítico - requiere intervención ("&TEXT(H13,"0.0")&" p.p.)")))) -> Atraso crítico - requiere intervención (53.1 p.p.) | K13: Iniciado | L13: NOGALES LEON LUIS GUSTAVO;#17 | M13: COE Arquitectura | N13: Proyecto | O13: =IF(AND(E13<>"",YEAR(E13)=YEAR(Parametros!$B$3),MONTH(E13)>=10),1,0) -> 1 | P13: =IF(AND(E13<Parametros!$B$3,K13<>"Finalizado"),1,0) -> 0 | Q13: =IF(AND(E13>=Parametros!$B$3,E13<=Parametros!$B$3+30,K13<>"Finalizado"),1,0) -> 0
A14: AR-14 | B14: Control de Acceso a Información IRM | C14: Configuración y publicación de etiquetado de información de Office 365 en formatos de archivos soportados por la herramienta. Despliegue de agentes Purview en los equipos Windows de maqueta de Banco. | D14: 45658 | E14: 46111 | F14: 98 | G14: =IF(OR(D14="",E14="",E14<=D14),"",MIN(100,MAX(0,(Parametros!$B$3-D14)/(E14-D14)*100))) -> 100 | H14: =IF(G14="","",G14-F14) -> 2 | I14: =IF(K14="Finalizado","Verde",IF(G14="","Amarillo",IF(H14<=Parametros!$B$4,"Verde",IF(H14<=Parametros!$B$5,"Amarillo","Rojo")))) -> Verde | J14: =IF(K14="Finalizado","Completado",IF(G14="","Sin fecha válida - revisar plazos",IF(H14<=Parametros!$B$4,"En tiempo, según lo planificado",IF(H14<=Parametros!$B$5,"Atraso leve - seguimiento cercano ("&TEXT(H14,"0.0")&" p.p.)","Atraso crítico - requiere intervención ("&TEXT(H14,"0.0")&" p.p.)")))) -> En tiempo, según lo planificado | K14: En ejecución | L14: EXTERNO RODRIGUEZ VARILLAS ABRAHAM JESUS;#390;#EXTERNO RIERA CHAVEZ MARIO ALBERTO;#466 | M14: COE Arquitectura | N14: POA | O14: =IF(AND(E14<>"",YEAR(E14)=YEAR(Parametros!$B$3),MONTH(E14)>=10),1,0) -> 0 | P14: =IF(AND(E14<Parametros!$B$3,K14<>"Finalizado"),1,0) -> 1 | Q14: =IF(AND(E14>=Parametros!$B$3,E14<=Parametros!$B$3+30,K14<>"Finalizado"),1,0) -> 0
A15: CD-01 | B15: Despliegue MISP Banco Pichincha en la nube empresarial | C15: 1. Despliegue de MISP en ambiente TEST. | D15: 46023 | E15: 46173 | F15: 100 | G15: =IF(OR(D15="",E15="",E15<=D15),"",MIN(100,MAX(0,(Parametros!$B$3-D15)/(E15-D15)*100))) -> 100 | H15: =IF(G15="","",G15-F15) -> 0 | I15: =IF(K15="Finalizado","Verde",IF(G15="","Amarillo",IF(H15<=Parametros!$B$4,"Verde",IF(H15<=Parametros!$B$5,"Amarillo","Rojo")))) -> Verde | J15: =IF(K15="Finalizado","Completado",IF(G15="","Sin fecha válida - revisar plazos",IF(H15<=Parametros!$B$4,"En tiempo, según lo planificado",IF(H15<=Parametros!$B$5,"Atraso leve - seguimiento cercano ("&TEXT(H15,"0.0")&" p.p.)","Atraso crítico - requiere intervención ("&TEXT(H15,"0.0")&" p.p.)")))) -> Completado | K15: Finalizado | M15: Ciberdefensa | N15: POA | O15: =IF(AND(E15<>"",YEAR(E15)=YEAR(Parametros!$B$3),MONTH(E15)>=10),1,0) -> 0 | P15: =IF(AND(E15<Parametros!$B$3,K15<>"Finalizado"),1,0) -> 0 | Q15: =IF(AND(E15>=Parametros!$B$3,E15<=Parametros!$B$3+30,K15<>"Finalizado"),1,0) -> 0
A16: CD-01 | B16: Despliegue MISP Banco Pichincha en la nube empresarial | C16: 2. Despliegue de MISP en ambiente PRODUCCIÓN. | D16: 46174 | E16: 46387 | F16: 50 | G16: =IF(OR(D16="",E16="",E16<=D16),"",MIN(100,MAX(0,(Parametros!$B$3-D16)/(E16-D16)*100))) -> 39.43662 | H16: =IF(G16="","",G16-F16) -> -10.56338 | I16: =IF(K16="Finalizado","Verde",IF(G16="","Amarillo",IF(H16<=Parametros!$B$4,"Verde",IF(H16<=Parametros!$B$5,"Amarillo","Rojo")))) -> Verde | J16: =IF(K16="Finalizado","Completado",IF(G16="","Sin fecha válida - revisar plazos",IF(H16<=Parametros!$B$4,"En tiempo, según lo planificado",IF(H16<=Parametros!$B$5,"Atraso leve - seguimiento cercano ("&TEXT(H16,"0.0")&" p.p.)","Atraso crítico - requiere intervención ("&TEXT(H16,"0.0")&" p.p.)")))) -> En tiempo, según lo planificado | K16: En ejecución | M16: Ciberdefensa | N16: POA | O16: =IF(AND(E16<>"",YEAR(E16)=YEAR(Parametros!$B$3),MONTH(E16)>=10),1,0) -> 1 | P16: =IF(AND(E16<Parametros!$B$3,K16<>"Finalizado"),1,0) -> 0 | Q16: =IF(AND(E16>=Parametros!$B$3,E16<=Parametros!$B$3+30,K16<>"Finalizado"),1,0) -> 0
A17: CD-02 | B17: Integración de Ciberinteligencia y Monitoreo Marca Corporativa | C17: 1. Actualización del instructivo de gestión de ciberinteligencia. | D17: 46023 | E17: 46142 | F17: 100 | G17: =IF(OR(D17="",E17="",E17<=D17),"",MIN(100,MAX(0,(Parametros!$B$3-D17)/(E17-D17)*100))) -> 100 | H17: =IF(G17="","",G17-F17) -> 0 | I17: =IF(K17="Finalizado","Verde",IF(G17="","Amarillo",IF(H17<=Parametros!$B$4,"Verde",IF(H17<=Parametros!$B$5,"Amarillo","Rojo")))) -> Verde | J17: =IF(K17="Finalizado","Completado",IF(G17="","Sin fecha válida - revisar plazos",IF(H17<=Parametros!$B$4,"En tiempo, según lo planificado",IF(H17<=Parametros!$B$5,"Atraso leve - seguimiento cercano ("&TEXT(H17,"0.0")&" p.p.)","Atraso crítico - requiere intervención ("&TEXT(H17,"0.0")&" p.p.)")))) -> Completado | K17: Finalizado | M17: Ciberdefensa | N17: POA | O17: =IF(AND(E17<>"",YEAR(E17)=YEAR(Parametros!$B$3),MONTH(E17)>=10),1,0) -> 0 | P17: =IF(AND(E17<Parametros!$B$3,K17<>"Finalizado"),1,0) -> 0 | Q17: =IF(AND(E17>=Parametros!$B$3,E17<=Parametros!$B$3+30,K17<>"Finalizado"),1,0) -> 0
A18: CD-02 | B18: Integración de Ciberinteligencia y Monitoreo Marca Corporativa | C18: 2. Ejecución de la producción de informes de ciberinteligencia para el área de marca corporativa. | D18: 46143 | E18: 46387 | F18: 25 | G18: =IF(OR(D18="",E18="",E18<=D18),"",MIN(100,MAX(0,(Parametros!$B$3-D18)/(E18-D18)*100))) -> 47.131148 | H18: =IF(G18="","",G18-F18) -> 22.131148 | I18: =IF(K18="Finalizado","Verde",IF(G18="","Amarillo",IF(H18<=Parametros!$B$4,"Verde",IF(H18<=Parametros!$B$5,"Amarillo","Rojo")))) -> Rojo | J18: =IF(K18="Finalizado","Completado",IF(G18="","Sin fecha válida - revisar plazos",IF(H18<=Parametros!$B$4,"En tiempo, según lo planificado",IF(H18<=Parametros!$B$5,"Atraso leve - seguimiento cercano ("&TEXT(H18,"0.0")&" p.p.)","Atraso crítico - requiere intervención ("&TEXT(H18,"0.0")&" p.p.)")))) -> Atraso crítico - requiere intervención (22.1 p.p.) | K18: En ejecución | M18: Ciberdefensa | N18: POA | O18: =IF(AND(E18<>"",YEAR(E18)=YEAR(Parametros!$B$3),MONTH(E18)>=10),1,0) -> 1 | P18: =IF(AND(E18<Parametros!$B$3,K18<>"Finalizado"),1,0) -> 0 | Q18: =IF(AND(E18>=Parametros!$B$3,E18<=Parametros!$B$3+30,K18<>"Finalizado"),1,0) -> 0
A19: CD-02 | B19: Integración de Ciberinteligencia y Monitoreo Marca Corporativa | C19: Conectar los procesos de Ciberinteligencia con el manejo de marca corporativa conceptualizando la relación como área consumidora de los productos de inteligencia relacionadas al monitoreo de marca. | D19: 46023 | E19: 46387 | F19: 62.5 | G19: =IF(OR(D19="",E19="",E19<=D19),"",MIN(100,MAX(0,(Parametros!$B$3-D19)/(E19-D19)*100))) -> 64.56044 | H19: =IF(G19="","",G19-F19) -> 2.0604396 | I19: =IF(K19="Finalizado","Verde",IF(G19="","Amarillo",IF(H19<=Parametros!$B$4,"Verde",IF(H19<=Parametros!$B$5,"Amarillo","Rojo")))) -> Verde | J19: =IF(K19="Finalizado","Completado",IF(G19="","Sin fecha válida - revisar plazos",IF(H19<=Parametros!$B$4,"En tiempo, según lo planificado",IF(H19<=Parametros!$B$5,"Atraso leve - seguimiento cercano ("&TEXT(H19,"0.0")&" p.p.)","Atraso crítico - requiere intervención ("&TEXT(H19,"0.0")&" p.p.)")))) -> En tiempo, según lo planificado | K19: En ejecución | L19: ZULES ACOSTA FABRICIO ANDRES;#349 | M19: Ciberdefensa | N19: POA | O19: =IF(AND(E19<>"",YEAR(E19)=YEAR(Parametros!$B$3),MONTH(E19)>=10),1,0) -> 1 | P19: =IF(AND(E19<Parametros!$B$3,K19<>"Finalizado"),1,0) -> 0 | Q19: =IF(AND(E19>=Parametros!$B$3,E19<=Parametros!$B$3+30,K19<>"Finalizado"),1,0) -> 0
A20: CD-03 | B20: Automatización de actividades en cacería de amenazas | C20: 1. Definición, diseño y despliegue de la automatización de la fase de ejecución de cacería de amenazas para al menos 20 ejercicios con información de 1 plataforma de ciberseguridad (EDR). | D20: 46023 | E20: 46203 | F20: 100 | G20: =IF(OR(D20="",E20="",E20<=D20),"",MIN(100,MAX(0,(Parametros!$B$3-D20)/(E20-D20)*100))) -> 100 | H20: =IF(G20="","",G20-F20) -> 0 | I20: =IF(K20="Finalizado","Verde",IF(G20="","Amarillo",IF(H20<=Parametros!$B$4,"Verde",IF(H20<=Parametros!$B$5,"Amarillo","Rojo")))) -> Verde | J20: =IF(K20="Finalizado","Completado",IF(G20="","Sin fecha válida - revisar plazos",IF(H20<=Parametros!$B$4,"En tiempo, según lo planificado",IF(H20<=Parametros!$B$5,"Atraso leve - seguimiento cercano ("&TEXT(H20,"0.0")&" p.p.)","Atraso crítico - requiere intervención ("&TEXT(H20,"0.0")&" p.p.)")))) -> Completado | K20: Finalizado | M20: Ciberdefensa | N20: POA | O20: =IF(AND(E20<>"",YEAR(E20)=YEAR(Parametros!$B$3),MONTH(E20)>=10),1,0) -> 0 | P20: =IF(AND(E20<Parametros!$B$3,K20<>"Finalizado"),1,0) -> 0 | Q20: =IF(AND(E20>=Parametros!$B$3,E20<=Parametros!$B$3+30,K20<>"Finalizado"),1,0) -> 0
A21: CD-03 | B21: Automatización de actividades en cacería de amenazas | C21: 2. Validación, optimización y medición de la automatización de la fase de ejecución de cacería de amenazas para al menos 20 ejercicios con información de 1 plataforma de ciberseguridad (EDR). | D21: 46204 | E21: 46387 | F21: 15 | G21: =IF(OR(D21="",E21="",E21<=D21),"",MIN(100,MAX(0,(Parametros!$B$3-D21)/(E21-D21)*100))) -> 29.508197 | H21: =IF(G21="","",G21-F21) -> 14.508197 | I21: =IF(K21="Finalizado","Verde",IF(G21="","Amarillo",IF(H21<=Parametros!$B$4,"Verde",IF(H21<=Parametros!$B$5,"Amarillo","Rojo")))) -> Amarillo | J21: =IF(K21="Finalizado","Completado",IF(G21="","Sin fecha válida - revisar plazos",IF(H21<=Parametros!$B$4,"En tiempo, según lo planificado",IF(H21<=Parametros!$B$5,"Atraso leve - seguimiento cercano ("&TEXT(H21,"0.0")&" p.p.)","Atraso crítico - requiere intervención ("&TEXT(H21,"0.0")&" p.p.)")))) -> Atraso leve - seguimiento cercano (14.5 p.p.) | K21: En ejecución | M21: Ciberdefensa | N21: POA | O21: =IF(AND(E21<>"",YEAR(E21)=YEAR(Parametros!$B$3),MONTH(E21)>=10),1,0) -> 1 | P21: =IF(AND(E21<Parametros!$B$3,K21<>"Finalizado"),1,0) -> 0 | Q21: =IF(AND(E21>=Parametros!$B$3,E21<=Parametros!$B$3+30,K21<>"Finalizado"),1,0) -> 0
A22: CD-03 | B22: Automatización de actividades en cacería de amenazas | C22: Automatizar la fase de ejecución de cacería de amenazas para al menos 20 ejercicios con información de 1 plataforma de ciberseguridad (EDR). | D22: 46023 | E22: 46387 | F22: 57.5 | G22: =IF(OR(D22="",E22="",E22<=D22),"",MIN(100,MAX(0,(Parametros!$B$3-D22)/(E22-D22)*100))) -> 64.56044 | H22: =IF(G22="","",G22-F22) -> 7.0604396 | I22: =IF(K22="Finalizado","Verde",IF(G22="","Amarillo",IF(H22<=Parametros!$B$4,"Verde",IF(H22<=Parametros!$B$5,"Amarillo","Rojo")))) -> Amarillo | J22: =IF(K22="Finalizado","Completado",IF(G22="","Sin fecha válida - revisar plazos",IF(H22<=Parametros!$B$4,"En tiempo, según lo planificado",IF(H22<=Parametros!$B$5,"Atraso leve - seguimiento cercano ("&TEXT(H22,"0.0")&" p.p.)","Atraso crítico - requiere intervención ("&TEXT(H22,"0.0")&" p.p.)")))) -> Atraso leve - seguimiento cercano (7.1 p.p.) | K22: En ejecución | L22: ZULES ACOSTA FABRICIO ANDRES;#349 | M22: Ciberdefensa | N22: POA | O22: =IF(AND(E22<>"",YEAR(E22)=YEAR(Parametros!$B$3),MONTH(E22)>=10),1,0) -> 1 | P22: =IF(AND(E22<Parametros!$B$3,K22<>"Finalizado"),1,0) -> 0 | Q22: =IF(AND(E22>=Parametros!$B$3,E22<=Parametros!$B$3+30,K22<>"Finalizado"),1,0) -> 0
A23: CD-04 | B23: Implementación del Dashboard - Normalidad, Alerta y Crisis | C23: Arquitectura y ambiente Splunk | D23: 46078 | E23: 46087 | F23: 100 | G23: =IF(OR(D23="",E23="",E23<=D23),"",MIN(100,MAX(0,(Parametros!$B$3-D23)/(E23-D23)*100))) -> 100 | H23: =IF(G23="","",G23-F23) -> 0 | I23: =IF(K23="Finalizado","Verde",IF(G23="","Amarillo",IF(H23<=Parametros!$B$4,"Verde",IF(H23<=Parametros!$B$5,"Amarillo","Rojo")))) -> Verde | J23: =IF(K23="Finalizado","Completado",IF(G23="","Sin fecha válida - revisar plazos",IF(H23<=Parametros!$B$4,"En tiempo, según lo planificado",IF(H23<=Parametros!$B$5,"Atraso leve - seguimiento cercano ("&TEXT(H23,"0.0")&" p.p.)","Atraso crítico - requiere intervención ("&TEXT(H23,"0.0")&" p.p.)")))) -> Completado | K23: Finalizado | M23: Ciberdefensa | N23: POA | O23: =IF(AND(E23<>"",YEAR(E23)=YEAR(Parametros!$B$3),MONTH(E23)>=10),1,0) -> 0 | P23: =IF(AND(E23<Parametros!$B$3,K23<>"Finalizado"),1,0) -> 0 | Q23: =IF(AND(E23>=Parametros!$B$3,E23<=Parametros!$B$3+30,K23<>"Finalizado"),1,0) -> 0
A24: CD-04 | B24: Implementación del Dashboard - Normalidad, Alerta y Crisis | C24: Automatización y alertamiento | D24: 46222 | E24: 46276 | F24: 25 | G24: =IF(OR(D24="",E24="",E24<=D24),"",MIN(100,MAX(0,(Parametros!$B$3-D24)/(E24-D24)*100))) -> 66.666667 | H24: =IF(G24="","",G24-F24) -> 41.666667 | I24: =IF(K24="Finalizado","Verde",IF(G24="","Amarillo",IF(H24<=Parametros!$B$4,"Verde",IF(H24<=Parametros!$B$5,"Amarillo","Rojo")))) -> Rojo | J24: =IF(K24="Finalizado","Completado",IF(G24="","Sin fecha válida - revisar plazos",IF(H24<=Parametros!$B$4,"En tiempo, según lo planificado",IF(H24<=Parametros!$B$5,"Atraso leve - seguimiento cercano ("&TEXT(H24,"0.0")&" p.p.)","Atraso crítico - requiere intervención ("&TEXT(H24,"0.0")&" p.p.)")))) -> Atraso crítico - requiere intervención (41.7 p.p.) | K24: En ejecución | M24: Ciberdefensa | N24: POA | O24: =IF(AND(E24<>"",YEAR(E24)=YEAR(Parametros!$B$3),MONTH(E24)>=10),1,0) -> 0 | P24: =IF(AND(E24<Parametros!$B$3,K24<>"Finalizado"),1,0) -> 0 | Q24: =IF(AND(E24>=Parametros!$B$3,E24<=Parametros!$B$3+30,K24<>"Finalizado"),1,0) -> 1
A25: CD-04 | B25: Implementación del Dashboard - Normalidad, Alerta y Crisis | C25: Capacitación y adopción | D25: 46155 | E25: 46164 | F25: 100 | G25: =IF(OR(D25="",E25="",E25<=D25),"",MIN(100,MAX(0,(Parametros!$B$3-D25)/(E25-D25)*100))) -> 100 | H25: =IF(G25="","",G25-F25) -> 0 | I25: =IF(K25="Finalizado","Verde",IF(G25="","Amarillo",IF(H25<=Parametros!$B$4,"Verde",IF(H25<=Parametros!$B$5,"Amarillo","Rojo")))) -> Verde | J25: =IF(K25="Finalizado","Completado",IF(G25="","Sin fecha válida - revisar plazos",IF(H25<=Parametros!$B$4,"En tiempo, según lo planificado",IF(H25<=Parametros!$B$5,"Atraso leve - seguimiento cercano ("&TEXT(H25,"0.0")&" p.p.)","Atraso crítico - requiere intervención ("&TEXT(H25,"0.0")&" p.p.)")))) -> Completado | K25: Finalizado | M25: Ciberdefensa | N25: POA | O25: =IF(AND(E25<>"",YEAR(E25)=YEAR(Parametros!$B$3),MONTH(E25)>=10),1,0) -> 0 | P25: =IF(AND(E25<Parametros!$B$3,K25<>"Finalizado"),1,0) -> 0 | Q25: =IF(AND(E25>=Parametros!$B$3,E25<=Parametros!$B$3+30,K25<>"Finalizado"),1,0) -> 0
A26: CD-04 | B26: Implementación del Dashboard - Normalidad, Alerta y Crisis | C26: Cierre del proyecto | D26: 46266 | E26: 46295 | F26: 0 | G26: =IF(OR(D26="",E26="",E26<=D26),"",MIN(100,MAX(0,(Parametros!$B$3-D26)/(E26-D26)*100))) -> 0 | H26: =IF(G26="","",G26-F26) -> 0 | I26: =IF(K26="Finalizado","Verde",IF(G26="","Amarillo",IF(H26<=Parametros!$B$4,"Verde",IF(H26<=Parametros!$B$5,"Amarillo","Rojo")))) -> Verde | J26: =IF(K26="Finalizado","Completado",IF(G26="","Sin fecha válida - revisar plazos",IF(H26<=Parametros!$B$4,"En tiempo, según lo planificado",IF(H26<=Parametros!$B$5,"Atraso leve - seguimiento cercano ("&TEXT(H26,"0.0")&" p.p.)","Atraso crítico - requiere intervención ("&TEXT(H26,"0.0")&" p.p.)")))) -> En tiempo, según lo planificado | K26: No iniciado | M26: Ciberdefensa | N26: POA | O26: =IF(AND(E26<>"",YEAR(E26)=YEAR(Parametros!$B$3),MONTH(E26)>=10),1,0) -> 0 | P26: =IF(AND(E26<Parametros!$B$3,K26<>"Finalizado"),1,0) -> 0 | Q26: =IF(AND(E26>=Parametros!$B$3,E26<=Parametros!$B$3+30,K26<>"Finalizado"),1,0) -> 0
A27: CD-04 | B27: Implementación del Dashboard - Normalidad, Alerta y Crisis | C27: Construcción del Dashboard | D27: 46084 | E27: 46115 | F27: 100 | G27: =IF(OR(D27="",E27="",E27<=D27),"",MIN(100,MAX(0,(Parametros!$B$3-D27)/(E27-D27)*100))) -> 100 | H27: =IF(G27="","",G27-F27) -> 0 | I27: =IF(K27="Finalizado","Verde",IF(G27="","Amarillo",IF(H27<=Parametros!$B$4,"Verde",IF(H27<=Parametros!$B$5,"Amarillo","Rojo")))) -> Verde | J27: =IF(K27="Finalizado","Completado",IF(G27="","Sin fecha válida - revisar plazos",IF(H27<=Parametros!$B$4,"En tiempo, según lo planificado",IF(H27<=Parametros!$B$5,"Atraso leve - seguimiento cercano ("&TEXT(H27,"0.0")&" p.p.)","Atraso crítico - requiere intervención ("&TEXT(H27,"0.0")&" p.p.)")))) -> Completado | K27: Finalizado | M27: Ciberdefensa | N27: POA | O27: =IF(AND(E27<>"",YEAR(E27)=YEAR(Parametros!$B$3),MONTH(E27)>=10),1,0) -> 0 | P27: =IF(AND(E27<Parametros!$B$3,K27<>"Finalizado"),1,0) -> 0 | Q27: =IF(AND(E27>=Parametros!$B$3,E27<=Parametros!$B$3+30,K27<>"Finalizado"),1,0) -> 0
A28: CD-04 | B28: Implementación del Dashboard - Normalidad, Alerta y Crisis | C28: Definición de umbrales y estados | D28: 46118 | E28: 46157 | F28: 100 | G28: =IF(OR(D28="",E28="",E28<=D28),"",MIN(100,MAX(0,(Parametros!$B$3-D28)/(E28-D28)*100))) -> 100 | H28: =IF(G28="","",G28-F28) -> 0 | I28: =IF(K28="Finalizado","Verde",IF(G28="","Amarillo",IF(H28<=Parametros!$B$4,"Verde",IF(H28<=Parametros!$B$5,"Amarillo","Rojo")))) -> Verde | J28: =IF(K28="Finalizado","Completado",IF(G28="","Sin fecha válida - revisar plazos",IF(H28<=Parametros!$B$4,"En tiempo, según lo planificado",IF(H28<=Parametros!$B$5,"Atraso leve - seguimiento cercano ("&TEXT(H28,"0.0")&" p.p.)","Atraso crítico - requiere intervención ("&TEXT(H28,"0.0")&" p.p.)")))) -> Completado | K28: Finalizado | M28: Ciberdefensa | N28: POA | O28: =IF(AND(E28<>"",YEAR(E28)=YEAR(Parametros!$B$3),MONTH(E28)>=10),1,0) -> 0 | P28: =IF(AND(E28<Parametros!$B$3,K28<>"Finalizado"),1,0) -> 0 | Q28: =IF(AND(E28>=Parametros!$B$3,E28<=Parametros!$B$3+30,K28<>"Finalizado"),1,0) -> 0
A29: CD-04 | B29: Implementación del Dashboard - Normalidad, Alerta y Crisis | C29: Diseño conceptual del Dashboard | D29: 46078 | E29: 46094 | F29: 100 | G29: =IF(OR(D29="",E29="",E29<=D29),"",MIN(100,MAX(0,(Parametros!$B$3-D29)/(E29-D29)*100))) -> 100 | H29: =IF(G29="","",G29-F29) -> 0 | I29: =IF(K29="Finalizado","Verde",IF(G29="","Amarillo",IF(H29<=Parametros!$B$4,"Verde",IF(H29<=Parametros!$B$5,"Amarillo","Rojo")))) -> Verde | J29: =IF(K29="Finalizado","Completado",IF(G29="","Sin fecha válida - revisar plazos",IF(H29<=Parametros!$B$4,"En tiempo, según lo planificado",IF(H29<=Parametros!$B$5,"Atraso leve - seguimiento cercano ("&TEXT(H29,"0.0")&" p.p.)","Atraso crítico - requiere intervención ("&TEXT(H29,"0.0")&" p.p.)")))) -> Completado | K29: Finalizado | M29: Ciberdefensa | N29: POA | O29: =IF(AND(E29<>"",YEAR(E29)=YEAR(Parametros!$B$3),MONTH(E29)>=10),1,0) -> 0 | P29: =IF(AND(E29<Parametros!$B$3,K29<>"Finalizado"),1,0) -> 0 | Q29: =IF(AND(E29>=Parametros!$B$3,E29<=Parametros!$B$3+30,K29<>"Finalizado"),1,0) -> 0
A30: CD-04 | B30: Implementación del Dashboard - Normalidad, Alerta y Crisis | C30: Gobierno y flujo operativo.. | D30: 46258 | E30: 46276 | F30: 0 | G30: =IF(OR(D30="",E30="",E30<=D30),"",MIN(100,MAX(0,(Parametros!$B$3-D30)/(E30-D30)*100))) -> 0 | H30: =IF(G30="","",G30-F30) -> 0 | I30: =IF(K30="Finalizado","Verde",IF(G30="","Amarillo",IF(H30<=Parametros!$B$4,"Verde",IF(H30<=Parametros!$B$5,"Amarillo","Rojo")))) -> Verde | J30: =IF(K30="Finalizado","Completado",IF(G30="","Sin fecha válida - revisar plazos",IF(H30<=Parametros!$B$4,"En tiempo, según lo planificado",IF(H30<=Parametros!$B$5,"Atraso leve - seguimiento cercano ("&TEXT(H30,"0.0")&" p.p.)","Atraso crítico - requiere intervención ("&TEXT(H30,"0.0")&" p.p.)")))) -> En tiempo, según lo planificado | K30: No iniciado | M30: Ciberdefensa | N30: POA | O30: =IF(AND(E30<>"",YEAR(E30)=YEAR(Parametros!$B$3),MONTH(E30)>=10),1,0) -> 0 | P30: =IF(AND(E30<Parametros!$B$3,K30<>"Finalizado"),1,0) -> 0 | Q30: =IF(AND(E30>=Parametros!$B$3,E30<=Parametros!$B$3+30,K30<>"Finalizado"),1,0) -> 1
A31: CD-04 | B31: Implementación del Dashboard - Normalidad, Alerta y Crisis | C31: Mejoras y ampliaciones | D31: 46160 | E31: 46272 | F31: 68 | G31: =IF(OR(D31="",E31="",E31<=D31),"",MIN(100,MAX(0,(Parametros!$B$3-D31)/(E31-D31)*100))) -> 87.5 | H31: =IF(G31="","",G31-F31) -> 19.5 | I31: =IF(K31="Finalizado","Verde",IF(G31="","Amarillo",IF(H31<=Parametros!$B$4,"Verde",IF(H31<=Parametros!$B$5,"Amarillo","Rojo")))) -> Amarillo | J31: =IF(K31="Finalizado","Completado",IF(G31="","Sin fecha válida - revisar plazos",IF(H31<=Parametros!$B$4,"En tiempo, según lo planificado",IF(H31<=Parametros!$B$5,"Atraso leve - seguimiento cercano ("&TEXT(H31,"0.0")&" p.p.)","Atraso crítico - requiere intervención ("&TEXT(H31,"0.0")&" p.p.)")))) -> Atraso leve - seguimiento cercano (19.5 p.p.) | K31: En ejecución | M31: Ciberdefensa | N31: POA | O31: =IF(AND(E31<>"",YEAR(E31)=YEAR(Parametros!$B$3),MONTH(E31)>=10),1,0) -> 0 | P31: =IF(AND(E31<Parametros!$B$3,K31<>"Finalizado"),1,0) -> 0 | Q31: =IF(AND(E31>=Parametros!$B$3,E31<=Parametros!$B$3+30,K31<>"Finalizado"),1,0) -> 1
A32: CD-04 | B32: Implementación del Dashboard - Normalidad, Alerta y Crisis | C32: Organización y definición de iniciativa | D32: 46063 | E32: 46078 | F32: 100 | G32: =IF(OR(D32="",E32="",E32<=D32),"",MIN(100,MAX(0,(Parametros!$B$3-D32)/(E32-D32)*100))) -> 100 | H32: =IF(G32="","",G32-F32) -> 0 | I32: =IF(K32="Finalizado","Verde",IF(G32="","Amarillo",IF(H32<=Parametros!$B$4,"Verde",IF(H32<=Parametros!$B$5,"Amarillo","Rojo")))) -> Verde | J32: =IF(K32="Finalizado","Completado",IF(G32="","Sin fecha válida - revisar plazos",IF(H32<=Parametros!$B$4,"En tiempo, según lo planificado",IF(H32<=Parametros!$B$5,"Atraso leve - seguimiento cercano ("&TEXT(H32,"0.0")&" p.p.)","Atraso crítico - requiere intervención ("&TEXT(H32,"0.0")&" p.p.)")))) -> Completado | K32: Finalizado | L32: GOMEZ PRADO SANDRA PATRICIA;#144 | M32: Ciberdefensa | N32: POA | O32: =IF(AND(E32<>"",YEAR(E32)=YEAR(Parametros!$B$3),MONTH(E32)>=10),1,0) -> 0 | P32: =IF(AND(E32<Parametros!$B$3,K32<>"Finalizado"),1,0) -> 0 | Q32: =IF(AND(E32>=Parametros!$B$3,E32<=Parametros!$B$3+30,K32<>"Finalizado"),1,0) -> 0
A33: CD-05 | B33: Automatización de actividades de Respuesta a incidentes | C33: Despliegue en ambiente final- Cierre del proyecto | D33: 46329 | E33: 46349 | F33: 0 | G33: =IF(OR(D33="",E33="",E33<=D33),"",MIN(100,MAX(0,(Parametros!$B$3-D33)/(E33-D33)*100))) -> 0 | H33: =IF(G33="","",G33-F33) -> 0 | I33: =IF(K33="Finalizado","Verde",IF(G33="","Amarillo",IF(H33<=Parametros!$B$4,"Verde",IF(H33<=Parametros!$B$5,"Amarillo","Rojo")))) -> Verde | J33: =IF(K33="Finalizado","Completado",IF(G33="","Sin fecha válida - revisar plazos",IF(H33<=Parametros!$B$4,"En tiempo, según lo planificado",IF(H33<=Parametros!$B$5,"Atraso leve - seguimiento cercano ("&TEXT(H33,"0.0")&" p.p.)","Atraso crítico - requiere intervención ("&TEXT(H33,"0.0")&" p.p.)")))) -> En tiempo, según lo planificado | K33: No iniciado | M33: Ciberdefensa | N33: POA | O33: =IF(AND(E33<>"",YEAR(E33)=YEAR(Parametros!$B$3),MONTH(E33)>=10),1,0) -> 1 | P33: =IF(AND(E33<Parametros!$B$3,K33<>"Finalizado"),1,0) -> 0 | Q33: =IF(AND(E33>=Parametros!$B$3,E33<=Parametros!$B$3+30,K33<>"Finalizado"),1,0) -> 0
A34: CD-05 | B34: Automatización de actividades de Respuesta a incidentes | C34: Diseño teorico de playbooks | D34: 46149 | E34: 46209 | F34: 100 | G34: =IF(OR(D34="",E34="",E34<=D34),"",MIN(100,MAX(0,(Parametros!$B$3-D34)/(E34-D34)*100))) -> 100 | H34: =IF(G34="","",G34-F34) -> 0 | I34: =IF(K34="Finalizado","Verde",IF(G34="","Amarillo",IF(H34<=Parametros!$B$4,"Verde",IF(H34<=Parametros!$B$5,"Amarillo","Rojo")))) -> Verde | J34: =IF(K34="Finalizado","Completado",IF(G34="","Sin fecha válida - revisar plazos",IF(H34<=Parametros!$B$4,"En tiempo, según lo planificado",IF(H34<=Parametros!$B$5,"Atraso leve - seguimiento cercano ("&TEXT(H34,"0.0")&" p.p.)","Atraso crítico - requiere intervención ("&TEXT(H34,"0.0")&" p.p.)")))) -> Completado | K34: Finalizado | M34: Ciberdefensa | N34: POA | O34: =IF(AND(E34<>"",YEAR(E34)=YEAR(Parametros!$B$3),MONTH(E34)>=10),1,0) -> 0 | P34: =IF(AND(E34<Parametros!$B$3,K34<>"Finalizado"),1,0) -> 0 | Q34: =IF(AND(E34>=Parametros!$B$3,E34<=Parametros!$B$3+30,K34<>"Finalizado"),1,0) -> 0
A35: CD-05 | B35: Automatización de actividades de Respuesta a incidentes | C35: Estabilización y afinamientos de playbooks en Test | D35: 46269 | E35: 46329 | F35: 0 | G35: =IF(OR(D35="",E35="",E35<=D35),"",MIN(100,MAX(0,(Parametros!$B$3-D35)/(E35-D35)*100))) -> 0 | H35: =IF(G35="","",G35-F35) -> 0 | I35: =IF(K35="Finalizado","Verde",IF(G35="","Amarillo",IF(H35<=Parametros!$B$4,"Verde",IF(H35<=Parametros!$B$5,"Amarillo","Rojo")))) -> Verde | J35: =IF(K35="Finalizado","Completado",IF(G35="","Sin fecha válida - revisar plazos",IF(H35<=Parametros!$B$4,"En tiempo, según lo planificado",IF(H35<=Parametros!$B$5,"Atraso leve - seguimiento cercano ("&TEXT(H35,"0.0")&" p.p.)","Atraso crítico - requiere intervención ("&TEXT(H35,"0.0")&" p.p.)")))) -> En tiempo, según lo planificado | K35: No iniciado | M35: Ciberdefensa | N35: POA | O35: =IF(AND(E35<>"",YEAR(E35)=YEAR(Parametros!$B$3),MONTH(E35)>=10),1,0) -> 1 | P35: =IF(AND(E35<Parametros!$B$3,K35<>"Finalizado"),1,0) -> 0 | Q35: =IF(AND(E35>=Parametros!$B$3,E35<=Parametros!$B$3+30,K35<>"Finalizado"),1,0) -> 0
A36: CD-05 | B36: Automatización de actividades de Respuesta a incidentes | C36: Implementación y pruebas de playbooks en Test | D36: 46209 | E36: 46269 | F36: 44 | G36: =IF(OR(D36="",E36="",E36<=D36),"",MIN(100,MAX(0,(Parametros!$B$3-D36)/(E36-D36)*100))) -> 81.666667 | H36: =IF(G36="","",G36-F36) -> 37.666667 | I36: =IF(K36="Finalizado","Verde",IF(G36="","Amarillo",IF(H36<=Parametros!$B$4,"Verde",IF(H36<=Parametros!$B$5,"Amarillo","Rojo")))) -> Rojo | J36: =IF(K36="Finalizado","Completado",IF(G36="","Sin fecha válida - revisar plazos",IF(H36<=Parametros!$B$4,"En tiempo, según lo planificado",IF(H36<=Parametros!$B$5,"Atraso leve - seguimiento cercano ("&TEXT(H36,"0.0")&" p.p.)","Atraso crítico - requiere intervención ("&TEXT(H36,"0.0")&" p.p.)")))) -> Atraso crítico - requiere intervención (37.7 p.p.) | K36: En ejecución | M36: Ciberdefensa | N36: POA | O36: =IF(AND(E36<>"",YEAR(E36)=YEAR(Parametros!$B$3),MONTH(E36)>=10),1,0) -> 0 | P36: =IF(AND(E36<Parametros!$B$3,K36<>"Finalizado"),1,0) -> 0 | Q36: =IF(AND(E36>=Parametros!$B$3,E36<=Parametros!$B$3+30,K36<>"Finalizado"),1,0) -> 1
A37: CD-05 | B37: Automatización de actividades de Respuesta a incidentes | C37: Integración de plataformas a XSOAR | D37: 46147 | E37: 46192 | F37: 100 | G37: =IF(OR(D37="",E37="",E37<=D37),"",MIN(100,MAX(0,(Parametros!$B$3-D37)/(E37-D37)*100))) -> 100 | H37: =IF(G37="","",G37-F37) -> 0 | I37: =IF(K37="Finalizado","Verde",IF(G37="","Amarillo",IF(H37<=Parametros!$B$4,"Verde",IF(H37<=Parametros!$B$5,"Amarillo","Rojo")))) -> Verde | J37: =IF(K37="Finalizado","Completado",IF(G37="","Sin fecha válida - revisar plazos",IF(H37<=Parametros!$B$4,"En tiempo, según lo planificado",IF(H37<=Parametros!$B$5,"Atraso leve - seguimiento cercano ("&TEXT(H37,"0.0")&" p.p.)","Atraso crítico - requiere intervención ("&TEXT(H37,"0.0")&" p.p.)")))) -> Completado | K37: Finalizado | M37: Ciberdefensa | N37: POA | O37: =IF(AND(E37<>"",YEAR(E37)=YEAR(Parametros!$B$3),MONTH(E37)>=10),1,0) -> 0 | P37: =IF(AND(E37<Parametros!$B$3,K37<>"Finalizado"),1,0) -> 0 | Q37: =IF(AND(E37>=Parametros!$B$3,E37<=Parametros!$B$3+30,K37<>"Finalizado"),1,0) -> 0
A38: CD-05 | B38: Automatización de actividades de Respuesta a incidentes | C38: Integración de plataformas a XSOAR Test | D38: 46147 | E38: 46162 | F38: 100 | G38: =IF(OR(D38="",E38="",E38<=D38),"",MIN(100,MAX(0,(Parametros!$B$3-D38)/(E38-D38)*100))) -> 100 | H38: =IF(G38="","",G38-F38) -> 0 | I38: =IF(K38="Finalizado","Verde",IF(G38="","Amarillo",IF(H38<=Parametros!$B$4,"Verde",IF(H38<=Parametros!$B$5,"Amarillo","Rojo")))) -> Verde | J38: =IF(K38="Finalizado","Completado",IF(G38="","Sin fecha válida - revisar plazos",IF(H38<=Parametros!$B$4,"En tiempo, según lo planificado",IF(H38<=Parametros!$B$5,"Atraso leve - seguimiento cercano ("&TEXT(H38,"0.0")&" p.p.)","Atraso crítico - requiere intervención ("&TEXT(H38,"0.0")&" p.p.)")))) -> Completado | K38: Finalizado | M38: Ciberdefensa | N38: POA | O38: =IF(AND(E38<>"",YEAR(E38)=YEAR(Parametros!$B$3),MONTH(E38)>=10),1,0) -> 0 | P38: =IF(AND(E38<Parametros!$B$3,K38<>"Finalizado"),1,0) -> 0 | Q38: =IF(AND(E38>=Parametros!$B$3,E38<=Parametros!$B$3+30,K38<>"Finalizado"),1,0) -> 0
A39: CD-05 | B39: Automatización de actividades de Respuesta a incidentes | C39: Organización y definición de iniciativa | D39: 46083 | E39: 46121 | F39: 100 | G39: =IF(OR(D39="",E39="",E39<=D39),"",MIN(100,MAX(0,(Parametros!$B$3-D39)/(E39-D39)*100))) -> 100 | H39: =IF(G39="","",G39-F39) -> 0 | I39: =IF(K39="Finalizado","Verde",IF(G39="","Amarillo",IF(H39<=Parametros!$B$4,"Verde",IF(H39<=Parametros!$B$5,"Amarillo","Rojo")))) -> Verde | J39: =IF(K39="Finalizado","Completado",IF(G39="","Sin fecha válida - revisar plazos",IF(H39<=Parametros!$B$4,"En tiempo, según lo planificado",IF(H39<=Parametros!$B$5,"Atraso leve - seguimiento cercano ("&TEXT(H39,"0.0")&" p.p.)","Atraso crítico - requiere intervención ("&TEXT(H39,"0.0")&" p.p.)")))) -> Completado | K39: Finalizado | L39: GOMEZ PRADO SANDRA PATRICIA;#144 | M39: Ciberdefensa | N39: POA | O39: =IF(AND(E39<>"",YEAR(E39)=YEAR(Parametros!$B$3),MONTH(E39)>=10),1,0) -> 0 | P39: =IF(AND(E39<Parametros!$B$3,K39<>"Finalizado"),1,0) -> 0 | Q39: =IF(AND(E39>=Parametros!$B$3,E39<=Parametros!$B$3+30,K39<>"Finalizado"),1,0) -> 0
A40: CD-06 | B40: Preparacion y resiliencia operacional ante incidentes críticos | C40: 1er ejercicio preparación | D40: 46202 | E40: 46262 | F40: 83 | G40: =IF(OR(D40="",E40="",E40<=D40),"",MIN(100,MAX(0,(Parametros!$B$3-D40)/(E40-D40)*100))) -> 93.333333 | H40: =IF(G40="","",G40-F40) -> 10.333333 | I40: =IF(K40="Finalizado","Verde",IF(G40="","Amarillo",IF(H40<=Parametros!$B$4,"Verde",IF(H40<=Parametros!$B$5,"Amarillo","Rojo")))) -> Amarillo | J40: =IF(K40="Finalizado","Completado",IF(G40="","Sin fecha válida - revisar plazos",IF(H40<=Parametros!$B$4,"En tiempo, según lo planificado",IF(H40<=Parametros!$B$5,"Atraso leve - seguimiento cercano ("&TEXT(H40,"0.0")&" p.p.)","Atraso crítico - requiere intervención ("&TEXT(H40,"0.0")&" p.p.)")))) -> Atraso leve - seguimiento cercano (10.3 p.p.) | K40: En ejecución | M40: Ciberdefensa | N40: POA | O40: =IF(AND(E40<>"",YEAR(E40)=YEAR(Parametros!$B$3),MONTH(E40)>=10),1,0) -> 0 | P40: =IF(AND(E40<Parametros!$B$3,K40<>"Finalizado"),1,0) -> 0 | Q40: =IF(AND(E40>=Parametros!$B$3,E40<=Parametros!$B$3+30,K40<>"Finalizado"),1,0) -> 1
...

Sheet Resumen_Gerencias
A1: Gerencia | B1: Total_Registros | C1: Finalizados | D1: Tasa_Cumplimiento_Pct | E1: Avance_Real_Prom | F1: Avance_Esperado_Prom | G1: Gap_prom_pp | H1: Pct_Cierres_Q4 | I1: No_Iniciado_Q4 | J1: Vencidas | K1: Veredicto_Ritmo
A2: COE Arquitectura | B2: =COUNTIF(Datos_POA!$M$2:$M$295,A2) -> 13 | C2: =COUNTIFS(Datos_POA!$M$2:$M$295,A2,Datos_POA!$K$2:$K$295,"Finalizado") -> 5 | D2: =IFERROR(C2/B2*100,0) -> 38.461538 | E2: =AVERAGEIFS(Datos_POA!$F$2:$F$295,Datos_POA!$M$2:$M$295,A2) -> 78.461538 | F2: =AVERAGEIFS(Datos_POA!$G$2:$G$295,Datos_POA!$M$2:$M$295,A2) -> 83.158005 | G2: =F2-E2 -> 4.6964661 | H2: =IFERROR(SUMIFS(Datos_POA!$O$2:$O$295,Datos_POA!$M$2:$M$295,A2)/COUNTIFS(Datos_POA!$M$2:$M$295,A2)*100,0) -> 23.076923 | I2: =SUMIFS(Datos_POA!$O$2:$O$295,Datos_POA!$M$2:$M$295,A2,Datos_POA!$K$2:$K$295,"No iniciado") -> 0 | J2: =SUMIFS(Datos_POA!$P$2:$P$295,Datos_POA!$M$2:$M$295,A2) -> 2 | K2: =IF(AND(G2<=3,H2<=45),"Ejecución constante",IF(OR(H2>Parametros!$B$6,G2>Parametros!$B$7),"Carga concentrada al cierre","Ritmo moderado")) -> Ritmo moderado
A3: Ciberdefensa | B3: =COUNTIF(Datos_POA!$M$2:$M$295,A3) -> 100 | C3: =COUNTIFS(Datos_POA!$M$2:$M$295,A3,Datos_POA!$K$2:$K$295,"Finalizado") -> 49 | D3: =IFERROR(C3/B3*100,0) -> 49 | E3: =AVERAGEIFS(Datos_POA!$F$2:$F$295,Datos_POA!$M$2:$M$295,A3) -> 61.69 | F3: =AVERAGEIFS(Datos_POA!$G$2:$G$295,Datos_POA!$M$2:$M$295,A3) -> 63.989268 | G3: =F3-E3 -> 2.2992682 | H3: =IFERROR(SUMIFS(Datos_POA!$O$2:$O$295,Datos_POA!$M$2:$M$295,A3)/COUNTIFS(Datos_POA!$M$2:$M$295,A3)*100,0) -> 29 | I3: =SUMIFS(Datos_POA!$O$2:$O$295,Datos_POA!$M$2:$M$295,A3,Datos_POA!$K$2:$K$295,"No iniciado") -> 22 | J3: =SUMIFS(Datos_POA!$P$2:$P$295,Datos_POA!$M$2:$M$295,A3) -> 4 | K3: =IF(AND(G3<=3,H3<=45),"Ejecución constante",IF(OR(H3>Parametros!$B$6,G3>Parametros!$B$7),"Carga concentrada al cierre","Ritmo moderado")) -> Ejecución constante
A4: Estrategia y Gobierno | B4: =COUNTIF(Datos_POA!$M$2:$M$295,A4) -> 55 | C4: =COUNTIFS(Datos_POA!$M$2:$M$295,A4,Datos_POA!$K$2:$K$295,"Finalizado") -> 12 | D4: =IFERROR(C4/B4*100,0) -> 21.818182 | E4: =AVERAGEIFS(Datos_POA!$F$2:$F$295,Datos_POA!$M$2:$M$295,A4) -> 47.321091 | F4: =AVERAGEIFS(Datos_POA!$G$2:$G$295,Datos_POA!$M$2:$M$295,A4) -> 54.958455 | G4: =F4-E4 -> 7.6373636 | H4: =IFERROR(SUMIFS(Datos_POA!$O$2:$O$295,Datos_POA!$M$2:$M$295,A4)/COUNTIFS(Datos_POA!$M$2:$M$295,A4)*100,0) -> 67.272727 | I4: =SUMIFS(Datos_POA!$O$2:$O$295,Datos_POA!$M$2:$M$295,A4,Datos_POA!$K$2:$K$295,"No iniciado") -> 11 | J4: =SUMIFS(Datos_POA!$P$2:$P$295,Datos_POA!$M$2:$M$295,A4) -> 1 | K4: =IF(AND(G4<=3,H4<=45),"Ejecución constante",IF(OR(H4>Parametros!$B$6,G4>Parametros!$B$7),"Carga concentrada al cierre","Ritmo moderado")) -> Carga concentrada al cierre
A5: Fraude | B5: =COUNTIF(Datos_POA!$M$2:$M$295,A5) -> 23 | C5: =COUNTIFS(Datos_POA!$M$2:$M$295,A5,Datos_POA!$K$2:$K$295,"Finalizado") -> 12 | D5: =IFERROR(C5/B5*100,0) -> 52.173913 | E5: =AVERAGEIFS(Datos_POA!$F$2:$F$295,Datos_POA!$M$2:$M$295,A5) -> 73.913043 | F5: =AVERAGEIFS(Datos_POA!$G$2:$G$295,Datos_POA!$M$2:$M$295,A5) -> 72.589984 | G5: =F5-E5 -> -1.3230595 | H5: =IFERROR(SUMIFS(Datos_POA!$O$2:$O$295,Datos_POA!$M$2:$M$295,A5)/COUNTIFS(Datos_POA!$M$2:$M$295,A5)*100,0) -> 34.782609 | I5: =SUMIFS(Datos_POA!$O$2:$O$295,Datos_POA!$M$2:$M$295,A5,Datos_POA!$K$2:$K$295,"No iniciado") -> 3 | J5: =SUMIFS(Datos_POA!$P$2:$P$295,Datos_POA!$M$2:$M$295,A5) -> 0 | K5: =IF(AND(G5<=3,H5<=45),"Ejecución constante",IF(OR(H5>Parametros!$B$6,G5>Parametros!$B$7),"Carga concentrada al cierre","Ritmo moderado")) -> Ejecución constante
A6: Operaciones | B6: =COUNTIF(Datos_POA!$M$2:$M$295,A6) -> 61 | C6: =COUNTIFS(Datos_POA!$M$2:$M$295,A6,Datos_POA!$K$2:$K$295,"Finalizado") -> 28 | D6: =IFERROR(C6/B6*100,0) -> 45.901639 | E6: =AVERAGEIFS(Datos_POA!$F$2:$F$295,Datos_POA!$M$2:$M$295,A6) -> 67.868852 | F6: =AVERAGEIFS(Datos_POA!$G$2:$G$295,Datos_POA!$M$2:$M$295,A6) -> 69.256594 | G6: =F6-E6 -> 1.387742 | H6: =IFERROR(SUMIFS(Datos_POA!$O$2:$O$295,Datos_POA!$M$2:$M$295,A6)/COUNTIFS(Datos_POA!$M$2:$M$295,A6)*100,0) -> 47.540984 | I6: =SUMIFS(Datos_POA!$O$2:$O$295,Datos_POA!$M$2:$M$295,A6,Datos_POA!$K$2:$K$295,"No iniciado") -> 9 | J6: =SUMIFS(Datos_POA!$P$2:$P$295,Datos_POA!$M$2:$M$295,A6) -> 1 | K6: =IF(AND(G6<=3,H6<=45),"Ejecución constante",IF(OR(H6>Parametros!$B$6,G6>Parametros!$B$7),"Carga concentrada al cierre","Ritmo moderado")) -> Ritmo moderado
A7: Seguridad física | B7: =COUNTIF(Datos_POA!$M$2:$M$295,A7) -> 39 | C7: =COUNTIFS(Datos_POA!$M$2:$M$295,A7,Datos_POA!$K$2:$K$295,"Finalizado") -> 9 | D7: =IFERROR(C7/B7*100,0) -> 23.076923 | E7: =AVERAGEIFS(Datos_POA!$F$2:$F$295,Datos_POA!$M$2:$M$295,A7) -> 44.789744 | F7: =AVERAGEIFS(Datos_POA!$G$2:$G$295,Datos_POA!$M$2:$M$295,A7) -> 49.765676 | G7: =F7-E7 -> 4.9759329 | H7: =IFERROR(SUMIFS(Datos_POA!$O$2:$O$295,Datos_POA!$M$2:$M$295,A7)/COUNTIFS(Datos_POA!$M$2:$M$295,A7)*100,0) -> 43.589744 | I7: =SUMIFS(Datos_POA!$O$2:$O$295,Datos_POA!$M$2:$M$295,A7,Datos_POA!$K$2:$K$295,"No iniciado") -> 9 | J7: =SUMIFS(Datos_POA!$P$2:$P$295,Datos_POA!$M$2:$M$295,A7) -> 1 | K7: =IF(AND(G7<=3,H7<=45),"Ejecución constante",IF(OR(H7>Parametros!$B$6,G7>Parametros!$B$7),"Carga concentrada al cierre","Ritmo moderado")) -> Ritmo moderado
A8: Tribu Ciberseguridad | B8: =COUNTIF(Datos_POA!$M$2:$M$295,A8) -> 3 | C8: =COUNTIFS(Datos_POA!$M$2:$M$295,A8,Datos_POA!$K$2:$K$295,"Finalizado") -> 1 | D8: =IFERROR(C8/B8*100,0) -> 33.333333 | E8: =AVERAGEIFS(Datos_POA!$F$2:$F$295,Datos_POA!$M$2:$M$295,A8) -> 36.666667 | F8: =AVERAGEIFS(Datos_POA!$G$2:$G$295,Datos_POA!$M$2:$M$295,A8) -> 43.169399 | G8: =F8-E8 -> 6.5027322 | H8: =IFERROR(SUMIFS(Datos_POA!$O$2:$O$295,Datos_POA!$M$2:$M$295,A8)/COUNTIFS(Datos_POA!$M$2:$M$295,A8)*100,0) -> 66.666667 | I8: =SUMIFS(Datos_POA!$O$2:$O$295,Datos_POA!$M$2:$M$295,A8,Datos_POA!$K$2:$K$295,"No iniciado") -> 1 | J8: =SUMIFS(Datos_POA!$P$2:$P$295,Datos_POA!$M$2:$M$295,A8) -> 0 | K8: =IF(AND(G8<=3,H8<=45),"Ejecución constante",IF(OR(H8>Parametros!$B$6,G8>Parametros!$B$7),"Carga concentrada al cierre","Ritmo moderado")) -> Carga concentrada al cierre

Sheet DAX_Medidas
A1: MEDIDAS DAX — MODELO POA 2026 (copiar/pegar en Power BI Desktop)
A3: Medida | B3: Fórmula DAX | C3: Descripción
A4: Total Registros | B4: Total Registros = COUNTROWS(Datos_POA) | C4: Total de hitos/registros del POA
A5: Total Iniciativas | B5: Total Iniciativas = DISTINCTCOUNT(Datos_POA[Codigo]) | C5: Iniciativas o mejoras únicas (los registros son hitos de estas)
A6: Promedio Hitos x Iniciativa | B6: Promedio Hitos x Iniciativa = DIVIDE([Total Registros],[Total Iniciativas]) | C6: Cuántos hitos agrupa en promedio cada iniciativa
A7: Avance Promedio Real | B7: Avance Promedio Real = AVERAGE(Datos_POA[Avance_Real_Pct]) | C7: % de avance real promedio
A8: Avance Promedio Esperado | B8: Avance Promedio Esperado = AVERAGE(Datos_POA[Avance_Esperado_Pct]) | C8: % de avance que debería existir a la fecha de corte según cronograma
A9: Brecha vs Plan | B9: Brecha vs Plan = [Avance Promedio Esperado] - [Avance Promedio Real] | C9: Puntos porcentuales de atraso frente al plan
A10: Finalizadas | B10: Finalizadas = CALCULATE(COUNTROWS(Datos_POA), Datos_POA[Estado] = "Finalizado") | C10: Actividades cerradas
A11: En Curso | B11: En Curso = CALCULATE(COUNTROWS(Datos_POA), Datos_POA[Estado] IN {"En ejecución","Iniciado"}) | C11: Actividades en ejecución o iniciadas
A12: Sin Iniciar | B12: Sin Iniciar = CALCULATE(COUNTROWS(Datos_POA), Datos_POA[Estado] = "No iniciado") | C12: Actividades que no han arrancado
A13: Tasa de Cumplimiento | B13: Tasa de Cumplimiento = DIVIDE([Finalizadas], [Total Registros]) | C13: % finalizado sobre el total (formatear como %)
A14: Verde | B14: Verde = CALCULATE(COUNTROWS(Datos_POA), Datos_POA[Semaforo] = "Verde") | C14: Actividades en semáforo verde
... A28: Iniciativas con Multiples Hitos | B28: Iniciativas Multi-Hito = VAR T = SUMMARIZE(Datos_POA, Datos_POA[Codigo], "NHitos", COUNTROWS(Datos_POA)) RETURN COUNTROWS(FILTER(T,[NHitos]>1)) | C28: Cuántas iniciativas están desagregadas en más de un hito (48 en el corte actual)

Sheet Instrucciones_PowerBI
A1: CÓMO USAR ESTE ARCHIVO EN POWER BI DESKTOP
A3: 1. Importar datos | B3: Abrir Power BI Desktop → Obtener datos → Excel → seleccionar este archivo → cargar las hojas 'Datos_POA' y 'Parametros' (Resumen_Gerencias es opcional, ya que las medidas DAX lo recalculan).
A5: 2. Crear relaciones | B5: No se requieren relaciones adicionales: todo el análisis parte de una única tabla 'Datos_POA'. Si se agrega una tabla de fechas, relacionarla por 'Fecha_Fin'.
A7: 3. Crear medidas | B7: Abrir la hoja 'DAX_Medidas' de este archivo y copiar cada fórmula en Modelado → Nueva medida (o Nueva columna, según corresponda) dentro de la tabla Datos_POA.
A9: 4. Construir visuales | B9: Reproducir los bloques de la lámina PNG: tarjetas KPI (medidas), gráfico de dispersión (Gerencia_Responsable, Pct Cierres Q4, Brecha vs Plan, tamaño=Total Registros), tabla matricial (Gerencia_Responsable en filas), gráfico de barras (Sin Iniciar y Vencidas por gerencia), anillo (Semaforo).
A11: 5. Formato | B11: Aplicar la paleta corporativa: azul marino #0A185B, amarillo #FCEC7C, verde #3FA772, ámbar #F2A93B, rojo #D6553F, fondo #F4F6F9.
A13: 6. Incrustar el HTML | B13: Agregar el visual 'HTML Content' (AppSource, gratuito) o 'Web content' nativo de Power BI y pegar/enlazar el archivo Dashboard_POA2026_PowerBI.html incluido en esta entrega para mostrar el resumen ejecutivo dentro del mismo reporte.
A15: 7. Guardar como .pbix | B15: Guardar el reporte desde Power BI Desktop; se generará el archivo .pbix nativo. Este formato solo puede crearse dentro de Power BI Desktop, por lo que no se entrega prearmado — este Excel + las medidas DAX permiten reconstruirlo en menos de 15 minutos.
