Workbook

Sheet Leeme
B2: Modelo Power BI · Recepción de aplicaciones 2026
B3: Especificación para replicar en Power BI el dashboard PDF de 4 páginas. Hito liderado por Jhonny Barreiro. Fuentes: Matriz de Aplicaciones GI (agosto 2026) e informe de conciliación CMDB (DatosSN, 11-ago-2026).
B5: Hojas
B6: Parametros | C6: Fecha de corte, meta, alcance, cifra del informe y responsable del hito. Celdas amarillas con texto azul: se editan.
B7: fAplicaciones | C7: Tabla de hechos: una fila por registro de la matriz. Columnas A–N son copia de la matriz; O en adelante son columnas calculadas (fórmula Excel; su DAX está en «Columnas_DAX»).
B8: Dimensiones | C8: dEtapa (etapa de recepción, orden y color), dCriticidad (A–E, orden, color, si es crítica), dConciliacion (cascada CMDB → universo, datos del informe), dAlcance (criterios que ampliaron el alcance), dDuplicadosGI (posibles duplicados ID GI vs. CMDB, editable), dCalendario.
B9: Validacion | C9: KPIs del dashboard calculados con fórmulas y el valor publicado en el PDF. Todo debe decir «OK».
B10: Medidas_DAX | C10: Medidas base (conteos, avance, ritmo, conciliación, criticidad).
B11: Textos_DAX | C11: Medidas de texto dinámico: subtítulos, etiquetas y notas, con el resultado esperado al corte.
B12: HTML_Content | C12: Medidas que devuelven HTML/SVG para el visual HTML Content: encabezados, KPIs, gráficos SVG (barra del universo, curva acumulada, cascada, barras apiladas) y tablas.
B13: Visuales | C13: Qué medida va en cada visual de cada página, con tamaño sugerido.
B14: PowerQuery_M | C14: Script para cargar la matriz original en Power BI.
B15: Tema_PowerBI | C15: JSON con la paleta Banco Pichincha.
B16: Archivo .txt | C16: Recepcion_Aplicaciones_DAX.txt trae todas las medidas listas para copiar (copiar desde celdas de Excel con saltos de línea agrega comillas).
B18: Modelo
B19: Relaciones | C19: dEtapa[Etapa] 1 → * fAplicaciones[Etapa] dCriticidad[Letra] 1 → * fAplicaciones[CritLetra] dCalendario[Fecha] 1 → * fAplicaciones[Fecha Recepcion] Parametros, dConciliacion, dAlcance y dDuplicadosGI: tablas desconectadas.
B20: Orden de creación | C20: 1) Tablas y relaciones · 2) Columnas calculadas (Columnas_DAX, en orden) · 3) Medidas_DAX · 4) Textos_DAX · 5) HTML_Content.
B21: Parámetros en DAX | C21: La tabla Parametros tiene columnas Valor (números y fechas, tipo Decimal) y Texto. Las medidas convierten las fechas con DATE(YEAR(),MONTH(),DAY()).
B22: Configuración regional | C22: Idioma del modelo Español (Ecuador) para que FORMAT use coma decimal. Los nombres de mes vienen de dCalendario[MesCorto]/[MesLargo].
B24: Reglas de negocio
B25: Aplicación única | C25: Se cuenta una vez cada combinación Nombre + Bp Id (columna Cuenta). La matriz tiene 3 filas repetidas exactas.
B26: Gobernada | C26: «Entregada Identidades» = Si (equivale a Priorización «N/A ENTREGADA»).
B27: Etapa | C27: Gobernada, Criterio 1, Criterio 2, Criterio 3 o Planificada 2027, según la columna Priorización.
B28: Universo | C28: CMDB + ajustes de conciliación (tabla dConciliacion): 331 + 35 + 16 + 23 + 12 = 417.
B29: Ritmo | C29: Recepciones del año de corte / meses transcurridos (días / 30,4). Ritmo requerido = brecha a la meta / meses restantes hasta FinAnio.
B30: Crítica | C30: Criticidad A, B o C (Prioridad de la matriz).
B31: ID propio GI | C31: Bp Id que empieza con GI0 o GA0: aplicación registrada por Identidades porque no existe en la CMDB.
B32: Posible duplicado GI | C32: Aplicación pendiente cuyo nombre normalizado coincide con una gobernada con ID GI (tabla dDuplicadosGI, validar caso a caso).
B33: Gobernadas sin fecha | C33: Hay 2 gobernadas sin Fecha Recepcion: se cuentan en el acumulado desde el inicio.

Sheet fAplicaciones
A1: ID | B1: Nombre | C1: Bp Id | D1: Descripcion | E1: Prioridad | F1: Ubicacion | G1: Equipo Administrado Por | H1: Dueno Aplicacion | I1: Dueno Negocio | J1: Administrado Por | K1: Categoria Identidades | L1: Entregada Identidades | M1: Fecha Recepcion | N1: Priorización | O1: Cuenta | P1: Etapa | Q1: Gobernada | R1: Priorizada2026 | S1: CritLetra | T1: EsCritica | U1: IDPropioGI | V1: Equipo | W1: UbicacionN | X1: AnioRecepcion | Y1: MesRecepcion | Z1: PosibleDuplicadoGI | AA1: Pendiente
A2: 1 | B2: IBM WebSphere Portal | C2: CHL0017 | D2: IBM Websphere Portal, es el portal web empresarial que ofrece experiencias sociales altamente personalizadas a los usuarios. Brinda a los usuarios un único punto de acceso a las aplicaciones, servicios, información y conexiones sociales que necesiten. El usuario puede acceder de manera directa a aplicaciones como: BancsLink, Administrador de Remesas, Asesores, Balcones, Cardholder, CreditosCom, Riesgo Global, Reclamos y Requerimientos, BPM, Informes Legales. | E2: A - Apetito de Riesgo Disponibilidad | F2: On Premise | G2: TRIBU_CANALES | H2: MIGUEL ALEXANDER MEJIA BRONCANO | I2: JORGE HUMBERTO BRAVO YUNDA | J2: Luis Remigio Bayas Rea | K2: Aplicación del negocio | L2: Si | N2: N/A ENTREGADA | O2: =IF(COUNTIFS($B$2:B2,B2,$C$2:C2,C2)=1,1,0) -> 1 | P2: =IFERROR(INDEX(dEtapa!$A$2:$A$6,MATCH(N2,dEtapa!$B$2:$B$6,0)),"Sin etapa") -> Gobernada | Q2: =IF(L2="Si",1,0) -> 1 | R2: =IF(ISNUMBER(SEARCH("CRITERIO",N2)),1,0) -> 0 | S2: =IF(E2="","Sin dato",LEFT(E2,1)) -> A | T2: =IFERROR(INDEX(dCriticidad!$G$2:$G$7,MATCH(S2,dCriticidad!$A$2:$A$7,0)),0) -> 1 | U2: =IF(OR(LEFT(C2,3)="GI0",LEFT(C2,3)="GA0"),1,0) -> 0 | V2: =IF(G2="","Sin dato (ID GI)",TRIM(G2)) -> TRIBU_CANALES | W2: =IF(F2="","Sin dato",F2) -> On Premise | X2: =IF(M2="","",YEAR(M2)) | Y2: =IF(M2="","",DATE(YEAR(M2),MONTH(M2),1)) | Z2: =IF(AND(Q2=0,COUNTIF(dDuplicadosGI!$A$2:$A$60,C2)>0),1,0) -> 0 | AA2: =IF(Q2=0,1,0) -> 0
A3: 2 | B3: ICEPanel | C3: ITM0068 | D3: Modelado de Arquitectura de Soluciones | E3: D - BIA No Crítica | F3: Nube | G3: COE ARQUITECTURA | H3: MAURICIO BLADIMIR AUQUI MIRANDA | I3: LUIS MIGUEL ULLOA MOREIRA | J3: LUIS MIGUEL ULLOA MOREIRA | K3: Aplicación complementaria | L3: No | N3: PRIORIZACIÓN CRITERIO 1 | O3: =IF(COUNTIFS($B$2:B3,B3,$C$2:C3,C3)=1,1,0) -> 1 | P3: =IFERROR(INDEX(dEtapa!$A$2:$A$6,MATCH(N3,dEtapa!$B$2:$B$6,0)),"Sin etapa") -> Criterio 1 | Q3: =IF(L3="Si",1,0) -> 0 | R3: =IF(ISNUMBER(SEARCH("CRITERIO",N3)),1,0) -> 1 | S3: =IF(E3="","Sin dato",LEFT(E3,1)) -> D | T3: =IFERROR(INDEX(dCriticidad!$G$2:$G$7,MATCH(S3,dCriticidad!$A$2:$A$7,0)),0) -> 0 | U3: =IF(OR(LEFT(C3,3)="GI0",LEFT(C3,3)="GA0"),1,0) -> 0 | V3: =IF(G3="","Sin dato (ID GI)",TRIM(G3)) -> COE ARQUITECTURA | W3: =IF(F3="","Sin dato",F3) -> Nube | X3: =IF(M3="","",YEAR(M3)) | Y3: =IF(M3="","",DATE(YEAR(M3),MONTH(M3),1)) | Z3: =IF(AND(Q3=0,COUNTIF(dDuplicadosGI!$A$2:$A$60,C3)>0),1,0) -> 0 | AA3: =IF(Q3=0,1,0) -> 1
A4: 3 | B4: Idera | C4: ITM0035 | D4: Es una aplicación para administrar motores SQL, donde se visualiza eventos que ocurran en las bases de datos como en el servidor | E4: D - BIA No Crítica | F4: On Premise | G4: INFRAESTRUCTURA | H4: BYRON ORLANDO MELENDREZ CABRERA | I4: NELSON ANDRES POZO YEPEZ | J4: FELIX ALEXANDER MANJARRES QUEZADA | K4: Consolas de Administración TI | L4: No | N4: PLANIFICADA 2027 | O4: =IF(COUNTIFS($B$2:B4,B4,$C$2:C4,C4)=1,1,0) -> 1 | P4: =IFERROR(INDEX(dEtapa!$A$2:$A$6,MATCH(N4,dEtapa!$B$2:$B$6,0)),"Sin etapa") -> Planificada 2027 | Q4: =IF(L4="Si",1,0) -> 0 | R4: =IF(ISNUMBER(SEARCH("CRITERIO",N4)),1,0) -> 0 | S4: =IF(E4="","Sin dato",LEFT(E4,1)) -> D | T4: =IFERROR(INDEX(dCriticidad!$G$2:$G$7,MATCH(S4,dCriticidad!$A$2:$A$7,0)),0) -> 0 | U4: =IF(OR(LEFT(C4,3)="GI0",LEFT(C4,3)="GA0"),1,0) -> 0 | V4: =IF(G4="","Sin dato (ID GI)",TRIM(G4)) -> INFRAESTRUCTURA | W4: =IF(F4="","Sin dato",F4) -> On Premise | X4: =IF(M4="","",YEAR(M4)) | Y4: =IF(M4="","",DATE(YEAR(M4),MONTH(M4),1)) | Z4: =IF(AND(Q4=0,COUNTIF(dDuplicadosGI!$A$2:$A$60,C4)>0),1,0) -> 0 | AA4: =IF(Q4=0,1,0) -> 1
A5: 4 | B5: IGNITION | C5: ITM0069 | D5: Monitoreo de las facilidades de los centros de datos, Sistemas Electricos, Enfriamiento, Electrogenos | E5: C - BIA Crítica | F5: On Premise | G5: INFRAESTRUCTURA | H5: BYRON ORLANDO MELENDREZ CABRERA | I5: DIEGO JAVIER SALAZAR MOLINA | J5: DIEGO PAUL BETANCOURT REYES | K5: Aplicación complementaria | L5: No | N5: PLANIFICADA 2027 | O5: =IF(COUNTIFS($B$2:B5,B5,$C$2:C5,C5)=1,1,0) -> 1 | P5: =IFERROR(INDEX(dEtapa!$A$2:$A$6,MATCH(N5,dEtapa!$B$2:$B$6,0)),"Sin etapa") -> Planificada 2027 | Q5: =IF(L5="Si",1,0) -> 0 | R5: =IF(ISNUMBER(SEARCH("CRITERIO",N5)),1,0) -> 0 | S5: =IF(E5="","Sin dato",LEFT(E5,1)) -> C | T5: =IFERROR(INDEX(dCriticidad!$G$2:$G$7,MATCH(S5,dCriticidad!$A$2:$A$7,0)),0) -> 1 | U5: =IF(OR(LEFT(C5,3)="GI0",LEFT(C5,3)="GA0"),1,0) -> 0 | V5: =IF(G5="","Sin dato (ID GI)",TRIM(G5)) -> INFRAESTRUCTURA | W5: =IF(F5="","Sin dato",F5) -> On Premise | X5: =IF(M5="","",YEAR(M5)) | Y5: =IF(M5="","",DATE(YEAR(M5),MONTH(M5),1)) | Z5: =IF(AND(Q5=0,COUNTIF(dDuplicadosGI!$A$2:$A$60,C5)>0),1,0) -> 0 | AA5: =IF(Q5=0,1,0) -> 1
A6: 5 | B6: ILMT | C6: ITM0036 | D6: Monitoreo de Software IBM instalado en servidores licenciamiento | E6: E - No Crítica | F6: On Premise | G6: INFRAESTRUCTURA | H6: BYRON ORLANDO MELENDREZ CABRERA | I6: HORACIO LEONEL HOLGUIN ALCIVAR | J6: FREDDY VINICIO ESTRELLA HIDALGO | K6: Consolas de Administración TI | L6: No | N6: PLANIFICADA 2027 | O6: =IF(COUNTIFS($B$2:B6,B6,$C$2:C6,C6)=1,1,0) -> 1 | P6: =IFERROR(INDEX(dEtapa!$A$2:$A$6,MATCH(N6,dEtapa!$B$2:$B$6,0)),"Sin etapa") -> Planificada 2027 | Q6: =IF(L6="Si",1,0) -> 0 | R6: =IF(ISNUMBER(SEARCH("CRITERIO",N6)),1,0) -> 0 | S6: =IF(E6="","Sin dato",LEFT(E6,1)) -> E | T6: =IFERROR(INDEX(dCriticidad!$G$2:$G$7,MATCH(S6,dCriticidad!$A$2:$A$7,0)),0) -> 0 | U6: =IF(OR(LEFT(C6,3)="GI0",LEFT(C6,3)="GA0"),1,0) -> 0 | V6: =IF(G6="","Sin dato (ID GI)",TRIM(G6)) -> INFRAESTRUCTURA | W6: =IF(F6="","Sin dato",F6) -> On Premise | X6: =IF(M6="","",YEAR(M6)) | Y6: =IF(M6="","",DATE(YEAR(M6),MONTH(M6),1)) | Z6: =IF(AND(Q6=0,COUNTIF(dDuplicadosGI!$A$2:$A$60,C6)>0),1,0) -> 0 | AA6: =IF(Q6=0,1,0) -> 1
A7: 6 | B7: Impacto 360 | C7: DAT0015 | D7: la iniciativa es una plataforma de inteligencia empresarial y análisis de mercado con un enfoque específico en los clientes que utilizan medios de pago del Banco Pichincha (tarjetas de crédito, tarjetas de débito y transferencias digitales). Esta plataforma brinda a los empresarios la capacidad de acceder y visualizar información histórica y resumida de estos clientes, permitiéndoles obtener una visión más detallada y específica de su base de clientes y sus comportamientos de pago. | E7: E - No Crítica | F7: Nube | G7: Negocios y Monetización | H7: ANTONIO ALEJANDRO CANAVERAL GIL | I7: SEBASTIAN MUNOZ ANDERSEN | J7: HEVER GONZALEZ GARCIA | K7: Aplicación del negocio | L7: No | N7: PLANIFICADA 2027 | O7: =IF(COUNTIFS($B$2:B7,B7,$C$2:C7,C7)=1,1,0) -> 1 | P7: =IFERROR(INDEX(dEtapa!$A$2:$A$6,MATCH(N7,dEtapa!$B$2:$B$6,0)),"Sin etapa") -> Planificada 2027 | Q7: =IF(L7="Si",1,0) -> 0 | R7: =IF(ISNUMBER(SEARCH("CRITERIO",N7)),1,0) -> 0 | S7: =IF(E7="","Sin dato",LEFT(E7,1)) -> E | T7: =IFERROR(INDEX(dCriticidad!$G$2:$G$7,MATCH(S7,dCriticidad!$A$2:$A$7,0)),0) -> 0 | U7: =IF(OR(LEFT(C7,3)="GI0",LEFT(C7,3)="GA0"),1,0) -> 0 | V7: =IF(G7="","Sin dato (ID GI)",TRIM(G7)) -> Negocios y Monetización | W7: =IF(F7="","Sin dato",F7) -> Nube | X7: =IF(M7="","",YEAR(M7)) | Y7: =IF(M7="","",DATE(YEAR(M7),MONTH(M7),1)) | Z7: =IF(AND(Q7=0,COUNTIF(dDuplicadosGI!$A$2:$A$60,C7)>0),1,0) -> 0 | AA7: =IF(Q7=0,1,0) -> 1
A8: 7 | B8: Impresion Documentos | C8: TIE0018 | D8: Aplicación que permite levantar documentos de word ejecutando macros. Genera documentos entregados a los clientes, principalmente de solicitudes de crédito. | E8: E - No Crítica | F8: On Premise | G8: ACTIVOS | H8: LAURA ELIZABETH CARRASCO UQUILLAS | I8: ANDREA FERNANDA ORTIZ CISNEROS | J8: ERISLAN MARTINEZ JERA | K8: Aplicación del negocio | L8: Si | M8: 45199 | N8: N/A ENTREGADA | O8: =IF(COUNTIFS($B$2:B8,B8,$C$2:C8,C8)=1,1,0) -> 1 | P8: =IFERROR(INDEX(dEtapa!$A$2:$A$6,MATCH(N8,dEtapa!$B$2:$B$6,0)),"Sin etapa") -> Gobernada | Q8: =IF(L8="Si",1,0) -> 1 | R8: =IF(ISNUMBER(SEARCH("CRITERIO",N8)),1,0) -> 0 | S8: =IF(E8="","Sin dato",LEFT(E8,1)) -> E | T8: =IFERROR(INDEX(dCriticidad!$G$2:$G$7,MATCH(S8,dCriticidad!$A$2:$A$7,0)),0) -> 0 | U8: =IF(OR(LEFT(C8,3)="GI0",LEFT(C8,3)="GA0"),1,0) -> 0 | V8: =IF(G8="","Sin dato (ID GI)",TRIM(G8)) -> ACTIVOS | W8: =IF(F8="","Sin dato",F8) -> On Premise | X8: =IF(M8="","",YEAR(M8)) -> 2023 | Y8: =IF(M8="","",DATE(YEAR(M8),MONTH(M8),1)) -> 45170 | Z8: =IF(AND(Q8=0,COUNTIF(dDuplicadosGI!$A$2:$A$60,C8)>0),1,0) -> 0 | AA8: =IF(Q8=0,1,0) -> 0
A9: 8 | B9: informesCredito | C9: PRD0021 | D9: Aplicación utilizada por las empresas que contratan el servicio para ver referencias bancarias de los clientes del Banco del Pichincha, pueden ver la cantidad de cifras, altas o bajas de sus cuentas, clientes como Dinners, Artefacta, Movistar lo utilizan. Cada consulta de los clientes tiene un costo. | E9: E - No Crítica | F9: Nube | G9: Frente de Soluciones Empresariales | H9: LUIS MIGUEL ULLOA MOREIRA | I9: FABRICIO ANTONIO PEREIRA GARCIA | J9: WILLIAM PATRICIO PANCHI SHUGULI | K9: Aplicación del negocio | L9: Si | M9: 45199 | N9: N/A ENTREGADA | O9: =IF(COUNTIFS($B$2:B9,B9,$C$2:C9,C9)=1,1,0) -> 1 | P9: =IFERROR(INDEX(dEtapa!$A$2:$A$6,MATCH(N9,dEtapa!$B$2:$B$6,0)),"Sin etapa") -> Gobernada | Q9: =IF(L9="Si",1,0) -> 1 | R9: =IF(ISNUMBER(SEARCH("CRITERIO",N9)),1,0) -> 0 | S9: =IF(E9="","Sin dato",LEFT(E9,1)) -> E | T9: =IFERROR(INDEX(dCriticidad!$G$2:$G$7,MATCH(S9,dCriticidad!$A$2:$A$7,0)),0) -> 0 | U9: =IF(OR(LEFT(C9,3)="GI0",LEFT(C9,3)="GA0"),1,0) -> 0 | V9: =IF(G9="","Sin dato (ID GI)",TRIM(G9)) -> Frente de Soluciones Empresariales | W9: =IF(F9="","Sin dato",F9) -> Nube | X9: =IF(M9="","",YEAR(M9)) -> 2023 | Y9: =IF(M9="","",DATE(YEAR(M9),MONTH(M9),1)) -> 45170 | Z9: =IF(AND(Q9=0,COUNTIF(dDuplicadosGI!$A$2:$A$60,C9)>0),1,0) -> 0 | AA9: =IF(Q9=0,1,0) -> 0
A10: 9 | B10: Integration Bus Soporte | C10: INT0009 | D10: Integration Bus permite administrar y monitorear los flujos de integración que conectan múltiples canales digitales y sistemas backend. Facilita la gestión de servicios, procesamiento de mensajes y orquestación de transacciones entre aplicaciones. Es un componente clave para asegurar la operación continua y la integración eficiente en arquitecturas omnicanal. | E10: B - Ecosistema Apetito de Riesgo | F10: On Premise | G10: Tribu_Integraciones_Apis | H10: DAVID RODRIGO REVELO RIVERA | I10: DIEGO VLADIMIR JAYA GUAMANZARA | J10: DIEGO VLADIMIR JAYA GUAMANZARA | K10: Consolas de Administración TI | L10: Si | M10: 46197 | N10: N/A ENTREGADA | O10: =IF(COUNTIFS($B$2:B10,B10,$C$2:C10,C10)=1,1,0) -> 1 | P10: =IFERROR(INDEX(dEtapa!$A$2:$A$6,MATCH(N10,dEtapa!$B$2:$B$6,0)),"Sin etapa") -> Gobernada | Q10: =IF(L10="Si",1,0) -> 1 | R10: =IF(ISNUMBER(SEARCH("CRITERIO",N10)),1,0) -> 0 | S10: =IF(E10="","Sin dato",LEFT(E10,1)) -> B | T10: =IFERROR(INDEX(dCriticidad!$G$2:$G$7,MATCH(S10,dCriticidad!$A$2:$A$7,0)),0) -> 1 | U10: =IF(OR(LEFT(C10,3)="GI0",LEFT(C10,3)="GA0"),1,0) -> 0 | V10: =IF(G10="","Sin dato (ID GI)",TRIM(G10)) -> Tribu_Integraciones_Apis | W10: =IF(F10="","Sin dato",F10) -> On Premise | X10: =IF(M10="","",YEAR(M10)) -> 2026 | Y10: =IF(M10="","",DATE(YEAR(M10),MONTH(M10),1)) -> 46174 | Z10: =IF(AND(Q10=0,COUNTIF(dDuplicadosGI!$A$2:$A$60,C10)>0),1,0) -> 0 | AA10: =IF(Q10=0,1,0) -> 0
A11: 10 | B11: Interdin AS 400/ CAO | C11: PAY0010 | D11: No existe descripción | E11: C - BIA Crítica | F11: Terceros | G11: MEDIOS_DE_PAGO | H11: EDWIN GEOVANNY FLORES CASTRO | I11: KATHERINE FATIMA CJURO VERA | J11: JEAN ANEL PROANO FALCONES | K11: Aplicación del negocio | L11: Si | M11: 45199 | N11: N/A ENTREGADA | O11: =IF(COUNTIFS($B$2:B11,B11,$C$2:C11,C11)=1,1,0) -> 1 | P11: =IFERROR(INDEX(dEtapa!$A$2:$A$6,MATCH(N11,dEtapa!$B$2:$B$6,0)),"Sin etapa") -> Gobernada | Q11: =IF(L11="Si",1,0) -> 1 | R11: =IF(ISNUMBER(SEARCH("CRITERIO",N11)),1,0) -> 0 | S11: =IF(E11="","Sin dato",LEFT(E11,1)) -> C | T11: =IFERROR(INDEX(dCriticidad!$G$2:$G$7,MATCH(S11,dCriticidad!$A$2:$A$7,0)),0) -> 1 | U11: =IF(OR(LEFT(C11,3)="GI0",LEFT(C11,3)="GA0"),1,0) -> 0 | V11: =IF(G11="","Sin dato (ID GI)",TRIM(G11)) -> MEDIOS_DE_PAGO | W11: =IF(F11="","Sin dato",F11) -> Terceros | X11: =IF(M11="","",YEAR(M11)) -> 2023 | Y11: =IF(M11="","",DATE(YEAR(M11),MONTH(M11),1)) -> 45170 | Z11: =IF(AND(Q11=0,COUNTIF(dDuplicadosGI!$A$2:$A$60,C11)>0),1,0) -> 0 | AA11: =IF(Q11=0,1,0) -> 0
A12: 11 | B12: Inversiones | C12: PRD0060 | D12: Aplicacion para venta y postventa de Inversiones. | E12: E - No Crítica | F12: Nube | G12: PASIVOS Y SEGUROS | H12: LAURA ELIZABETH CARRASCO UQUILLAS | I12: JONATHAN HERNAN ARIAS HERNANDEZ | J12: MANUEL ABELARDO HARO MONTERO | K12: Aplicación del negocio | L12: No | N12: PLANIFICADA 2027 | O12: =IF(COUNTIFS($B$2:B12,B12,$C$2:C12,C12)=1,1,0) -> 1 | P12: =IFERROR(INDEX(dEtapa!$A$2:$A$6,MATCH(N12,dEtapa!$B$2:$B$6,0)),"Sin etapa") -> Planificada 2027 | Q12: =IF(L12="Si",1,0) -> 0 | R12: =IF(ISNUMBER(SEARCH("CRITERIO",N12)),1,0) -> 0 | S12: =IF(E12="","Sin dato",LEFT(E12,1)) -> E | T12: =IFERROR(INDEX(dCriticidad!$G$2:$G$7,MATCH(S12,dCriticidad!$A$2:$A$7,0)),0) -> 0 | U12: =IF(OR(LEFT(C12,3)="GI0",LEFT(C12,3)="GA0"),1,0) -> 0 | V12: =IF(G12="","Sin dato (ID GI)",TRIM(G12)) -> PASIVOS Y SEGUROS | W12: =IF(F12="","Sin dato",F12) -> Nube | X12: =IF(M12="","",YEAR(M12)) | Y12: =IF(M12="","",DATE(YEAR(M12),MONTH(M12),1)) | Z12: =IF(AND(Q12=0,COUNTIF(dDuplicadosGI!$A$2:$A$60,C12)>0),1,0) -> 0 | AA12: =IF(Q12=0,1,0) -> 1
A13: 12 | B13: IPS Intrusion Prevention System | C13: SEC0025 | D13: Cisco Firepower Management Center 4600 | E13: C - BIA Crítica | F13: On Premise | G13: Ciberseguridad | H13: ERICK DAMIAN RISUENO BENITEZ | I13: MARCO FABRICIO FALCONI NORIEGA | J13: JORGE XAVIER LUCERO GALLEGOS | K13: Consolas de Administración Seguridad | L13: Si | M13: 45929 | N13: N/A ENTREGADA | O13: =IF(COUNTIFS($B$2:B13,B13,$C$2:C13,C13)=1,1,0) -> 1 | P13: =IFERROR(INDEX(dEtapa!$A$2:$A$6,MATCH(N13,dEtapa!$B$2:$B$6,0)),"Sin etapa") -> Gobernada | Q13: =IF(L13="Si",1,0) -> 1 | R13: =IF(ISNUMBER(SEARCH("CRITERIO",N13)),1,0) -> 0 | S13: =IF(E13="","Sin dato",LEFT(E13,1)) -> C | T13: =IFERROR(INDEX(dCriticidad!$G$2:$G$7,MATCH(S13,dCriticidad!$A$2:$A$7,0)),0) -> 1 | U13: =IF(OR(LEFT(C13,3)="GI0",LEFT(C13,3)="GA0"),1,0) -> 0 | V13: =IF(G13="","Sin dato (ID GI)",TRIM(G13)) -> Ciberseguridad | W13: =IF(F13="","Sin dato",F13) -> On Premise | X13: =IF(M13="","",YEAR(M13)) -> 2025 | Y13: =IF(M13="","",DATE(YEAR(M13),MONTH(M13),1)) -> 45901 | Z13: =IF(AND(Q13=0,COUNTIF(dDuplicadosGI!$A$2:$A$60,C13)>0),1,0) -> 0 | AA13: =IF(Q13=0,1,0) -> 0
A14: 13 | B14: ISE | C14: SEC0026 | D14: CONTROL DE ACCESO A LA RED | E14: C - BIA Crítica | F14: On Premise | G14: Ciberseguridad | H14: JORGE XAVIER LUCERO GALLEGOS | I14: MARCO FABRICIO FALCONI NORIEGA | J14: ROBERT STALIN SOTO CORONEL | K14: Consolas de Administración Seguridad | L14: Si | M14: 45772 | N14: N/A ENTREGADA | O14: =IF(COUNTIFS($B$2:B14,B14,$C$2:C14,C14)=1,1,0) -> 1 | P14: =IFERROR(INDEX(dEtapa!$A$2:$A$6,MATCH(N14,dEtapa!$B$2:$B$6,0)),"Sin etapa") -> Gobernada | Q14: =IF(L14="Si",1,0) -> 1 | R14: =IF(ISNUMBER(SEARCH("CRITERIO",N14)),1,0) -> 0 | S14: =IF(E14="","Sin dato",LEFT(E14,1)) -> C | T14: =IFERROR(INDEX(dCriticidad!$G$2:$G$7,MATCH(S14,dCriticidad!$A$2:$A$7,0)),0) -> 1 | U14: =IF(OR(LEFT(C14,3)="GI0",LEFT(C14,3)="GA0"),1,0) -> 0 | V14: =IF(G14="","Sin dato (ID GI)",TRIM(G14)) -> Ciberseguridad | W14: =IF(F14="","Sin dato",F14) -> On Premise | X14: =IF(M14="","",YEAR(M14)) -> 2025 | Y14: =IF(M14="","",DATE(YEAR(M14),MONTH(M14),1)) -> 45748 | Z14: =IF(AND(Q14=0,COUNTIF(dDuplicadosGI!$A$2:$A$60,C14)>0),1,0) -> 0 | AA14: =IF(Q14=0,1,0) -> 0
A15: 14 | B15: Kafka | C15: OMN0004 | D15: Basado en una transmisión de evetos,captura datos en tiempo real desde varias fuentes, enruta los flujos de datos a diferentes tecnologías de destino según sea necesario. | E15: B - Ecosistema Apetito de Riesgo | F15: On Premise | G15: Tribu_Integraciones_Apis | H15: DAVID RODRIGO REVELO RIVERA | I15: DIEGO VLADIMIR JAYA GUAMANZARA | J15: DIEGO VLADIMIR JAYA GUAMANZARA | K15: Consolas de Administración TI | L15: No | N15: PRIORIZACIÓN CRITERIO 2 | O15: =IF(COUNTIFS($B$2:B15,B15,$C$2:C15,C15)=1,1,0) -> 1 | P15: =IFERROR(INDEX(dEtapa!$A$2:$A$6,MATCH(N15,dEtapa!$B$2:$B$6,0)),"Sin etapa") -> Criterio 2 | Q15: =IF(L15="Si",1,0) -> 0 | R15: =IF(ISNUMBER(SEARCH("CRITERIO",N15)),1,0) -> 1 | S15: =IF(E15="","Sin dato",LEFT(E15,1)) -> B | T15: =IFERROR(INDEX(dCriticidad!$G$2:$G$7,MATCH(S15,dCriticidad!$A$2:$A$7,0)),0) -> 1 | U15: =IF(OR(LEFT(C15,3)="GI0",LEFT(C15,3)="GA0"),1,0) -> 0 | V15: =IF(G15="","Sin dato (ID GI)",TRIM(G15)) -> Tribu_Integraciones_Apis | W15: =IF(F15="","Sin dato",F15) -> On Premise | X15: =IF(M15="","",YEAR(M15)) | Y15: =IF(M15="","",DATE(YEAR(M15),MONTH(M15),1)) | Z15: =IF(AND(Q15=0,COUNTIF(dDuplicadosGI!$A$2:$A$60,C15)>0),1,0) -> 0 | AA15: =IF(Q15=0,1,0) -> 1
A16: 15 | B16: Keeper Security | C16: SEC0053 | D16: Solución para la gestión de contraseñas de los usuarios | E16: E - No Crítica | F16: Nube | G16: Ciberseguridad | H16: lvtandaz@pichincha.com TANDAZO GALLEGOS | I16: MARCO FABRICIO FALCONI NORIEGA | J16: ISRAEL SEBASTIAN DE LA TORRE TRUJILLO | K16: Consolas de Administración Seguridad | L16: No | N16: PRIORIZACIÓN CRITERIO 1 | O16: =IF(COUNTIFS($B$2:B16,B16,$C$2:C16,C16)=1,1,0) -> 1 | P16: =IFERROR(INDEX(dEtapa!$A$2:$A$6,MATCH(N16,dEtapa!$B$2:$B$6,0)),"Sin etapa") -> Criterio 1 | Q16: =IF(L16="Si",1,0) -> 0 | R16: =IF(ISNUMBER(SEARCH("CRITERIO",N16)),1,0) -> 1 | S16: =IF(E16="","Sin dato",LEFT(E16,1)) -> E | T16: =IFERROR(INDEX(dCriticidad!$G$2:$G$7,MATCH(S16,dCriticidad!$A$2:$A$7,0)),0) -> 0 | U16: =IF(OR(LEFT(C16,3)="GI0",LEFT(C16,3)="GA0"),1,0) -> 0 | V16: =IF(G16="","Sin dato (ID GI)",TRIM(G16)) -> Ciberseguridad | W16: =IF(F16="","Sin dato",F16) -> Nube | X16: =IF(M16="","",YEAR(M16)) | Y16: =IF(M16="","",DATE(YEAR(M16),MONTH(M16),1)) | Z16: =IF(AND(Q16=0,COUNTIF(dDuplicadosGI!$A$2:$A$60,C16)>0),1,0) -> 0 | AA16: =IF(Q16=0,1,0) -> 1
A17: 16 | B17: Kriptos | C17: SEC0055 | D17: Solución basada en clasificación artificial que tiene la capacidad de identificar y clasificar los datos de la empresa. | E17: E - No Crítica | F17: Nube | G17: Ciberseguridad | H17: FERNANDO JAVIER PALADINES BUSTAMANTE | I17: MARCO FABRICIO FALCONI NORIEGA | J17: MARIA DEL CARMEN PENAHERRERA PLUA | K17: Consolas de Administración Seguridad | L17: No | N17: PRIORIZACIÓN CRITERIO 3 | O17: =IF(COUNTIFS($B$2:B17,B17,$C$2:C17,C17)=1,1,0) -> 1 | P17: =IFERROR(INDEX(dEtapa!$A$2:$A$6,MATCH(N17,dEtapa!$B$2:$B$6,0)),"Sin etapa") -> Criterio 3 | Q17: =IF(L17="Si",1,0) -> 0 | R17: =IF(ISNUMBER(SEARCH("CRITERIO",N17)),1,0) -> 1 | S17: =IF(E17="","Sin dato",LEFT(E17,1)) -> E | T17: =IFERROR(INDEX(dCriticidad!$G$2:$G$7,MATCH(S17,dCriticidad!$A$2:$A$7,0)),0) -> 0 | U17: =IF(OR(LEFT(C17,3)="GI0",LEFT(C17,3)="GA0"),1,0) -> 0 | V17: =IF(G17="","Sin dato (ID GI)",TRIM(G17)) -> Ciberseguridad | W17: =IF(F17="","Sin dato",F17) -> Nube | X17: =IF(M17="","",YEAR(M17)) | Y17: =IF(M17="","",DATE(YEAR(M17),MONTH(M17),1)) | Z17: =IF(AND(Q17=0,COUNTIF(dDuplicadosGI!$A$2:$A$60,C17)>0),1,0) -> 0 | AA17: =IF(Q17=0,1,0) -> 1
A18: 17 | B18: Fielweb | C18: SUP0011 | D18: No existe descripción | E18: E - No Crítica | F18: Terceros | G18: AREAS_DE_APOYO | H18: FABIAN GEOVANNI PAZMINO UBIDIA | I18: JOSE LUIS ZAPATA ROSERO | J18: FERNANDO JOSE ROLDAN CORREA | K18: Aplicación complementaria | L18: No | N18: PLANIFICADA 2027 | O18: =IF(COUNTIFS($B$2:B18,B18,$C$2:C18,C18)=1,1,0) -> 1 | P18: =IFERROR(INDEX(dEtapa!$A$2:$A$6,MATCH(N18,dEtapa!$B$2:$B$6,0)),"Sin etapa") -> Planificada 2027 | Q18: =IF(L18="Si",1,0) -> 0 | R18: =IF(ISNUMBER(SEARCH("CRITERIO",N18)),1,0) -> 0 | S18: =IF(E18="","Sin dato",LEFT(E18,1)) -> E | T18: =IFERROR(INDEX(dCriticidad!$G$2:$G$7,MATCH(S18,dCriticidad!$A$2:$A$7,0)),0) -> 0 | U18: =IF(OR(LEFT(C18,3)="GI0",LEFT(C18,3)="GA0"),1,0) -> 0 | V18: =IF(G18="","Sin dato (ID GI)",TRIM(G18)) -> AREAS_DE_APOYO | W18: =IF(F18="","Sin dato",F18) -> Terceros | X18: =IF(M18="","",YEAR(M18)) | Y18: =IF(M18="","",DATE(YEAR(M18),MONTH(M18),1)) | Z18: =IF(AND(Q18=0,COUNTIF(dDuplicadosGI!$A$2:$A$60,C18)>0),1,0) -> 0 | AA18: =IF(Q18=0,1,0) -> 1
A19: 18 | B19: LEXMARK CLOUD PRINT MANAGEMENT (CPM) | C19: ITM0038 | D19: Administración Multifunción Lexmark para Integración multifuncionales con Talla Impresión | E19: E - No Crítica | F19: Nube | G19: Gerencia Arquitectura Usuario Final | H19: AMPARO MARIANA CARDENAS HUILCA | I19: ABNER ANDY AREVALO BRACAMONTE | J19: ABNER ANDY AREVALO BRACAMONTE | K19: Aplicación complementaria | L19: No | N19: PLANIFICADA 2027 | O19: =IF(COUNTIFS($B$2:B19,B19,$C$2:C19,C19)=1,1,0) -> 1 | P19: =IFERROR(INDEX(dEtapa!$A$2:$A$6,MATCH(N19,dEtapa!$B$2:$B$6,0)),"Sin etapa") -> Planificada 2027 | Q19: =IF(L19="Si",1,0) -> 0 | R19: =IF(ISNUMBER(SEARCH("CRITERIO",N19)),1,0) -> 0 | S19: =IF(E19="","Sin dato",LEFT(E19,1)) -> E | T19: =IFERROR(INDEX(dCriticidad!$G$2:$G$7,MATCH(S19,dCriticidad!$A$2:$A$7,0)),0) -> 0 | U19: =IF(OR(LEFT(C19,3)="GI0",LEFT(C19,3)="GA0"),1,0) -> 0 | V19: =IF(G19="","Sin dato (ID GI)",TRIM(G19)) -> Gerencia Arquitectura Usuario Final | W19: =IF(F19="","Sin dato",F19) -> Nube | X19: =IF(M19="","",YEAR(M19)) | Y19: =IF(M19="","",DATE(YEAR(M19),MONTH(M19),1)) | Z19: =IF(AND(Q19=0,COUNTIF(dDuplicadosGI!$A$2:$A$60,C19)>0),1,0) -> 0 | AA19: =IF(Q19=0,1,0) -> 1
A20: 19 | B20: ListaObservados | C20: GOB0013 | D20: Es una aplicación que permite la validación de clientes en listas de validación utilizando componentes de terceros (Bridger). | E20: B - Ecosistema Apetito de Riesgo | F20: Nube | G20: AREAS_DE_APOYO | H20: FABIAN GEOVANNI PAZMINO UBIDIA | I20: JOSE LUIS ZAPATA ROSERO | J20: FERNANDO JOSE ROLDAN CORREA | K20: Aplicación del negocio | L20: No | N20: PRIORIZACIÓN CRITERIO 2 | O20: =IF(COUNTIFS($B$2:B20,B20,$C$2:C20,C20)=1,1,0) -> 1 | P20: =IFERROR(INDEX(dEtapa!$A$2:$A$6,MATCH(N20,dEtapa!$B$2:$B$6,0)),"Sin etapa") -> Criterio 2 | Q20: =IF(L20="Si",1,0) -> 0 | R20: =IF(ISNUMBER(SEARCH("CRITERIO",N20)),1,0) -> 1 | S20: =IF(E20="","Sin dato",LEFT(E20,1)) -> B | T20: =IFERROR(INDEX(dCriticidad!$G$2:$G$7,MATCH(S20,dCriticidad!$A$2:$A$7,0)),0) -> 1 | U20: =IF(OR(LEFT(C20,3)="GI0",LEFT(C20,3)="GA0"),1,0) -> 0 | V20: =IF(G20="","Sin dato (ID GI)",TRIM(G20)) -> AREAS_DE_APOYO | W20: =IF(F20="","Sin dato",F20) -> Nube | X20: =IF(M20="","",YEAR(M20)) | Y20: =IF(M20="","",DATE(YEAR(M20),MONTH(M20),1)) | Z20: =IF(AND(Q20=0,COUNTIF(dDuplicadosGI!$A$2:$A$60,C20)>0),1,0) -> 1 | AA20: =IF(Q20=0,1,0) -> 1
A21: 20 | B21: LogiFlow | C21: TIE0019 | D21: Portal de aplicaciones para la gestión y administracion de procesos del Banco. | E21: C - BIA Crítica | F21: On Premise | G21: ACTIVOS | H21: LAURA ELIZABETH CARRASCO UQUILLAS | I21: ANDREA FERNANDA ORTIZ CISNEROS | J21: ERISLAN MARTINEZ JERA | K21: Aplicación del negocio | L21: Si | M21: 45200 | N21: N/A ENTREGADA | O21: =IF(COUNTIFS($B$2:B21,B21,$C$2:C21,C21)=1,1,0) -> 1 | P21: =IFERROR(INDEX(dEtapa!$A$2:$A$6,MATCH(N21,dEtapa!$B$2:$B$6,0)),"Sin etapa") -> Gobernada | Q21: =IF(L21="Si",1,0) -> 1 | R21: =IF(ISNUMBER(SEARCH("CRITERIO",N21)),1,0) -> 0 | S21: =IF(E21="","Sin dato",LEFT(E21,1)) -> C | T21: =IFERROR(INDEX(dCriticidad!$G$2:$G$7,MATCH(S21,dCriticidad!$A$2:$A$7,0)),0) -> 1 | U21: =IF(OR(LEFT(C21,3)="GI0",LEFT(C21,3)="GA0"),1,0) -> 0 | V21: =IF(G21="","Sin dato (ID GI)",TRIM(G21)) -> ACTIVOS | W21: =IF(F21="","Sin dato",F21) -> On Premise | X21: =IF(M21="","",YEAR(M21)) -> 2023 | Y21: =IF(M21="","",DATE(YEAR(M21),MONTH(M21),1)) -> 45200 | Z21: =IF(AND(Q21=0,COUNTIF(dDuplicadosGI!$A$2:$A$60,C21)>0),1,0) -> 0 | AA21: =IF(Q21=0,1,0) -> 0
A22: 21 | B22: LoginCentral | C22: SEC0028 | D22: Aplicación que reemplaza al Portal Empresarial respecto al tema de ingreso a las aplicaciones portalizadas, por esta aplicación permite el logueo a todas las aplicaciones portalizadas que dispone BP, el Login Central consume el serbvicio de WsConexioLdap, pose conexión con una BD de datos BD_TALOS y consume servicios del Process Server. | E22: B - Ecosistema Apetito de Riesgo | F22: On Premise | G22: Tribu Ciberseguridad | H22: JUAN FELIPE GALLEGO COSSIO | I22: FRANCISCO DAVID CEVALLOS GRANJA | J22: ROBERTO CARLOS PINO CEDENO | K22: Aplicación del negocio | L22: Si | M22: 45200 | N22: N/A ENTREGADA | O22: =IF(COUNTIFS($B$2:B22,B22,$C$2:C22,C22)=1,1,0) -> 1 | P22: =IFERROR(INDEX(dEtapa!$A$2:$A$6,MATCH(N22,dEtapa!$B$2:$B$6,0)),"Sin etapa") -> Gobernada | Q22: =IF(L22="Si",1,0) -> 1 | R22: =IF(ISNUMBER(SEARCH("CRITERIO",N22)),1,0) -> 0 | S22: =IF(E22="","Sin dato",LEFT(E22,1)) -> B | T22: =IFERROR(INDEX(dCriticidad!$G$2:$G$7,MATCH(S22,dCriticidad!$A$2:$A$7,0)),0) -> 1 | U22: =IF(OR(LEFT(C22,3)="GI0",LEFT(C22,3)="GA0"),1,0) -> 0 | V22: =IF(G22="","Sin dato (ID GI)",TRIM(G22)) -> Tribu Ciberseguridad | W22: =IF(F22="","Sin dato",F22) -> On Premise | X22: =IF(M22="","",YEAR(M22)) -> 2023 | Y22: =IF(M22="","",DATE(YEAR(M22),MONTH(M22),1)) -> 45200 | Z22: =IF(AND(Q22=0,COUNTIF(dDuplicadosGI!$A$2:$A$60,C22)>0),1,0) -> 0 | AA22: =IF(Q22=0,1,0) -> 0
A23: 22 | B23: Logística de Efectivo | C23: CHL0001 | D23: Aplicación que permite controlar el pedido de remesas de efectivo desde las agencias a los centros de acopio. Permite administrar en forma adecuada el proceso de Gestión de Logística de Efectivo y Valorados, desde el registro de la recepción de la solicitud, procesamiento, envío y contabilización de remesas en los centros de acopio, ATM¿s, agencias o sucursales y Banco Central. | E23: C - BIA Crítica | F23: On Premise | G23: AREAS_DE_APOYO | H23: FABIAN GEOVANNI PAZMINO UBIDIA | I23: PRISCILA ALEXANDRA PARRA LEON | J23: PRISCILA ALEXANDRA PARRA LEON | K23: Aplicación del negocio | L23: Si | M23: 45199 | N23: N/A ENTREGADA | O23: =IF(COUNTIFS($B$2:B23,B23,$C$2:C23,C23)=1,1,0) -> 1 | P23: =IFERROR(INDEX(dEtapa!$A$2:$A$6,MATCH(N23,dEtapa!$B$2:$B$6,0)),"Sin etapa") -> Gobernada | Q23: =IF(L23="Si",1,0) -> 1 | R23: =IF(ISNUMBER(SEARCH("CRITERIO",N23)),1,0) -> 0 | S23: =IF(E23="","Sin dato",LEFT(E23,1)) -> C | T23: =IFERROR(INDEX(dCriticidad!$G$2:$G$7,MATCH(S23,dCriticidad!$A$2:$A$7,0)),0) -> 1 | U23: =IF(OR(LEFT(C23,3)="GI0",LEFT(C23,3)="GA0"),1,0) -> 0 | V23: =IF(G23="","Sin dato (ID GI)",TRIM(G23)) -> AREAS_DE_APOYO | W23: =IF(F23="","Sin dato",F23) -> On Premise | X23: =IF(M23="","",YEAR(M23)) -> 2023 | Y23: =IF(M23="","",DATE(YEAR(M23),MONTH(M23),1)) -> 45170 | Z23: =IF(AND(Q23=0,COUNTIF(dDuplicadosGI!$A$2:$A$60,C23)>0),1,0) -> 0 | AA23: =IF(Q23=0,1,0) -> 0
A24: 23 | B24: Mail Control System | C24: SUP0012 | D24: Aplicación utilizada por el área Administrativa para gestionar el proceso de entrega y recepción de correspondencia interna. | E24: E - No Crítica | F24: Nube | G24: AREAS_DE_APOYO | H24: FABIAN GEOVANNI PAZMINO UBIDIA | I24: LIZETH AURORA ENCALADA RAMON | J24: ABRAHAM JOSUE MOGOLLON VASQUEZ | K24: Aplicación del negocio | L24: No | N24: PRIORIZACIÓN CRITERIO 1 | O24: =IF(COUNTIFS($B$2:B24,B24,$C$2:C24,C24)=1,1,0) -> 1 | P24: =IFERROR(INDEX(dEtapa!$A$2:$A$6,MATCH(N24,dEtapa!$B$2:$B$6,0)),"Sin etapa") -> Criterio 1 | Q24: =IF(L24="Si",1,0) -> 0 | R24: =IF(ISNUMBER(SEARCH("CRITERIO",N24)),1,0) -> 1 | S24: =IF(E24="","Sin dato",LEFT(E24,1)) -> E | T24: =IFERROR(INDEX(dCriticidad!$G$2:$G$7,MATCH(S24,dCriticidad!$A$2:$A$7,0)),0) -> 0 | U24: =IF(OR(LEFT(C24,3)="GI0",LEFT(C24,3)="GA0"),1,0) -> 0 | V24: =IF(G24="","Sin dato (ID GI)",TRIM(G24)) -> AREAS_DE_APOYO | W24: =IF(F24="","Sin dato",F24) -> Nube | X24: =IF(M24="","",YEAR(M24)) | Y24: =IF(M24="","",DATE(YEAR(M24),MONTH(M24),1)) | Z24: =IF(AND(Q24=0,COUNTIF(dDuplicadosGI!$A$2:$A$60,C24)>0),1,0) -> 1 | AA24: =IF(Q24=0,1,0) -> 1
A25: 24 | B25: MatiBOT | C25: ITM0075 | D25: Brindar a los usuarios la capacidad de realizar solicitudes a través de una interfaz de chat en diversos canales conversacionales, como Microsoft Teams, Web Chat o WhatsApp. | E25: E - No Crítica | F25: Nube | G25: Gerencia Arquitectura Usuario Final | H25: FAYOL SMITH MONTANO MELENDEZ | I25: ABNER ANDY AREVALO BRACAMONTE | J25: CARMEN ROCIO AGUILAR MAYANQUER | K25: Aplicación complementaria | L25: No | N25: PLANIFICADA 2027 | O25: =IF(COUNTIFS($B$2:B25,B25,$C$2:C25,C25)=1,1,0) -> 1 | P25: =IFERROR(INDEX(dEtapa!$A$2:$A$6,MATCH(N25,dEtapa!$B$2:$B$6,0)),"Sin etapa") -> Planificada 2027 | Q25: =IF(L25="Si",1,0) -> 0 | R25: =IF(ISNUMBER(SEARCH("CRITERIO",N25)),1,0) -> 0 | S25: =IF(E25="","Sin dato",LEFT(E25,1)) -> E | T25: =IFERROR(INDEX(dCriticidad!$G$2:$G$7,MATCH(S25,dCriticidad!$A$2:$A$7,0)),0) -> 0 | U25: =IF(OR(LEFT(C25,3)="GI0",LEFT(C25,3)="GA0"),1,0) -> 0 | V25: =IF(G25="","Sin dato (ID GI)",TRIM(G25)) -> Gerencia Arquitectura Usuario Final | W25: =IF(F25="","Sin dato",F25) -> Nube | X25: =IF(M25="","",YEAR(M25)) | Y25: =IF(M25="","",DATE(YEAR(M25),MONTH(M25),1)) | Z25: =IF(AND(Q25=0,COUNTIF(dDuplicadosGI!$A$2:$A$60,C25)>0),1,0) -> 0 | AA25: =IF(Q25=0,1,0) -> 1
A26: 25 | B26: Maze | C26: EDC0006 | D26: Herramienta de pruebas con usuarios de prototipos y encuestas masivas moderadas y no moderadas. | E26: E - No Crítica | F26: Nube | G26: COE Experiencia | H26: ANTONIO ALEJANDRO CANAVERAL GIL | I26: GABRIEL ANDRES PACHECO TELLO | J26: GABRIEL ANDRES PACHECO TELLO | K26: Utilitario | L26: No | N26: PLANIFICADA 2027 | O26: =IF(COUNTIFS($B$2:B26,B26,$C$2:C26,C26)=1,1,0) -> 1 | P26: =IFERROR(INDEX(dEtapa!$A$2:$A$6,MATCH(N26,dEtapa!$B$2:$B$6,0)),"Sin etapa") -> Planificada 2027 | Q26: =IF(L26="Si",1,0) -> 0 | R26: =IF(ISNUMBER(SEARCH("CRITERIO",N26)),1,0) -> 0 | S26: =IF(E26="","Sin dato",LEFT(E26,1)) -> E | T26: =IFERROR(INDEX(dCriticidad!$G$2:$G$7,MATCH(S26,dCriticidad!$A$2:$A$7,0)),0) -> 0 | U26: =IF(OR(LEFT(C26,3)="GI0",LEFT(C26,3)="GA0"),1,0) -> 0 | V26: =IF(G26="","Sin dato (ID GI)",TRIM(G26)) -> COE Experiencia | W26: =IF(F26="","Sin dato",F26) -> Nube | X26: =IF(M26="","",YEAR(M26)) | Y26: =IF(M26="","",DATE(YEAR(M26),MONTH(M26),1)) | Z26: =IF(AND(Q26=0,COUNTIF(dDuplicadosGI!$A$2:$A$60,C26)>0),1,0) -> 0 | AA26: =IF(Q26=0,1,0) -> 1
A27: 26 | B27: Mi Portal (4u) | C27: SUP0013 | D27: Es una aplicación web desarrollada en Angular y Node JS con base de datos postgres y se encuentra alojada en la nube de Google Cloud. En esta aplicación se disponibiliza para la autogestión del colaborador en temas internos | E27: D - BIA No Crítica | F27: Nube | G27: AREAS_DE_APOYO | H27: FABIAN GEOVANNI PAZMINO UBIDIA | I27: ANDREA PAULINA PARDO ULLAGUARI | J27: FRANKLIN STALIN GARZON ANDRADE | K27: Aplicación complementaria | L27: No | N27: PLANIFICADA 2027 | O27: =IF(COUNTIFS($B$2:B27,B27,$C$2:C27,C27)=1,1,0) -> 1 | P27: =IFERROR(INDEX(dEtapa!$A$2:$A$6,MATCH(N27,dEtapa!$B$2:$B$6,0)),"Sin etapa") -> Planificada 2027 | Q27: =IF(L27="Si",1,0) -> 0 | R27: =IF(ISNUMBER(SEARCH("CRITERIO",N27)),1,0) -> 0 | S27: =IF(E27="","Sin dato",LEFT(E27,1)) -> D | T27: =IFERROR(INDEX(dCriticidad!$G$2:$G$7,MATCH(S27,dCriticidad!$A$2:$A$7,0)),0) -> 0 | U27: =IF(OR(LEFT(C27,3)="GI0",LEFT(C27,3)="GA0"),1,0) -> 0 | V27: =IF(G27="","Sin dato (ID GI)",TRIM(G27)) -> AREAS_DE_APOYO | W27: =IF(F27="","Sin dato",F27) -> Nube | X27: =IF(M27="","",YEAR(M27)) | Y27: =IF(M27="","",DATE(YEAR(M27),MONTH(M27),1)) | Z27: =IF(AND(Q27=0,COUNTIF(dDuplicadosGI!$A$2:$A$60,C27)>0),1,0) -> 0 | AA27: =IF(Q27=0,1,0) -> 1
A28: 27 | B28: Microcrédito Digital | C28: PRD0053 | D28: Aplicativo para Microcredito en Linea de Microfinanzas | E28: E - No Crítica | F28: Nube | G28: MICROFINANZAS | H28: EUDOCIA BEATRIZ VASQUEZ CASTILLO | I28: LAURA ELIZABETH CARRASCO UQUILLAS | J28: ERISLAN MARTINEZ JERA | K28: Aplicación del negocio | L28: No | N28: PLANIFICADA 2027 | O28: =IF(COUNTIFS($B$2:B28,B28,$C$2:C28,C28)=1,1,0) -> 1 | P28: =IFERROR(INDEX(dEtapa!$A$2:$A$6,MATCH(N28,dEtapa!$B$2:$B$6,0)),"Sin etapa") -> Planificada 2027 | Q28: =IF(L28="Si",1,0) -> 0 | R28: =IF(ISNUMBER(SEARCH("CRITERIO",N28)),1,0) -> 0 | S28: =IF(E28="","Sin dato",LEFT(E28,1)) -> E | T28: =IFERROR(INDEX(dCriticidad!$G$2:$G$7,MATCH(S28,dCriticidad!$A$2:$A$7,0)),0) -> 0 | U28: =IF(OR(LEFT(C28,3)="GI0",LEFT(C28,3)="GA0"),1,0) -> 0 | V28: =IF(G28="","Sin dato (ID GI)",TRIM(G28)) -> MICROFINANZAS | W28: =IF(F28="","Sin dato",F28) -> Nube | X28: =IF(M28="","",YEAR(M28)) | Y28: =IF(M28="","",DATE(YEAR(M28),MONTH(M28),1)) | Z28: =IF(AND(Q28=0,COUNTIF(dDuplicadosGI!$A$2:$A$60,C28)>0),1,0) -> 0 | AA28: =IF(Q28=0,1,0) -> 1
A29: 28 | B29: Microfinance Portal | C29: PRD0063 | D29: Aplicativo para la aprobación, instrumentación y desembolso de créditos de la metodología Microfinanzas Individual y Grupal | E29: E - No Crítica | F29: Nube | G29: MICROFINANZAS | H29: LAURA ELIZABETH CARRASCO UQUILLAS | I29: FREDDY NEY BASTIDAS CALERO | J29: Willam Marcel Ontaneda Yaguana | K29: Aplicación del negocio | L29: No | N29: PRIORIZACIÓN CRITERIO 1 | O29: =IF(COUNTIFS($B$2:B29,B29,$C$2:C29,C29)=1,1,0) -> 1 | P29: =IFERROR(INDEX(dEtapa!$A$2:$A$6,MATCH(N29,dEtapa!$B$2:$B$6,0)),"Sin etapa") -> Criterio 1 | Q29: =IF(L29="Si",1,0) -> 0 | R29: =IF(ISNUMBER(SEARCH("CRITERIO",N29)),1,0) -> 1 | S29: =IF(E29="","Sin dato",LEFT(E29,1)) -> E | T29: =IFERROR(INDEX(dCriticidad!$G$2:$G$7,MATCH(S29,dCriticidad!$A$2:$A$7,0)),0) -> 0 | U29: =IF(OR(LEFT(C29,3)="GI0",LEFT(C29,3)="GA0"),1,0) -> 0 | V29: =IF(G29="","Sin dato (ID GI)",TRIM(G29)) -> MICROFINANZAS | W29: =IF(F29="","Sin dato",F29) -> Nube | X29: =IF(M29="","",YEAR(M29)) | Y29: =IF(M29="","",DATE(YEAR(M29),MONTH(M29),1)) | Z29: =IF(AND(Q29=0,COUNTIF(dDuplicadosGI!$A$2:$A$60,C29)>0),1,0) -> 0 | AA29: =IF(Q29=0,1,0) -> 1
A30: 29 | B30: Mis Riesgos | C30: RIS0008 | D30: Agrupación lógica de las aplicaciones internas desarrolladas por Banco, que no cuentan con un ambiente controlado, Banco realiza cambios directos y sus actualizaciones no sigue el proceso de control de cambios. | E30: E - No Crítica | F30: On Premise | G30: Tribu Administración de Créditos | H30: JORGE MARIO PULGARIN MAZO | I30: JOHANNA NATALIA RODRIGUEZ SANCHEZ | J30: CHRISTIAN PAUL ENRIQUEZ LOPEZ | K30: Aplicación del negocio | L30: No | N30: PRIORIZACIÓN CRITERIO 1 | O30: =IF(COUNTIFS($B$2:B30,B30,$C$2:C30,C30)=1,1,0) -> 1 | P30: =IFERROR(INDEX(dEtapa!$A$2:$A$6,MATCH(N30,dEtapa!$B$2:$B$6,0)),"Sin etapa") -> Criterio 1 | Q30: =IF(L30="Si",1,0) -> 0 | R30: =IF(ISNUMBER(SEARCH("CRITERIO",N30)),1,0) -> 1 | S30: =IF(E30="","Sin dato",LEFT(E30,1)) -> E | T30: =IFERROR(INDEX(dCriticidad!$G$2:$G$7,MATCH(S30,dCriticidad!$A$2:$A$7,0)),0) -> 0 | U30: =IF(OR(LEFT(C30,3)="GI0",LEFT(C30,3)="GA0"),1,0) -> 0 | V30: =IF(G30="","Sin dato (ID GI)",TRIM(G30)) -> Tribu Administración de Créditos | W30: =IF(F30="","Sin dato",F30) -> On Premise | X30: =IF(M30="","",YEAR(M30)) | Y30: =IF(M30="","",DATE(YEAR(M30),MONTH(M30),1)) | Z30: =IF(AND(Q30=0,COUNTIF(dDuplicadosGI!$A$2:$A$60,C30)>0),1,0) -> 0 | AA30: =IF(Q30=0,1,0) -> 1
A31: 30 | B31: MODELO PREDICTIVO CIIU | C31: DAT0006 | D31: Modelo de Sector y Actividad Económica | E31: E - No Crítica | F31: On Premise | G31: COE DATOS&ANALITICA | H31: ARNALDO UTRIA AZAN | I31: ARNALDO UTRIA AZAN | J31: ARNALDO UTRIA AZAN | K31: Aplicación complementaria | L31: No | N31: PLANIFICADA 2027 | O31: =IF(COUNTIFS($B$2:B31,B31,$C$2:C31,C31)=1,1,0) -> 1 | P31: =IFERROR(INDEX(dEtapa!$A$2:$A$6,MATCH(N31,dEtapa!$B$2:$B$6,0)),"Sin etapa") -> Planificada 2027 | Q31: =IF(L31="Si",1,0) -> 0 | R31: =IF(ISNUMBER(SEARCH("CRITERIO",N31)),1,0) -> 0 | S31: =IF(E31="","Sin dato",LEFT(E31,1)) -> E | T31: =IFERROR(INDEX(dCriticidad!$G$2:$G$7,MATCH(S31,dCriticidad!$A$2:$A$7,0)),0) -> 0 | U31: =IF(OR(LEFT(C31,3)="GI0",LEFT(C31,3)="GA0"),1,0) -> 0 | V31: =IF(G31="","Sin dato (ID GI)",TRIM(G31)) -> COE DATOS&ANALITICA | W31: =IF(F31="","Sin dato",F31) -> On Premise | X31: =IF(M31="","",YEAR(M31)) | Y31: =IF(M31="","",DATE(YEAR(M31),MONTH(M31),1)) | Z31: =IF(AND(Q31=0,COUNTIF(dDuplicadosGI!$A$2:$A$60,C31)>0),1,0) -> 0 | AA31: =IF(Q31=0,1,0) -> 1
A32: 31 | B32: Moengage | C32: OMN0001 | D32: Es una plataforma de compromiso del cliente y automatización de marketing que ayuda a las empresas a interactuar con sus usuarios a través de canales como notificaciones push, mensajes dentro de la aplicación, correos electrónicos, mensajes de texto (SMS) y más | E32: B - Ecosistema Apetito de Riesgo | F32: Nube | G32: INFRAESTRUCTURA | H32: BYRON ORLANDO MELENDREZ CABRERA | I32: CESAR ALEJANDRO VELASCO TORO | J32: HORACIO LEONEL HOLGUIN ALCIVAR | K32: Aplicación complementaria | L32: No | N32: PRIORIZACIÓN CRITERIO 1 | O32: =IF(COUNTIFS($B$2:B32,B32,$C$2:C32,C32)=1,1,0) -> 1 | P32: =IFERROR(INDEX(dEtapa!$A$2:$A$6,MATCH(N32,dEtapa!$B$2:$B$6,0)),"Sin etapa") -> Criterio 1 | Q32: =IF(L32="Si",1,0) -> 0 | R32: =IF(ISNUMBER(SEARCH("CRITERIO",N32)),1,0) -> 1 | S32: =IF(E32="","Sin dato",LEFT(E32,1)) -> B | T32: =IFERROR(INDEX(dCriticidad!$G$2:$G$7,MATCH(S32,dCriticidad!$A$2:$A$7,0)),0) -> 1 | U32: =IF(OR(LEFT(C32,3)="GI0",LEFT(C32,3)="GA0"),1,0) -> 0 | V32: =IF(G32="","Sin dato (ID GI)",TRIM(G32)) -> INFRAESTRUCTURA | W32: =IF(F32="","Sin dato",F32) -> Nube | X32: =IF(M32="","",YEAR(M32)) | Y32: =IF(M32="","",DATE(YEAR(M32),MONTH(M32),1)) | Z32: =IF(AND(Q32=0,COUNTIF(dDuplicadosGI!$A$2:$A$60,C32)>0),1,0) -> 0 | AA32: =IF(Q32=0,1,0) -> 1
A33: 32 | B33: Monitor Plus | C33: GOB0005 | D33: Aplicación que permite realizar el monitoreo de las transacciones de clientes para identificación de lavado de dinero y fraude, es de tercero (nombre proveedor plus Holding) implementado en datacenter de Banco. | E33: E - No Crítica | F33: Híbrida | G33: AREAS_DE_APOYO | H33: FABIAN GEOVANNI PAZMINO UBIDIA | I33: JOSE LUIS ZAPATA ROSERO | J33: FERNANDO JOSE ROLDAN CORREA | K33: Aplicación complementaria | L33: No | N33: PRIORIZACIÓN CRITERIO 1 | O33: =IF(COUNTIFS($B$2:B33,B33,$C$2:C33,C33)=1,1,0) -> 1 | P33: =IFERROR(INDEX(dEtapa!$A$2:$A$6,MATCH(N33,dEtapa!$B$2:$B$6,0)),"Sin etapa") -> Criterio 1 | Q33: =IF(L33="Si",1,0) -> 0 | R33: =IF(ISNUMBER(SEARCH("CRITERIO",N33)),1,0) -> 1 | S33: =IF(E33="","Sin dato",LEFT(E33,1)) -> E | T33: =IFERROR(INDEX(dCriticidad!$G$2:$G$7,MATCH(S33,dCriticidad!$A$2:$A$7,0)),0) -> 0 | U33: =IF(OR(LEFT(C33,3)="GI0",LEFT(C33,3)="GA0"),1,0) -> 0 | V33: =IF(G33="","Sin dato (ID GI)",TRIM(G33)) -> AREAS_DE_APOYO | W33: =IF(F33="","Sin dato",F33) -> Híbrida | X33: =IF(M33="","",YEAR(M33)) | Y33: =IF(M33="","",DATE(YEAR(M33),MONTH(M33),1)) | Z33: =IF(AND(Q33=0,COUNTIF(dDuplicadosGI!$A$2:$A$60,C33)>0),1,0) -> 0 | AA33: =IF(Q33=0,1,0) -> 1
A34: 33 | B34: CreditoDistribuidor | C34: PRD0014 | D34: Aplicación web en la Intranet que genera créditos a pequeñas y medianas empresas que se encuentran afiliadas a Banco Pichincha. Se manejan créditos a proveedores y distribuidores basados en una empresa mayorista o ancla, en el caso de créditos a proveedores se deposita en la cuenta de la empresa directamente afiliada a BP y en el caso de créditos a proveedores en la cuenta del proveedor de la empresa afiliada a Banco Pichincha. | E34: D - BIA No Crítica | F34: On Premise | G34: Frente de Soluciones Empresariales | H34: LUIS MIGUEL ULLOA MOREIRA | I34: FABRICIO ANTONIO PEREIRA GARCIA | J34: WILLIAM PATRICIO PANCHI SHUGULI | K34: Aplicación del negocio | L34: Si | M34: 45199 | N34: N/A ENTREGADA | O34: =IF(COUNTIFS($B$2:B34,B34,$C$2:C34,C34)=1,1,0) -> 1 | P34: =IFERROR(INDEX(dEtapa!$A$2:$A$6,MATCH(N34,dEtapa!$B$2:$B$6,0)),"Sin etapa") -> Gobernada | Q34: =IF(L34="Si",1,0) -> 1 | R34: =IF(ISNUMBER(SEARCH("CRITERIO",N34)),1,0) -> 0 | S34: =IF(E34="","Sin dato",LEFT(E34,1)) -> D | T34: =IFERROR(INDEX(dCriticidad!$G$2:$G$7,MATCH(S34,dCriticidad!$A$2:$A$7,0)),0) -> 0 | U34: =IF(OR(LEFT(C34,3)="GI0",LEFT(C34,3)="GA0"),1,0) -> 0 | V34: =IF(G34="","Sin dato (ID GI)",TRIM(G34)) -> Frente de Soluciones Empresariales | W34: =IF(F34="","Sin dato",F34) -> On Premise | X34: =IF(M34="","",YEAR(M34)) -> 2023 | Y34: =IF(M34="","",DATE(YEAR(M34),MONTH(M34),1)) -> 45170 | Z34: =IF(AND(Q34=0,COUNTIF(dDuplicadosGI!$A$2:$A$60,C34)>0),1,0) -> 0 | AA34: =IF(Q34=0,1,0) -> 0
A35: 34 | B35: CreditosCOM | C35: PRD0015 | D35: Aplicación que maneja el flujo de créditos para Crédito Distribuidor. | E35: D - BIA No Crítica | F35: On Premise | G35: ACTIVOS | H35: LAURA ELIZABETH CARRASCO UQUILLAS | I35: ANDREA FERNANDA ORTIZ CISNEROS | J35: ERISLAN MARTINEZ JERA | K35: Aplicación del negocio | L35: Si | M35: 45199 | N35: N/A ENTREGADA | O35: =IF(COUNTIFS($B$2:B35,B35,$C$2:C35,C35)=1,1,0) -> 1 | P35: =IFERROR(INDEX(dEtapa!$A$2:$A$6,MATCH(N35,dEtapa!$B$2:$B$6,0)),"Sin etapa") -> Gobernada | Q35: =IF(L35="Si",1,0) -> 1 | R35: =IF(ISNUMBER(SEARCH("CRITERIO",N35)),1,0) -> 0 | S35: =IF(E35="","Sin dato",LEFT(E35,1)) -> D | T35: =IFERROR(INDEX(dCriticidad!$G$2:$G$7,MATCH(S35,dCriticidad!$A$2:$A$7,0)),0) -> 0 | U35: =IF(OR(LEFT(C35,3)="GI0",LEFT(C35,3)="GA0"),1,0) -> 0 | V35: =IF(G35="","Sin dato (ID GI)",TRIM(G35)) -> ACTIVOS | W35: =IF(F35="","Sin dato",F35) -> On Premise | X35: =IF(M35="","",YEAR(M35)) -> 2023 | Y35: =IF(M35="","",DATE(YEAR(M35),MONTH(M35),1)) -> 45170 | Z35: =IF(AND(Q35=0,COUNTIF(dDuplicadosGI!$A$2:$A$60,C35)>0),1,0) -> 0 | AA35: =IF(Q35=0,1,0) -> 0
A36: 35 | B36: CRM (salesforce - Financial services) | C36: CUS0007 | D36: No existe descripción | E36: C - BIA Crítica | F36: Nube | G36: Negocios y Monetización | H36: ANTONIO ALEJANDRO CANAVERAL GIL | I36: JULIEN LOUIS ADRIEN LEREBOULLET | J36: HECTOR EDUARDO JARAMILLO RUALES | K36: Aplicación del negocio | L36: Si | M36: 45200 | N36: N/A ENTREGADA | O36: =IF(COUNTIFS($B$2:B36,B36,$C$2:C36,C36)=1,1,0) -> 1 | P36: =IFERROR(INDEX(dEtapa!$A$2:$A$6,MATCH(N36,dEtapa!$B$2:$B$6,0)),"Sin etapa") -> Gobernada | Q36: =IF(L36="Si",1,0) -> 1 | R36: =IF(ISNUMBER(SEARCH("CRITERIO",N36)),1,0) -> 0 | S36: =IF(E36="","Sin dato",LEFT(E36,1)) -> C | T36: =IFERROR(INDEX(dCriticidad!$G$2:$G$7,MATCH(S36,dCriticidad!$A$2:$A$7,0)),0) -> 1 | U36: =IF(OR(LEFT(C36,3)="GI0",LEFT(C36,3)="GA0"),1,0) -> 0 | V36: =IF(G36="","Sin dato (ID GI)",TRIM(G36)) -> Negocios y Monetización | W36: =IF(F36="","Sin dato",F36) -> Nube | X36: =IF(M36="","",YEAR(M36)) -> 2023 | Y36: =IF(M36="","",DATE(YEAR(M36),MONTH(M36),1)) -> 45200 | Z36: =IF(AND(Q36=0,COUNTIF(dDuplicadosGI!$A$2:$A$60,C36)>0),1,0) -> 0 | AA36: =IF(Q36=0,1,0) -> 0
A37: 36 | B37: CRM (salesforce - Marketing Cloud) | C37: CUS0008 | D37: Es una plataforma de automatización de marketing digital en la nube, parte del ecosistema CRM de Salesforce, diseñada para gestionar campañas multicanal (email, móvil, redes sociales, web). | E37: E - No Crítica | F37: Nube | G37: Negocios y Monetización | H37: ANTONIO ALEJANDRO CANAVERAL GIL | I37: SEBASTIAN MUNOZ ANDERSEN | J37: HECTOR EDUARDO JARAMILLO RUALES | K37: Aplicación del negocio | L37: Si | M37: 46052 | N37: N/A ENTREGADA | O37: =IF(COUNTIFS($B$2:B37,B37,$C$2:C37,C37)=1,1,0) -> 1 | P37: =IFERROR(INDEX(dEtapa!$A$2:$A$6,MATCH(N37,dEtapa!$B$2:$B$6,0)),"Sin etapa") -> Gobernada | Q37: =IF(L37="Si",1,0) -> 1 | R37: =IF(ISNUMBER(SEARCH("CRITERIO",N37)),1,0) -> 0 | S37: =IF(E37="","Sin dato",LEFT(E37,1)) -> E | T37: =IFERROR(INDEX(dCriticidad!$G$2:$G$7,MATCH(S37,dCriticidad!$A$2:$A$7,0)),0) -> 0 | U37: =IF(OR(LEFT(C37,3)="GI0",LEFT(C37,3)="GA0"),1,0) -> 0 | V37: =IF(G37="","Sin dato (ID GI)",TRIM(G37)) -> Negocios y Monetización | W37: =IF(F37="","Sin dato",F37) -> Nube | X37: =IF(M37="","",YEAR(M37)) -> 2026 | Y37: =IF(M37="","",DATE(YEAR(M37),MONTH(M37),1)) -> 46023 | Z37: =IF(AND(Q37=0,COUNTIF(dDuplicadosGI!$A$2:$A$60,C37)>0),1,0) -> 0 | AA37: =IF(Q37=0,1,0) -> 0
A38: 37 | B38: Crowdstrike | C38: SEC0009 | D38: Ofrece una prevención de amenazas óptima, mediante el uso de inteligencia artificial (AI) y aprendizaje automático (ML) con detección y respuesta avanzada e información sobre amenazas, integrada a través de una consola de gestión altamente intuitiva. | E38: C - BIA Crítica | F38: Nube | G38: Ciberseguridad | H38: ERICK DAMIAN RISUENO BENITEZ | I38: MARCO FABRICIO FALCONI NORIEGA | J38: lvtandaz@pichincha.com TANDAZO GALLEGOS | K38: Consolas de Administración Seguridad | L38: Si | M38: 45715 | N38: N/A ENTREGADA | O38: =IF(COUNTIFS($B$2:B38,B38,$C$2:C38,C38)=1,1,0) -> 1 | P38: =IFERROR(INDEX(dEtapa!$A$2:$A$6,MATCH(N38,dEtapa!$B$2:$B$6,0)),"Sin etapa") -> Gobernada | Q38: =IF(L38="Si",1,0) -> 1 | R38: =IF(ISNUMBER(SEARCH("CRITERIO",N38)),1,0) -> 0 | S38: =IF(E38="","Sin dato",LEFT(E38,1)) -> C | T38: =IFERROR(INDEX(dCriticidad!$G$2:$G$7,MATCH(S38,dCriticidad!$A$2:$A$7,0)),0) -> 1 | U38: =IF(OR(LEFT(C38,3)="GI0",LEFT(C38,3)="GA0"),1,0) -> 0 | V38: =IF(G38="","Sin dato (ID GI)",TRIM(G38)) -> Ciberseguridad | W38: =IF(F38="","Sin dato",F38) -> Nube | X38: =IF(M38="","",YEAR(M38)) -> 2025 | Y38: =IF(M38="","",DATE(YEAR(M38),MONTH(M38),1)) -> 45689 | Z38: =IF(AND(Q38=0,COUNTIF(dDuplicadosGI!$A$2:$A$60,C38)>0),1,0) -> 0 | AA38: =IF(Q38=0,1,0) -> 0
A39: 38 | B39: Cuadre Atms | C39: SUP0021 | D39: Aplicación que dispone de procesos para cuadre de cajeros automáticos (cuadre físico vs reporte del Switch de Servicios ATMs) y conciliación de transacciones en ATMs propios (clientes BP y clientes de otras redes). | E39: C - BIA Crítica | F39: On Premise | G39: TRIBU_CANALES | H39: MIGUEL ALEXANDER MEJIA BRONCANO | I39: MILTON PATRICIO MANTILLA CAYO | J39: JUAN FRANCISCO PROCEL MICHILENA | K39: Aplicación del negocio | L39: Si | M39: 45199 | N39: N/A ENTREGADA | O39: =IF(COUNTIFS($B$2:B39,B39,$C$2:C39,C39)=1,1,0) -> 1 | P39: =IFERROR(INDEX(dEtapa!$A$2:$A$6,MATCH(N39,dEtapa!$B$2:$B$6,0)),"Sin etapa") -> Gobernada | Q39: =IF(L39="Si",1,0) -> 1 | R39: =IF(ISNUMBER(SEARCH("CRITERIO",N39)),1,0) -> 0 | S39: =IF(E39="","Sin dato",LEFT(E39,1)) -> C | T39: =IFERROR(INDEX(dCriticidad!$G$2:$G$7,MATCH(S39,dCriticidad!$A$2:$A$7,0)),0) -> 1 | U39: =IF(OR(LEFT(C39,3)="GI0",LEFT(C39,3)="GA0"),1,0) -> 0 | V39: =IF(G39="","Sin dato (ID GI)",TRIM(G39)) -> TRIBU_CANALES | W39: =IF(F39="","Sin dato",F39) -> On Premise | X39: =IF(M39="","",YEAR(M39)) -> 2023 | Y39: =IF(M39="","",DATE(YEAR(M39),MONTH(M39),1)) -> 45170 | Z39: =IF(AND(Q39=0,COUNTIF(dDuplicadosGI!$A$2:$A$60,C39)>0),1,0) -> 0 | AA39: =IF(Q39=0,1,0) -> 0
A40: 39 | B40: Cuenta Digital Personas | C40: CHL0037 | D40: APP ONBOARDING, aplicación movil de Banco Pichincha, en la que podrá crear clientes, activar cuentas, crear chequeras. | E40: C - BIA Crítica | F40: Nube | G40: PASIVOS Y SEGUROS | H40: LAURA ELIZABETH CARRASCO UQUILLAS | I40: JONATHAN HERNAN ARIAS HERNANDEZ | J40: MANUEL ABELARDO HARO MONTERO | K40: Aplicación complementaria | L40: No | N40: PLANIFICADA 2027 | O40: =IF(COUNTIFS($B$2:B40,B40,$C$2:C40,C40)=1,1,0) -> 1 | P40: =IFERROR(INDEX(dEtapa!$A$2:$A$6,MATCH(N40,dEtapa!$B$2:$B$6,0)),"Sin etapa") -> Planificada 2027 | Q40: =IF(L40="Si",1,0) -> 0 | R40: =IF(ISNUMBER(SEARCH("CRITERIO",N40)),1,0) -> 0 | S40: =IF(E40="","Sin dato",LEFT(E40,1)) -> C | T40: =IFERROR(INDEX(dCriticidad!$G$2:$G$7,MATCH(S40,dCriticidad!$A$2:$A$7,0)),0) -> 1 | U40: =IF(OR(LEFT(C40,3)="GI0",LEFT(C40,3)="GA0"),1,0) -> 0 | V40: =IF(G40="","Sin dato (ID GI)",TRIM(G40)) -> PASIVOS Y SEGUROS | W40: =IF(F40="","Sin dato",F40) -> Nube | X40: =IF(M40="","",YEAR(M40)) | Y40: =IF(M40="","",DATE(YEAR(M40),MONTH(M40),1)) | Z40: =IF(AND(Q40=0,COUNTIF(dDuplicadosGI!$A$2:$A$60,C40)>0),1,0) -> 0 | AA40: =IF(Q40=0,1,0) -> 1
...

Sheet Validacion
A1: Validación: KPIs con fórmulas vs. valor publicado en el PDF (corte 17-sep-2026)
A2: Si cambia la matriz o los parámetros, la diferencia deja de ser 0 y es lo esperado.
A4: Métrica | B4: Valor (fórmula) | C4: Valor PDF | D4: Control | E4: Medida DAX | F4: Página
A5: Universo (CMDB + ajustes) | B5: =SUM(dConciliacion!$C$2:$C$6) -> 417 | C5: 417 | D5: =IF(ABS(B5-C5)<=0.5,"OK",B5-C5) -> OK | E5: [Universo] | F5: 1
A6: CMDB | B6: =SUMIFS(dConciliacion!$C$2:$C$7,dConciliacion!$D$2:$D$7,"Base") -> 331 | C6: 331 | D6: =IF(ABS(B6-C6)<=0.5,"OK",B6-C6) -> OK | E6: [CMDB] | F6: 2
A7: Filas en la matriz | B7: =COUNTA(fAplicaciones!$A$2:$A$414) -> 413 | C7: 413 | D7: =IF(ABS(B7-C7)<=0.5,"OK",B7-C7) -> OK | E7: [Filas Matriz] | F7: 2
A8: Aplicaciones únicas | B8: =SUM(fAplicaciones!$O$2:$O$414) -> 410 | C8: 410 | D8: =IF(ABS(B8-C8)<=0.5,"OK",B8-C8) -> OK | E8: [Aplicaciones Unicas] | F8: 2
A9: Sin fila en la matriz | B9: =B5-B8 -> 7 | C9: 7 | D9: =IF(ABS(B9-C9)<=0.5,"OK",B9-C9) -> OK | E9: [Sin Fila en Matriz] | F9: 2
A10: Gobernadas | B10: =SUMIFS(fAplicaciones!$O$2:$O$414,fAplicaciones!$Q$2:$Q$414,1) -> 188 | C10: 188 | D10: =IF(ABS(B10-C10)<=0.5,"OK",B10-C10) -> OK | E10: [Gobernadas] | F10: 1
A11: % gobernadas sobre universo | B11: =B10/B5 -> 0.45083933 | C11: 0.45 | D11: =IF(ABS(B11-C11)<=0.005,"OK",B11-C11) -> OK | E11: [% Gobernadas Universo] | F11: 1
A12: Brecha a la meta | B12: =MAX(0,Meta-B10) -> 44 | C12: 44 | D12: =IF(ABS(B12-C12)<=0.5,"OK",B12-C12) -> OK | E12: [Brecha Meta] | F12: 1
A13: Criterio 1 | B13: =COUNTIFS(fAplicaciones!$P$2:$P$414,"Criterio 1",fAplicaciones!$O$2:$O$414,1) -> 22 | C13: 22 | D13: =IF(ABS(B13-C13)<=0.5,"OK",B13-C13) -> OK | E13: [Criterio 1] | F13: 1
A14: Criterio 2 | B14: =COUNTIFS(fAplicaciones!$P$2:$P$414,"Criterio 2",fAplicaciones!$O$2:$O$414,1) -> 27 | C14: 27 | D14: =IF(ABS(B14-C14)<=0.5,"OK",B14-C14) -> OK | E14: [Criterio 2] | F14: 1
A15: Criterio 3 | B15: =COUNTIFS(fAplicaciones!$P$2:$P$414,"Criterio 3",fAplicaciones!$O$2:$O$414,1) -> 14 | C15: 14 | D15: =IF(ABS(B15-C15)<=0.5,"OK",B15-C15) -> OK | E15: [Criterio 3] | F15: 1
A16: Planificadas 2027 | B16: =COUNTIFS(fAplicaciones!$P$2:$P$414,"Planificada 2027",fAplicaciones!$O$2:$O$414,1) -> 159 | C16: 159 | D16: =IF(ABS(B16-C16)<=0.5,"OK",B16-C16) -> OK | E16: [Planificadas 2027] | F16: 1
A17: Recibidas en el año de corte | B17: =COUNTIFS(fAplicaciones!$Q$2:$Q$414,1,fAplicaciones!$O$2:$O$414,1,fAplicaciones!$M$2:$M$414,">="&DATE(YEAR(FechaCorte),1,1),fAplicaciones!$M$2:$M$414,"<="&FechaCorte) -> 42 | C17: 42 | D17: =IF(ABS(B17-C17)<=0.5,"OK",B17-C17) -> OK | E17: [Recibidas Anio] | F17: 1
A18: Ritmo mensual | B18: =B17/((FechaCorte-DATE(YEAR(FechaCorte),1,1))/DiasMes) -> 4.9297297 | C18: 4.9 | D18: =IF(ABS(B18-C18)<=0.05,"OK",B18-C18) -> OK | E18: [Ritmo Mensual] | F18: 1
A19: Meses restantes | B19: =(FinAnio-FechaCorte)/DiasMes -> 3.4539474 | C19: 3.5 | D19: =IF(ABS(B19-C19)<=0.05,"OK",B19-C19) -> OK | E19: [Meses Restantes] | F19: 1
A20: Ritmo requerido | B20: =B12/B19 -> 12.739048 | C20: 12.7 | D20: =IF(ABS(B20-C20)<=0.05,"OK",B20-C20) -> OK | E20: [Ritmo Requerido] | F20: 1
A21: Multiplicador de ritmo | B21: =B20/B18 -> 2.584127 | C21: 2.6 | D21: =IF(ABS(B21-C21)<=0.05,"OK",B21-C21) -> OK | E21: [Multiplicador Ritmo] | F21: 1
A22: Proyección a fin de año | B22: =B10+B18*B19 -> 205.02703 | C22: 205 | D22: =IF(ABS(B22-C22)<=0.5,"OK",B22-C22) -> OK | E22: [Proyeccion Fin Anio] | F22: 1
A23: % gobernadas sobre CMDB | B23: =B10/B6 -> 0.56797583 | C23: 0.57 | D23: =IF(ABS(B23-C23)<=0.005,"OK",B23-C23) -> OK | E23: [% Gobernadas sobre CMDB] | F23: 2
A24: % informe sobre CMDB | B24: =GobernadasInforme/B6 -> 0.53172205 | C24: 0.53 | D24: =IF(ABS(B24-C24)<=0.005,"OK",B24-C24) -> OK | E24: [% Informe sobre CMDB] | F24: 2
A25: % informe sobre universo | B25: =GobernadasInforme/B5 -> 0.42206235 | C25: 0.42 | D25: =IF(ABS(B25-C25)<=0.005,"OK",B25-C25) -> OK | E25: [% Informe sobre Universo] | F25: 2
A26: Gobernadas con ID GI | B26: =COUNTIFS(fAplicaciones!$Q$2:$Q$414,1,fAplicaciones!$O$2:$O$414,1,fAplicaciones!$U$2:$U$414,1) -> 41 | C26: 41 | D26: =IF(ABS(B26-C26)<=0.5,"OK",B26-C26) -> OK | E26: [Gobernadas ID GI] | F26: 2
A27: Críticas (A, B, C) | B27: =COUNTIFS(fAplicaciones!$T$2:$T$414,1,fAplicaciones!$O$2:$O$414,1) -> 136 | C27: 136 | D27: =IF(ABS(B27-C27)<=0.5,"OK",B27-C27) -> OK | E27: [Criticas] | F27: 3
A28: Críticas gobernadas | B28: =COUNTIFS(fAplicaciones!$T$2:$T$414,1,fAplicaciones!$O$2:$O$414,1,fAplicaciones!$Q$2:$Q$414,1) -> 83 | C28: 83 | D28: =IF(ABS(B28-C28)<=0.5,"OK",B28-C28) -> OK | E28: [Criticas Gobernadas] | F28: 3
A29: Críticas planificadas 2027 | B29: =COUNTIFS(fAplicaciones!$T$2:$T$414,1,fAplicaciones!$O$2:$O$414,1,fAplicaciones!$P$2:$P$414,"Planificada 2027") -> 21 | C29: 21 | D29: =IF(ABS(B29-C29)<=0.5,"OK",B29-C29) -> OK | E29: [Criticas 2027] | F29: 3
A30: Criterio 1 de baja criticidad (D, E) | B30: =COUNTIFS(fAplicaciones!$P$2:$P$414,"Criterio 1",fAplicaciones!$O$2:$O$414,1,fAplicaciones!$S$2:$S$414,"D")+COUNTIFS(fAplicaciones!$P$2:$P$414,"Criterio 1",fAplicaciones!$O$2:$O$414,1,fAplicaciones!$S$2:$S$414,"E") -> 15 | C30: 15 | D30: =IF(ABS(B30-C30)<=0.5,"OK",B30-C30) -> OK | E30: [Criterio 1 Baja Criticidad] | F30: 3
A31: Criterio 2 críticas | B31: =COUNTIFS(fAplicaciones!$P$2:$P$414,"Criterio 2",fAplicaciones!$O$2:$O$414,1,fAplicaciones!$T$2:$T$414,1) -> 25 | C31: 25 | D31: =IF(ABS(B31-C31)<=0.5,"OK",B31-C31) -> OK | E31: [Criterio 2 Criticas] | F31: 3
A32: Posibles duplicados GI | B32: =SUMIFS(fAplicaciones!$Z$2:$Z$414,fAplicaciones!$O$2:$O$414,1) -> 4 | C32: 4 | D32: =IF(ABS(B32-C32)<=0.5,"OK",B32-C32) -> OK | E32: [Posibles Duplicados GI] | F32: 4
A35: Etapa por criticidad (página 3)
A36: Criticidad | B36: Gobernada | C36: Criterio 1 | D36: Criterio 2 | E36: Criterio 3 | F36: Planificada 2027 | G36: Total | H36: % gobernadas
A37: A | B37: =COUNTIFS(fAplicaciones!$S$2:$S$414,$A37,fAplicaciones!$P$2:$P$414,"Gobernada",fAplicaciones!$O$2:$O$414,1) -> 10 | C37: =COUNTIFS(fAplicaciones!$S$2:$S$414,$A37,fAplicaciones!$P$2:$P$414,"Criterio 1",fAplicaciones!$O$2:$O$414,1) -> 0 | D37: =COUNTIFS(fAplicaciones!$S$2:$S$414,$A37,fAplicaciones!$P$2:$P$414,"Criterio 2",fAplicaciones!$O$2:$O$414,1) -> 1 | E37: =COUNTIFS(fAplicaciones!$S$2:$S$414,$A37,fAplicaciones!$P$2:$P$414,"Criterio 3",fAplicaciones!$O$2:$O$414,1) -> 0 | F37: =COUNTIFS(fAplicaciones!$S$2:$S$414,$A37,fAplicaciones!$P$2:$P$414,"Planificada 2027",fAplicaciones!$O$2:$O$414,1) -> 7 | G37: =SUM(B37:F37) -> 18 | H37: =IFERROR(B37/G37,0) -> 0.55555556
A38: B | B38: =COUNTIFS(fAplicaciones!$S$2:$S$414,$A38,fAplicaciones!$P$2:$P$414,"Gobernada",fAplicaciones!$O$2:$O$414,1) -> 28 | C38: =COUNTIFS(fAplicaciones!$S$2:$S$414,$A38,fAplicaciones!$P$2:$P$414,"Criterio 1",fAplicaciones!$O$2:$O$414,1) -> 5 | D38: =COUNTIFS(fAplicaciones!$S$2:$S$414,$A38,fAplicaciones!$P$2:$P$414,"Criterio 2",fAplicaciones!$O$2:$O$414,1) -> 15 | E38: =COUNTIFS(fAplicaciones!$S$2:$S$414,$A38,fAplicaciones!$P$2:$P$414,"Criterio 3",fAplicaciones!$O$2:$O$414,1) -> 0 | F38: =COUNTIFS(fAplicaciones!$S$2:$S$414,$A38,fAplicaciones!$P$2:$P$414,"Planificada 2027",fAplicaciones!$O$2:$O$414,1) -> 6 | G38: =SUM(B38:F38) -> 54 | H38: =IFERROR(B38/G38,0) -> 0.51851852
A39: C | B39: =COUNTIFS(fAplicaciones!$S$2:$S$414,$A39,fAplicaciones!$P$2:$P$414,"Gobernada",fAplicaciones!$O$2:$O$414,1) -> 45 | C39: =COUNTIFS(fAplicaciones!$S$2:$S$414,$A39,fAplicaciones!$P$2:$P$414,"Criterio 1",fAplicaciones!$O$2:$O$414,1) -> 2 | D39: =COUNTIFS(fAplicaciones!$S$2:$S$414,$A39,fAplicaciones!$P$2:$P$414,"Criterio 2",fAplicaciones!$O$2:$O$414,1) -> 9 | E39: =COUNTIFS(fAplicaciones!$S$2:$S$414,$A39,fAplicaciones!$P$2:$P$414,"Criterio 3",fAplicaciones!$O$2:$O$414,1) -> 0 | F39: =COUNTIFS(fAplicaciones!$S$2:$S$414,$A39,fAplicaciones!$P$2:$P$414,"Planificada 2027",fAplicaciones!$O$2:$O$414,1) -> 8 | G39: =SUM(B39:F39) -> 64 | H39: =IFERROR(B39/G39,0) -> 0.703125
A40: D | B40: =COUNTIFS(fAplicaciones!$S$2:$S$414,$A40,fAplicaciones!$P$2:$P$414,"Gobernada",fAplicaciones!$O$2:$O$414,1) -> 7 | C40: =COUNTIFS(fAplicaciones!$S$2:$S$414,$A40,fAplicaciones!$P$2:$P$414,"Criterio 1",fAplicaciones!$O$2:$O$414,1) -> 1 | D40: =COUNTIFS(fAplicaciones!$S$2:$S$414,$A40,fAplicaciones!$P$2:$P$414,"Criterio 2",fAplicaciones!$O$2:$O$414,1) -> 0 | E40: =COUNTIFS(fAplicaciones!$S$2:$S$414,$A40,fAplicaciones!$P$2:$P$414,"Criterio 3",fAplicaciones!$O$2:$O$414,1) -> 0 | F40: =COUNTIFS(fAplicaciones!$S$2:$S$414,$A40,fAplicaciones!$P$2:$P$414,"Planificada 2027",fAplicaciones!$O$2:$O$414,1) -> 16 | G40: =SUM(B40:F40) -> 24 | H40: =IFERROR(B40/G40,0) -> 0.29166667
